File: 20.12.09/1Layer_12.is_flex_RawData/Specimen_RawData_1.csv
Specimen properties : Thickness,"4.20000",mm
Specimen properties : Width,"8.50000",mm
Specimen properties : Support span,"67.20000",mm

Time,Extension,Load
(s),(mm),(kgf)
"0.00000","0.00000","-0.00436"
"0.20000","0.01125","0.00246"
"0.40000","0.02505","0.00932"
"0.60000","0.03812","0.01404"
"0.80000","0.05225","0.01902"
"1.00000","0.06506","0.02369"
"1.20000","0.07897","0.02872"
"1.40000","0.09180","0.03318"
"1.60000","0.10509","0.03742"
"1.80000","0.11869","0.04236"
"2.00000","0.13207","0.04636"
"2.20000","0.14503","0.05073"
"2.40000","0.15888","0.05517"
"2.60000","0.17164","0.05893"
"2.80000","0.18592","0.06353"
"3.00000","0.19830","0.06729"
"3.20000","0.21200","0.07152"
"3.40000","0.22536","0.07494"
"3.60000","0.23858","0.07880"
"3.80000","0.25198","0.08272"
"4.00000","0.26513","0.08615"
"4.20000","0.27870","0.08998"
"4.40000","0.29245","0.09343"
"4.60000","0.30500","0.09674"
"4.80000","0.31874","0.10018"
"5.00000","0.33187","0.10374"
"5.20000","0.34554","0.10742"
"5.40000","0.35874","0.11055"
"5.60000","0.37159","0.11364"
"5.80000","0.38556","0.11672"
"6.00000","0.39853","0.12028"
"6.20000","0.41203","0.12380"
"6.40000","0.42521","0.12666"
"6.60000","0.43841","0.12971"
"6.80000","0.45228","0.13334"
"7.00000","0.46531","0.13604"
"7.20000","0.47825","0.13912"
"7.40000","0.49215","0.14221"
"7.60000","0.50504","0.14517"
"7.80000","0.51903","0.14843"
"8.00000","0.53152","0.15115"
"8.20000","0.54552","0.15440"
"8.40000","0.55869","0.15689"
"8.60000","0.57192","0.16026"
"8.80000","0.58517","0.16330"
"9.00000","0.59856","0.16593"
"9.20000","0.61188","0.16880"
"9.40000","0.62577","0.17145"
"9.60000","0.63807","0.17391"
"9.80000","0.65238","0.17727"
"10.00000","0.66511","0.17986"
"10.20000","0.67887","0.18275"
"10.40000","0.69179","0.18546"
"10.60000","0.70514","0.18846"
"10.80000","0.71856","0.19067"
"11.00000","0.73199","0.19361"
"11.20000","0.74511","0.19583"
"11.40000","0.75889","0.19896"
"11.60000","0.77160","0.20147"
"11.80000","0.78578","0.20419"
"12.00000","0.79840","0.20664"
"12.20000","0.81202","0.20935"
"12.40000","0.82537","0.21170"
"12.60000","0.83858","0.21444"
"12.80000","0.85200","0.21682"
"13.00000","0.86507","0.21927"
"13.20000","0.87873","0.22211"
"13.40000","0.89236","0.22392"
"13.60000","0.90503","0.22649"
"13.80000","0.91873","0.22916"
"14.00000","0.93198","0.23140"
"14.20000","0.94558","0.23426"
"14.40000","0.95877","0.23609"
"14.60000","0.97151","0.23836"
"14.80000","0.98552","0.24069"
"15.00000","0.99870","0.24306"
"15.20000","1.01210","0.24570"
"15.40000","1.02520","0.24757"
"15.60000","1.03838","0.25014"
"15.80000","1.05231","0.25261"
"16.00000","1.06530","0.25426"
"16.20000","1.07824","0.25658"
"16.40000","1.09219","0.25888"
"16.60000","1.10506","0.26094"
"16.80000","1.11905","0.26288"
"17.00000","1.13150","0.26486"
"17.20000","1.14551","0.26744"
"17.40000","1.15866","0.26951"
"17.60000","1.17197","0.27148"
"17.80000","1.18515","0.27330"
"18.00000","1.19851","0.27567"
"18.20000","1.21193","0.27753"
"18.40000","1.22582","0.27994"
"18.60000","1.23815","0.28146"
"18.80000","1.25235","0.28387"
"19.00000","1.26506","0.28573"
"19.20000","1.27891","0.28764"
"19.40000","1.29186","0.28943"
"19.60000","1.30514","0.29139"
"19.80000","1.31865","0.29362"
"20.00000","1.33192","0.29531"
"20.20000","1.34509","0.29708"
"20.40000","1.35885","0.29934"
"20.60000","1.37163","0.30113"
"20.80000","1.38591","0.30291"
"21.00000","1.39830","0.30427"
"21.20000","1.41199","0.30662"
"21.40000","1.42538","0.30807"
"21.60000","1.43864","0.30987"
"21.80000","1.45207","0.31185"
"22.00000","1.46497","0.31317"
"22.20000","1.47866","0.31574"
"22.40000","1.49239","0.31739"
"22.60000","1.50503","0.31873"
"22.80000","1.51881","0.32047"
"23.00000","1.53182","0.32240"
"23.20000","1.54561","0.32385"
"23.40000","1.55877","0.32574"
"23.60000","1.57152","0.32706"
"23.80000","1.58558","0.32908"
"24.00000","1.59860","0.33031"
"24.20000","1.61201","0.33207"
"24.40000","1.62521","0.33348"
"24.60000","1.63845","0.33520"
"24.80000","1.65230","0.33711"
"25.00000","1.66533","0.33856"
"25.20000","1.67818","0.33966"
"25.40000","1.69214","0.34178"
"25.60000","1.70509","0.34292"
"25.80000","1.71905","0.34472"
"26.00000","1.73156","0.34600"
"26.20000","1.74552","0.34767"
"26.40000","1.75876","0.34918"
"26.60000","1.77192","0.35051"
"26.80000","1.78510","0.35210"
"27.00000","1.79858","0.35372"
"27.20000","1.81180","0.35502"
"27.40000","1.82575","0.35692"
"27.60000","1.83811","0.35814"
"27.80000","1.85235","0.35969"
"28.00000","1.86512","0.36105"
"28.20000","1.87890","0.36306"
"28.40000","1.89172","0.36422"
"28.60000","1.90514","0.36555"
"28.80000","1.91862","0.36738"
"29.00000","1.93200","0.36877"
"29.20000","1.94510","0.37010"
"29.40000","1.95883","0.37180"
"29.60000","1.97162","0.37287"
"29.80000","1.98580","0.37459"
"30.00000","1.99833","0.37573"
"30.20000","2.01211","0.37793"
"30.40000","2.02535","0.37887"
"30.60000","2.03856","0.38036"
"30.80000","2.05201","0.38164"
"31.00000","2.06506","0.38315"
"31.20000","2.07878","0.38489"
"31.40000","2.09241","0.38620"
"31.60000","2.10494","0.38710"
"31.80000","2.11880","0.38919"
"32.00000","2.13196","0.39005"
"32.20000","2.14559","0.39156"
"32.40000","2.15877","0.39246"
"32.60000","2.17157","0.39368"
"32.80000","2.18557","0.39522"
"33.00000","2.19856","0.39700"
"33.20000","2.21205","0.39783"
"33.40000","2.22530","0.39918"
"33.60000","2.23845","0.40000"
"33.80000","2.25225","0.40203"
"34.00000","2.26536","0.40302"
"34.20000","2.27831","0.40389"
"34.40000","2.29216","0.40567"
"34.60000","2.30509","0.40655"
"34.80000","2.31908","0.40785"
"35.00000","2.33149","0.40882"
"35.20000","2.34541","0.41012"
"35.40000","2.35869","0.41117"
"35.60000","2.37195","0.41298"
"35.80000","2.38525","0.41378"
"36.00000","2.39856","0.41472"
"36.20000","2.41190","0.41571"
"36.40000","2.42570","0.41740"
"36.60000","2.43816","0.41800"
"36.80000","2.45245","0.41966"
"37.00000","2.46497","0.42009"
"37.20000","2.47888","0.42160"
"37.40000","2.49189","0.42207"
"37.60000","2.50511","0.42335"
"37.80000","2.51871","0.42487"
"38.00000","2.53189","0.42584"
"38.20000","2.54507","0.42659"
"38.40000","2.55888","0.42823"
"38.60000","2.57162","0.42851"
"38.80000","2.58594","0.43034"
"39.00000","2.59834","0.43098"
"39.20000","2.61199","0.43201"
"39.40000","2.62542","0.43273"
"39.60000","2.63853","0.43374"
"39.80000","2.65216","0.43517"
"40.00000","2.66508","0.43597"
"40.20000","2.67863","0.43686"
"40.40000","2.69240","0.43799"
"40.60000","2.70503","0.43908"
"40.80000","2.71872","0.44012"
"41.00000","2.73182","0.44052"
"41.20000","2.74561","0.44181"
"41.40000","2.75881","0.44297"
"41.60000","2.77153","0.44362"
"41.80000","2.78560","0.44469"
"42.00000","2.79857","0.44602"
"42.20000","2.81206","0.44687"
"42.40000","2.82527","0.44770"
"42.60000","2.83834","0.44816"
"42.80000","2.85232","0.44965"
"43.00000","2.86529","0.45036"
"43.20000","2.87831","0.45119"
"43.40000","2.89224","0.45251"
"43.60000","2.90511","0.45285"
"43.80000","2.91907","0.45428"
"44.00000","2.93140","0.45487"
"44.20000","2.94546","0.45603"
"44.40000","2.95875","0.45665"
"44.60000","2.97190","0.45740"
"44.80000","2.98516","0.45824"
"45.00000","2.99847","0.45955"
"45.20000","3.01191","0.46032"
"45.40000","3.02565","0.46133"
"45.60000","3.03817","0.46200"
"45.80000","3.05236","0.46309"
"46.00000","3.06507","0.46346"
"46.20000","3.07887","0.46443"
"46.40000","3.09179","0.46552"
"46.60000","3.10510","0.46588"
"46.80000","3.11870","0.46705"
"47.00000","3.13188","0.46763"
"47.20000","3.14508","0.46823"
"47.40000","3.15879","0.46904"
"47.60000","3.17162","0.46993"
"47.80000","3.18595","0.47086"
"48.00000","3.19839","0.47156"
"48.20000","3.21201","0.47242"
"48.40000","3.22537","0.47288"
"48.60000","3.23857","0.47381"
"48.80000","3.25200","0.47477"
"49.00000","3.26521","0.47526"
"49.20000","3.27860","0.47608"
"49.40000","3.29237","0.47711"
"49.60000","3.30500","0.47773"
"49.80000","3.31878","0.47865"
"50.00000","3.33202","0.47908"
"50.20000","3.34562","0.48025"
"50.40000","3.35873","0.48069"
"50.60000","3.37160","0.48108"
"50.80000","3.38543","0.48245"
"51.00000","3.39875","0.48305"
"51.20000","3.41189","0.48375"
"51.40000","3.42516","0.48451"
"51.60000","3.43847","0.48501"
"51.80000","3.45212","0.48579"
"52.00000","3.46547","0.48697"
"52.20000","3.47826","0.48711"
"52.40000","3.49209","0.48789"
"52.60000","3.50519","0.48863"
"52.80000","3.51895","0.48956"
"53.00000","3.53167","0.48967"
"53.20000","3.54544","0.49057"
"53.40000","3.55859","0.49138"
"53.60000","3.57206","0.49183"
"53.80000","3.58516","0.49243"
"54.00000","3.59856","0.49340"
"54.20000","3.61192","0.49376"
"54.40000","3.62561","0.49508"
"54.60000","3.63820","0.49507"
"54.80000","3.65229","0.49591"
"55.00000","3.66511","0.49594"
"55.20000","3.67887","0.49728"
"55.40000","3.69174","0.49747"
"55.60000","3.70519","0.49817"
"55.80000","3.71857","0.49892"
"56.00000","3.73213","0.49985"
"56.20000","3.74509","0.49950"
"56.40000","3.75866","0.50046"
"56.60000","3.77173","0.50124"
"56.80000","3.78578","0.50177"
"57.00000","3.79848","0.50242"
"57.20000","3.81194","0.50276"
"57.40000","3.82529","0.50338"
"57.60000","3.83866","0.50408"
"57.80000","3.85194","0.50479"
"58.00000","3.86531","0.50557"
"58.20000","3.87866","0.50605"
"58.40000","3.89221","0.50679"
"58.60000","3.90514","0.50664"
"58.80000","3.91863","0.50776"
"59.00000","3.93203","0.50790"
"59.20000","3.94553","0.50893"
"59.40000","3.95872","0.50925"
"59.60000","3.97164","0.50959"
"59.80000","3.98549","0.51010"
"60.00000","3.99879","0.51056"
"60.20000","4.01199","0.51117"
"60.40000","4.02508","0.51220"
"60.60000","4.03854","0.51222"
"60.80000","4.05215","0.51316"
"61.00000","4.06550","0.51332"
"61.20000","4.07829","0.51376"
"61.40000","4.09205","0.51486"
"61.60000","4.10533","0.51513"
"61.80000","4.11898","0.51556"
"62.00000","4.13155","0.51564"
"62.20000","4.14545","0.51619"
"62.40000","4.15856","0.51664"
"62.60000","4.17209","0.51729"
"62.80000","4.18508","0.51741"
"63.00000","4.19871","0.51769"
"63.20000","4.21181","0.51807"
"63.40000","4.22562","0.51923"
"63.60000","4.23832","0.51907"
"63.80000","4.25227","0.51984"
"64.00000","4.26510","0.52011"
"64.20000","4.27887","0.52115"
"64.40000","4.29178","0.52126"
"64.60000","4.30514","0.52237"
"64.80000","4.31854","0.52269"
"65.00000","4.33213","0.52347"
"65.20000","4.34505","0.52330"
"65.40000","4.35866","0.52419"
"65.60000","4.37177","0.52489"
"65.80000","4.38567","0.52539"
"66.00000","4.39850","0.52548"
"66.20000","4.41195","0.52632"
"66.40000","4.42533","0.52688"
"66.60000","4.43868","0.52712"
"66.80000","4.45205","0.52779"
"67.00000","4.46518","0.52795"
"67.20000","4.47864","0.52832"
"67.40000","4.49234","0.52891"
"67.60000","4.50507","0.52893"
"67.80000","4.51870","0.52924"
"68.00000","4.53197","0.52970"
"68.20000","4.54559","0.53021"
"68.40000","4.55872","0.53030"
"68.60000","4.57158","0.53100"
"68.80000","4.58547","0.53127"
"69.00000","4.59860","0.53161"
"69.20000","4.61204","0.53230"
"69.40000","4.62510","0.53260"
"69.60000","4.63856","0.53266"
"69.80000","4.65219","0.53269"
"70.00000","4.66536","0.53312"
"70.20000","4.67823","0.53353"
"70.40000","4.69218","0.53393"
"70.60000","4.70513","0.53429"
"70.80000","4.71906","0.53495"
"71.00000","4.73152","0.53503"
"71.20000","4.74543","0.53541"
"71.40000","4.75865","0.53562"
"71.60000","4.77194","0.53623"
"71.80000","4.78515","0.53634"
"72.00000","4.79853","0.53651"
"72.20000","4.81194","0.53708"
"72.40000","4.82568","0.53750"
"72.60000","4.83814","0.53762"
"72.80000","4.85240","0.53848"
"73.00000","4.86504","0.53873"
"73.20000","4.87893","0.53922"
"73.40000","4.89182","0.53950"
"73.60000","4.90514","0.54003"
"73.80000","4.91871","0.53991"
"74.00000","4.93192","0.54015"
"74.20000","4.94510","0.54032"
"74.40000","4.95889","0.54124"
"74.60000","4.97159","0.54151"
"74.80000","4.98588","0.54212"
"75.00000","4.99834","0.54186"
"75.20000","5.01203","0.54231"
"75.40000","5.02539","0.54230"
"75.60000","5.03855","0.54296"
"75.80000","5.05201","0.54305"
"76.00000","5.06514","0.54382"
"76.20000","5.07867","0.54457"
"76.40000","5.09233","0.54452"
"76.60000","5.10505","0.54499"
"76.80000","5.11873","0.54530"
"77.00000","5.13198","0.54549"
"77.20000","5.14567","0.54605"
"77.40000","5.15871","0.54581"
"77.60000","5.17163","0.54609"
"77.80000","5.18554","0.54674"
"78.00000","5.19858","0.54658"
"78.20000","5.21208","0.54702"
"78.40000","5.22519","0.54773"
"78.60000","5.23839","0.54772"
"78.80000","5.25225","0.54825"
"79.00000","5.26540","0.54856"
"79.20000","5.27829","0.54920"
"79.40000","5.29212","0.54932"
"79.60000","5.30519","0.54919"
"79.80000","5.31894","0.54960"
"80.00000","5.33165","0.54952"
"80.20000","5.34550","0.54994"
"80.40000","5.35856","0.54984"
"80.60000","5.37204","0.55004"
"80.80000","5.38519","0.55083"
"81.00000","5.39865","0.55104"
"81.20000","5.41184","0.55121"
"81.40000","5.42571","0.55118"
"81.60000","5.43817","0.55153"
"81.80000","5.45229","0.55233"
"82.00000","5.46515","0.55217"
"82.20000","5.47890","0.55249"
"82.40000","5.49176","0.55291"
"82.60000","5.50514","0.55353"
"82.80000","5.51860","0.55350"
"83.00000","5.53203","0.55357"
"83.20000","5.54512","0.55390"
"83.40000","5.55877","0.55443"
"83.60000","5.57159","0.55490"
"83.80000","5.58586","0.55534"
"84.00000","5.59832","0.55504"
"84.20000","5.61211","0.55563"
"84.40000","5.62532","0.55564"
"84.60000","5.63857","0.55583"
"84.80000","5.65197","0.55623"
"85.00000","5.66513","0.55635"
"85.20000","5.67857","0.55700"
"85.40000","5.69235","0.55722"
"85.60000","5.70500","0.55732"
"85.80000","5.71868","0.55780"
"86.00000","5.73195","0.55763"
"86.20000","5.74565","0.55799"
"86.40000","5.75874","0.55849"
"86.60000","5.77165","0.55856"
"86.80000","5.78549","0.55891"
"87.00000","5.79869","0.55866"
"87.20000","5.81207","0.55896"
"87.40000","5.82513","0.55895"
"87.60000","5.83840","0.55912"
"87.80000","5.85222","0.55940"
"88.00000","5.86538","0.55892"
"88.20000","5.87830","0.55920"
"88.40000","5.89211","0.55974"
"88.60000","5.90508","0.55979"
"88.80000","5.91908","0.56012"
"89.00000","5.93151","0.55995"
"89.20000","5.94554","0.56023"
"89.40000","5.95864","0.56021"
"89.60000","5.97193","0.56042"
"89.80000","5.98514","0.56010"
"90.00000","5.99862","0.56012"
"90.20000","6.01182","0.56060"
"90.40000","6.02571","0.56042"
"90.60000","6.03819","0.56039"
"90.80000","6.05233","0.56078"
"91.00000","6.06505","0.56051"
"91.20000","6.07892","0.56100"
"91.40000","6.09180","0.56040"
"91.60000","6.10510","0.56086"
"91.80000","6.11873","0.56107"
"92.00000","6.13206","0.56099"
"92.20000","6.14507","0.56111"
"92.40000","6.15883","0.56157"
"92.60000","6.17156","0.56100"
"92.80000","6.18587","0.56185"
"93.00000","6.19846","0.56141"
"93.20000","6.21203","0.56177"
"93.40000","6.22537","0.56178"
"93.60000","6.23855","0.56189"
"93.80000","6.25200","0.56164"
"94.00000","6.26512","0.56160"
"94.20000","6.27867","0.56231"
"94.40000","6.29238","0.56170"
"94.60000","6.30502","0.56187"
"94.80000","6.31878","0.56203"
"95.00000","6.33195","0.56147"
"95.20000","6.34560","0.56234"
"95.40000","6.35877","0.56204"
"95.60000","6.37151","0.56188"
"95.80000","6.38562","0.56207"
"96.00000","6.39852","0.56179"
"96.20000","6.41200","0.56185"
"96.40000","6.42515","0.56200"
"96.60000","6.43844","0.56174"
"96.80000","6.45223","0.56157"
"97.00000","6.46541","0.56094"
"97.20000","6.47824","0.56136"
"97.40000","6.49219","0.56057"
"97.60000","6.50508","0.56118"
"97.80000","6.51902","0.56114"
"98.00000","6.53158","0.56091"
"98.20000","6.54545","0.56115"
"98.40000","6.55873","0.56071"
"98.60000","6.57192","0.56070"
"98.80000","6.58513","0.56102"
"99.00000","6.59858","0.56065"
"99.20000","6.61183","0.55965"
"99.40000","6.62581","0.56044"
"99.60000","6.63818","0.56053"
"99.80000","6.65230","0.56035"
"100.00000","6.66499","0.56007"
"100.20000","6.67890","0.56035"
"100.40000","6.69183","0.55952"
"100.60000","6.70501","0.55935"
"100.80000","6.71875","0.55914"
"101.00000","6.73198","0.55902"
"101.20000","6.74505","0.55923"
"101.40000","6.75896","0.55956"
"101.60000","6.77161","0.55876"
"101.80000","6.78585","0.55938"
"102.00000","6.79836","0.55894"
"102.20000","6.81197","0.55907"
"102.40000","6.82544","0.55880"
"102.60000","6.83849","0.55864"
"102.80000","6.85204","0.55874"
"103.00000","6.86517","0.55796"
"103.20000","6.87864","0.55811"
"103.40000","6.89242","0.55773"
"103.60000","6.90502","0.55713"
"103.80000","6.91875","0.55700"
"104.00000","6.93187","0.55634"
"104.20000","6.94563","0.55657"
"104.40000","6.95878","0.55618"
"104.60000","6.97155","0.55525"
"104.80000","6.98559","0.55491"
"105.00000","6.99867","0.55476"
"105.20000","7.01203","0.55466"
"105.40000","7.02524","0.55431"
"105.60000","7.03847","0.55398"
"105.80000","7.05226","0.55383"
"106.00000","7.06530","0.55351"
"106.20000","7.07826","0.55277"
"106.40000","7.09220","0.55216"
"106.60000","7.10494","0.55203"
"106.80000","7.11908","0.55140"
"107.00000","7.13152","0.55006"
"107.20000","7.14541","0.54998"
"107.40000","7.15866","0.54862"
"107.60000","7.17192","0.54868"
"107.80000","7.18507","0.54757"
"108.00000","7.19859","0.54709"
"108.20000","7.21197","0.54697"
"108.40000","7.22577","0.54681"
"108.60000","7.23809","0.54526"
"108.80000","7.25239","0.54572"
"109.00000","7.26512","0.54509"
"109.20000","7.27895","0.54495"
"109.40000","7.29184","0.54392"
"109.60000","7.30503","0.54347"
"109.80000","7.31858","0.54291"
"110.00000","7.33199","0.54210"
"110.20000","7.34503","0.54153"
"110.40000","7.35895","0.54108"
"110.60000","7.37163","0.54067"
"110.80000","7.38589","0.54045"
"111.00000","7.39838","0.53989"
"111.20000","7.41199","0.53952"
"111.40000","7.42537","0.53919"
"111.60000","7.43856","0.53833"
"111.80000","7.45199","0.53812"
"112.00000","7.46514","0.53714"
"112.20000","7.47868","0.53702"
"112.40000","7.49235","0.53628"
"112.60000","7.50501","0.53522"
"112.80000","7.51867","0.53479"
"113.00000","7.53196","0.53325"
"113.20000","7.54570","0.53311"
"113.40000","7.55873","0.53167"
"113.60000","7.57158","0.53111"
"113.80000","7.58550","0.53047"
"114.00000","7.59864","0.52925"
"114.20000","7.61206","0.52887"
"114.40000","7.62521","0.52776"
"114.60000","7.63847","0.52713"
"114.80000","7.65219","0.52629"
"115.00000","7.66541","0.52471"
"115.20000","7.67830","0.52381"
"115.40000","7.69213","0.52275"
"115.60000","7.70508","0.52178"
"115.80000","7.71908","0.52037"
"116.00000","7.73156","0.51953"
"116.20000","7.74546","0.51874"
"116.40000","7.75868","0.51708"
"116.60000","7.77199","0.51573"
"116.80000","7.78513","0.51446"
"117.00000","7.79860","0.51268"
"117.20000","7.81189","0.51087"
"117.40000","7.82572","0.50889"
"117.60000","7.83816","0.50653"
"117.80000","7.85224","0.50515"
"118.00000","7.86507","0.50289"
"118.20000","7.87898","0.50186"
"118.40000","7.89184","0.49969"
"118.60000","7.90510","0.49840"
"118.80000","7.91868","0.49629"
"119.00000","7.93191","0.49447"
"119.20000","7.94508","0.49301"
"119.40000","7.95891","0.49157"
"119.60000","7.97156","0.49061"
"119.80000","7.98582","0.48940"
"120.00000","7.99833","0.48813"
"120.20000","8.01201","0.48707"
"120.40000","8.02538","0.48539"
"120.60000","8.03858","0.48383"
"120.80000","8.05198","0.48250"
"121.00000","8.06509","0.48091"
"121.20000","8.07862","0.47992"
"121.40000","8.09248","0.47870"
"121.60000","8.10503","0.47721"
"121.80000","8.11875","0.47624"
"122.00000","8.13192","0.47529"
"122.20000","8.14556","0.47467"
"122.40000","8.15881","0.47259"
"122.60000","8.17155","0.47162"
"122.80000","8.18559","0.47052"
"123.00000","8.19866","0.46915"
"123.20000","8.21205","0.46799"
"123.40000","8.22523","0.46697"
"123.60000","8.23845","0.46581"
"123.80000","8.25226","0.46514"
"124.00000","8.26531","0.46319"
"124.20000","8.27828","0.46251"
"124.40000","8.29221","0.46087"
"124.60000","8.30509","0.45988"
"124.80000","8.31904","0.45934"
"125.00000","8.33157","0.45785"
"125.20000","8.34541","0.45713"
"125.40000","8.35868","0.45589"
"125.60000","8.37191","0.45432"
"125.80000","8.38523","0.45330"
"126.00000","8.39854","0.45160"
"126.20000","8.41196","0.45068"
"126.40000","8.42573","0.44931"
"126.60000","8.43816","0.44754"
"126.80000","8.45228","0.44663"
"127.00000","8.46515","0.44548"
"127.20000","8.47889","0.44436"
"127.40000","8.49188","0.44300"
"127.60000","8.50513","0.44217"
"127.80000","8.51856","0.44145"
"128.00000","8.53199","0.44022"
"128.20000","8.54515","0.43909"
"128.40000","8.55877","0.43813"
"128.60000","8.57165","0.43716"
"128.80000","8.58579","0.43700"
"129.00000","8.59839","0.43453"
"129.20000","8.61199","0.43401"
"129.40000","8.62538","0.43279"
"129.60000","8.63857","0.43182"
"129.80000","8.65200","0.43014"
"130.00000","8.66516","0.42853"
"130.20000","8.67863","0.42696"
"130.40000","8.69243","0.42543"
"130.60000","8.70505","0.42333"
"130.80000","8.71863","0.42079"
"131.00000","8.73190","0.41918"
"131.20000","8.74554","0.41747"
"131.40000","8.75879","0.41466"
"131.60000","8.77157","0.41352"
"131.80000","8.78555","0.41138"
"132.00000","8.79863","0.40916"
"132.20000","8.81203","0.40730"
"132.40000","8.82529","0.40542"
"132.60000","8.83842","0.40345"
"132.80000","8.85219","0.40179"
"133.00000","8.86539","0.39924"
"133.20000","8.87830","0.39805"
"133.40000","8.89215","0.39604"
"133.60000","8.90511","0.39432"
"133.80000","8.91903","0.39242"
"134.00000","8.93149","0.38991"
"134.20000","8.94552","0.38821"
"134.40000","8.95876","0.38671"
"134.60000","8.97193","0.38431"
"134.80000","8.98512","0.38245"
"135.00000","8.99859","0.38057"
"135.20000","9.01192","0.37818"
"135.40000","9.02571","0.37649"
"135.60000","9.03811","0.37416"
"135.80000","9.05233","0.37225"
"136.00000","9.06504","0.36991"
"136.20000","9.07901","0.36868"
"136.40000","9.09180","0.36583"
"136.60000","9.10513","0.36450"
"136.80000","9.11869","0.36262"
"137.00000","9.13202","0.36105"
"137.20000","9.14513","0.35946"
"137.40000","9.15873","0.35802"
"137.60000","9.17161","0.35576"
"137.80000","9.18582","0.35433"
"138.00000","9.19832","0.35133"
"138.20000","9.21198","0.35021"
"138.40000","9.22541","0.34800"
"138.60000","9.23857","0.34634"
"138.80000","9.25210","0.34456"
"139.00000","9.26499","0.34236"
"139.20000","9.27868","0.34080"
"139.40000","9.29248","0.33938"
"139.60000","9.30499","0.33686"
"139.80000","9.31868","0.33529"
"140.00000","9.33195","0.33314"
"140.20000","9.34562","0.33189"
"140.40000","9.35880","0.32964"
"140.60000","9.37149","0.32807"
"140.80000","9.38554","0.32683"
"141.00000","9.39861","0.32457"
"141.20000","9.41199","0.32316"
"141.40000","9.42524","0.32142"
"141.60000","9.43841","0.31987"
"141.80000","9.45233","0.31812"
"142.00000","9.46528","0.31596"
"142.20000","9.47826","0.31432"
"142.40000","9.49222","0.31241"
"142.60000","9.50506","0.31073"
"142.80000","9.51907","0.30855"
"143.00000","9.53143","0.30666"
"143.20000","9.54550","0.30524"
"143.40000","9.55874","0.30302"
"143.60000","9.57193","0.30119"
"143.80000","9.58513","0.29852"
"144.00000","9.59851","0.29717"
"144.20000","9.61180","0.29569"
"144.40000","9.62584","0.29336"
"144.60000","9.63816","0.29128"
"144.80000","9.65233","0.29031"
"145.00000","9.66489","0.28779"
"145.20000","9.67900","0.28631"
"145.40000","9.69183","0.28357"
"145.60000","9.70510","0.28217"
"145.80000","9.71873","0.28043"
"146.00000","9.73194","0.27879"
"146.20000","9.74508","0.27794"
"146.40000","9.75886","0.27649"
"146.60000","9.77163","0.27426"
"146.80000","9.78599","0.27327"
"147.00000","9.79827","0.27095"
"147.20000","9.81203","0.27034"
"147.40000","9.82538","0.26818"
"147.60000","9.83854","0.26631"
"147.80000","9.85201","0.26490"
"148.00000","9.86503","0.26325"
"148.20000","9.87868","0.26224"
"148.40000","9.89240","0.26088"
"148.60000","9.90498","0.25926"
"148.80000","9.91879","0.25779"
"149.00000","9.93197","0.25615"
"149.20000","9.94561","0.25507"
"149.40000","9.95881","0.25311"
"149.60000","9.97151","0.25275"
"149.80000","9.98559","0.25104"
"150.00000","9.99860","0.24995"
"150.20000","10.01208","0.24889"
"150.40000","10.02516","0.24720"
"150.60000","10.03844","0.24554"
"150.80000","10.05218","0.24427"
"151.00000","10.06547","0.24260"
"151.20000","10.07833","0.24139"
"151.40000","10.09218","0.23991"
"151.60000","10.10500","0.23771"
"151.80000","10.11900","0.23572"
"152.00000","10.13166","0.23448"
"152.20000","10.14549","0.23268"
"152.40000","10.15864","0.23094"
"152.60000","10.17197","0.22926"
"152.80000","10.18505","0.22737"
"153.00000","10.19874","0.22586"
"153.20000","10.21188","0.22466"
"153.40000","10.22563","0.22319"
"153.60000","10.23813","0.22168"
"153.80000","10.25237","0.22015"
"154.00000","10.26527","0.21776"
"154.20000","10.27880","0.21613"
"154.40000","10.29174","0.21381"
"154.60000","10.30513","0.21216"
"154.80000","10.31864","0.20977"
"155.00000","10.33209","0.20827"
"155.20000","10.34511","0.20597"
"155.40000","10.35872","0.20265"
"155.60000","10.37158","0.20059"
"155.80000","10.38586","0.19775"
"156.00000","10.39848","0.19465"
"156.16400","10.40952","0.19274"