File: 20.12.09/1Layer_14.is_flex_RawData/Specimen_RawData_1.csv
Specimen properties : Thickness,"3.70000",mm
Specimen properties : Width,"13.00000",mm
Specimen properties : Support span,"59.20000",mm

Time,Extension,Load
(s),(mm),(kgf)
"0.00000","0.00000","-0.00843"
"0.20000","0.00569","-0.00606"
"0.40000","0.02472","0.00361"
"0.60000","0.03828","0.00973"
"0.80000","0.05232","0.01545"
"1.00000","0.06482","0.02028"
"1.20000","0.07879","0.02549"
"1.40000","0.09191","0.03033"
"1.60000","0.10535","0.03590"
"1.80000","0.11844","0.04044"
"2.00000","0.13174","0.04481"
"2.20000","0.14525","0.04931"
"2.40000","0.15894","0.05383"
"2.60000","0.17153","0.05783"
"2.80000","0.18564","0.06224"
"3.00000","0.19835","0.06622"
"3.20000","0.21235","0.07071"
"3.40000","0.22516","0.07386"
"3.60000","0.23854","0.07825"
"3.80000","0.25209","0.08165"
"4.00000","0.26521","0.08533"
"4.20000","0.27852","0.08882"
"4.40000","0.29213","0.09252"
"4.60000","0.30506","0.09584"
"4.80000","0.31909","0.09929"
"5.00000","0.33164","0.10245"
"5.20000","0.34548","0.10555"
"5.40000","0.35879","0.10872"
"5.60000","0.37195","0.11208"
"5.80000","0.38539","0.11474"
"6.00000","0.39821","0.11728"
"6.20000","0.41200","0.12069"
"6.40000","0.42561","0.12329"
"6.60000","0.43841","0.12594"
"6.80000","0.45210","0.12893"
"7.00000","0.46508","0.13132"
"7.20000","0.47898","0.13453"
"7.40000","0.49211","0.13671"
"7.60000","0.50491","0.13926"
"7.80000","0.51890","0.14235"
"8.00000","0.53186","0.14430"
"8.20000","0.54556","0.14709"
"8.40000","0.55848","0.14928"
"8.60000","0.57190","0.15176"
"8.80000","0.58558","0.15411"
"9.00000","0.59856","0.15601"
"9.20000","0.61179","0.15889"
"9.40000","0.62546","0.16113"
"9.60000","0.63850","0.16336"
"9.80000","0.65237","0.16587"
"10.00000","0.66474","0.16715"
"10.20000","0.67880","0.16984"
"10.40000","0.69195","0.17186"
"10.60000","0.70524","0.17413"
"10.80000","0.71849","0.17633"
"11.00000","0.73177","0.17884"
"11.20000","0.74527","0.18090"
"11.40000","0.75890","0.18352"
"11.60000","0.77156","0.18485"
"11.80000","0.78556","0.18728"
"12.00000","0.79837","0.18934"
"12.20000","0.81235","0.19182"
"12.40000","0.82519","0.19321"
"12.60000","0.83844","0.19555"
"12.80000","0.85208","0.19770"
"13.00000","0.86528","0.19992"
"13.20000","0.87855","0.20180"
"13.40000","0.89209","0.20364"
"13.60000","0.90503","0.20568"
"13.80000","0.91910","0.20791"
"14.00000","0.93171","0.20949"
"14.20000","0.94542","0.21143"
"14.40000","0.95868","0.21341"
"14.60000","0.97201","0.21559"
"14.80000","0.98534","0.21742"
"15.00000","0.99835","0.21921"
"15.20000","1.01201","0.22152"
"15.40000","1.02558","0.22321"
"15.60000","1.03843","0.22471"
"15.80000","1.05207","0.22665"
"16.00000","1.06518","0.22875"
"16.20000","1.07895","0.23036"
"16.40000","1.09210","0.23250"
"16.60000","1.10500","0.23430"
"16.80000","1.11889","0.23594"
"17.00000","1.13183","0.23755"
"17.20000","1.14554","0.23990"
"17.40000","1.15849","0.24132"
"17.60000","1.17193","0.24320"
"17.80000","1.18554","0.24526"
"18.00000","1.19859","0.24693"
"18.20000","1.21174","0.24825"
"18.40000","1.22545","0.25013"
"18.60000","1.23847","0.25230"
"18.80000","1.25247","0.25403"
"19.00000","1.26471","0.25486"
"19.20000","1.27886","0.25726"
"19.40000","1.29190","0.25876"
"19.60000","1.30534","0.26018"
"19.80000","1.31846","0.26252"
"20.00000","1.33177","0.26392"
"20.20000","1.34528","0.26545"
"20.40000","1.35888","0.26720"
"20.60000","1.37150","0.26827"
"20.80000","1.38555","0.27040"
"21.00000","1.39832","0.27164"
"21.20000","1.41236","0.27339"
"21.40000","1.42516","0.27446"
"21.60000","1.43842","0.27638"
"21.80000","1.45211","0.27807"
"22.00000","1.46520","0.27931"
"22.20000","1.47860","0.28061"
"22.40000","1.49212","0.28229"
"22.60000","1.50511","0.28391"
"22.80000","1.51911","0.28507"
"23.00000","1.53156","0.28625"
"23.20000","1.54548","0.28804"
"23.40000","1.55868","0.28953"
"23.60000","1.57193","0.29109"
"23.80000","1.58532","0.29226"
"24.00000","1.59830","0.29348"
"24.20000","1.61207","0.29539"
"24.40000","1.62560","0.29675"
"24.60000","1.63841","0.29741"
"24.80000","1.65215","0.29942"
"25.00000","1.66494","0.30051"
"25.20000","1.67899","0.30235"
"25.40000","1.69216","0.30335"
"25.60000","1.70493","0.30414"
"25.80000","1.71894","0.30632"
"26.00000","1.73182","0.30716"
"26.20000","1.74557","0.30891"
"26.40000","1.75848","0.30980"
"26.60000","1.77187","0.31077"
"26.80000","1.78561","0.31234"
"27.00000","1.79861","0.31357"
"27.20000","1.81181","0.31488"
"27.40000","1.82538","0.31623"
"27.60000","1.83853","0.31714"
"27.80000","1.85239","0.31877"
"28.00000","1.86476","0.31960"
"28.20000","1.87877","0.32152"
"28.40000","1.89203","0.32251"
"28.60000","1.90526","0.32384"
"28.80000","1.91845","0.32442"
"29.00000","1.93163","0.32595"
"29.20000","1.94529","0.32689"
"29.40000","1.95893","0.32814"
"29.60000","1.97154","0.32909"
"29.80000","1.98562","0.33079"
"30.00000","1.99832","0.33129"
"30.20000","2.01228","0.33260"
"30.40000","2.02519","0.33372"
"30.60000","2.03856","0.33438"
"30.80000","2.05211","0.33580"
"31.00000","2.06520","0.33676"
"31.20000","2.07855","0.33801"
"31.40000","2.09216","0.33928"
"31.60000","2.10506","0.33990"
"31.80000","2.11916","0.34136"
"32.00000","2.13170","0.34213"
"32.20000","2.14550","0.34332"
"32.40000","2.15872","0.34431"
"32.60000","2.17190","0.34507"
"32.80000","2.18536","0.34663"
"33.00000","2.19830","0.34700"
"33.20000","2.21193","0.34838"
"33.40000","2.22557","0.34968"
"33.60000","2.23841","0.35041"
"33.80000","2.25207","0.35116"
"34.00000","2.26512","0.35199"
"34.20000","2.27894","0.35371"
"34.40000","2.29204","0.35456"
"34.60000","2.30494","0.35543"
"34.80000","2.31888","0.35648"
"35.00000","2.33181","0.35723"
"35.20000","2.34560","0.35839"
"35.40000","2.35844","0.35907"
"35.60000","2.37188","0.36034"
"35.80000","2.38549","0.36156"
"36.00000","2.39866","0.36189"
"36.20000","2.41177","0.36298"
"36.40000","2.42552","0.36412"
"36.60000","2.43837","0.36487"
"36.80000","2.45247","0.36591"
"37.00000","2.46480","0.36651"
"37.20000","2.47877","0.36756"
"37.40000","2.49188","0.36869"
"37.60000","2.50537","0.36947"
"37.80000","2.51839","0.36995"
"38.00000","2.53181","0.37081"
"38.20000","2.54522","0.37186"
"38.40000","2.55887","0.37285"
"38.60000","2.57158","0.37323"
"38.80000","2.58547","0.37425"
"39.00000","2.59858","0.37507"
"39.20000","2.61230","0.37590"
"39.40000","2.62512","0.37725"
"39.60000","2.63853","0.37825"
"39.80000","2.65201","0.37885"
"40.00000","2.66536","0.37912"
"40.20000","2.67855","0.38000"
"40.40000","2.69196","0.38076"
"40.60000","2.70520","0.38164"
"40.80000","2.71902","0.38317"
"41.00000","2.73180","0.38339"
"41.20000","2.74536","0.38446"
"41.40000","2.75857","0.38488"
"41.60000","2.77206","0.38628"
"41.80000","2.78530","0.38647"
"42.00000","2.79847","0.38779"
"42.20000","2.81199","0.38835"
"42.40000","2.82552","0.38908"
"42.60000","2.83851","0.38974"
"42.80000","2.85189","0.39058"
"43.00000","2.86536","0.39114"
"43.20000","2.87888","0.39192"
"43.40000","2.89207","0.39282"
"43.60000","2.90508","0.39333"
"43.80000","2.91872","0.39384"
"44.00000","2.93204","0.39503"
"44.20000","2.94550","0.39550"
"44.40000","2.95836","0.39593"
"44.60000","2.97204","0.39689"
"44.80000","2.98544","0.39765"
"45.00000","2.99874","0.39817"
"45.20000","3.01170","0.39861"
"45.40000","3.02533","0.39974"
"45.60000","3.03862","0.40006"
"45.80000","3.05233","0.40064"
"46.00000","3.06491","0.40142"
"46.20000","3.07874","0.40199"
"46.40000","3.09187","0.40266"
"46.60000","3.10540","0.40351"
"46.80000","3.11836","0.40368"
"47.00000","3.13188","0.40436"
"47.20000","3.14518","0.40508"
"47.40000","3.15882","0.40562"
"47.60000","3.17166","0.40579"
"47.80000","3.18542","0.40693"
"48.00000","3.19859","0.40744"
"48.20000","3.21234","0.40850"
"48.40000","3.22508","0.40846"
"48.60000","3.23863","0.40907"
"48.80000","3.25198","0.40976"
"49.00000","3.26544","0.41015"
"49.20000","3.27855","0.41100"
"49.40000","3.29205","0.41107"
"49.60000","3.30510","0.41213"
"49.80000","3.31901","0.41259"
"50.00000","3.33181","0.41265"
"50.20000","3.34544","0.41359"
"50.40000","3.35866","0.41375"
"50.60000","3.37205","0.41442"
"50.80000","3.38530","0.41480"
"51.00000","3.39840","0.41496"
"51.20000","3.41192","0.41573"
"51.40000","3.42546","0.41673"
"51.60000","3.43847","0.41667"
"51.80000","3.45197","0.41744"
"52.00000","3.46517","0.41755"
"52.20000","3.47898","0.41888"
"52.40000","3.49202","0.41857"
"52.60000","3.50503","0.41925"
"52.80000","3.51876","0.41976"
"53.00000","3.53195","0.42017"
"53.20000","3.54554","0.42046"
"53.40000","3.55840","0.42090"
"53.60000","3.57194","0.42187"
"53.80000","3.58547","0.42185"
"54.00000","3.59870","0.42261"
"54.20000","3.61168","0.42280"
"54.40000","3.62543","0.42314"
"54.60000","3.63861","0.42393"
"54.80000","3.65240","0.42438"
"55.00000","3.66480","0.42420"
"55.20000","3.67863","0.42472"
"55.40000","3.69193","0.42550"
"55.60000","3.70535","0.42551"
"55.80000","3.71838","0.42591"
"56.00000","3.73172","0.42599"
"56.20000","3.74520","0.42661"
"56.40000","3.75885","0.42746"
"56.60000","3.77158","0.42747"
"56.80000","3.78558","0.42828"
"57.00000","3.79834","0.42843"
"57.20000","3.81239","0.42914"
"57.40000","3.82517","0.42912"
"57.60000","3.83853","0.42987"
"57.80000","3.85210","0.42991"
"58.00000","3.86516","0.43009"
"58.20000","3.87862","0.43046"
"58.40000","3.89207","0.43143"
"58.60000","3.90508","0.43138"
"58.80000","3.91910","0.43217"
"59.00000","3.93161","0.43204"
"59.20000","3.94543","0.43294"
"59.40000","3.95877","0.43278"
"59.60000","3.97197","0.43349"
"59.80000","3.98540","0.43380"
"60.00000","3.99830","0.43391"
"60.20000","4.01203","0.43465"
"60.40000","4.02548","0.43503"
"60.60000","4.03848","0.43528"
"60.80000","4.05210","0.43571"
"61.00000","4.06503","0.43550"
"61.20000","4.07891","0.43663"
"61.40000","4.09213","0.43693"
"61.60000","4.10490","0.43697"
"61.80000","4.11901","0.43806"
"62.00000","4.13181","0.43818"
"62.20000","4.14558","0.43864"
"62.40000","4.15841","0.43863"
"62.60000","4.17188","0.43953"
"62.80000","4.18556","0.43963"
"63.00000","4.19859","0.43968"
"63.20000","4.21175","0.44019"
"63.40000","4.22538","0.44072"
"63.60000","4.23838","0.44112"
"63.80000","4.25252","0.44160"
"64.00000","4.26474","0.44127"
"64.20000","4.27885","0.44209"
"64.40000","4.29184","0.44237"
"64.60000","4.30531","0.44243"
"64.80000","4.31838","0.44278"
"65.00000","4.33176","0.44282"
"65.20000","4.34526","0.44362"
"65.40000","4.35888","0.44378"
"65.60000","4.37153","0.44375"
"65.80000","4.38563","0.44456"
"66.00000","4.39832","0.44429"
"66.20000","4.41234","0.44479"
"66.40000","4.42510","0.44512"
"66.60000","4.43855","0.44563"
"66.80000","4.45203","0.44555"
"67.00000","4.46533","0.44568"
"67.20000","4.47858","0.44599"
"67.40000","4.49208","0.44647"
"67.60000","4.50512","0.44625"
"67.80000","4.51903","0.44658"
"68.00000","4.53177","0.44650"
"68.20000","4.54539","0.44756"
"68.40000","4.55861","0.44749"
"68.60000","4.57201","0.44775"
"68.80000","4.58531","0.44803"
"69.00000","4.59839","0.44814"
"69.20000","4.61200","0.44854"
"69.40000","4.62549","0.44869"
"69.60000","4.63849","0.44901"
"69.80000","4.65207","0.44961"
"70.00000","4.66504","0.44916"
"70.20000","4.67897","0.45025"
"70.40000","4.69205","0.44995"
"70.60000","4.70502","0.45039"
"70.80000","4.71880","0.45015"
"71.00000","4.73187","0.45063"
"71.20000","4.74555","0.45082"
"71.40000","4.75838","0.45065"
"71.60000","4.77193","0.45097"
"71.80000","4.78555","0.45141"
"72.00000","4.79865","0.45146"
"72.20000","4.81169","0.45134"
"72.40000","4.82544","0.45204"
"72.60000","4.83844","0.45218"
"72.80000","4.85245","0.45216"
"73.00000","4.86475","0.45212"
"73.20000","4.87879","0.45281"
"73.40000","4.89200","0.45263"
"73.60000","4.90538","0.45291"
"73.80000","4.91844","0.45273"
"74.00000","4.93175","0.45294"
"74.20000","4.94525","0.45335"
"74.40000","4.95890","0.45365"
"74.60000","4.97157","0.45367"
"74.80000","4.98561","0.45453"
"75.00000","4.99838","0.45368"
"75.20000","5.01235","0.45466"
"75.40000","5.02519","0.45433"
"75.60000","5.03854","0.45432"
"75.80000","5.05209","0.45434"
"76.00000","5.06527","0.45434"
"76.20000","5.07870","0.45486"
"76.40000","5.09206","0.45499"
"76.60000","5.10514","0.45482"
"76.80000","5.11908","0.45501"
"77.00000","5.13170","0.45464"
"77.20000","5.14548","0.45528"
"77.40000","5.15866","0.45530"
"77.60000","5.17192","0.45533"
"77.80000","5.18538","0.45516"
"78.00000","5.19827","0.45563"
"78.20000","5.21197","0.45579"
"78.40000","5.22566","0.45629"
"78.60000","5.23843","0.45579"
"78.80000","5.25205","0.45626"
"79.00000","5.26510","0.45608"
"79.20000","5.27893","0.45659"
"79.40000","5.29209","0.45609"
"79.60000","5.30495","0.45628"
"79.80000","5.31889","0.45675"
"80.00000","5.33186","0.45657"
"80.20000","5.34551","0.45658"
"80.40000","5.35848","0.45691"
"80.60000","5.37185","0.45722"
"80.80000","5.38551","0.45697"
"81.00000","5.39865","0.45690"
"81.20000","5.41181","0.45740"
"81.40000","5.42543","0.45701"
"81.60000","5.43846","0.45744"
"81.80000","5.45239","0.45757"
"82.00000","5.46477","0.45702"
"82.20000","5.47877","0.45765"
"82.40000","5.49195","0.45752"
"82.60000","5.50521","0.45820"
"82.80000","5.51845","0.45760"
"83.00000","5.53172","0.45845"
"83.20000","5.54526","0.45837"
"83.40000","5.55883","0.45824"
"83.60000","5.57156","0.45886"
"83.80000","5.58556","0.45904"
"84.00000","5.59837","0.45890"
"84.20000","5.61241","0.45867"
"84.40000","5.62517","0.45820"
"84.60000","5.63845","0.45901"
"84.80000","5.65204","0.45893"
"85.00000","5.66525","0.45870"
"85.20000","5.67861","0.45905"
"85.40000","5.69210","0.45924"
"85.60000","5.70505","0.45907"
"85.80000","5.71910","0.45898"
"86.00000","5.73160","0.45885"
"86.20000","5.74551","0.45928"
"86.40000","5.75871","0.45882"
"86.60000","5.77195","0.45915"
"86.80000","5.78538","0.45939"
"87.00000","5.79828","0.45920"
"87.20000","5.81195","0.45884"
"87.40000","5.82557","0.45941"
"87.60000","5.83836","0.45866"
"87.80000","5.85213","0.45869"
"88.00000","5.86500","0.45820"
"88.20000","5.87890","0.45819"
"88.40000","5.89208","0.45785"
"88.60000","5.90496","0.45799"
"88.80000","5.91892","0.45758"
"89.00000","5.93178","0.45759"
"89.20000","5.94561","0.45795"
"89.40000","5.95846","0.45728"
"89.60000","5.97185","0.45713"
"89.80000","5.98559","0.45741"
"90.00000","5.99855","0.45706"
"90.20000","6.01177","0.45680"
"90.40000","6.02545","0.45677"
"90.60000","6.03841","0.45694"
"90.80000","6.05250","0.45721"
"91.00000","6.06477","0.45687"
"91.20000","6.07879","0.45697"
"91.40000","6.09194","0.45705"
"91.60000","6.10529","0.45696"
"91.80000","6.11854","0.45655"
"92.00000","6.13173","0.45636"
"92.20000","6.14524","0.45641"
"92.40000","6.15896","0.45639"
"92.60000","6.17152","0.45649"
"92.80000","6.18563","0.45654"
"93.00000","6.19837","0.45622"
"93.20000","6.21238","0.45656"
"93.40000","6.22515","0.45631"
"93.60000","6.23851","0.45623"
"93.80000","6.25203","0.45623"
"94.00000","6.26521","0.45622"
"94.20000","6.27854","0.45612"
"94.40000","6.29214","0.45624"
"94.60000","6.30514","0.45595"
"94.80000","6.31905","0.45606"
"95.00000","6.33161","0.45594"
"95.20000","6.34549","0.45617"
"95.40000","6.35875","0.45542"
"95.60000","6.37201","0.45590"
"95.80000","6.38536","0.45518"
"96.00000","6.39835","0.45480"
"96.20000","6.41198","0.45507"
"96.40000","6.42560","0.45489"
"96.60000","6.43839","0.45477"
"96.80000","6.45209","0.45473"
"97.00000","6.46510","0.45417"
"97.20000","6.47898","0.45506"
"97.40000","6.49206","0.45409"
"97.60000","6.50493","0.45412"
"97.80000","6.51886","0.45396"
"98.00000","6.53189","0.45399"
"98.20000","6.54552","0.45388"
"98.40000","6.55844","0.45389"
"98.60000","6.57190","0.45403"
"98.80000","6.58553","0.45425"
"99.00000","6.59861","0.45452"
"99.20000","6.61177","0.45426"
"99.40000","6.62540","0.45458"
"99.60000","6.63847","0.45379"
"99.80000","6.65238","0.45398"
"100.00000","6.66486","0.45372"
"100.20000","6.67883","0.45406"
"100.40000","6.69195","0.45371"
"100.60000","6.70523","0.45398"
"100.80000","6.71846","0.45382"
"101.00000","6.73174","0.45375"
"101.20000","6.74524","0.45359"
"101.40000","6.75893","0.45340"
"101.60000","6.77156","0.45297"
"101.80000","6.78552","0.45319"
"102.00000","6.79847","0.45300"
"102.20000","6.81229","0.45342"
"102.40000","6.82523","0.45353"
"102.60000","6.83859","0.45348"
"102.80000","6.85204","0.45319"
"103.00000","6.86529","0.45328"
"103.20000","6.87858","0.45240"
"103.40000","6.89213","0.45233"
"103.60000","6.90514","0.45235"
"103.80000","6.91899","0.45230"
"104.00000","6.93167","0.45201"
"104.20000","6.94543","0.45211"
"104.40000","6.95869","0.45156"
"104.60000","6.97202","0.45181"
"104.80000","6.98535","0.45113"
"105.00000","6.99829","0.45102"
"105.20000","7.01204","0.45077"
"105.40000","7.02554","0.45023"
"105.60000","7.03847","0.45021"
"105.80000","7.05206","0.45011"
"106.00000","7.06505","0.44982"
"106.20000","7.07900","0.44974"
"106.40000","7.09214","0.44925"
"106.60000","7.10494","0.44943"
"106.80000","7.11882","0.44940"
"107.00000","7.13184","0.44899"
"107.20000","7.14551","0.44877"
"107.40000","7.15853","0.44846"
"107.60000","7.17183","0.44829"
"107.80000","7.18553","0.44801"
"108.00000","7.19857","0.44792"
"108.20000","7.21180","0.44739"
"108.40000","7.22550","0.44747"
"108.60000","7.23841","0.44682"
"108.80000","7.25244","0.44635"
"109.00000","7.26465","0.44599"
"109.20000","7.27887","0.44597"
"109.40000","7.29196","0.44590"
"109.60000","7.30528","0.44549"
"109.80000","7.31856","0.44526"
"110.00000","7.33165","0.44526"
"110.20000","7.34527","0.44479"
"110.40000","7.35896","0.44466"
"110.60000","7.37151","0.44400"
"110.80000","7.38557","0.44410"
"111.00000","7.39841","0.44327"
"111.20000","7.41240","0.44370"
"111.40000","7.42513","0.44257"
"111.60000","7.43842","0.44244"
"111.80000","7.45205","0.44204"
"112.00000","7.46526","0.44108"
"112.20000","7.47854","0.44089"
"112.40000","7.49217","0.44040"
"112.60000","7.50513","0.43995"
"112.80000","7.51913","0.44009"
"113.00000","7.53166","0.43950"
"113.20000","7.54540","0.43932"
"113.40000","7.55871","0.43882"
"113.60000","7.57198","0.43820"
"113.80000","7.58535","0.43750"
"114.00000","7.59837","0.43711"
"114.20000","7.61198","0.43662"
"114.40000","7.62564","0.43654"
"114.60000","7.63843","0.43548"
"114.80000","7.65200","0.43592"
"115.00000","7.66524","0.43511"
"115.20000","7.67888","0.43506"
"115.40000","7.69210","0.43417"
"115.60000","7.70500","0.43408"
"115.80000","7.71881","0.43301"
"116.00000","7.73192","0.43287"
"116.20000","7.74556","0.43193"
"116.40000","7.75844","0.43119"
"116.60000","7.77185","0.43064"
"116.80000","7.78553","0.43023"
"117.00000","7.79864","0.42904"
"117.20000","7.81175","0.42863"
"117.40000","7.82543","0.42799"
"117.60000","7.83854","0.42795"
"117.80000","7.85238","0.42687"
"118.00000","7.86471","0.42554"
"118.20000","7.87880","0.42522"
"118.40000","7.89206","0.42484"
"118.60000","7.90530","0.42480"
"118.80000","7.91839","0.42352"
"119.00000","7.93169","0.42265"
"119.20000","7.94525","0.42212"
"119.40000","7.95896","0.42132"
"119.60000","7.97157","0.42048"
"119.80000","7.98558","0.41963"
"120.00000","7.99842","0.41912"
"120.20000","8.01229","0.41839"
"120.40000","8.02518","0.41715"
"120.60000","8.03855","0.41683"
"120.80000","8.05205","0.41560"
"121.00000","8.06527","0.41487"
"121.20000","8.07858","0.41345"
"121.40000","8.09205","0.41328"
"121.60000","8.10512","0.41207"
"121.80000","8.11912","0.41093"
"122.00000","8.13165","0.41019"
"122.20000","8.14544","0.40956"
"122.40000","8.15865","0.40824"
"122.60000","8.17202","0.40855"
"122.80000","8.18534","0.40705"
"123.00000","8.19829","0.40617"
"123.20000","8.21205","0.40540"
"123.40000","8.22564","0.40409"
"123.60000","8.23841","0.40316"
"123.80000","8.25205","0.40228"
"124.00000","8.26503","0.40120"
"124.20000","8.27891","0.40098"
"124.40000","8.29211","0.39935"
"124.60000","8.30497","0.39914"
"124.80000","8.31890","0.39884"
"125.00000","8.33186","0.39811"
"125.20000","8.34561","0.39685"
"125.40000","8.35840","0.39583"
"125.60000","8.37185","0.39542"
"125.80000","8.38555","0.39397"
"126.00000","8.39855","0.39273"
"126.20000","8.41176","0.39110"
"126.40000","8.42549","0.39010"
"126.60000","8.43841","0.38939"
"126.80000","8.45249","0.38786"
"127.00000","8.46474","0.38687"
"127.20000","8.47876","0.38573"
"127.40000","8.49188","0.38504"
"127.60000","8.50525","0.38361"
"127.80000","8.51844","0.38217"
"128.00000","8.53178","0.38143"
"128.20000","8.54532","0.38028"
"128.40000","8.55890","0.37925"
"128.60000","8.57150","0.37730"
"128.80000","8.58563","0.37656"
"129.00000","8.59829","0.37481"
"129.20000","8.61237","0.37390"
"129.40000","8.62524","0.37147"
"129.60000","8.63853","0.37088"
"129.80000","8.65200","0.36915"
"130.00000","8.66522","0.36802"
"130.20000","8.67864","0.36659"
"130.40000","8.69211","0.36509"
"130.60000","8.70502","0.36383"
"130.80000","8.71913","0.36216"
"131.00000","8.73157","0.36060"
"131.20000","8.74555","0.35899"
"131.40000","8.75869","0.35692"
"131.60000","8.77191","0.35511"
"131.80000","8.78544","0.35299"
"132.00000","8.79821","0.35139"
"132.20000","8.81203","0.34956"
"132.40000","8.82565","0.34743"
"132.60000","8.83842","0.34518"
"132.80000","8.85211","0.34300"
"133.00000","8.86506","0.34005"
"133.20000","8.87897","0.33744"
"133.40000","8.89214","0.33418"
"133.60000","8.90492","0.33175"
"133.80000","8.91890","0.32864"
"134.00000","8.93180","0.32516"
"134.20000","8.94559","0.32177"
"134.40000","8.95848","0.31683"
"134.60000","8.97182","0.31219"
"134.80000","8.98554","0.30772"
"135.00000","8.99861","0.30174"
"135.20000","9.01179","0.29686"
"135.40000","9.02545","0.29062"
"135.60000","9.03839","0.28523"
"135.80000","9.05250","0.27875"
"136.00000","9.06472","0.27343"
"136.20000","9.07882","0.26844"
"136.40000","9.09187","0.26378"
"136.60000","9.10524","0.25865"
"136.80000","9.11850","0.25336"
"137.00000","9.13171","0.24851"
"137.20000","9.14527","0.24420"
"137.40000","9.15889","0.23994"
"137.60000","9.17157","0.23570"
"137.80000","9.18551","0.23242"
"138.00000","9.19849","0.22795"
"138.20000","9.21227","0.22477"
"138.40000","9.22517","0.22008"
"138.60000","9.23844","0.21610"
"138.80000","9.25200","0.21292"
"139.00000","9.26545","0.20928"
"139.20000","9.27855","0.20496"
"139.40000","9.29199","0.20121"
"139.60000","9.30513","0.19748"
"139.80000","9.31900","0.19287"
"140.00000","9.33166","0.18904"
"140.20000","9.34556","0.18546"
"140.40000","9.35866","0.18169"
"140.60000","9.37204","0.17873"
"140.80000","9.38528","0.17561"
"141.00000","9.39843","0.17329"
"141.20000","9.41197","0.16988"
"141.40000","9.42553","0.16698"
"141.60000","9.43847","0.16363"
"141.80000","9.45199","0.16107"
"142.00000","9.46525","0.15825"
"142.20000","9.47888","0.15596"
"142.40000","9.49204","0.15332"
"142.60000","9.50500","0.15202"
"142.80000","9.51875","0.14890"
"143.00000","9.53206","0.14619"
"143.20000","9.54544","0.14339"
"143.40000","9.55836","0.14119"
"143.60000","9.57196","0.13893"
"143.80000","9.58541","0.13625"
"144.00000","9.59885","0.13343"
"144.20000","9.61166","0.13085"
"144.40000","9.62538","0.12821"
"144.60000","9.63848","0.12607"
"144.80000","9.65233","0.12376"
"145.00000","9.66490","0.12042"
"145.20000","9.67873","0.11945"
"145.40000","9.69188","0.11764"
"145.60000","9.70542","0.11629"
"145.80000","9.71828","0.11485"
"146.00000","9.73190","0.11330"
"146.20000","9.74513","0.11133"
"146.40000","9.75888","0.10952"
"146.60000","9.77158","0.10782"
"146.80000","9.78551","0.10660"
"147.00000","9.79853","0.10518"
"147.20000","9.81231","0.10385"
"147.40000","9.82509","0.10156"
"147.60000","9.83868","0.10060"
"147.80000","9.85199","0.09940"
"148.00000","9.86543","0.09779"
"148.20000","9.87857","0.09565"
"148.40000","9.89199","0.09231"
"148.60000","9.90518","0.08783"
"148.80000","9.91892","0.08522"
"149.00000","9.93177","0.08203"
"149.20000","9.94543","0.07945"
"149.40000","9.95863","0.07742"
"149.60000","9.97207","0.07534"
"149.80000","9.98527","0.07303"
"150.00000","9.99846","0.07120"
"150.20000","10.01194","0.06784"
"150.40000","10.02552","0.06638"
"150.60000","10.03848","0.06434"
"150.80000","10.05194","0.06331"
"151.00000","10.06519","0.06059"
"151.20000","10.07890","0.05872"
"151.40000","10.09207","0.05576"
"151.43000","10.09391","0.05539"