File: 20.12.09/1Layer_13.is_flex_RawData/Specimen_RawData_1.csv
Specimen properties : Thickness,"3.30000",mm
Specimen properties : Width,"6.90000",mm
Specimen properties : Support span,"52.80000",mm

Time,Extension,Load
(s),(mm),(kgf)
"0.00000","0.00000","-0.00145"
"0.10000","0.00080","-0.00141"
"0.20000","0.00575","0.00241"
"0.30000","0.01745","0.01076"
"0.40000","0.02465","0.01436"
"0.50000","0.03140","0.01823"
"0.60000","0.03821","0.02203"
"0.70000","0.04517","0.02574"
"0.80000","0.05210","0.02956"
"0.90000","0.05852","0.03284"
"1.00000","0.06490","0.03651"
"1.10000","0.07212","0.04033"
"1.20000","0.07908","0.04414"
"1.30000","0.08548","0.04727"
"1.40000","0.09165","0.05058"
"1.50000","0.09819","0.05398"
"1.60000","0.10544","0.05763"
"1.70000","0.11220","0.06070"
"1.80000","0.11861","0.06436"
"1.90000","0.12501","0.06758"
"2.00000","0.13190","0.07118"
"2.10000","0.13897","0.07024"
"2.20000","0.14532","0.06729"
"2.30000","0.15174","0.07156"
"2.40000","0.15845","0.07497"
"2.50000","0.16523","0.07835"
"2.60000","0.17213","0.08130"
"2.70000","0.17893","0.08399"
"2.80000","0.18578","0.08685"
"2.90000","0.19202","0.08945"
"3.00000","0.19826","0.09216"
"3.10000","0.20503","0.09515"
"3.20000","0.21213","0.09823"
"3.30000","0.21882","0.10057"
"3.40000","0.22519","0.10350"
"3.50000","0.23173","0.10576"
"3.60000","0.23904","0.10939"
"3.70000","0.24578","0.11237"
"3.80000","0.25199","0.11493"
"3.90000","0.25821","0.11771"
"4.00000","0.26499","0.12056"
"4.10000","0.27206","0.12386"
"4.20000","0.27883","0.12691"
"4.30000","0.28526","0.12984"
"4.40000","0.29203","0.13250"
"4.50000","0.29866","0.13562"
"4.60000","0.30537","0.13863"
"4.70000","0.31177","0.14139"
"4.80000","0.31854","0.14453"
"4.90000","0.32507","0.14720"
"5.00000","0.33182","0.15041"
"5.10000","0.33861","0.15334"
"5.20000","0.34564","0.15624"
"5.30000","0.35225","0.15928"
"5.40000","0.35856","0.16207"
"5.50000","0.36485","0.16449"
"5.60000","0.37173","0.16796"
"5.70000","0.37895","0.17134"
"5.80000","0.38542","0.17363"
"5.90000","0.39171","0.17655"
"6.00000","0.39857","0.17975"
"6.10000","0.40567","0.18246"
"6.20000","0.41231","0.18541"
"6.30000","0.41846","0.18792"
"6.40000","0.42480","0.19082"
"6.50000","0.43179","0.19359"
"6.60000","0.43886","0.19664"
"6.70000","0.44539","0.19905"
"6.80000","0.45204","0.20189"
"6.90000","0.45863","0.20450"
"7.00000","0.46527","0.20805"
"7.10000","0.47192","0.21068"
"7.20000","0.47845","0.21318"
"7.30000","0.48542","0.21613"
"7.40000","0.49179","0.21851"
"7.50000","0.49842","0.22108"
"7.60000","0.50534","0.22430"
"7.70000","0.51253","0.22732"
"7.80000","0.51903","0.22960"
"7.90000","0.52506","0.23220"
"8.00000","0.53146","0.23520"
"8.10000","0.53869","0.23776"
"8.20000","0.54559","0.24059"
"8.30000","0.55222","0.24332"
"8.40000","0.55833","0.24557"
"8.50000","0.56524","0.24841"
"8.60000","0.57231","0.25106"
"8.70000","0.57874","0.25327"
"8.80000","0.58510","0.25614"
"8.90000","0.59156","0.25832"
"9.00000","0.59846","0.26120"
"9.10000","0.60541","0.26370"
"9.20000","0.61199","0.26660"
"9.30000","0.61899","0.26925"
"9.40000","0.62520","0.27116"
"9.50000","0.63175","0.27346"
"9.60000","0.63838","0.27634"
"9.70000","0.64537","0.27926"
"9.80000","0.65218","0.28121"
"9.90000","0.65845","0.28322"
"10.00000","0.66500","0.28593"
"10.10000","0.67216","0.28844"
"10.20000","0.67927","0.29123"
"10.30000","0.68552","0.29282"
"10.40000","0.69150","0.29479"
"10.50000","0.69814","0.29776"
"10.60000","0.70547","0.30028"
"10.70000","0.71224","0.30234"
"10.80000","0.71865","0.30444"
"10.90000","0.72514","0.30688"
"11.00000","0.73197","0.30883"
"11.10000","0.73899","0.31144"
"11.20000","0.74538","0.31371"
"11.30000","0.75176","0.31531"
"11.40000","0.75841","0.31775"
"11.50000","0.76527","0.31981"
"11.60000","0.77192","0.32189"
"11.70000","0.77884","0.32389"
"11.80000","0.78569","0.32639"
"11.90000","0.79194","0.32821"
"12.00000","0.79826","0.32993"
"12.10000","0.80505","0.33204"
"12.20000","0.81223","0.33447"
"12.30000","0.81878","0.33622"
"12.40000","0.82509","0.33786"
"12.50000","0.83177","0.34016"
"12.60000","0.83904","0.34235"
"12.70000","0.84583","0.34437"
"12.80000","0.85197","0.34524"
"12.90000","0.85810","0.34718"
"13.00000","0.86501","0.34944"
"13.10000","0.87209","0.35120"
"13.20000","0.87893","0.35300"
"13.30000","0.88523","0.35484"
"13.40000","0.89189","0.35681"
"13.50000","0.89855","0.35836"
"13.60000","0.90536","0.36010"
"13.70000","0.91191","0.36178"
"13.80000","0.91858","0.36358"
"13.90000","0.92509","0.36481"
"14.00000","0.93183","0.36652"
"14.10000","0.93853","0.36864"
"14.20000","0.94571","0.37020"
"14.30000","0.95229","0.37173"
"14.40000","0.95854","0.37326"
"14.50000","0.96491","0.37457"
"14.60000","0.97165","0.37649"
"14.70000","0.97893","0.37789"
"14.80000","0.98549","0.37964"
"14.90000","0.99182","0.38062"
"15.00000","0.99852","0.38271"
"15.10000","1.00556","0.38413"
"15.20000","1.01230","0.38585"
"15.30000","1.01859","0.38686"
"15.40000","1.02489","0.38826"
"15.50000","1.03169","0.39004"
"15.60000","1.03881","0.39176"
"15.70000","1.04544","0.39262"
"15.80000","1.05208","0.39431"
"15.90000","1.05863","0.39588"
"16.00000","1.06528","0.39760"
"16.10000","1.07187","0.39897"
"16.20000","1.07845","0.40005"
"16.30000","1.08549","0.40151"
"16.40000","1.09187","0.40269"
"16.50000","1.09839","0.40386"
"16.60000","1.10525","0.40568"
"16.70000","1.11244","0.40746"
"16.80000","1.11901","0.40850"
"16.90000","1.12512","0.40971"
"17.00000","1.13146","0.41118"
"17.10000","1.13873","0.41258"
"17.20000","1.14559","0.41392"
"17.30000","1.15204","0.41508"
"17.40000","1.15840","0.41590"
"17.50000","1.16532","0.41771"
"17.60000","1.17231","0.41964"
"17.70000","1.17876","0.42043"
"17.80000","1.18498","0.42149"
"17.90000","1.19168","0.42287"
"18.00000","1.19845","0.42420"
"18.10000","1.20530","0.42556"
"18.20000","1.21195","0.42648"
"18.30000","1.21896","0.42841"
"18.40000","1.22534","0.42912"
"18.50000","1.23180","0.43046"
"18.60000","1.23839","0.43200"
"18.70000","1.24528","0.43303"
"18.80000","1.25214","0.43448"
"18.90000","1.25859","0.43516"
"19.00000","1.26493","0.43646"
"19.10000","1.27216","0.43833"
"19.20000","1.27914","0.43952"
"19.30000","1.28554","0.44026"
"19.40000","1.29155","0.44115"
"19.50000","1.29822","0.44221"
"19.60000","1.30547","0.44378"
"19.70000","1.31219","0.44513"
"19.80000","1.31865","0.44620"
"19.90000","1.32514","0.44722"
"20.00000","1.33191","0.44846"
"20.10000","1.33889","0.45023"
"20.20000","1.34532","0.45083"
"20.30000","1.35182","0.45176"
"20.40000","1.35840","0.45295"
"20.50000","1.36522","0.45432"
"20.60000","1.37215","0.45521"
"20.70000","1.37881","0.45614"
"20.80000","1.38571","0.45767"
"20.90000","1.39195","0.45901"
"21.00000","1.39832","0.45968"
"21.10000","1.40509","0.46084"
"21.20000","1.41211","0.46184"
"21.30000","1.41877","0.46312"
"21.40000","1.42524","0.46403"
"21.50000","1.43179","0.46548"
"21.60000","1.43900","0.46674"
"21.70000","1.44583","0.46753"
"21.80000","1.45205","0.46842"
"21.90000","1.45812","0.46867"
"22.00000","1.46496","0.47012"
"22.10000","1.47214","0.47200"
"22.20000","1.47890","0.47275"
"22.30000","1.48521","0.47357"
"22.40000","1.49185","0.47469"
"22.50000","1.49857","0.47563"
"22.60000","1.50541","0.47677"
"22.70000","1.51194","0.47780"
"22.80000","1.51866","0.47871"
"22.90000","1.52514","0.47973"
"23.00000","1.53182","0.48059"
"23.10000","1.53857","0.48240"
"23.20000","1.54564","0.48318"
"23.30000","1.55227","0.48432"
"23.40000","1.55862","0.48524"
"23.50000","1.56491","0.48576"
"23.60000","1.57174","0.48681"
"23.70000","1.57888","0.48811"
"23.80000","1.58545","0.48883"
"23.90000","1.59171","0.48966"
"24.00000","1.59855","0.49104"
"24.10000","1.60562","0.49210"
"24.20000","1.61228","0.49295"
"24.30000","1.61851","0.49390"
"24.40000","1.62476","0.49456"
"24.50000","1.63169","0.49597"
"24.60000","1.63883","0.49719"
"24.70000","1.64546","0.49787"
"24.80000","1.65207","0.49902"
"24.90000","1.65860","0.49954"
"25.00000","1.66526","0.50083"
"25.10000","1.67190","0.50155"
"25.20000","1.67853","0.50306"
"25.30000","1.68544","0.50385"
"25.40000","1.69185","0.50436"
"25.50000","1.69846","0.50580"
"25.60000","1.70540","0.50650"
"25.70000","1.71245","0.50768"
"25.80000","1.71894","0.50862"
"25.90000","1.72498","0.50919"
"26.00000","1.73149","0.50999"
"26.10000","1.73872","0.51158"
"26.20000","1.74572","0.51265"
"26.30000","1.75207","0.51312"
"26.40000","1.75829","0.51403"
"26.50000","1.76524","0.51507"
"26.60000","1.77230","0.51616"
"26.70000","1.77876","0.51685"
"26.80000","1.78521","0.51795"
"26.90000","1.79157","0.51859"
"27.00000","1.79844","0.51971"
"27.10000","1.80538","0.52082"
"27.20000","1.81203","0.52137"
"27.30000","1.81894","0.52254"
"27.40000","1.82518","0.52323"
"27.50000","1.83183","0.52470"
"27.60000","1.83845","0.52516"
"27.70000","1.84532","0.52650"
"27.80000","1.85225","0.52717"
"27.90000","1.85846","0.52773"
"28.00000","1.86486","0.52871"
"28.10000","1.87214","0.52973"
"28.20000","1.87930","0.53088"
"28.30000","1.88555","0.53128"
"28.40000","1.89159","0.53183"
"28.50000","1.89820","0.53303"
"28.60000","1.90539","0.53461"
"28.70000","1.91226","0.53518"
"28.80000","1.91868","0.53553"
"28.90000","1.92513","0.53653"
"29.00000","1.93194","0.53736"
"29.10000","1.93894","0.53833"
"29.20000","1.94536","0.53893"
"29.30000","1.95180","0.54011"
"29.40000","1.95841","0.54075"
"29.50000","1.96519","0.54169"
"29.60000","1.97201","0.54267"
"29.70000","1.97885","0.54336"
"29.80000","1.98568","0.54405"
"29.90000","1.99199","0.54471"
"30.00000","1.99824","0.54536"
"30.10000","2.00500","0.54624"
"30.20000","2.01227","0.54731"
"30.30000","2.01884","0.54799"
"30.40000","2.02514","0.54854"
"30.50000","2.03175","0.54948"
"30.60000","2.03896","0.55068"
"30.70000","2.04584","0.55174"
"30.80000","2.05204","0.55191"
"30.90000","2.05810","0.55255"
"31.00000","2.06499","0.55326"
"31.10000","2.07210","0.55448"
"31.20000","2.07887","0.55518"
"31.30000","2.08533","0.55589"
"31.40000","2.09186","0.55632"
"31.50000","2.09847","0.55737"
"31.60000","2.10542","0.55808"
"31.70000","2.11196","0.55858"
"31.80000","2.11860","0.55958"
"31.90000","2.12498","0.56017"
"32.00000","2.13179","0.56112"
"32.10000","2.13859","0.56188"
"32.20000","2.14564","0.56303"
"32.30000","2.15230","0.56377"
"32.40000","2.15856","0.56397"
"32.50000","2.16493","0.56454"
"32.60000","2.17175","0.56549"
"32.70000","2.17890","0.56657"
"32.80000","2.18551","0.56738"
"32.90000","2.19167","0.56764"
"33.00000","2.19853","0.56840"
"33.10000","2.20566","0.56963"
"33.20000","2.21234","0.57039"
"33.30000","2.21856","0.57066"
"33.40000","2.22474","0.57117"
"33.50000","2.23175","0.57235"
"33.60000","2.23885","0.57308"
"33.70000","2.24550","0.57381"
"33.80000","2.25210","0.57427"
"33.90000","2.25856","0.57482"
"34.00000","2.26524","0.57564"
"34.10000","2.27188","0.57628"
"34.20000","2.27852","0.57727"
"34.30000","2.28555","0.57798"
"34.40000","2.29180","0.57793"
"34.50000","2.29840","0.57894"
"34.60000","2.30533","0.57974"
"34.70000","2.31248","0.58074"
"34.80000","2.31893","0.58109"
"34.90000","2.32502","0.58161"
"35.00000","2.33145","0.58196"
"35.10000","2.33877","0.58314"
"35.20000","2.34576","0.58397"
"35.30000","2.35207","0.58452"
"35.40000","2.35835","0.58514"
"35.50000","2.36527","0.58580"
"35.60000","2.37230","0.58662"
"35.70000","2.37874","0.58680"
"35.80000","2.38505","0.58751"
"35.90000","2.39156","0.58819"
"36.00000","2.39849","0.58869"
"36.10000","2.40539","0.58975"
"36.20000","2.41201","0.58988"
"36.30000","2.41888","0.59106"
"36.40000","2.42521","0.59121"
"36.50000","2.43178","0.59205"
"36.60000","2.43845","0.59254"
"36.70000","2.44533","0.59314"
"36.80000","2.45214","0.59404"
"36.90000","2.45845","0.59450"
"37.00000","2.46496","0.59506"
"37.10000","2.47214","0.59615"
"37.20000","2.47922","0.59672"
"37.30000","2.48549","0.59716"
"37.40000","2.49161","0.59753"
"37.50000","2.49812","0.59790"
"37.60000","2.50544","0.59894"
"37.70000","2.51229","0.59982"
"37.80000","2.51867","0.59990"
"37.90000","2.52521","0.60097"
"38.00000","2.53187","0.60147"
"38.10000","2.53892","0.60193"
"38.20000","2.54535","0.60276"
"38.30000","2.55170","0.60317"
"38.40000","2.55848","0.60344"
"38.50000","2.56521","0.60445"
"38.60000","2.57196","0.60497"
"38.70000","2.57879","0.60544"
"38.80000","2.58566","0.60657"
"38.90000","2.59210","0.60683"
"39.00000","2.59830","0.60718"
"39.10000","2.60502","0.60760"
"39.20000","2.61213","0.60837"
"39.30000","2.61885","0.60898"
"39.40000","2.62528","0.60947"
"39.50000","2.63170","0.61018"
"39.60000","2.63895","0.61112"
"39.70000","2.64576","0.61159"
"39.80000","2.65202","0.61161"
"39.90000","2.65822","0.61192"
"40.00000","2.66497","0.61253"
"40.10000","2.67205","0.61359"
"40.20000","2.67880","0.61443"
"40.30000","2.68525","0.61471"
"40.40000","2.69209","0.61525"
"40.50000","2.69861","0.61578"
"40.60000","2.70523","0.61642"
"40.70000","2.71182","0.61684"
"40.80000","2.71855","0.61749"
"40.90000","2.72520","0.61796"
"41.00000","2.73181","0.61829"
"41.10000","2.73854","0.61912"
"41.20000","2.74559","0.61965"
"41.30000","2.75220","0.62001"
"41.40000","2.75865","0.62066"
"41.50000","2.76496","0.62074"
"41.60000","2.77175","0.62135"
"41.70000","2.77884","0.62230"
"41.80000","2.78543","0.62296"
"41.90000","2.79190","0.62293"
"42.00000","2.79857","0.62326"
"42.10000","2.80555","0.62440"
"42.20000","2.81228","0.62462"
"42.30000","2.81851","0.62499"
"42.40000","2.82498","0.62510"
"42.50000","2.83181","0.62597"
"42.60000","2.83874","0.62673"
"42.70000","2.84534","0.62726"
"42.80000","2.85192","0.62746"
"42.90000","2.85876","0.62799"
"43.00000","2.86540","0.62823"
"43.10000","2.87189","0.62873"
"43.20000","2.87848","0.62917"
"43.30000","2.88537","0.62964"
"43.40000","2.89203","0.62990"
"43.50000","2.89849","0.63084"
"43.60000","2.90525","0.63134"
"43.70000","2.91236","0.63195"
"43.80000","2.91891","0.63247"
"43.90000","2.92517","0.63236"
"44.00000","2.93150","0.63243"
"44.10000","2.93862","0.63362"
"44.20000","2.94566","0.63424"
"44.30000","2.95196","0.63421"
"44.40000","2.95837","0.63438"
"44.50000","2.96535","0.63500"
"44.60000","2.97227","0.63598"
"44.70000","2.97867","0.63626"
"44.80000","2.98497","0.63653"
"44.90000","2.99182","0.63670"
"45.00000","2.99859","0.63695"
"45.10000","3.00526","0.63804"
"45.20000","3.01186","0.63784"
"45.30000","3.01884","0.63875"
"45.40000","3.02550","0.63889"
"45.50000","3.03188","0.63929"
"45.60000","3.03838","0.63982"
"45.70000","3.04520","0.64016"
"45.80000","3.05208","0.64078"
"45.90000","3.05869","0.64101"
"46.00000","3.06506","0.64126"
"46.10000","3.07216","0.64178"
"46.20000","3.07909","0.64251"
"46.30000","3.08544","0.64269"
"46.40000","3.09168","0.64253"
"46.50000","3.09829","0.64337"
"46.60000","3.10539","0.64327"
"46.70000","3.11210","0.64348"
"46.80000","3.11856","0.64404"
"46.90000","3.12535","0.64484"
"47.00000","3.13201","0.64476"
"47.10000","3.13886","0.64500"
"47.20000","3.14525","0.64544"
"47.30000","3.15169","0.64516"
"47.40000","3.15869","0.64574"
"47.50000","3.16537","0.64607"
"47.60000","3.17200","0.64623"
"47.70000","3.17877","0.64641"
"47.80000","3.18558","0.64695"
"47.90000","3.19214","0.64714"
"48.00000","3.19844","0.64671"
"48.10000","3.20500","0.64724"
"48.20000","3.21202","0.64737"
"48.30000","3.21865","0.64797"
"48.40000","3.22533","0.64802"
"48.50000","3.23186","0.64828"
"48.60000","3.23890","0.64902"
"48.70000","3.24566","0.64897"
"48.80000","3.25198","0.64909"
"48.90000","3.25836","0.64931"
"49.00000","3.26512","0.64969"
"49.10000","3.27201","0.65038"
"49.20000","3.27875","0.64996"
"49.30000","3.28517","0.65033"
"49.40000","3.29215","0.65113"
"49.50000","3.29870","0.65129"
"49.60000","3.30531","0.65153"
"49.70000","3.31176","0.65145"
"49.80000","3.31839","0.65208"
"49.90000","3.32523","0.65312"
"50.00000","3.33193","0.65315"
"50.10000","3.33854","0.65345"
"50.20000","3.34550","0.65387"
"50.30000","3.35215","0.65383"
"50.40000","3.35879","0.65415"
"50.50000","3.36501","0.65435"
"50.60000","3.37165","0.65456"
"50.70000","3.37876","0.65542"
"50.80000","3.38542","0.65561"
"50.90000","3.39200","0.65566"
"51.00000","3.39868","0.65565"
"51.10000","3.40553","0.65667"
"51.20000","3.41222","0.65649"
"51.30000","3.41849","0.65625"
"51.40000","3.42490","0.65618"
"51.50000","3.43186","0.65696"
"51.60000","3.43877","0.65722"
"51.70000","3.44535","0.65703"
"51.80000","3.45192","0.65757"
"51.90000","3.45881","0.65796"
"52.00000","3.46545","0.65866"
"52.10000","3.47196","0.65862"
"52.20000","3.47839","0.65815"
"52.30000","3.48529","0.65907"
"52.40000","3.49196","0.65964"
"52.50000","3.49852","0.65918"
"52.60000","3.50528","0.66001"
"52.70000","3.51231","0.66032"
"52.80000","3.51892","0.66053"
"52.90000","3.52521","0.66043"
"53.00000","3.53158","0.66028"
"53.10000","3.53866","0.66131"
"53.20000","3.54563","0.66152"
"53.30000","3.55203","0.66167"
"53.40000","3.55841","0.66141"
"53.50000","3.56535","0.66210"
"53.60000","3.57220","0.66233"
"53.70000","3.57864","0.66247"
"53.80000","3.58502","0.66256"
"53.90000","3.59178","0.66338"
"54.00000","3.59858","0.66372"
"54.10000","3.60522","0.66337"
"54.20000","3.61187","0.66400"
"54.30000","3.61883","0.66479"
"54.40000","3.62545","0.66511"
"54.50000","3.63179","0.66493"
"54.60000","3.63843","0.66523"
"54.70000","3.64524","0.66584"
"54.80000","3.65209","0.66610"
"54.90000","3.65855","0.66600"
"55.00000","3.66501","0.66649"
"55.10000","3.67219","0.66677"
"55.20000","3.67911","0.66720"
"55.30000","3.68545","0.66735"
"55.40000","3.69164","0.66702"
"55.50000","3.69827","0.66739"
"55.60000","3.70542","0.66814"
"55.70000","3.71212","0.66827"
"55.80000","3.71859","0.66818"
"55.90000","3.72530","0.66829"
"56.00000","3.73198","0.66867"
"56.10000","3.73892","0.66880"
"56.20000","3.74529","0.66864"
"56.30000","3.75174","0.66891"
"56.40000","3.75852","0.66928"
"56.50000","3.76526","0.66928"
"56.60000","3.77203","0.66974"
"56.70000","3.77869","0.66990"
"56.80000","3.78560","0.67011"
"56.90000","3.79211","0.67044"
"57.00000","3.79837","0.67038"
"57.10000","3.80498","0.67070"
"57.20000","3.81213","0.67131"
"57.30000","3.81875","0.67123"
"57.40000","3.82525","0.67154"
"57.50000","3.83191","0.67192"
"57.60000","3.83894","0.67224"
"57.70000","3.84571","0.67256"
"57.80000","3.85200","0.67252"
"57.90000","3.85819","0.67206"
"58.00000","3.86503","0.67256"
"58.10000","3.87193","0.67319"
"58.20000","3.87883","0.67342"
"58.30000","3.88527","0.67320"
"58.40000","3.89195","0.67358"
"58.50000","3.89860","0.67431"
"58.60000","3.90531","0.67425"
"58.70000","3.91180","0.67455"
"58.80000","3.91859","0.67474"
"58.90000","3.92508","0.67428"
"59.00000","3.93183","0.67506"
"59.10000","3.93851","0.67483"
"59.20000","3.94563","0.67502"
"59.30000","3.95224","0.67536"
"59.40000","3.95860","0.67500"
"59.50000","3.96495","0.67506"
"59.60000","3.97170","0.67551"
"59.70000","3.97898","0.67601"
"59.80000","3.98545","0.67552"
"59.90000","3.99174","0.67563"
"60.00000","3.99857","0.67614"
"60.10000","4.00565","0.67671"
"60.20000","4.01233","0.67667"
"60.30000","4.01849","0.67663"
"60.40000","4.02481","0.67650"
"60.50000","4.03180","0.67638"
"60.60000","4.03887","0.67726"
"60.70000","4.04542","0.67711"
"60.80000","4.05209","0.67719"
"60.90000","4.05862","0.67731"
"61.00000","4.06530","0.67773"
"61.10000","4.07187","0.67794"
"61.20000","4.07853","0.67792"
"61.30000","4.08545","0.67821"
"61.40000","4.09185","0.67808"
"61.50000","4.09848","0.67850"
"61.60000","4.10524","0.67883"
"61.70000","4.11247","0.67921"
"61.80000","4.11896","0.67899"
"61.90000","4.12490","0.67863"
"62.00000","4.13140","0.67887"
"62.10000","4.13876","0.67959"
"62.20000","4.14575","0.67951"
"62.30000","4.15216","0.67927"
"62.40000","4.15829","0.67912"
"62.50000","4.16527","0.67972"
"62.60000","4.17235","0.68008"
"62.70000","4.17882","0.67975"
"62.80000","4.18508","0.67983"
"62.90000","4.19155","0.67966"
"63.00000","4.19850","0.68005"
"63.10000","4.20533","0.68048"
"63.20000","4.21202","0.68037"
"63.30000","4.21886","0.68053"
"63.40000","4.22521","0.68077"
"63.50000","4.23184","0.68104"
"63.60000","4.23847","0.68113"
"63.70000","4.24537","0.68159"
"63.80000","4.25212","0.68146"
"63.90000","4.25847","0.68154"
"64.00000","4.26496","0.68118"
"64.10000","4.27213","0.68156"
"64.20000","4.27916","0.68175"
"64.30000","4.28544","0.68115"
"64.40000","4.29162","0.68173"
"64.50000","4.29822","0.68163"
"64.60000","4.30543","0.68217"
"64.70000","4.31229","0.68191"
"64.80000","4.31863","0.68191"
"64.90000","4.32515","0.68200"
"65.00000","4.33193","0.68167"
"65.10000","4.33891","0.68221"
"65.20000","4.34529","0.68192"
"65.30000","4.35169","0.68167"
"65.40000","4.35842","0.68174"
"65.50000","4.36525","0.68213"
"65.60000","4.37209","0.68175"
"65.70000","4.37882","0.68209"
"65.80000","4.38565","0.68219"
"65.90000","4.39205","0.68153"
"66.00000","4.39829","0.68166"
"66.10000","4.40497","0.68134"
"66.20000","4.41214","0.68201"
"66.30000","4.41878","0.68179"
"66.40000","4.42526","0.68146"
"66.50000","4.43175","0.68128"
"66.60000","4.43899","0.68095"
"66.70000","4.44579","0.68021"
"66.80000","4.45200","0.68026"
"66.90000","4.45818","0.67949"
"67.00000","4.46499","0.67940"
"67.10000","4.47207","0.67941"
"67.20000","4.47893","0.67885"
"67.30000","4.48521","0.67846"
"67.40000","4.49191","0.67819"
"67.50000","4.49859","0.67781"
"67.60000","4.50538","0.67803"
"67.70000","4.51175","0.67715"
"67.80000","4.51849","0.67667"
"67.90000","4.52512","0.67625"
"68.00000","4.53185","0.67640"
"68.10000","4.53849","0.67570"
"68.20000","4.54564","0.67547"
"68.30000","4.55220","0.67450"
"68.40000","4.55869","0.67439"
"68.50000","4.56496","0.67364"
"68.60000","4.57171","0.67316"
"68.70000","4.57895","0.67269"
"68.80000","4.58545","0.67191"
"68.90000","4.59175","0.67064"
"69.00000","4.59852","0.66986"
"69.10000","4.60563","0.66898"
"69.20000","4.61229","0.66844"
"69.30000","4.61848","0.66680"
"69.40000","4.62499","0.66558"
"69.50000","4.63175","0.66417"
"69.60000","4.63882","0.66178"
"69.70000","4.64545","0.65874"
"69.80000","4.65203","0.65631"
"69.90000","4.65869","0.65376"
"70.00000","4.66533","0.65188"
"70.10000","4.67191","0.64988"
"70.20000","4.67847","0.64767"
"70.30000","4.68533","0.64597"
"70.40000","4.69196","0.64372"
"70.50000","4.69847","0.64192"
"70.60000","4.70534","0.63967"
"70.70000","4.71246","0.63808"
"70.80000","4.71892","0.63570"
"70.90000","4.72507","0.63330"
"71.00000","4.73152","0.63088"
"71.10000","4.73869","0.62928"
"71.20000","4.74567","0.62706"
"71.30000","4.75201","0.62530"
"71.40000","4.75839","0.62375"
"71.50000","4.76523","0.62219"
"71.60000","4.77231","0.62123"
"71.70000","4.77875","0.61921"
"71.80000","4.78503","0.61756"
"71.90000","4.79166","0.61595"
"72.00000","4.79854","0.61461"
"72.10000","4.80537","0.61306"
"72.20000","4.81197","0.61161"
"72.30000","4.81884","0.61040"
"72.40000","4.82535","0.60952"
"72.50000","4.83190","0.60836"
"72.60000","4.83847","0.60728"
"72.70000","4.84525","0.60636"
"72.80000","4.85207","0.60573"
"72.90000","4.85850","0.60455"
"73.00000","4.86500","0.60393"
"73.10000","4.87213","0.60365"
"73.20000","4.87908","0.60184"
"73.30000","4.88547","0.60063"
"73.40000","4.89162","0.59953"
"73.50000","4.89824","0.59881"
"73.60000","4.90546","0.59841"
"73.70000","4.91220","0.59674"
"73.80000","4.91865","0.59573"
"73.90000","4.92520","0.59440"
"74.00000","4.93190","0.59297"
"74.10000","4.93892","0.59157"
"74.20000","4.94532","0.58995"
"74.30000","4.95176","0.58866"
"74.40000","4.95845","0.58707"
"74.50000","4.96518","0.58550"
"74.60000","4.97197","0.58437"
"74.70000","4.97875","0.58273"
"74.80000","4.98566","0.58064"
"74.90000","4.99209","0.57882"
"75.00000","4.99832","0.57698"
"75.10000","5.00502","0.57575"
"75.20000","5.01212","0.57462"
"75.30000","5.01873","0.57306"
"75.40000","5.02524","0.57149"
"75.50000","5.03173","0.57032"
"75.60000","5.03898","0.56968"
"75.70000","5.04580","0.56868"
"75.80000","5.05203","0.56655"
"75.90000","5.05820","0.56551"
"76.00000","5.06500","0.56409"
"76.10000","5.07210","0.56307"
"76.20000","5.07889","0.56167"
"76.30000","5.08533","0.56009"
"76.40000","5.09198","0.55887"
"76.50000","5.09854","0.55741"
"76.60000","5.10537","0.55646"
"76.70000","5.11181","0.55482"
"76.80000","5.11853","0.55348"
"76.90000","5.12511","0.55147"
"77.00000","5.13175","0.55004"
"77.10000","5.13860","0.54880"
"77.20000","5.14568","0.54781"
"77.30000","5.15221","0.54611"
"77.40000","5.15856","0.54539"
"77.50000","5.16492","0.54327"
"77.60000","5.17173","0.54237"
"77.70000","5.17896","0.54121"
"77.80000","5.18544","0.53964"
"77.90000","5.19176","0.53820"
"78.00000","5.19855","0.53701"
"78.10000","5.20562","0.53553"
"78.20000","5.21234","0.53426"
"78.30000","5.21861","0.53264"
"78.40000","5.22483","0.53114"
"78.50000","5.23170","0.53011"
"78.60000","5.23884","0.52831"
"78.70000","5.24538","0.52687"
"78.80000","5.25206","0.52551"
"78.90000","5.25864","0.52383"
"79.00000","5.26538","0.52237"
"79.10000","5.27199","0.52125"
"79.20000","5.27848","0.51919"
"79.30000","5.28538","0.51752"
"79.40000","5.29192","0.51551"
"79.50000","5.29845","0.51361"
"79.60000","5.30531","0.51116"
"79.70000","5.31242","0.50850"
"79.80000","5.31898","0.50618"
"79.90000","5.32510","0.50374"
"80.00000","5.33146","0.50162"
"80.10000","5.33870","0.49997"
"80.20000","5.34567","0.49779"
"80.30000","5.35211","0.49547"
"80.40000","5.35833","0.49346"
"80.50000","5.36522","0.49171"
"80.60000","5.37232","0.48982"
"80.70000","5.37873","0.48789"
"80.80000","5.38503","0.48596"
"80.90000","5.39165","0.48366"
"81.00000","5.39848","0.48253"
"81.10000","5.40536","0.48053"
"81.20000","5.41201","0.47831"
"81.30000","5.41899","0.47731"
"81.40000","5.42530","0.47488"
"81.50000","5.43178","0.47346"
"81.60000","5.43849","0.47237"
"81.70000","5.44531","0.47019"
"81.80000","5.45205","0.46894"
"81.90000","5.45848","0.46688"
"82.00000","5.46493","0.46537"
"82.10000","5.47217","0.46469"
"82.20000","5.47927","0.46267"
"82.30000","5.48551","0.46103"
"82.40000","5.49167","0.45930"
"82.50000","5.49816","0.45756"
"82.60000","5.50541","0.45574"
"82.70000","5.51225","0.45356"
"82.80000","5.51867","0.45135"
"82.90000","5.52519","0.44867"
"83.00000","5.53185","0.44659"
"83.10000","5.53887","0.44477"
"83.20000","5.54532","0.44320"
"83.30000","5.55177","0.44123"
"83.40000","5.55844","0.43986"
"83.50000","5.56519","0.43732"
"83.60000","5.57197","0.43580"
"83.70000","5.57882","0.43388"
"83.80000","5.58571","0.43157"
"83.90000","5.59200","0.42923"
"84.00000","5.59833","0.42808"
"84.10000","5.60504","0.42663"
"84.20000","5.61215","0.42513"
"84.30000","5.61881","0.42369"
"84.40000","5.62525","0.42154"
"84.50000","5.63169","0.41974"
"84.60000","5.63894","0.41867"
"84.70000","5.64580","0.41720"
"84.80000","5.65206","0.41476"
"84.90000","5.65815","0.41287"
"85.00000","5.66494","0.41113"
"85.10000","5.67201","0.40930"
"85.20000","5.67890","0.40809"
"85.30000","5.68530","0.40638"
"85.40000","5.69187","0.40495"
"85.50000","5.69852","0.40349"
"85.60000","5.70532","0.40261"
"85.70000","5.71175","0.40104"
"85.80000","5.71853","0.40004"
"85.90000","5.72516","0.39887"
"86.00000","5.73184","0.39779"
"86.10000","5.73851","0.39645"
"86.20000","5.74566","0.39564"
"86.30000","5.75222","0.39399"
"86.40000","5.75861","0.39279"
"86.50000","5.76484","0.39055"
"86.60000","5.77174","0.38982"
"86.70000","5.77894","0.38915"
"86.80000","5.78549","0.38752"
"86.90000","5.79183","0.38591"
"87.00000","5.79850","0.38506"
"87.10000","5.80556","0.38345"
"87.20000","5.81237","0.38158"
"87.30000","5.81857","0.38027"
"87.40000","5.82493","0.37898"
"87.50000","5.83177","0.37802"
"87.60000","5.83880","0.37697"
"87.70000","5.84542","0.37554"
"87.80000","5.85203","0.37447"
"87.90000","5.85853","0.37370"
"88.00000","5.86528","0.37307"
"88.10000","5.87204","0.37175"
"88.20000","5.87850","0.37045"
"88.30000","5.88536","0.36930"
"88.40000","5.89188","0.36721"
"88.50000","5.89840","0.36604"
"88.60000","5.90540","0.36419"
"88.70000","5.91241","0.36189"
"88.80000","5.91901","0.35973"
"88.90000","5.92502","0.35744"
"89.00000","5.93149","0.35562"
"89.10000","5.93870","0.35397"
"89.20000","5.94560","0.35155"
"89.30000","5.95211","0.34940"
"89.40000","5.95828","0.34748"
"89.50000","5.96524","0.34675"
"89.60000","5.97235","0.34520"
"89.70000","5.97875","0.34256"
"89.80000","5.98510","0.34049"
"89.90000","5.99151","0.33885"
"90.00000","5.99840","0.33736"
"90.10000","6.00537","0.33545"
"90.20000","6.01201","0.33349"
"90.30000","6.01897","0.33230"
"90.40000","6.02531","0.33115"
"90.50000","6.03177","0.32927"
"90.60000","6.03841","0.32789"
"90.70000","6.04531","0.32644"
"90.80000","6.05224","0.32505"
"90.90000","6.05842","0.32373"
"91.00000","6.06490","0.32193"
"91.10000","6.07218","0.32035"
"91.20000","6.07918","0.31857"
"91.30000","6.08553","0.31596"
"91.40000","6.09162","0.31412"
"91.50000","6.09815","0.31278"
"91.60000","6.10538","0.31142"
"91.70000","6.11240","0.30984"
"91.80000","6.11869","0.30814"
"91.90000","6.12513","0.30696"
"92.00000","6.13188","0.30587"
"92.10000","6.13890","0.30403"
"92.20000","6.14534","0.30231"
"92.30000","6.15184","0.30120"
"92.40000","6.15847","0.29952"
"92.50000","6.16515","0.29880"
"92.60000","6.17192","0.29714"
"92.70000","6.17892","0.29563"
"92.80000","6.18576","0.29403"
"92.90000","6.19192","0.29277"
"93.00000","6.19823","0.29139"
"93.10000","6.20508","0.28994"
"93.20000","6.21222","0.28879"
"93.30000","6.21877","0.28671"
"93.40000","6.22514","0.28499"
"93.50000","6.23171","0.28285"
"93.60000","6.23898","0.28158"
"93.70000","6.24584","0.28005"
"93.80000","6.25205","0.27811"
"93.90000","6.25816","0.27686"
"94.00000","6.26497","0.27624"
"94.10000","6.27212","0.27512"
"94.20000","6.27889","0.27403"
"94.30000","6.28522","0.27302"
"94.40000","6.29199","0.27146"
"94.50000","6.29851","0.27127"
"94.60000","6.30532","0.26973"
"94.70000","6.31184","0.26879"
"94.80000","6.31862","0.26717"
"94.90000","6.32503","0.26651"
"95.00000","6.33184","0.26495"
"95.10000","6.33856","0.26448"
"95.20000","6.34563","0.26233"
"95.30000","6.35231","0.26136"
"95.40000","6.35857","0.25965"
"95.50000","6.36492","0.25844"
"95.60000","6.37170","0.25720"
"95.70000","6.37890","0.25601"
"95.80000","6.38552","0.25416"
"95.90000","6.39181","0.25285"
"96.00000","6.39843","0.25181"
"96.10000","6.40567","0.25074"
"96.20000","6.41229","0.24916"
"96.30000","6.41854","0.24801"
"96.40000","6.42488","0.24644"
"96.50000","6.43170","0.24543"
"96.60000","6.43886","0.24473"
"96.70000","6.44537","0.24302"
"96.80000","6.45202","0.24209"
"96.90000","6.45856","0.24053"
"97.00000","6.46527","0.23990"
"97.10000","6.47202","0.23849"
"97.20000","6.47849","0.23715"
"97.30000","6.48536","0.23636"
"97.40000","6.49183","0.23574"
"97.50000","6.49848","0.23414"
"97.60000","6.50538","0.23288"
"97.70000","6.51240","0.23140"
"97.80000","6.51906","0.23015"
"97.90000","6.52498","0.22842"
"98.00000","6.53145","0.22772"
"98.10000","6.53869","0.22701"
"98.20000","6.54563","0.22596"
"98.30000","6.55215","0.22476"
"98.40000","6.55840","0.22386"
"98.50000","6.56532","0.22299"
"98.60000","6.57231","0.22261"
"98.70000","6.57871","0.22171"
"98.80000","6.58508","0.22049"
"98.90000","6.59165","0.21982"
"99.00000","6.59840","0.21931"
"99.10000","6.60537","0.21876"
"99.20000","6.61203","0.21803"
"99.30000","6.61892","0.21716"
"99.40000","6.62518","0.21651"
"99.50000","6.63175","0.21550"
"99.60000","6.63845","0.21489"
"99.70000","6.64531","0.21481"
"99.80000","6.65225","0.21388"
"99.90000","6.65844","0.21315"
"100.00000","6.66497","0.21231"
"100.10000","6.67221","0.21198"
"100.20000","6.67924","0.21119"
"100.30000","6.68552","0.21005"
"100.40000","6.69157","0.20933"
"100.50000","6.69811","0.20889"
"100.60000","6.70544","0.20772"
"100.70000","6.71232","0.20716"
"100.80000","6.71866","0.20615"
"100.90000","6.72524","0.20569"
"101.00000","6.73185","0.20513"
"101.10000","6.73893","0.20403"
"101.20000","6.74535","0.20323"
"101.20800","6.74586","0.20332"