File: 20.12.09/1Layer_3.is_flex_RawData/Specimen_RawData_1.csv
Specimen properties : Thickness,"3.80000",mm
Specimen properties : Width,"7.20000",mm
Specimen properties : Support span,"60.80000",mm

Time,Extension,Load
(s),(mm),(kgf)
"0.00000","0.00000","-0.00187"
"0.10000","0.00052","-0.00132"
"0.20000","0.00658","0.00331"
"0.30000","0.01800","0.01027"
"0.40000","0.02514","0.01420"
"0.50000","0.03202","0.01791"
"0.60000","0.03854","0.02139"
"0.70000","0.04500","0.02496"
"0.80000","0.05167","0.02909"
"0.90000","0.05850","0.03230"
"1.00000","0.06529","0.03629"
"1.10000","0.07222","0.03995"
"1.20000","0.07900","0.04342"
"1.30000","0.08520","0.04680"
"1.40000","0.09169","0.05007"
"1.50000","0.09843","0.05340"
"1.60000","0.10552","0.05752"
"1.70000","0.11210","0.06056"
"1.80000","0.11853","0.06374"
"1.90000","0.12518","0.06681"
"2.00000","0.13238","0.07087"
"2.10000","0.13905","0.07272"
"2.20000","0.14520","0.07513"
"2.30000","0.15145","0.07854"
"2.40000","0.15848","0.08187"
"2.50000","0.16544","0.08519"
"2.60000","0.17217","0.08790"
"2.70000","0.17866","0.09085"
"2.80000","0.18531","0.09397"
"2.90000","0.19200","0.09725"
"3.00000","0.19863","0.09960"
"3.10000","0.20504","0.10304"
"3.20000","0.21191","0.10582"
"3.30000","0.21838","0.10885"
"3.40000","0.22527","0.11186"
"3.50000","0.23196","0.11458"
"3.60000","0.23900","0.11783"
"3.70000","0.24554","0.12061"
"3.80000","0.25182","0.12353"
"3.90000","0.25825","0.12620"
"4.00000","0.26521","0.12938"
"4.10000","0.27223","0.13224"
"4.20000","0.27882","0.13539"
"4.30000","0.28494","0.13797"
"4.40000","0.29197","0.14122"
"4.50000","0.29910","0.14331"
"4.60000","0.30559","0.14643"
"4.70000","0.31187","0.14879"
"4.80000","0.31815","0.15164"
"4.90000","0.32521","0.15460"
"5.00000","0.33218","0.15780"
"5.10000","0.33873","0.16047"
"5.20000","0.34543","0.16359"
"5.30000","0.35188","0.16603"
"5.40000","0.35868","0.16937"
"5.50000","0.36524","0.17191"
"5.60000","0.37189","0.17437"
"5.70000","0.37879","0.17742"
"5.80000","0.38518","0.17991"
"5.90000","0.39171","0.18301"
"6.00000","0.39877","0.18587"
"6.10000","0.40571","0.18844"
"6.20000","0.41226","0.19125"
"6.30000","0.41832","0.19369"
"6.40000","0.42488","0.19616"
"6.50000","0.43215","0.19950"
"6.60000","0.43899","0.20220"
"6.70000","0.44534","0.20477"
"6.80000","0.45160","0.20695"
"6.90000","0.45862","0.21018"
"7.00000","0.46574","0.21274"
"7.10000","0.47204","0.21532"
"7.20000","0.47840","0.21800"
"7.30000","0.48492","0.22006"
"7.40000","0.49179","0.22296"
"7.50000","0.49863","0.22600"
"7.60000","0.50530","0.22842"
"7.70000","0.51217","0.23126"
"7.80000","0.51868","0.23379"
"7.90000","0.52512","0.23649"
"8.00000","0.53174","0.23871"
"8.10000","0.53871","0.24203"
"8.20000","0.54539","0.24464"
"8.30000","0.55168","0.24657"
"8.40000","0.55840","0.24976"
"8.50000","0.56577","0.25256"
"8.60000","0.57246","0.25503"
"8.70000","0.57863","0.25715"
"8.80000","0.58476","0.25976"
"8.90000","0.59167","0.26234"
"9.00000","0.59895","0.26494"
"9.10000","0.60548","0.26758"
"9.20000","0.61194","0.27040"
"9.30000","0.61856","0.27257"
"9.40000","0.62535","0.27512"
"9.50000","0.63219","0.27794"
"9.60000","0.63867","0.28053"
"9.70000","0.64516","0.28305"
"9.80000","0.65176","0.28538"
"9.90000","0.65856","0.28778"
"10.00000","0.66540","0.29087"
"10.10000","0.67223","0.29306"
"10.20000","0.67898","0.29563"
"10.30000","0.68524","0.29799"
"10.40000","0.69158","0.29999"
"10.50000","0.69852","0.30255"
"10.60000","0.70564","0.30565"
"10.70000","0.71211","0.30752"
"10.80000","0.71834","0.30979"
"10.90000","0.72510","0.31216"
"11.00000","0.73232","0.31499"
"11.10000","0.73903","0.31782"
"11.20000","0.74530","0.31945"
"11.30000","0.75145","0.32146"
"11.40000","0.75844","0.32390"
"11.50000","0.76552","0.32654"
"11.60000","0.77217","0.32868"
"11.70000","0.77861","0.33104"
"11.80000","0.78515","0.33362"
"11.90000","0.79193","0.33593"
"12.00000","0.79867","0.33796"
"12.10000","0.80517","0.34054"
"12.20000","0.81193","0.34267"
"12.30000","0.81836","0.34462"
"12.40000","0.82513","0.34689"
"12.50000","0.83187","0.34942"
"12.60000","0.83904","0.35184"
"12.70000","0.84552","0.35413"
"12.80000","0.85180","0.35606"
"12.90000","0.85828","0.35824"
"13.00000","0.86521","0.36040"
"13.10000","0.87217","0.36294"
"13.20000","0.87885","0.36468"
"13.30000","0.88500","0.36661"
"13.40000","0.89189","0.36935"
"13.50000","0.89902","0.37168"
"13.60000","0.90562","0.37367"
"13.70000","0.91184","0.37524"
"13.80000","0.91816","0.37728"
"13.90000","0.92526","0.37985"
"14.00000","0.93217","0.38206"
"14.10000","0.93876","0.38411"
"14.20000","0.94548","0.38605"
"14.30000","0.95191","0.38796"
"14.40000","0.95860","0.38994"
"14.50000","0.96520","0.39242"
"14.60000","0.97181","0.39427"
"14.70000","0.97876","0.39658"
"14.80000","0.98513","0.39831"
"14.90000","0.99177","0.40007"
"15.00000","0.99887","0.40271"
"15.10000","1.00573","0.40477"
"15.20000","1.01222","0.40643"
"15.30000","1.01824","0.40804"
"15.40000","1.02480","0.40986"
"15.50000","1.03216","0.41204"
"15.60000","1.03888","0.41440"
"15.70000","1.04537","0.41655"
"15.80000","1.05167","0.41835"
"15.90000","1.05864","0.42011"
"16.00000","1.06569","0.42231"
"16.10000","1.07198","0.42426"
"16.20000","1.07825","0.42627"
"16.30000","1.08506","0.42780"
"16.40000","1.09191","0.42984"
"16.50000","1.09870","0.43202"
"16.60000","1.10532","0.43347"
"16.70000","1.11217","0.43566"
"16.80000","1.11863","0.43734"
"16.90000","1.12511","0.43943"
"17.00000","1.13175","0.44119"
"17.10000","1.13868","0.44306"
"17.20000","1.14550","0.44509"
"17.30000","1.15175","0.44667"
"17.40000","1.15835","0.44885"
"17.50000","1.16563","0.45074"
"17.60000","1.17242","0.45246"
"17.70000","1.17873","0.45385"
"17.80000","1.18492","0.45540"
"17.90000","1.19167","0.45789"
"18.00000","1.19879","0.45970"
"18.10000","1.20551","0.46145"
"18.20000","1.21192","0.46319"
"18.30000","1.21850","0.46478"
"18.40000","1.22535","0.46667"
"18.50000","1.23221","0.46866"
"18.60000","1.23859","0.47043"
"18.70000","1.24513","0.47192"
"18.80000","1.25171","0.47349"
"18.90000","1.25860","0.47552"
"19.00000","1.26542","0.47727"
"19.10000","1.27225","0.47928"
"19.20000","1.27897","0.48072"
"19.30000","1.28523","0.48221"
"19.40000","1.29160","0.48387"
"19.50000","1.29841","0.48544"
"19.60000","1.30561","0.48790"
"19.70000","1.31211","0.48919"
"19.80000","1.31851","0.49057"
"19.90000","1.32516","0.49222"
"20.00000","1.33237","0.49453"
"20.10000","1.33910","0.49579"
"20.20000","1.34524","0.49717"
"20.30000","1.35139","0.49880"
"20.40000","1.35844","0.50055"
"20.50000","1.36545","0.50241"
"20.60000","1.37214","0.50366"
"20.70000","1.37864","0.50517"
"20.80000","1.38531","0.50682"
"20.90000","1.39201","0.50867"
"21.00000","1.39866","0.51001"
"21.10000","1.40508","0.51155"
"21.20000","1.41191","0.51330"
"21.30000","1.41837","0.51477"
"21.40000","1.42517","0.51640"
"21.50000","1.43198","0.51802"
"21.60000","1.43902","0.51971"
"21.70000","1.44550","0.52067"
"21.80000","1.45171","0.52227"
"21.90000","1.45820","0.52383"
"22.00000","1.46531","0.52530"
"22.10000","1.47222","0.52677"
"22.20000","1.47877","0.52836"
"22.30000","1.48498","0.52951"
"22.40000","1.49204","0.53157"
"22.50000","1.49905","0.53308"
"22.60000","1.50550","0.53436"
"22.70000","1.51178","0.53554"
"22.80000","1.51819","0.53701"
"22.90000","1.52527","0.53872"
"23.00000","1.53219","0.54006"
"23.10000","1.53874","0.54169"
"23.20000","1.54550","0.54329"
"23.30000","1.55187","0.54479"
"23.40000","1.55864","0.54578"
"23.50000","1.56527","0.54732"
"23.60000","1.57181","0.54877"
"23.70000","1.57875","0.55011"
"23.80000","1.58514","0.55137"
"23.90000","1.59177","0.55284"
"24.00000","1.59880","0.55438"
"24.10000","1.60573","0.55599"
"24.20000","1.61225","0.55711"
"24.30000","1.61826","0.55803"
"24.40000","1.62487","0.55960"
"24.50000","1.63219","0.56143"
"24.60000","1.63895","0.56270"
"24.70000","1.64538","0.56398"
"24.80000","1.65166","0.56494"
"24.90000","1.65869","0.56671"
"25.00000","1.66566","0.56842"
"25.10000","1.67199","0.56935"
"25.20000","1.67833","0.57061"
"25.30000","1.68501","0.57172"
"25.40000","1.69188","0.57314"
"25.50000","1.69870","0.57427"
"25.60000","1.70525","0.57596"
"25.70000","1.71221","0.57721"
"25.80000","1.71858","0.57798"
"25.90000","1.72508","0.57948"
"26.00000","1.73169","0.58058"
"26.10000","1.73880","0.58220"
"26.20000","1.74546","0.58319"
"26.30000","1.75171","0.58455"
"26.40000","1.75833","0.58576"
"26.50000","1.76574","0.58742"
"26.60000","1.77254","0.58854"
"26.70000","1.77874","0.58975"
"26.80000","1.78478","0.59052"
"26.90000","1.79161","0.59174"
"27.00000","1.79896","0.59385"
"27.10000","1.80556","0.59488"
"27.20000","1.81197","0.59574"
"27.30000","1.81847","0.59707"
"27.40000","1.82527","0.59830"
"27.50000","1.83223","0.59934"
"27.60000","1.83870","0.60056"
"27.70000","1.84514","0.60147"
"27.80000","1.85179","0.60286"
"27.90000","1.85857","0.60436"
"28.00000","1.86541","0.60546"
"28.10000","1.87223","0.60664"
"28.20000","1.87894","0.60770"
"28.30000","1.88524","0.60864"
"28.40000","1.89159","0.60995"
"28.50000","1.89840","0.61112"
"28.60000","1.90558","0.61269"
"28.70000","1.91213","0.61357"
"28.80000","1.91841","0.61426"
"28.90000","1.92516","0.61571"
"29.00000","1.93247","0.61735"
"29.10000","1.93909","0.61828"
"29.20000","1.94523","0.61872"
"29.30000","1.95136","0.61997"
"29.40000","1.95840","0.62145"
"29.50000","1.96551","0.62271"
"29.60000","1.97216","0.62428"
"29.70000","1.97857","0.62492"
"29.80000","1.98525","0.62596"
"29.90000","1.99195","0.62730"
"30.00000","1.99868","0.62826"
"30.10000","2.00519","0.62923"
"30.20000","2.01189","0.63020"
"30.30000","2.01839","0.63138"
"30.40000","2.02515","0.63247"
"30.50000","2.03190","0.63361"
"30.60000","2.03902","0.63468"
"30.70000","2.04562","0.63584"
"30.80000","2.05180","0.63658"
"30.90000","2.05815","0.63753"
"31.00000","2.06524","0.63931"
"31.10000","2.07227","0.64006"
"31.20000","2.07880","0.64097"
"31.30000","2.08506","0.64190"
"31.40000","2.09191","0.64296"
"31.50000","2.09904","0.64422"
"31.60000","2.10555","0.64543"
"31.70000","2.11181","0.64607"
"31.80000","2.11816","0.64692"
"31.90000","2.12522","0.64798"
"32.00000","2.13223","0.64943"
"32.10000","2.13870","0.65025"
"32.20000","2.14547","0.65142"
"32.30000","2.15193","0.65213"
"32.40000","2.15860","0.65305"
"32.50000","2.16519","0.65400"
"32.60000","2.17182","0.65523"
"32.70000","2.17875","0.65656"
"32.80000","2.18517","0.65734"
"32.90000","2.19178","0.65792"
"33.00000","2.19879","0.65953"
"33.10000","2.20569","0.66069"
"33.20000","2.21216","0.66125"
"33.30000","2.21840","0.66206"
"33.40000","2.22488","0.66348"
"33.50000","2.23213","0.66430"
"33.60000","2.23894","0.66539"
"33.70000","2.24530","0.66610"
"33.80000","2.25163","0.66698"
"33.90000","2.25872","0.66809"
"34.00000","2.26571","0.66875"
"34.10000","2.27195","0.66972"
"34.20000","2.27821","0.67029"
"34.30000","2.28503","0.67164"
"34.40000","2.29193","0.67312"
"34.50000","2.29870","0.67351"
"34.60000","2.30535","0.67466"
"34.70000","2.31221","0.67595"
"34.80000","2.31864","0.67664"
"34.90000","2.32510","0.67756"
"35.00000","2.33173","0.67792"
"35.10000","2.33877","0.67894"
"35.20000","2.34539","0.67991"
"35.30000","2.35186","0.68124"
"35.40000","2.35837","0.68155"
"35.50000","2.36561","0.68329"
"35.60000","2.37234","0.68410"
"35.70000","2.37870","0.68499"
"35.80000","2.38480","0.68552"
"35.90000","2.39179","0.68708"
"36.00000","2.39885","0.68760"
"36.10000","2.40550","0.68852"
"36.20000","2.41193","0.68935"
"36.30000","2.41850","0.69039"
"36.40000","2.42528","0.69129"
"36.50000","2.43216","0.69228"
"36.60000","2.43863","0.69283"
"36.70000","2.44521","0.69347"
"36.80000","2.45178","0.69505"
"36.90000","2.45859","0.69542"
"37.00000","2.46534","0.69663"
"37.10000","2.47223","0.69725"
"37.20000","2.47897","0.69806"
"37.30000","2.48520","0.69905"
"37.40000","2.49171","0.70013"
"37.50000","2.49852","0.70077"
"37.60000","2.50558","0.70161"
"37.70000","2.51212","0.70232"
"37.80000","2.51844","0.70290"
"37.90000","2.52522","0.70434"
"38.00000","2.53239","0.70519"
"38.10000","2.53908","0.70574"
"38.20000","2.54524","0.70618"
"38.30000","2.55143","0.70681"
"38.40000","2.55843","0.70793"
"38.50000","2.56547","0.70942"
"38.60000","2.57218","0.70991"
"38.70000","2.57859","0.71079"
"38.80000","2.58519","0.71176"
"38.90000","2.59201","0.71242"
"39.00000","2.59868","0.71287"
"39.10000","2.60514","0.71367"
"39.20000","2.61193","0.71462"
"39.30000","2.61841","0.71529"
"39.40000","2.62520","0.71609"
"39.50000","2.63192","0.71687"
"39.60000","2.63908","0.71798"
"39.70000","2.64553","0.71858"
"39.80000","2.65183","0.71910"
"39.90000","2.65819","0.71969"
"40.00000","2.66526","0.72084"
"40.10000","2.67221","0.72148"
"40.20000","2.67878","0.72225"
"40.30000","2.68493","0.72247"
"40.40000","2.69195","0.72365"
"40.50000","2.69907","0.72482"
"40.60000","2.70552","0.72517"
"40.70000","2.71176","0.72562"
"40.80000","2.71819","0.72650"
"40.90000","2.72507","0.72740"
"41.00000","2.73223","0.72813"
"41.10000","2.73881","0.72889"
"41.20000","2.74539","0.72967"
"41.30000","2.75191","0.73012"
"41.40000","2.75871","0.73087"
"41.50000","2.76535","0.73177"
"41.60000","2.77190","0.73236"
"41.70000","2.77877","0.73309"
"41.80000","2.78515","0.73388"
"41.90000","2.79180","0.73418"
"42.00000","2.79876","0.73509"
"42.10000","2.80580","0.73614"
"42.20000","2.81212","0.73618"
"42.30000","2.81821","0.73710"
"42.40000","2.82487","0.73767"
"42.50000","2.83222","0.73878"
"42.60000","2.83900","0.73941"
"42.70000","2.84530","0.73970"
"42.80000","2.85157","0.74009"
"42.90000","2.85856","0.74074"
"43.00000","2.86570","0.74183"
"43.10000","2.87205","0.74249"
"43.20000","2.87839","0.74288"
"43.30000","2.88494","0.74324"
"43.40000","2.89186","0.74450"
"43.50000","2.89867","0.74496"
"43.60000","2.90546","0.74586"
"43.70000","2.91227","0.74636"
"43.80000","2.91847","0.74688"
"43.90000","2.92510","0.74736"
"44.00000","2.93171","0.74766"
"44.10000","2.93879","0.74862"
"44.20000","2.94547","0.74919"
"44.30000","2.95172","0.75008"
"44.40000","2.95828","0.75036"
"44.50000","2.96567","0.75174"
"44.60000","2.97258","0.75231"
"44.70000","2.97881","0.75259"
"44.80000","2.98481","0.75263"
"44.90000","2.99163","0.75366"
"45.00000","2.99891","0.75483"
"45.10000","3.00563","0.75509"
"45.20000","3.01193","0.75560"
"45.30000","3.01845","0.75613"
"45.40000","3.02529","0.75686"
"45.50000","3.03223","0.75725"
"45.60000","3.03864","0.75795"
"45.70000","3.04510","0.75804"
"45.80000","3.05176","0.75926"
"45.90000","3.05857","0.75957"
"46.00000","3.06536","0.76014"
"46.10000","3.07225","0.76083"
"46.20000","3.07898","0.76162"
"46.30000","3.08526","0.76165"
"46.40000","3.09157","0.76197"
"46.50000","3.09848","0.76240"
"46.60000","3.10556","0.76368"
"46.70000","3.11214","0.76413"
"46.80000","3.11842","0.76464"
"46.90000","3.12515","0.76508"
"47.00000","3.13246","0.76598"
"47.10000","3.13911","0.76641"
"47.20000","3.14520","0.76679"
"47.30000","3.15136","0.76703"
"47.40000","3.15841","0.76762"
"47.50000","3.16554","0.76847"
"47.60000","3.17222","0.76904"
"47.70000","3.17862","0.76937"
"47.80000","3.18524","0.76981"
"47.90000","3.19199","0.77054"
"48.00000","3.19866","0.77101"
"48.10000","3.20512","0.77143"
"48.20000","3.21184","0.77168"
"48.30000","3.21839","0.77234"
"48.40000","3.22521","0.77298"
"48.50000","3.23191","0.77362"
"48.60000","3.23902","0.77425"
"48.70000","3.24559","0.77443"
"48.80000","3.25183","0.77493"
"48.90000","3.25818","0.77526"
"49.00000","3.26522","0.77625"
"49.10000","3.27219","0.77683"
"49.20000","3.27883","0.77743"
"49.30000","3.28502","0.77749"
"49.40000","3.29200","0.77819"
"49.50000","3.29905","0.77923"
"49.60000","3.30556","0.77934"
"49.70000","3.31181","0.77962"
"49.80000","3.31816","0.77970"
"49.90000","3.32517","0.78106"
"50.00000","3.33218","0.78131"
"50.10000","3.33878","0.78177"
"50.20000","3.34547","0.78220"
"50.30000","3.35178","0.78238"
"50.40000","3.35858","0.78286"
"50.50000","3.36521","0.78312"
"50.60000","3.37189","0.78403"
"50.70000","3.37887","0.78423"
"50.80000","3.38510","0.78445"
"50.90000","3.39173","0.78501"
"51.00000","3.39886","0.78585"
"51.10000","3.40579","0.78611"
"51.20000","3.41218","0.78640"
"51.30000","3.41827","0.78637"
"51.40000","3.42486","0.78708"
"51.50000","3.43220","0.78800"
"51.60000","3.43903","0.78805"
"51.70000","3.44533","0.78842"
"51.80000","3.45157","0.78820"
"51.90000","3.45865","0.78945"
"52.00000","3.46578","0.78975"
"52.10000","3.47204","0.78972"
"52.20000","3.47834","0.79040"
"52.30000","3.48491","0.79046"
"52.40000","3.49187","0.79131"
"52.50000","3.49872","0.79186"
"52.60000","3.50540","0.79207"
"52.70000","3.51221","0.79239"
"52.80000","3.51853","0.79255"
"52.90000","3.52505","0.79303"
"53.00000","3.53174","0.79352"
"53.10000","3.53872","0.79403"
"53.20000","3.54545","0.79400"
"53.30000","3.55173","0.79457"
"53.40000","3.55825","0.79484"
"53.50000","3.56566","0.79553"
"53.60000","3.57252","0.79590"
"53.70000","3.57871","0.79580"
"53.80000","3.58484","0.79606"
"53.90000","3.59166","0.79639"
"54.00000","3.59888","0.79701"
"54.10000","3.60554","0.79730"
"54.20000","3.61197","0.79769"
"54.30000","3.61860","0.79801"
"54.40000","3.62533","0.79901"
"54.50000","3.63212","0.79907"
"54.60000","3.63855","0.79916"
"54.70000","3.64513","0.79900"
"54.80000","3.65182","0.79960"
"54.90000","3.65851","0.80014"
"55.00000","3.66535","0.80005"
"55.10000","3.67224","0.80085"
"55.20000","3.67899","0.80096"
"55.30000","3.68528","0.80107"
"55.40000","3.69155","0.80178"
"55.50000","3.69842","0.80181"
"55.60000","3.70552","0.80256"
"55.70000","3.71215","0.80281"
"55.80000","3.71854","0.80288"
"55.90000","3.72515","0.80306"
"56.00000","3.73235","0.80384"
"56.10000","3.73904","0.80406"
"56.20000","3.74530","0.80407"
"56.30000","3.75151","0.80417"
"56.40000","3.75840","0.80508"
"56.50000","3.76548","0.80564"
"56.60000","3.77210","0.80569"
"56.70000","3.77859","0.80610"
"56.80000","3.78536","0.80662"
"56.90000","3.79187","0.80637"
"57.00000","3.79851","0.80709"
"57.10000","3.80506","0.80706"
"57.20000","3.81190","0.80772"
"57.30000","3.81855","0.80788"
"57.40000","3.82518","0.80841"
"57.50000","3.83190","0.80811"
"57.60000","3.83895","0.80872"
"57.70000","3.84554","0.80922"
"57.80000","3.85190","0.80925"
"57.90000","3.85823","0.80921"
"58.00000","3.86517","0.80976"
"58.10000","3.87214","0.81013"
"58.20000","3.87875","0.81072"
"58.30000","3.88516","0.81034"
"58.40000","3.89202","0.81069"
"58.50000","3.89896","0.81061"
"58.60000","3.90553","0.81105"
"58.70000","3.91182","0.81088"
"58.80000","3.91832","0.81128"
"58.90000","3.92524","0.81167"
"59.00000","3.93211","0.81193"
"59.10000","3.93860","0.81181"
"59.20000","3.94535","0.81240"
"59.30000","3.95202","0.81235"
"59.40000","3.95874","0.81302"
"59.50000","3.96519","0.81271"
"59.60000","3.97183","0.81307"
"59.70000","3.97865","0.81324"
"59.80000","3.98539","0.81386"
"59.90000","3.99181","0.81337"
"60.00000","3.99873","0.81381"
"60.10000","4.00567","0.81403"
"60.20000","4.01216","0.81400"
"60.30000","4.01847","0.81332"
"60.40000","4.02492","0.81330"
"60.50000","4.03214","0.81391"
"60.60000","4.03886","0.81387"
"60.70000","4.04528","0.81373"
"60.80000","4.05173","0.81420"
"60.90000","4.05868","0.81379"
"61.00000","4.06554","0.81397"
"61.10000","4.07191","0.81448"
"61.20000","4.07825","0.81386"
"61.30000","4.08522","0.81416"
"61.40000","4.09193","0.81457"
"61.50000","4.09855","0.81446"
"61.60000","4.10520","0.81477"
"61.70000","4.11214","0.81480"
"61.80000","4.11883","0.81510"
"61.90000","4.12518","0.81521"
"62.00000","4.13169","0.81504"
"62.10000","4.13865","0.81523"
"62.20000","4.14540","0.81556"
"62.30000","4.15196","0.81548"
"62.40000","4.15842","0.81562"
"62.50000","4.16553","0.81584"
"62.60000","4.17237","0.81611"
"62.70000","4.17867","0.81552"
"62.80000","4.18494","0.81527"
"62.90000","4.19178","0.81514"
"63.00000","4.19873","0.81502"
"63.10000","4.20537","0.81526"
"63.20000","4.21188","0.81517"
"63.30000","4.21868","0.81477"
"63.40000","4.22542","0.81470"
"63.50000","4.23218","0.81473"
"63.60000","4.23848","0.81398"
"63.70000","4.24504","0.81368"
"63.80000","4.25195","0.81353"
"63.90000","4.25862","0.81384"
"64.00000","4.26538","0.81344"
"64.10000","4.27214","0.81380"
"64.20000","4.27888","0.81307"
"64.30000","4.28544","0.81320"
"64.40000","4.29173","0.81272"
"64.50000","4.29835","0.81250"
"64.60000","4.30545","0.81261"
"64.70000","4.31205","0.81216"
"64.80000","4.31865","0.81238"
"64.90000","4.32523","0.81187"
"65.00000","4.33227","0.81252"
"65.10000","4.33895","0.81169"
"65.20000","4.34521","0.81171"
"65.30000","4.35157","0.81117"
"65.40000","4.35846","0.81144"
"65.50000","4.36542","0.81123"
"65.60000","4.37199","0.81107"
"65.70000","4.37848","0.81103"
"65.80000","4.38554","0.81065"
"65.90000","4.39205","0.81085"
"66.00000","4.39853","0.81059"
"66.10000","4.40498","0.81016"
"66.20000","4.41188","0.81038"
"66.30000","4.41859","0.81040"
"66.40000","4.42528","0.81049"
"66.50000","4.43187","0.81015"
"66.60000","4.43880","0.81011"
"66.70000","4.44553","0.81000"
"66.80000","4.45202","0.80975"
"66.90000","4.45829","0.80947"
"67.00000","4.46516","0.80980"
"67.10000","4.47205","0.80928"
"67.20000","4.47871","0.80927"
"67.30000","4.48526","0.80873"
"67.40000","4.49212","0.80883"
"67.50000","4.49902","0.80877"
"67.60000","4.50541","0.80791"
"67.70000","4.51169","0.80748"
"67.80000","4.51835","0.80729"
"67.90000","4.52529","0.80719"
"68.00000","4.53212","0.80696"
"68.10000","4.53869","0.80665"
"68.20000","4.54533","0.80653"
"68.30000","4.55210","0.80571"
"68.40000","4.55867","0.80584"
"68.50000","4.56522","0.80539"
"68.60000","4.57180","0.80527"
"68.70000","4.57871","0.80452"
"68.80000","4.58534","0.80432"
"68.90000","4.59180","0.80428"
"69.00000","4.59870","0.80386"
"69.10000","4.60567","0.80374"
"69.20000","4.61218","0.80361"
"69.30000","4.61846","0.80330"
"69.40000","4.62490","0.80314"
"69.50000","4.63210","0.80292"
"69.60000","4.63894","0.80283"
"69.70000","4.64534","0.80243"
"69.80000","4.65170","0.80216"
"69.90000","4.65866","0.80263"
"70.00000","4.66555","0.80197"
"70.10000","4.67196","0.80156"
"70.20000","4.67831","0.80112"
"70.30000","4.68513","0.80107"
"70.40000","4.69193","0.80068"
"70.50000","4.69854","0.80049"
"70.60000","4.70521","0.80003"
"70.70000","4.71218","0.80001"
"70.80000","4.71868","0.79911"
"70.90000","4.72513","0.79897"
"71.00000","4.73168","0.79888"
"71.10000","4.73865","0.79898"
"71.20000","4.74543","0.79829"
"71.30000","4.75184","0.79814"
"71.40000","4.75839","0.79772"
"71.50000","4.76564","0.79815"
"71.60000","4.77239","0.79753"
"71.70000","4.77870","0.79719"
"71.80000","4.78491","0.79636"
"71.90000","4.79178","0.79660"
"72.00000","4.79878","0.79671"
"72.10000","4.80549","0.79607"
"72.20000","4.81188","0.79570"
"72.30000","4.81859","0.79574"
"72.40000","4.82532","0.79505"
"72.50000","4.83220","0.79476"
"72.60000","4.83855","0.79464"
"72.70000","4.84508","0.79402"
"72.80000","4.85184","0.79385"
"72.90000","4.85868","0.79343"
"73.00000","4.86538","0.79297"
"73.10000","4.87215","0.79279"
"73.20000","4.87889","0.79184"
"73.30000","4.88523","0.79180"
"73.40000","4.89169","0.79124"
"73.50000","4.89842","0.79130"
"73.60000","4.90550","0.79074"
"73.70000","4.91203","0.78963"
"73.80000","4.91849","0.78962"
"73.90000","4.92533","0.78909"
"74.00000","4.93233","0.78913"
"74.10000","4.93897","0.78808"
"74.20000","4.94521","0.78766"
"74.30000","4.95143","0.78713"
"74.40000","4.95855","0.78698"
"74.50000","4.96541","0.78623"
"74.60000","4.97215","0.78549"
"74.70000","4.97853","0.78505"
"74.80000","4.98522","0.78452"
"74.90000","4.99203","0.78388"
"75.00000","4.99855","0.78316"
"75.10000","5.00510","0.78243"
"75.20000","5.01191","0.78237"
"75.30000","5.01842","0.78156"
"75.40000","5.02522","0.78113"
"75.50000","5.03185","0.78040"
"75.60000","5.03904","0.78013"
"75.70000","5.04553","0.77930"
"75.80000","5.05180","0.77854"
"75.90000","5.05828","0.77810"
"76.00000","5.06522","0.77811"
"76.10000","5.07222","0.77758"
"76.20000","5.07870","0.77697"
"76.30000","5.08502","0.77671"
"76.40000","5.09209","0.77589"
"76.50000","5.09907","0.77565"
"76.60000","5.10554","0.77523"
"76.70000","5.11175","0.77425"
"76.80000","5.11819","0.77393"
"76.90000","5.12528","0.77386"
"77.00000","5.13216","0.77375"
"77.10000","5.13871","0.77294"
"77.20000","5.14539","0.77268"
"77.30000","5.15200","0.77270"
"77.40000","5.15870","0.77276"
"77.50000","5.16528","0.77223"
"77.60000","5.17188","0.77166"
"77.70000","5.17862","0.77152"
"77.80000","5.18510","0.77103"
"77.90000","5.19185","0.77070"
"78.00000","5.19885","0.77044"
"78.10000","5.20576","0.77020"
"78.20000","5.21214","0.76977"
"78.30000","5.21823","0.76921"
"78.40000","5.22483","0.76870"
"78.50000","5.23219","0.76879"
"78.60000","5.23895","0.76794"
"78.70000","5.24538","0.76734"
"78.80000","5.25164","0.76704"
"78.90000","5.25866","0.76653"
"79.00000","5.26580","0.76611"
"79.10000","5.27203","0.76546"
"79.20000","5.27829","0.76456"
"79.30000","5.28500","0.76417"
"79.40000","5.29193","0.76393"
"79.50000","5.29871","0.76377"
"79.60000","5.30539","0.76261"
"79.70000","5.31205","0.76210"
"79.80000","5.31856","0.76211"
"79.90000","5.32511","0.76192"
"80.00000","5.33178","0.76114"
"80.10000","5.33881","0.76062"
"80.20000","5.34541","0.75964"
"80.30000","5.35170","0.75963"
"80.40000","5.35829","0.75874"
"80.50000","5.36567","0.75956"
"80.60000","5.37248","0.75845"
"80.70000","5.37867","0.75747"
"80.80000","5.38481","0.75724"
"80.90000","5.39165","0.75672"
"81.00000","5.39896","0.75701"
"81.10000","5.40559","0.75581"
"81.20000","5.41187","0.75523"
"81.30000","5.41848","0.75522"
"81.40000","5.42540","0.75481"
"81.50000","5.43222","0.75457"
"81.60000","5.43862","0.75372"
"81.70000","5.44511","0.75306"
"81.80000","5.45172","0.75295"
"81.90000","5.45861","0.75258"
"82.00000","5.46544","0.75191"
"82.10000","5.47216","0.75175"
"82.20000","5.47895","0.75082"
"82.30000","5.48527","0.75013"
"82.40000","5.49166","0.74916"
"82.50000","5.49847","0.74879"
"82.60000","5.50556","0.74871"
"82.70000","5.51205","0.74764"
"82.80000","5.51856","0.74701"
"82.90000","5.52521","0.74691"
"83.00000","5.53241","0.74594"
"83.10000","5.53907","0.74529"
"83.20000","5.54525","0.74397"
"83.30000","5.55143","0.74332"
"83.40000","5.55846","0.74325"
"83.50000","5.56549","0.74260"
"83.60000","5.57215","0.74205"
"83.70000","5.57856","0.74123"
"83.80000","5.58522","0.74092"
"83.90000","5.59198","0.74066"
"84.00000","5.59869","0.73997"
"84.10000","5.60515","0.73885"
"84.20000","5.61189","0.73811"
"84.30000","5.61838","0.73792"
"84.40000","5.62515","0.73729"
"84.50000","5.63194","0.73633"
"84.60000","5.63904","0.73634"
"84.70000","5.64552","0.73518"
"84.80000","5.65184","0.73470"
"84.90000","5.65814","0.73373"
"85.00000","5.66518","0.73350"
"85.10000","5.67233","0.73314"
"85.20000","5.67879","0.73251"
"85.30000","5.68502","0.73158"
"85.40000","5.69205","0.73163"
"85.50000","5.69900","0.73110"
"85.60000","5.70547","0.73039"
"85.70000","5.71171","0.72956"
"85.80000","5.71830","0.72903"
"85.90000","5.72533","0.72795"
"86.00000","5.73215","0.72715"
"86.10000","5.73869","0.72623"
"86.20000","5.74534","0.72550"
"86.30000","5.75195","0.72492"
"86.40000","5.75875","0.72354"
"86.50000","5.76532","0.72242"
"86.60000","5.77184","0.72142"
"86.70000","5.77869","0.72048"
"86.80000","5.78520","0.71935"
"86.90000","5.79183","0.71850"
"87.00000","5.79875","0.71741"
"87.10000","5.80572","0.71654"
"87.20000","5.81217","0.71527"
"87.30000","5.81840","0.71389"
"87.40000","5.82496","0.71306"
"87.50000","5.83213","0.71156"
"87.60000","5.83884","0.70985"
"87.70000","5.84534","0.70816"
"87.80000","5.85172","0.70675"
"87.90000","5.85864","0.70604"
"88.00000","5.86562","0.70516"
"88.10000","5.87199","0.70410"
"88.20000","5.87828","0.70331"
"88.30000","5.88512","0.70271"
"88.40000","5.89198","0.70192"
"88.50000","5.89863","0.70089"
"88.60000","5.90520","0.69924"
"88.70000","5.91214","0.69877"
"88.80000","5.91872","0.69751"
"88.90000","5.92521","0.69615"
"89.00000","5.93171","0.69434"
"89.10000","5.93862","0.69331"
"89.20000","5.94541","0.69225"
"89.30000","5.95175","0.69067"
"89.40000","5.95835","0.68918"
"89.50000","5.96564","0.68820"
"89.60000","5.97243","0.68648"
"89.70000","5.97871","0.68460"
"89.80000","5.98488","0.68161"
"89.90000","5.99171","0.68054"
"90.00000","5.99886","0.67850"
"90.10000","6.00549","0.67613"
"90.20000","6.01194","0.67402"
"90.30000","6.01857","0.67156"
"90.40000","6.02530","0.66953"
"90.50000","6.03218","0.66757"
"90.60000","6.03860","0.66478"
"90.70000","6.04507","0.66280"
"90.80000","6.05176","0.66117"
"90.90000","6.05861","0.65901"
"91.00000","6.06535","0.65677"
"91.10000","6.07216","0.65427"
"91.20000","6.07886","0.65232"
"91.30000","6.08528","0.65030"
"91.40000","6.09170","0.64863"
"91.50000","6.09848","0.64712"
"91.60000","6.10549","0.64512"
"91.70000","6.11211","0.64292"
"91.80000","6.11852","0.64106"
"91.90000","6.12519","0.63928"
"92.00000","6.13237","0.63761"
"92.10000","6.13902","0.63627"
"92.20000","6.14525","0.63456"
"92.30000","6.15148","0.63249"
"92.40000","6.15849","0.63166"
"92.50000","6.16545","0.62949"
"92.60000","6.17207","0.62791"
"92.70000","6.17858","0.62700"
"92.80000","6.18535","0.62519"
"92.90000","6.19215","0.62357"
"93.00000","6.19864","0.62163"
"93.10000","6.20499","0.62006"
"93.20000","6.21187","0.61874"
"93.30000","6.21845","0.61729"
"93.40000","6.22516","0.61621"
"93.50000","6.23188","0.61434"
"93.60000","6.23909","0.61329"
"93.70000","6.24561","0.61158"
"93.80000","6.25180","0.60957"
"93.90000","6.25823","0.60860"
"94.00000","6.26521","0.60724"
"94.10000","6.27214","0.60589"
"94.20000","6.27875","0.60406"
"94.30000","6.28513","0.60215"
"94.40000","6.29210","0.60133"
"94.50000","6.29902","0.59915"
"94.60000","6.30546","0.59738"
"94.70000","6.31181","0.59563"
"94.80000","6.31821","0.59425"
"94.90000","6.32517","0.59295"
"95.00000","6.33214","0.59122"
"95.10000","6.33869","0.58945"
"95.20000","6.34545","0.58820"
"95.30000","6.35198","0.58666"
"95.40000","6.35874","0.58538"
"95.50000","6.36522","0.58410"
"95.60000","6.37185","0.58297"
"95.70000","6.37878","0.58158"
"95.80000","6.38518","0.57986"
"95.90000","6.39178","0.57906"
"96.00000","6.39873","0.57754"
"96.10000","6.40573","0.57630"
"96.20000","6.41224","0.57491"
"96.30000","6.41835","0.57383"
"96.40000","6.42489","0.57269"
"96.50000","6.43212","0.57174"
"96.60000","6.43902","0.57045"
"96.70000","6.44536","0.56971"
"96.80000","6.45164","0.56865"
"96.90000","6.45868","0.56781"
"97.00000","6.46560","0.56700"
"97.10000","6.47198","0.56602"
"97.20000","6.47840","0.56403"
"97.30000","6.48498","0.56364"
"97.40000","6.49188","0.56302"
"97.50000","6.49853","0.56211"
"97.60000","6.50529","0.56077"
"97.70000","6.51231","0.55969"
"97.80000","6.51869","0.55840"
"97.90000","6.52520","0.55731"
"98.00000","6.53178","0.55589"
"98.10000","6.53868","0.55457"
"98.20000","6.54550","0.55361"
"98.30000","6.55176","0.55255"
"98.40000","6.55824","0.55120"
"98.50000","6.56556","0.55057"
"98.60000","6.57251","0.54910"
"98.70000","6.57878","0.54698"
"98.80000","6.58488","0.54523"
"98.90000","6.59165","0.54469"
"99.00000","6.59877","0.54325"
"99.10000","6.60549","0.54166"
"99.20000","6.61201","0.53983"
"99.30000","6.61866","0.53826"
"99.40000","6.62536","0.53718"
"99.50000","6.63217","0.53602"
"99.60000","6.63861","0.53420"
"99.70000","6.64507","0.53309"
"99.80000","6.65177","0.53211"
"99.90000","6.65856","0.53089"
"100.00000","6.66540","0.52965"
"100.10000","6.67219","0.52798"
"100.20000","6.67896","0.52652"
"100.30000","6.68520","0.52517"
"100.40000","6.69161","0.52336"
"100.50000","6.69850","0.52209"
"100.60000","6.70561","0.52097"
"100.70000","6.71211","0.51951"
"100.80000","6.71857","0.51805"
"100.90000","6.72516","0.51649"
"101.00000","6.73229","0.51502"
"101.10000","6.73902","0.51343"
"101.20000","6.74529","0.51213"
"101.30000","6.75146","0.51041"
"101.40000","6.75842","0.50896"
"101.50000","6.76538","0.50717"
"101.60000","6.77214","0.50533"
"101.70000","6.77859","0.50319"
"101.80000","6.78514","0.50132"
"101.90000","6.79192","0.49974"
"102.00000","6.79862","0.49789"
"102.10000","6.80506","0.49533"
"102.20000","6.81194","0.49392"
"102.30000","6.81840","0.49183"
"102.40000","6.82519","0.49028"
"102.50000","6.83188","0.48823"
"102.60000","6.83907","0.48610"
"102.70000","6.84558","0.48449"
"102.80000","6.85178","0.48189"
"102.90000","6.85812","0.48005"
"103.00000","6.86520","0.47846"
"103.10000","6.87228","0.47721"
"103.20000","6.87879","0.47486"
"103.30000","6.88505","0.47312"
"103.40000","6.89198","0.47150"
"103.50000","6.89903","0.46914"
"103.60000","6.90558","0.46700"
"103.70000","6.91177","0.46513"
"103.80000","6.91820","0.46272"
"103.90000","6.92520","0.46036"
"104.00000","6.93225","0.45800"
"104.10000","6.93875","0.45507"
"104.20000","6.94542","0.45147"
"104.30000","6.95186","0.44762"
"104.40000","6.95864","0.44434"
"104.50000","6.96534","0.44091"
"104.60000","6.97192","0.43753"
"104.70000","6.97874","0.43536"
"104.80000","6.98516","0.43264"
"104.90000","6.99173","0.42945"
"105.00000","6.99879","0.42769"
"105.10000","7.00578","0.42544"
"105.20000","7.01222","0.42282"
"105.30000","7.01832","0.42122"
"105.40000","7.02490","0.41941"
"105.50000","7.03213","0.41738"
"105.60000","7.03888","0.41564"
"105.70000","7.04537","0.41374"
"105.80000","7.05158","0.41214"
"105.90000","7.05868","0.41116"
"106.00000","7.06575","0.40978"
"106.10000","7.07196","0.40789"
"106.20000","7.07826","0.40700"
"106.30000","7.08489","0.40599"
"106.40000","7.09194","0.40437"
"106.50000","7.09871","0.40259"
"106.60000","7.10535","0.40140"
"106.70000","7.11222","0.40005"
"106.80000","7.11862","0.39849"
"106.90000","7.12504","0.39721"
"107.00000","7.13167","0.39561"
"107.10000","7.13877","0.39485"
"107.20000","7.14551","0.39408"
"107.30000","7.15173","0.39268"
"107.40000","7.15831","0.39227"
"107.50000","7.16572","0.39131"
"107.60000","7.17251","0.39022"
"107.70000","7.17868","0.38869"
"107.80000","7.18477","0.38746"
"107.90000","7.19167","0.38628"
"108.00000","7.19897","0.38495"
"108.10000","7.20551","0.38309"
"108.20000","7.21196","0.38082"
"108.30000","7.21851","0.37890"
"108.40000","7.22520","0.37734"
"108.50000","7.23218","0.37480"
"108.60000","7.23867","0.37309"
"108.70000","7.24522","0.37091"
"108.80000","7.25180","0.36896"
"108.90000","7.25852","0.36709"
"109.00000","7.26533","0.36456"
"109.10000","7.27230","0.36225"
"109.20000","7.27901","0.36043"
"109.30000","7.28516","0.35777"
"109.40000","7.29164","0.35578"
"109.50000","7.29851","0.35371"
"109.60000","7.30554","0.35110"
"109.70000","7.31208","0.34854"
"109.80000","7.31847","0.34575"
"109.90000","7.32518","0.34360"
"110.00000","7.33236","0.34021"
"110.10000","7.33909","0.33513"
"110.20000","7.34523","0.32877"
"110.30000","7.35140","0.32137"
"110.40000","7.35843","0.31616"
"110.50000","7.36546","0.31176"
"110.60000","7.37222","0.30737"
"110.70000","7.37860","0.30326"
"110.80000","7.38533","0.29809"
"110.90000","7.39195","0.29383"
"111.00000","7.39863","0.28980"
"111.10000","7.40506","0.28622"
"111.20000","7.41193","0.28266"
"111.30000","7.41843","0.27967"
"111.40000","7.42519","0.27700"
"111.50000","7.43192","0.27445"
"111.60000","7.43909","0.27241"
"111.70000","7.44553","0.27076"
"111.80000","7.45171","0.26860"
"111.90000","7.45814","0.26689"
"112.00000","7.46526","0.26585"
"112.10000","7.47223","0.26444"
"112.20000","7.47878","0.26305"
"112.30000","7.48508","0.26122"
"112.40000","7.49200","0.26019"
"112.50000","7.49898","0.25824"
"112.60000","7.50550","0.25667"
"112.70000","7.51187","0.25576"
"112.80000","7.51817","0.25478"
"112.90000","7.52522","0.25359"
"113.00000","7.53217","0.25286"
"113.10000","7.53869","0.25145"
"113.20000","7.54543","0.25092"
"113.30000","7.55191","0.24935"
"113.40000","7.55862","0.24829"
"113.50000","7.56521","0.24778"
"113.60000","7.57187","0.24715"
"113.70000","7.57875","0.24584"
"113.80000","7.58521","0.24477"
"113.90000","7.59177","0.24383"
"114.00000","7.59875","0.24283"
"114.10000","7.60578","0.24219"
"114.20000","7.61224","0.24092"
"114.30000","7.61825","0.24029"
"114.40000","7.62478","0.23968"
"114.50000","7.63213","0.23958"
"114.60000","7.63900","0.23815"
"114.70000","7.64543","0.23751"
"114.80000","7.65161","0.23690"
"114.81600","7.65271","0.23677"