File: 20.12.09/1Layer_6.is_flex_RawData/Specimen_RawData_1.csv
Specimen properties : Thickness,"2.80000",mm
Specimen properties : Width,"13.40000",mm
Specimen properties : Support span,"44.80000",mm

Time,Extension,Load
(s),(mm),(kgf)
"0.00000","0.00000","-0.00247"
"0.10000","0.00077","-0.00247"
"0.20000","0.00545","0.00102"
"0.30000","0.01795","0.00899"
"0.40000","0.02513","0.01261"
"0.50000","0.03118","0.01651"
"0.60000","0.03783","0.01991"
"0.70000","0.04522","0.02447"
"0.80000","0.05224","0.02859"
"0.90000","0.05886","0.03227"
"1.00000","0.06504","0.03543"
"1.10000","0.07184","0.03920"
"1.20000","0.07896","0.04306"
"1.30000","0.08547","0.04661"
"1.40000","0.09188","0.04992"
"1.50000","0.09823","0.05372"
"1.60000","0.10506","0.05706"
"1.70000","0.11197","0.06105"
"1.80000","0.11864","0.06447"
"1.90000","0.12559","0.06770"
"2.00000","0.13188","0.07074"
"2.10000","0.13848","0.07394"
"2.20000","0.14509","0.07728"
"2.30000","0.15195","0.08053"
"2.40000","0.15892","0.08419"
"2.50000","0.16509","0.08650"
"2.60000","0.17161","0.09012"
"2.70000","0.17879","0.09370"
"2.80000","0.18590","0.09697"
"2.90000","0.19228","0.09985"
"3.00000","0.19826","0.10234"
"3.10000","0.20480","0.10551"
"3.20000","0.21213","0.10887"
"3.30000","0.21899","0.11171"
"3.40000","0.22535","0.11476"
"3.50000","0.23178","0.11745"
"3.60000","0.23857","0.12049"
"3.70000","0.24557","0.12329"
"3.80000","0.25212","0.12586"
"3.90000","0.25847","0.12861"
"4.00000","0.26505","0.13173"
"4.10000","0.27191","0.13434"
"4.20000","0.27868","0.13704"
"4.30000","0.28544","0.14008"
"4.40000","0.29238","0.14238"
"4.50000","0.29864","0.14506"
"4.60000","0.30501","0.14747"
"4.70000","0.31161","0.15001"
"4.80000","0.31881","0.15273"
"4.90000","0.32556","0.15532"
"5.00000","0.33179","0.15705"
"5.10000","0.33835","0.15983"
"5.20000","0.34552","0.16246"
"5.30000","0.35251","0.16543"
"5.40000","0.35879","0.16702"
"5.50000","0.36484","0.16896"
"5.60000","0.37158","0.17127"
"5.70000","0.37868","0.17395"
"5.80000","0.38553","0.17584"
"5.90000","0.39196","0.17822"
"6.00000","0.39853","0.18013"
"6.10000","0.40521","0.18232"
"6.20000","0.41204","0.18411"
"6.30000","0.41865","0.18694"
"6.40000","0.42524","0.18842"
"6.50000","0.43178","0.19047"
"6.60000","0.43842","0.19274"
"6.70000","0.44517","0.19442"
"6.80000","0.45236","0.19743"
"6.90000","0.45897","0.19903"
"7.00000","0.46536","0.20084"
"7.10000","0.47160","0.20236"
"7.20000","0.47824","0.20458"
"7.30000","0.48563","0.20651"
"7.40000","0.49216","0.20834"
"7.50000","0.49854","0.21031"
"7.60000","0.50508","0.21170"
"7.70000","0.51218","0.21377"
"7.80000","0.51908","0.21583"
"7.90000","0.52530","0.21728"
"8.00000","0.53154","0.21865"
"8.10000","0.53835","0.22122"
"8.20000","0.54546","0.22296"
"8.30000","0.55211","0.22443"
"8.40000","0.55876","0.22601"
"8.50000","0.56540","0.22797"
"8.60000","0.57198","0.22969"
"8.70000","0.57852","0.23149"
"8.80000","0.58510","0.23320"
"8.90000","0.59204","0.23496"
"9.00000","0.59854","0.23678"
"9.10000","0.60518","0.23825"
"9.20000","0.61192","0.24020"
"9.30000","0.61900","0.24190"
"9.40000","0.62568","0.24342"
"9.50000","0.63187","0.24481"
"9.60000","0.63818","0.24647"
"9.70000","0.64534","0.24853"
"9.80000","0.65224","0.24999"
"9.90000","0.65878","0.25148"
"10.00000","0.66510","0.25270"
"10.10000","0.67188","0.25475"
"10.20000","0.67898","0.25675"
"10.30000","0.68542","0.25772"
"10.40000","0.69174","0.25954"
"10.50000","0.69835","0.26099"
"10.60000","0.70513","0.26269"
"10.70000","0.71199","0.26436"
"10.80000","0.71869","0.26605"
"10.90000","0.72555","0.26772"
"11.00000","0.73199","0.26885"
"11.10000","0.73846","0.27053"
"11.20000","0.74512","0.27237"
"11.30000","0.75192","0.27377"
"11.40000","0.75881","0.27527"
"11.50000","0.76528","0.27668"
"11.60000","0.77158","0.27792"
"11.70000","0.77880","0.27977"
"11.80000","0.78576","0.28144"
"11.90000","0.79223","0.28276"
"12.00000","0.79830","0.28395"
"12.10000","0.80478","0.28546"
"12.20000","0.81204","0.28713"
"12.30000","0.81885","0.28889"
"12.40000","0.82535","0.28990"
"12.50000","0.83180","0.29168"
"12.60000","0.83857","0.29324"
"12.70000","0.84561","0.29498"
"12.80000","0.85200","0.29617"
"12.90000","0.85846","0.29765"
"13.00000","0.86512","0.29901"
"13.10000","0.87193","0.30029"
"13.20000","0.87870","0.30184"
"13.30000","0.88538","0.30329"
"13.40000","0.89236","0.30507"
"13.50000","0.89867","0.30579"
"13.60000","0.90503","0.30724"
"13.70000","0.91178","0.30898"
"13.80000","0.91880","0.31046"
"13.90000","0.92542","0.31218"
"14.00000","0.93187","0.31294"
"14.10000","0.93841","0.31446"
"14.20000","0.94562","0.31632"
"14.30000","0.95246","0.31756"
"14.40000","0.95876","0.31851"
"14.50000","0.96481","0.31983"
"14.60000","0.97159","0.32132"
"14.70000","0.97877","0.32290"
"14.80000","0.98553","0.32419"
"14.90000","0.99192","0.32571"
"15.00000","0.99854","0.32704"
"15.10000","1.00527","0.32824"
"15.20000","1.01210","0.32946"
"15.30000","1.01849","0.33095"
"15.40000","1.02526","0.33225"
"15.50000","1.03185","0.33346"
"15.60000","1.03845","0.33436"
"15.70000","1.04523","0.33633"
"15.80000","1.05225","0.33749"
"15.90000","1.05898","0.33870"
"16.00000","1.06535","0.33950"
"16.10000","1.07157","0.34063"
"16.20000","1.07832","0.34194"
"16.30000","1.08556","0.34358"
"16.40000","1.09218","0.34482"
"16.50000","1.09834","0.34550"
"16.60000","1.10495","0.34704"
"16.70000","1.11218","0.34871"
"16.80000","1.11908","0.34957"
"16.90000","1.12523","0.35093"
"17.00000","1.13151","0.35173"
"17.10000","1.13831","0.35340"
"17.20000","1.14548","0.35470"
"17.30000","1.15218","0.35590"
"17.40000","1.15870","0.35695"
"17.50000","1.16531","0.35825"
"17.60000","1.17198","0.35965"
"17.70000","1.17871","0.36048"
"17.80000","1.18527","0.36194"
"17.90000","1.19210","0.36276"
"18.00000","1.19850","0.36416"
"18.10000","1.20514","0.36499"
"18.20000","1.21196","0.36637"
"18.30000","1.21905","0.36812"
"18.40000","1.22566","0.36857"
"18.50000","1.23172","0.36983"
"18.60000","1.23814","0.37067"
"18.70000","1.24537","0.37236"
"18.80000","1.25242","0.37334"
"18.90000","1.25876","0.37460"
"19.00000","1.26500","0.37559"
"19.10000","1.27186","0.37701"
"19.20000","1.27894","0.37830"
"19.30000","1.28544","0.37924"
"19.40000","1.29182","0.37964"
"19.50000","1.29821","0.38069"
"19.60000","1.30515","0.38202"
"19.70000","1.31196","0.38299"
"19.80000","1.31869","0.38491"
"19.90000","1.32570","0.38549"
"20.00000","1.33187","0.38656"
"20.10000","1.33849","0.38775"
"20.20000","1.34511","0.38850"
"20.30000","1.35190","0.38982"
"20.40000","1.35888","0.39079"
"20.50000","1.36513","0.39182"
"20.60000","1.37164","0.39323"
"20.70000","1.37869","0.39441"
"20.80000","1.38585","0.39572"
"20.90000","1.39227","0.39624"
"21.00000","1.39833","0.39722"
"21.10000","1.40488","0.39856"
"21.20000","1.41207","0.39928"
"21.30000","1.41891","0.40104"
"21.40000","1.42542","0.40177"
"21.50000","1.43177","0.40287"
"21.60000","1.43856","0.40397"
"21.70000","1.44556","0.40537"
"21.80000","1.45205","0.40582"
"21.90000","1.45844","0.40708"
"22.00000","1.46510","0.40823"
"22.10000","1.47181","0.40962"
"22.20000","1.47868","0.41082"
"22.30000","1.48549","0.41219"
"22.40000","1.49239","0.41286"
"22.50000","1.49872","0.41390"
"22.60000","1.50501","0.41445"
"22.70000","1.51170","0.41654"
"22.80000","1.51881","0.41714"
"22.90000","1.52546","0.41803"
"23.00000","1.53180","0.41938"
"23.10000","1.53839","0.41977"
"23.20000","1.54556","0.42143"
"23.30000","1.55248","0.42281"
"23.40000","1.55881","0.42321"
"23.50000","1.56483","0.42415"
"23.60000","1.57150","0.42470"
"23.70000","1.57870","0.42636"
"23.80000","1.58567","0.42773"
"23.90000","1.59209","0.42809"
"24.00000","1.59857","0.42943"
"24.10000","1.60519","0.42996"
"24.20000","1.61205","0.43146"
"24.30000","1.61861","0.43231"
"24.40000","1.62522","0.43350"
"24.50000","1.63165","0.43390"
"24.60000","1.63844","0.43504"
"24.70000","1.64528","0.43628"
"24.80000","1.65229","0.43722"
"24.90000","1.65902","0.43848"
"25.00000","1.66530","0.43930"
"25.10000","1.67152","0.43949"
"25.20000","1.67826","0.44069"
"25.30000","1.68561","0.44174"
"25.40000","1.69224","0.44280"
"25.50000","1.69839","0.44352"
"25.60000","1.70514","0.44457"
"25.70000","1.71223","0.44631"
"25.80000","1.71905","0.44729"
"25.90000","1.72531","0.44771"
"26.00000","1.73146","0.44840"
"26.10000","1.73840","0.44954"
"26.20000","1.74544","0.45036"
"26.30000","1.75213","0.45137"
"26.40000","1.75871","0.45208"
"26.50000","1.76527","0.45332"
"26.60000","1.77190","0.45393"
"26.70000","1.77853","0.45484"
"26.80000","1.78517","0.45573"
"26.90000","1.79218","0.45648"
"27.00000","1.79846","0.45710"
"27.10000","1.80507","0.45809"
"27.20000","1.81195","0.45951"
"27.30000","1.81908","0.46034"
"27.40000","1.82569","0.46124"
"27.50000","1.83180","0.46168"
"27.60000","1.83813","0.46218"
"27.70000","1.84536","0.46386"
"27.80000","1.85242","0.46493"
"27.90000","1.85877","0.46547"
"28.00000","1.86503","0.46643"
"28.10000","1.87186","0.46706"
"28.20000","1.87900","0.46856"
"28.30000","1.88552","0.46860"
"28.40000","1.89181","0.46922"
"28.50000","1.89826","0.47032"
"28.60000","1.90506","0.47106"
"28.70000","1.91199","0.47225"
"28.80000","1.91870","0.47291"
"28.90000","1.92563","0.47415"
"29.00000","1.93192","0.47456"
"29.10000","1.93845","0.47559"
"29.20000","1.94508","0.47610"
"29.30000","1.95189","0.47726"
"29.40000","1.95877","0.47772"
"29.50000","1.96521","0.47887"
"29.60000","1.97165","0.47954"
"29.70000","1.97870","0.48087"
"29.80000","1.98584","0.48225"
"29.90000","1.99216","0.48247"
"30.00000","1.99836","0.48287"
"30.10000","2.00481","0.48399"
"30.20000","2.01202","0.48483"
"30.30000","2.01891","0.48544"
"30.40000","2.02537","0.48663"
"30.50000","2.03196","0.48720"
"30.60000","2.03855","0.48768"
"30.70000","2.04560","0.48895"
"30.80000","2.05202","0.49001"
"30.90000","2.05838","0.49000"
"31.00000","2.06516","0.49138"
"31.10000","2.07178","0.49189"
"31.20000","2.07862","0.49246"
"31.30000","2.08546","0.49405"
"31.40000","2.09237","0.49465"
"31.50000","2.09880","0.49501"
"31.60000","2.10495","0.49552"
"31.70000","2.11169","0.49648"
"31.80000","2.11879","0.49748"
"31.90000","2.12551","0.49826"
"32.00000","2.13200","0.49902"
"32.10000","2.13831","0.49925"
"32.20000","2.14554","0.50040"
"32.30000","2.15243","0.50154"
"32.40000","2.15878","0.50147"
"32.50000","2.16500","0.50213"
"32.60000","2.17156","0.50288"
"32.70000","2.17867","0.50375"
"32.80000","2.18552","0.50406"
"32.90000","2.19197","0.50507"
"33.00000","2.19876","0.50575"
"33.10000","2.20522","0.50635"
"33.20000","2.21192","0.50703"
"33.30000","2.21845","0.50720"
"33.40000","2.22517","0.50879"
"33.50000","2.23194","0.50888"
"33.60000","2.23846","0.50977"
"33.70000","2.24522","0.51024"
"33.80000","2.25220","0.51118"
"33.90000","2.25891","0.51171"
"34.00000","2.26541","0.51268"
"34.10000","2.27160","0.51295"
"34.20000","2.27831","0.51360"
"34.30000","2.28550","0.51474"
"34.40000","2.29209","0.51480"
"34.50000","2.29865","0.51563"
"34.60000","2.30519","0.51622"
"34.70000","2.31214","0.51761"
"34.80000","2.31901","0.51809"
"34.90000","2.32523","0.51819"
"35.00000","2.33162","0.51869"
"35.10000","2.33844","0.51922"
"35.20000","2.34539","0.52041"
"35.30000","2.35205","0.52077"
"35.40000","2.35860","0.52136"
"35.50000","2.36544","0.52207"
"35.60000","2.37213","0.52274"
"35.70000","2.37862","0.52344"
"35.80000","2.38505","0.52371"
"35.90000","2.39193","0.52474"
"36.00000","2.39862","0.52504"
"36.10000","2.40521","0.52599"
"36.20000","2.41194","0.52662"
"36.30000","2.41900","0.52747"
"36.40000","2.42564","0.52800"
"36.50000","2.43194","0.52816"
"36.60000","2.43819","0.52854"
"36.70000","2.44526","0.52933"
"36.80000","2.45229","0.53026"
"36.90000","2.45870","0.53034"
"37.00000","2.46517","0.53112"
"37.10000","2.47200","0.53198"
"37.20000","2.47888","0.53217"
"37.30000","2.48533","0.53286"
"37.40000","2.49169","0.53325"
"37.50000","2.49839","0.53359"
"37.60000","2.50523","0.53447"
"37.70000","2.51198","0.53489"
"37.80000","2.51856","0.53568"
"37.90000","2.52537","0.53649"
"38.00000","2.53223","0.53675"
"38.10000","2.53867","0.53723"
"38.20000","2.54504","0.53779"
"38.30000","2.55184","0.53860"
"38.40000","2.55871","0.53924"
"38.50000","2.56534","0.53982"
"38.60000","2.57178","0.54026"
"38.70000","2.57869","0.54078"
"38.80000","2.58578","0.54200"
"38.90000","2.59210","0.54188"
"39.00000","2.59843","0.54205"
"39.10000","2.60487","0.54274"
"39.20000","2.61203","0.54349"
"39.30000","2.61878","0.54408"
"39.40000","2.62524","0.54441"
"39.50000","2.63198","0.54501"
"39.60000","2.63871","0.54527"
"39.70000","2.64556","0.54613"
"39.80000","2.65190","0.54621"
"39.90000","2.65824","0.54669"
"40.00000","2.66527","0.54693"
"40.10000","2.67202","0.54729"
"40.20000","2.67873","0.54834"
"40.30000","2.68536","0.54877"
"40.40000","2.69214","0.54931"
"40.50000","2.69890","0.55011"
"40.60000","2.70515","0.54977"
"40.70000","2.71168","0.55044"
"40.80000","2.71870","0.55124"
"40.90000","2.72534","0.55174"
"41.00000","2.73199","0.55226"
"41.10000","2.73852","0.55253"
"41.20000","2.74559","0.55300"
"41.30000","2.75230","0.55391"
"41.40000","2.75866","0.55439"
"41.50000","2.76506","0.55453"
"41.60000","2.77163","0.55507"
"41.70000","2.77870","0.55581"
"41.80000","2.78545","0.55637"
"41.90000","2.79181","0.55636"
"42.00000","2.79877","0.55754"
"42.10000","2.80534","0.55796"
"42.20000","2.81200","0.55864"
"42.30000","2.81844","0.55909"
"42.40000","2.82505","0.55935"
"42.50000","2.83193","0.55985"
"42.60000","2.83856","0.56064"
"42.70000","2.84518","0.56074"
"42.80000","2.85217","0.56108"
"42.90000","2.85887","0.56155"
"43.00000","2.86552","0.56190"
"43.10000","2.87169","0.56189"
"43.20000","2.87831","0.56214"
"43.30000","2.88543","0.56327"
"43.40000","2.89203","0.56307"
"43.50000","2.89866","0.56315"
"43.60000","2.90530","0.56419"
"43.70000","2.91218","0.56430"
"43.80000","2.91886","0.56486"
"43.90000","2.92514","0.56462"
"44.00000","2.93164","0.56556"
"44.10000","2.93859","0.56615"
"44.20000","2.94538","0.56653"
"44.30000","2.95200","0.56694"
"44.40000","2.95859","0.56734"
"44.50000","2.96547","0.56822"
"44.60000","2.97210","0.56856"
"44.70000","2.97865","0.56879"
"44.80000","2.98506","0.56982"
"44.90000","2.99192","0.56986"
"45.00000","2.99861","0.57040"
"45.10000","3.00521","0.57079"
"45.20000","3.01193","0.57161"
"45.30000","3.01901","0.57215"
"45.40000","3.02558","0.57251"
"45.50000","3.03190","0.57264"
"45.60000","3.03831","0.57309"
"45.70000","3.04530","0.57368"
"45.80000","3.05224","0.57422"
"45.90000","3.05871","0.57420"
"46.00000","3.06514","0.57465"
"46.10000","3.07190","0.57526"
"46.20000","3.07887","0.57601"
"46.30000","3.08539","0.57569"
"46.40000","3.09176","0.57604"
"46.50000","3.09841","0.57679"
"46.60000","3.10521","0.57746"
"46.70000","3.11199","0.57762"
"46.80000","3.11862","0.57800"
"46.90000","3.12538","0.57859"
"47.00000","3.13203","0.57898"
"47.10000","3.13865","0.57918"
"47.20000","3.14506","0.57939"
"47.30000","3.15186","0.58027"
"47.40000","3.15868","0.58041"
"47.50000","3.16527","0.58045"
"47.60000","3.17172","0.58112"
"47.70000","3.17869","0.58141"
"47.80000","3.18578","0.58212"
"47.90000","3.19222","0.58223"
"48.00000","3.19841","0.58215"
"48.10000","3.20489","0.58264"
"48.20000","3.21205","0.58322"
"48.30000","3.21881","0.58348"
"48.40000","3.22530","0.58402"
"48.50000","3.23192","0.58407"
"48.60000","3.23855","0.58473"
"48.70000","3.24562","0.58498"
"48.80000","3.25197","0.58566"
"48.90000","3.25834","0.58578"
"49.00000","3.26521","0.58615"
"49.10000","3.27192","0.58649"
"49.20000","3.27872","0.58702"
"49.30000","3.28540","0.58737"
"49.40000","3.29228","0.58815"
"49.50000","3.29882","0.58789"
"49.60000","3.30509","0.58841"
"49.70000","3.31167","0.58833"
"49.80000","3.31866","0.58881"
"49.90000","3.32540","0.58913"
"50.00000","3.33198","0.58969"
"50.10000","3.33854","0.58983"
"50.20000","3.34556","0.59062"
"50.30000","3.35232","0.59062"
"50.40000","3.35866","0.59102"
"50.50000","3.36488","0.59142"
"50.60000","3.37173","0.59179"
"50.70000","3.37875","0.59218"
"50.80000","3.38552","0.59272"
"50.90000","3.39187","0.59274"
"51.00000","3.39858","0.59360"
"51.10000","3.40531","0.59382"
"51.20000","3.41200","0.59391"
"51.30000","3.41846","0.59408"
"51.40000","3.42512","0.59458"
"51.50000","3.43180","0.59480"
"51.60000","3.43852","0.59515"
"51.70000","3.44516","0.59557"
"51.80000","3.45228","0.59665"
"51.90000","3.45895","0.59662"
"52.00000","3.46532","0.59709"
"52.10000","3.47162","0.59715"
"52.20000","3.47827","0.59815"
"52.30000","3.48564","0.59857"
"52.40000","3.49211","0.59843"
"52.50000","3.49843","0.59906"
"52.60000","3.50517","0.59928"
"52.70000","3.51228","0.60008"
"52.80000","3.51905","0.60059"
"52.90000","3.52518","0.60061"
"53.00000","3.53148","0.60116"
"53.10000","3.53840","0.60212"
"53.20000","3.54546","0.60271"
"53.30000","3.55208","0.60333"
"53.40000","3.55864","0.60385"
"53.50000","3.56532","0.60448"
"53.60000","3.57204","0.60517"
"53.70000","3.57865","0.60532"
"53.80000","3.58508","0.60530"
"53.90000","3.59203","0.60638"
"54.00000","3.59851","0.60669"
"54.10000","3.60512","0.60719"
"54.20000","3.61186","0.60776"
"54.30000","3.61916","0.60850"
"54.40000","3.62574","0.60861"
"54.50000","3.63167","0.60882"
"54.60000","3.63809","0.60921"
"54.70000","3.64531","0.61059"
"54.80000","3.65238","0.61096"
"54.90000","3.65878","0.61142"
"55.00000","3.66501","0.61161"
"55.10000","3.67190","0.61203"
"55.20000","3.67903","0.61284"
"55.30000","3.68550","0.61300"
"55.40000","3.69180","0.61331"
"55.50000","3.69825","0.61378"
"55.60000","3.70518","0.61450"
"55.70000","3.71200","0.61535"
"55.80000","3.71871","0.61554"
"55.90000","3.72558","0.61642"
"56.00000","3.73197","0.61671"
"56.10000","3.73857","0.61681"
"56.20000","3.74511","0.61771"
"56.30000","3.75192","0.61859"
"56.40000","3.75885","0.61897"
"56.50000","3.76510","0.61953"
"56.60000","3.77159","0.61992"
"56.70000","3.77871","0.62113"
"56.80000","3.78593","0.62178"
"56.90000","3.79221","0.62180"
"57.00000","3.79832","0.62194"
"57.10000","3.80471","0.62240"
"57.20000","3.81203","0.62298"
"57.30000","3.81904","0.62301"
"57.40000","3.82535","0.62367"
"57.50000","3.83177","0.62399"
"57.60000","3.83862","0.62419"
"57.70000","3.84562","0.62492"
"57.80000","3.85202","0.62447"
"57.90000","3.85834","0.62466"
"58.00000","3.86518","0.62539"
"58.10000","3.87192","0.62544"
"58.20000","3.87865","0.62573"
"58.30000","3.88544","0.62626"
"58.40000","3.89233","0.62697"
"58.50000","3.89877","0.62660"
"58.60000","3.90503","0.62713"
"58.70000","3.91167","0.62734"
"58.80000","3.91881","0.62756"
"58.90000","3.92543","0.62801"
"59.00000","3.93193","0.62814"
"59.10000","3.93836","0.62880"
"59.20000","3.94568","0.62929"
"59.30000","3.95251","0.62974"
"59.40000","3.95874","0.62964"
"59.50000","3.96498","0.62941"
"59.60000","3.97161","0.62959"
"59.70000","3.97872","0.63054"
"59.80000","3.98559","0.63066"
"59.90000","3.99188","0.63052"
"60.00000","3.99856","0.63070"
"60.10000","4.00520","0.63139"
"60.20000","4.01207","0.63133"
"60.30000","4.01858","0.63147"
"60.40000","4.02515","0.63194"
"60.50000","4.03183","0.63218"
"60.60000","4.03846","0.63244"
"60.70000","4.04524","0.63264"
"60.80000","4.05220","0.63305"
"60.90000","4.05887","0.63336"
"61.00000","4.06540","0.63312"
"61.10000","4.07164","0.63342"
"61.20000","4.07828","0.63348"
"61.30000","4.08551","0.63405"
"61.40000","4.09214","0.63404"
"61.50000","4.09854","0.63419"
"61.60000","4.10518","0.63514"
"61.70000","4.11226","0.63530"
"61.80000","4.11899","0.63533"
"61.90000","4.12517","0.63500"
"62.00000","4.13158","0.63551"
"62.10000","4.13838","0.63571"
"62.20000","4.14550","0.63636"
"62.30000","4.15215","0.63674"
"62.40000","4.15860","0.63681"
"62.50000","4.16536","0.63692"
"62.60000","4.17194","0.63640"
"62.70000","4.17865","0.63667"
"62.80000","4.18514","0.63691"
"62.90000","4.19196","0.63672"
"63.00000","4.19866","0.63663"
"63.10000","4.20511","0.63690"
"63.20000","4.21195","0.63757"
"63.30000","4.21911","0.63803"
"63.40000","4.22564","0.63832"
"63.50000","4.23184","0.63837"
"63.60000","4.23820","0.63845"
"63.70000","4.24531","0.63948"
"63.80000","4.25224","0.63906"
"63.90000","4.25867","0.63935"
"64.00000","4.26504","0.63875"
"64.10000","4.27186","0.63971"
"64.20000","4.27896","0.64038"
"64.30000","4.28546","0.64017"
"64.40000","4.29174","0.63971"
"64.50000","4.29841","0.64057"
"64.60000","4.30526","0.64076"
"64.70000","4.31199","0.64066"
"64.80000","4.31856","0.64099"
"64.90000","4.32542","0.64118"
"65.00000","4.33202","0.64150"
"65.10000","4.33855","0.64123"
"65.20000","4.34506","0.64151"
"65.30000","4.35184","0.64206"
"65.40000","4.35873","0.64235"
"65.50000","4.36520","0.64252"
"65.60000","4.37171","0.64247"
"65.70000","4.37881","0.64342"
"65.80000","4.38582","0.64302"
"65.90000","4.39218","0.64313"
"66.00000","4.39834","0.64287"
"66.10000","4.40485","0.64267"
"66.20000","4.41207","0.64376"
"66.30000","4.41884","0.64344"
"66.40000","4.42535","0.64315"
"66.50000","4.43192","0.64294"
"66.60000","4.43857","0.64323"
"66.70000","4.44556","0.64294"
"66.80000","4.45200","0.64277"
"66.90000","4.45837","0.64284"
"67.00000","4.46515","0.64318"
"67.10000","4.47192","0.64323"
"67.20000","4.47858","0.64327"
"67.30000","4.48536","0.64386"
"67.40000","4.49238","0.64390"
"67.50000","4.49872","0.64372"
"67.60000","4.50495","0.64295"
"67.70000","4.51165","0.64331"
"67.80000","4.51877","0.64356"
"67.90000","4.52542","0.64298"
"68.00000","4.53199","0.64310"
"68.10000","4.53841","0.64360"
"68.20000","4.54564","0.64378"
"68.30000","4.55247","0.64415"
"68.40000","4.55871","0.64356"
"68.50000","4.56496","0.64376"
"68.60000","4.57158","0.64446"
"68.70000","4.57871","0.64412"
"68.80000","4.58555","0.64496"
"68.90000","4.59196","0.64518"
"69.00000","4.59853","0.64492"
"69.10000","4.60520","0.64506"
"69.20000","4.61209","0.64456"
"69.30000","4.61851","0.64453"
"69.40000","4.62516","0.64502"
"69.50000","4.63183","0.64464"
"69.60000","4.63842","0.64496"
"69.70000","4.64526","0.64437"
"69.80000","4.65231","0.64512"
"69.90000","4.65888","0.64467"
"70.00000","4.66525","0.64499"
"70.10000","4.67156","0.64520"
"70.20000","4.67830","0.64505"
"70.30000","4.68560","0.64527"
"70.40000","4.69217","0.64504"
"70.50000","4.69852","0.64466"
"70.60000","4.70514","0.64584"
"70.70000","4.71223","0.64619"
"70.80000","4.71900","0.64562"
"70.90000","4.72523","0.64579"
"71.00000","4.73151","0.64615"
"71.10000","4.73838","0.64603"
"71.20000","4.74551","0.64615"
"71.30000","4.75207","0.64583"
"71.40000","4.75870","0.64593"
"71.50000","4.76538","0.64554"
"71.60000","4.77194","0.64514"
"71.70000","4.77864","0.64553"
"71.80000","4.78508","0.64521"
"71.90000","4.79208","0.64527"
"72.00000","4.79860","0.64518"
"72.10000","4.80512","0.64509"
"72.20000","4.81188","0.64581"
"72.30000","4.81908","0.64631"
"72.40000","4.82573","0.64549"
"72.50000","4.83178","0.64529"
"72.60000","4.83814","0.64487"
"72.70000","4.84532","0.64545"
"72.80000","4.85236","0.64511"
"72.90000","4.85880","0.64497"
"73.00000","4.86501","0.64471"
"73.10000","4.87187","0.64583"
"73.20000","4.87891","0.64586"
"73.30000","4.88550","0.64546"
"73.40000","4.89180","0.64539"
"73.50000","4.89830","0.64544"
"73.60000","4.90511","0.64491"
"73.70000","4.91199","0.64544"
"73.80000","4.91864","0.64482"
"73.90000","4.92559","0.64501"
"74.00000","4.93204","0.64454"
"74.10000","4.93850","0.64417"
"74.20000","4.94516","0.64435"
"74.30000","4.95190","0.64350"
"74.40000","4.95879","0.64337"
"74.50000","4.96521","0.64326"
"74.60000","4.97155","0.64300"
"74.70000","4.97873","0.64360"
"74.80000","4.98583","0.64374"
"74.90000","4.99225","0.64323"
"75.00000","4.99840","0.64258"
"75.10000","5.00480","0.64283"
"75.20000","5.01211","0.64274"
"75.30000","5.01888","0.64262"
"75.40000","5.02534","0.64200"
"75.50000","5.03189","0.64079"
"75.60000","5.03856","0.64198"
"75.70000","5.04558","0.64183"
"75.80000","5.05196","0.64097"
"75.90000","5.05837","0.64059"
"76.00000","5.06517","0.64090"
"76.10000","5.07181","0.64093"
"76.20000","5.07868","0.64066"
"76.30000","5.08543","0.64031"
"76.40000","5.09240","0.64015"
"76.50000","5.09870","0.64002"
"76.60000","5.10496","0.63965"
"76.70000","5.11177","0.63934"
"76.80000","5.11878","0.63952"
"76.90000","5.12549","0.63899"
"77.00000","5.13195","0.63882"
"77.10000","5.13837","0.63884"
"77.20000","5.14562","0.63863"
"77.30000","5.15245","0.63831"
"77.40000","5.15872","0.63799"
"77.50000","5.16487","0.63706"
"77.60000","5.17153","0.63758"
"77.70000","5.17879","0.63768"
"77.80000","5.18555","0.63708"
"77.90000","5.19189","0.63693"
"78.00000","5.19846","0.63603"
"78.10000","5.20517","0.63584"
"78.20000","5.21204","0.63557"
"78.30000","5.21849","0.63491"
"78.40000","5.22517","0.63481"
"78.50000","5.23178","0.63417"
"78.60000","5.23845","0.63383"
"78.70000","5.24522","0.63324"
"78.80000","5.25235","0.63310"
"78.90000","5.25890","0.63226"
"79.00000","5.26531","0.63140"
"79.10000","5.27153","0.63099"
"79.20000","5.27831","0.63078"
"79.30000","5.28557","0.63092"
"79.40000","5.29215","0.62987"
"79.50000","5.29851","0.62889"
"79.60000","5.30508","0.62891"
"79.70000","5.31228","0.62860"
"79.80000","5.31905","0.62847"
"79.90000","5.32520","0.62771"
"80.00000","5.33154","0.62758"
"80.10000","5.33838","0.62755"
"80.20000","5.34542","0.62717"
"80.30000","5.35213","0.62640"
"80.40000","5.35873","0.62601"
"80.50000","5.36528","0.62556"
"80.60000","5.37198","0.62538"
"80.70000","5.37861","0.62487"
"80.80000","5.38517","0.62482"
"80.90000","5.39212","0.62491"
"81.00000","5.39860","0.62399"
"81.10000","5.40508","0.62344"
"81.20000","5.41189","0.62393"
"81.30000","5.41917","0.62335"
"81.40000","5.42574","0.62307"
"81.50000","5.43174","0.62227"
"81.60000","5.43811","0.62160"
"81.70000","5.44531","0.62223"
"81.80000","5.45229","0.62171"
"81.90000","5.45884","0.62184"
"82.00000","5.46511","0.62053"
"82.10000","5.47192","0.62077"
"82.20000","5.47889","0.62117"
"82.30000","5.48545","0.62060"
"82.40000","5.49183","0.62016"
"82.50000","5.49819","0.62003"
"82.60000","5.50505","0.62014"
"82.70000","5.51199","0.61985"
"82.80000","5.51872","0.61964"
"82.90000","5.52558","0.61972"
"83.00000","5.53200","0.61915"
"83.10000","5.53848","0.61857"
"83.20000","5.54504","0.61822"
"83.30000","5.55192","0.61769"
"83.40000","5.55891","0.61778"
"83.50000","5.56514","0.61728"
"83.60000","5.57165","0.61702"
"83.70000","5.57878","0.61770"
"83.80000","5.58586","0.61734"
"83.90000","5.59222","0.61652"
"84.00000","5.59834","0.61631"
"84.10000","5.60480","0.61619"
"84.20000","5.61205","0.61659"
"84.30000","5.61892","0.61616"
"84.40000","5.62541","0.61516"
"84.50000","5.63181","0.61538"
"84.60000","5.63854","0.61519"
"84.70000","5.64554","0.61521"
"84.80000","5.65204","0.61420"
"84.90000","5.65848","0.61352"
"85.00000","5.66512","0.61359"
"85.10000","5.67182","0.61357"
"85.20000","5.67869","0.61315"
"85.30000","5.68545","0.61279"
"85.40000","5.69241","0.61296"
"85.50000","5.69866","0.61198"
"85.60000","5.70501","0.61176"
"85.70000","5.71177","0.61131"
"85.80000","5.71876","0.61136"
"85.90000","5.72550","0.61056"
"86.00000","5.73188","0.61017"
"86.10000","5.73837","0.60986"
"86.20000","5.74559","0.60964"
"86.30000","5.75253","0.60918"
"86.40000","5.75873","0.60839"
"86.50000","5.76491","0.60773"
"86.60000","5.77155","0.60787"
"86.70000","5.77876","0.60787"
"86.80000","5.78557","0.60753"
"86.90000","5.79192","0.60650"
"87.00000","5.79857","0.60675"
"87.10000","5.80514","0.60595"
"87.20000","5.81207","0.60565"
"87.30000","5.81858","0.60557"
"87.40000","5.82523","0.60519"
"87.50000","5.83183","0.60478"
"87.60000","5.83849","0.60450"
"87.70000","5.84521","0.60409"
"87.80000","5.85225","0.60373"
"87.90000","5.85904","0.60335"
"88.00000","5.86529","0.60248"
"88.10000","5.87150","0.60187"
"88.20000","5.87825","0.60208"
"88.30000","5.88565","0.60182"
"88.40000","5.89217","0.60121"
"88.50000","5.89857","0.60082"
"88.60000","5.90506","0.60089"
"88.70000","5.91224","0.60096"
"88.80000","5.91905","0.60037"
"88.90000","5.92526","0.60068"
"89.00000","5.93142","0.59982"
"89.10000","5.93833","0.60044"
"89.20000","5.94548","0.60071"
"89.30000","5.95210","0.60027"
"89.40000","5.95866","0.59988"
"89.50000","5.96532","0.60002"
"89.60000","5.97192","0.59978"
"89.70000","5.97863","0.59912"
"89.80000","5.98517","0.59856"
"89.90000","5.99203","0.59854"
"90.00000","5.99853","0.59748"
"90.10000","6.00507","0.59725"
"90.20000","6.01192","0.59737"
"90.30000","6.01915","0.59666"
"90.40000","6.02576","0.59628"
"90.50000","6.03177","0.59536"
"90.60000","6.03814","0.59525"
"90.70000","6.04524","0.59532"
"90.80000","6.05228","0.59547"
"90.90000","6.05894","0.59486"
"91.00000","6.06513","0.59414"
"91.10000","6.07183","0.59431"
"91.20000","6.07892","0.59378"
"91.30000","6.08545","0.59325"
"91.40000","6.09181","0.59303"
"91.50000","6.09832","0.59348"
"91.60000","6.10509","0.59285"
"91.70000","6.11199","0.59286"
"91.80000","6.11863","0.59234"
"91.90000","6.12558","0.59224"
"92.00000","6.13196","0.59136"
"92.10000","6.13846","0.59151"
"92.20000","6.14507","0.59099"
"92.30000","6.15193","0.59117"
"92.40000","6.15893","0.59095"
"92.50000","6.16516","0.58974"
"92.60000","6.17158","0.58931"
"92.70000","6.17874","0.58880"
"92.80000","6.18590","0.58871"
"92.90000","6.19229","0.58796"
"93.00000","6.19834","0.58734"
"93.10000","6.20476","0.58747"
"93.20000","6.21198","0.58745"
"93.30000","6.21886","0.58715"
"93.40000","6.22535","0.58659"
"93.50000","6.23193","0.58591"
"93.60000","6.23853","0.58579"
"93.70000","6.24554","0.58548"
"93.80000","6.25205","0.58435"
"93.90000","6.25845","0.58449"
"94.00000","6.26518","0.58372"
"94.10000","6.27191","0.58350"
"94.20000","6.27875","0.58336"
"94.30000","6.28544","0.58372"
"94.40000","6.29240","0.58283"
"94.50000","6.29873","0.58302"
"94.60000","6.30495","0.58252"
"94.70000","6.31170","0.58224"
"94.80000","6.31870","0.58263"
"94.90000","6.32546","0.58185"
"95.00000","6.33197","0.58106"
"95.10000","6.33838","0.58125"
"95.20000","6.34559","0.58105"
"95.30000","6.35241","0.58045"
"95.40000","6.35875","0.57944"
"95.50000","6.36497","0.57863"
"95.60000","6.37156","0.57818"
"95.70000","6.37875","0.57842"
"95.80000","6.38556","0.57811"
"95.90000","6.39196","0.57763"
"96.00000","6.39859","0.57774"
"96.10000","6.40519","0.57703"
"96.20000","6.41203","0.57692"
"96.30000","6.41849","0.57660"
"96.40000","6.42517","0.57620"
"96.50000","6.43179","0.57579"
"96.60000","6.43850","0.57569"
"96.70000","6.44526","0.57541"
"96.80000","6.45225","0.57514"
"96.90000","6.45894","0.57477"
"97.00000","6.46532","0.57431"
"97.10000","6.47154","0.57383"
"97.20000","6.47831","0.57421"
"97.30000","6.48552","0.57359"
"97.40000","6.49211","0.57395"
"97.50000","6.49857","0.57298"
"97.60000","6.50518","0.57289"
"97.70000","6.51220","0.57203"
"97.80000","6.51902","0.57185"
"97.90000","6.52525","0.57149"
"98.00000","6.53155","0.57116"
"98.10000","6.53846","0.57076"
"98.20000","6.54542","0.57035"
"98.30000","6.55204","0.56986"
"98.40000","6.55873","0.56984"
"98.50000","6.56537","0.56918"
"98.60000","6.57199","0.56916"
"98.70000","6.57868","0.56845"
"98.80000","6.58511","0.56771"
"98.90000","6.59201","0.56753"
"99.00000","6.59855","0.56666"
"99.10000","6.60510","0.56631"
"99.20000","6.61188","0.56610"
"99.30000","6.61905","0.56610"
"99.40000","6.62571","0.56502"
"99.50000","6.63186","0.56442"
"99.60000","6.63818","0.56375"
"99.70000","6.64522","0.56415"
"99.80000","6.65221","0.56334"
"99.90000","6.65880","0.56263"
"100.00000","6.66511","0.56233"
"100.10000","6.67191","0.56264"
"100.20000","6.67892","0.56216"
"100.30000","6.68542","0.56119"
"100.40000","6.69185","0.56059"
"100.50000","6.69836","0.56064"
"100.60000","6.70519","0.56025"
"100.70000","6.71198","0.56015"
"100.80000","6.71859","0.55901"
"100.90000","6.72561","0.55888"
"101.00000","6.73187","0.55835"
"101.10000","6.73846","0.55741"
"101.20000","6.74516","0.55748"
"101.30000","6.75193","0.55689"
"101.40000","6.75881","0.55637"
"101.50000","6.76516","0.55633"
"101.60000","6.77158","0.55542"
"101.70000","6.77879","0.55581"
"101.80000","6.78582","0.55468"
"101.90000","6.79225","0.55421"
"102.00000","6.79828","0.55322"
"102.10000","6.80479","0.55361"
"102.20000","6.81211","0.55355"
"102.30000","6.81883","0.55301"
"102.40000","6.82539","0.55272"
"102.50000","6.83179","0.55241"
"102.60000","6.83854","0.55209"
"102.70000","6.84558","0.55196"
"102.80000","6.85202","0.55162"
"102.90000","6.85853","0.55088"
"103.00000","6.86508","0.55054"
"103.10000","6.87182","0.55046"
"103.20000","6.87862","0.55022"
"103.30000","6.88545","0.54981"
"103.40000","6.89241","0.54930"
"103.50000","6.89870","0.54850"
"103.60000","6.90496","0.54822"
"103.70000","6.91171","0.54771"
"103.80000","6.91879","0.54700"
"103.90000","6.92561","0.54649"
"104.00000","6.93191","0.54539"
"104.10000","6.93835","0.54510"
"104.20000","6.94559","0.54497"
"104.30000","6.95241","0.54417"
"104.40000","6.95878","0.54344"
"104.50000","6.96485","0.54264"
"104.60000","6.97153","0.54275"
"104.70000","6.97880","0.54258"
"104.80000","6.98564","0.54165"
"104.90000","6.99201","0.54030"
"105.00000","6.99857","0.53974"
"105.10000","7.00521","0.53932"
"105.20000","7.01211","0.53817"
"105.30000","7.01863","0.53804"
"105.40000","7.02526","0.53744"
"105.50000","7.03164","0.53657"
"105.60000","7.03844","0.53659"
"105.70000","7.04526","0.53613"
"105.80000","7.05221","0.53600"
"105.90000","7.05900","0.53488"
"106.00000","7.06531","0.53366"
"106.10000","7.07156","0.53312"
"106.20000","7.07832","0.53276"
"106.30000","7.08558","0.53205"
"106.40000","7.09211","0.53145"
"106.50000","7.09847","0.53044"
"106.60000","7.10513","0.53022"
"106.70000","7.11221","0.52980"
"106.80000","7.11903","0.52892"
"106.90000","7.12529","0.52843"
"107.00000","7.13149","0.52730"
"107.10000","7.13839","0.52746"
"107.20000","7.14543","0.52676"
"107.30000","7.15203","0.52582"
"107.40000","7.15869","0.52553"
"107.50000","7.16538","0.52479"
"107.60000","7.17193","0.52442"
"107.70000","7.17860","0.52389"
"107.80000","7.18514","0.52306"
"107.90000","7.19209","0.52280"
"108.00000","7.19860","0.52156"
"108.10000","7.20513","0.52090"
"108.20000","7.21197","0.52092"
"108.30000","7.21905","0.52025"
"108.40000","7.22571","0.51922"
"108.50000","7.23184","0.51867"
"108.60000","7.23814","0.51786"
"108.70000","7.24520","0.51733"
"108.80000","7.25228","0.51735"
"108.90000","7.25876","0.51605"
"109.00000","7.26515","0.51549"
"109.10000","7.27190","0.51482"
"109.20000","7.27902","0.51443"
"109.30000","7.28540","0.51347"
"109.40000","7.29179","0.51294"
"109.50000","7.29836","0.51231"
"109.60000","7.30510","0.51206"
"109.70000","7.31195","0.51145"
"109.80000","7.31866","0.51049"
"109.90000","7.32559","0.50997"
"110.00000","7.33198","0.50939"
"110.10000","7.33847","0.50847"
"110.20000","7.34514","0.50784"
"110.30000","7.35183","0.50715"
"110.40000","7.35884","0.50654"
"110.50000","7.36530","0.50618"
"110.60000","7.37168","0.50535"
"110.70000","7.37875","0.50466"
"110.80000","7.38574","0.50401"
"110.90000","7.39217","0.50296"
"111.00000","7.39841","0.50178"
"111.10000","7.40483","0.50160"
"111.20000","7.41211","0.50059"
"111.30000","7.41887","0.49973"
"111.40000","7.42536","0.49895"
"111.50000","7.43195","0.49787"
"111.60000","7.43850","0.49661"
"111.70000","7.44557","0.49605"
"111.80000","7.45191","0.49465"
"111.90000","7.45841","0.49336"
"112.00000","7.46516","0.49234"
"112.10000","7.47187","0.49167"
"112.20000","7.47866","0.49044"
"112.30000","7.48530","0.48988"
"112.40000","7.49237","0.48871"
"112.50000","7.49882","0.48774"
"112.60000","7.50499","0.48623"
"112.70000","7.51175","0.48548"
"112.80000","7.51866","0.48432"
"112.90000","7.52549","0.48307"
"113.00000","7.53198","0.48207"
"113.10000","7.53836","0.48060"
"113.20000","7.54556","0.48016"
"113.30000","7.55241","0.47865"
"113.40000","7.55873","0.47671"
"113.50000","7.56486","0.47505"
"113.60000","7.57158","0.47444"
"113.70000","7.57871","0.47293"
"113.80000","7.58551","0.47132"
"113.90000","7.59204","0.46945"
"114.00000","7.59867","0.46823"
"114.10000","7.60518","0.46734"
"114.20000","7.61202","0.46622"
"114.30000","7.61851","0.46499"
"114.40000","7.62522","0.46371"
"114.50000","7.63180","0.46213"
"114.60000","7.63851","0.46166"
"114.70000","7.64520","0.46058"
"114.80000","7.65211","0.45905"
"114.90000","7.65897","0.45827"
"115.00000","7.66538","0.45691"
"115.10000","7.67163","0.45625"
"115.20000","7.67828","0.45519"
"115.30000","7.68557","0.45436"
"115.40000","7.69222","0.45256"
"115.50000","7.69857","0.45109"
"115.60000","7.70514","0.45069"
"115.70000","7.71222","0.44961"
"115.80000","7.71901","0.44768"
"115.90000","7.72527","0.44644"
"116.00000","7.73151","0.44510"
"116.10000","7.73838","0.44489"
"116.20000","7.74543","0.44380"
"116.30000","7.75203","0.44269"
"116.40000","7.75877","0.44150"
"116.50000","7.76550","0.44010"
"116.60000","7.77192","0.43937"
"116.70000","7.77862","0.43804"
"116.80000","7.78507","0.43617"
"116.90000","7.79205","0.43583"
"117.00000","7.79859","0.43473"
"117.10000","7.80513","0.43354"
"117.20000","7.81195","0.43283"
"117.30000","7.81896","0.43168"
"117.40000","7.82567","0.43079"
"117.50000","7.83179","0.42889"
"117.60000","7.83816","0.42813"
"117.70000","7.84536","0.42741"
"117.80000","7.85229","0.42601"
"117.90000","7.85872","0.42506"
"118.00000","7.86505","0.42419"
"118.10000","7.87191","0.42325"
"118.20000","7.87898","0.42249"
"118.30000","7.88545","0.42090"
"118.40000","7.89179","0.41990"
"118.50000","7.89828","0.41925"
"118.60000","7.90519","0.41801"
"118.70000","7.91200","0.41739"
"118.80000","7.91869","0.41626"
"118.90000","7.92560","0.41522"
"119.00000","7.93199","0.41376"
"119.10000","7.93846","0.41283"
"119.20000","7.94512","0.41165"
"119.30000","7.95184","0.41052"
"119.40000","7.95875","0.40907"
"119.50000","7.96512","0.40787"
"119.60000","7.97162","0.40658"
"119.70000","7.97871","0.40615"
"119.80000","7.98585","0.40448"
"119.90000","7.99227","0.40308"
"120.00000","7.99831","0.40143"
"120.10000","8.00469","0.40040"
"120.20000","8.01202","0.39937"
"120.30000","8.01898","0.39837"
"120.40000","8.02548","0.39693"
"120.50000","8.03181","0.39571"
"120.60000","8.03857","0.39459"
"120.70000","8.04554","0.39318"
"120.80000","8.05209","0.39157"
"120.90000","8.05847","0.38984"
"121.00000","8.06504","0.38884"
"121.10000","8.07180","0.38736"
"121.20000","8.07862","0.38628"
"121.30000","8.08541","0.38453"
"121.40000","8.09246","0.38283"
"121.50000","8.09864","0.38095"
"121.60000","8.10505","0.37941"
"121.70000","8.11172","0.37811"
"121.80000","8.11875","0.37666"
"121.90000","8.12551","0.37493"
"122.00000","8.13192","0.37302"
"122.10000","8.13837","0.37122"
"122.20000","8.14560","0.36977"
"122.30000","8.15250","0.36803"
"122.40000","8.15876","0.36607"
"122.50000","8.16484","0.36395"
"122.60000","8.17156","0.36335"
"122.70000","8.17877","0.36154"
"122.80000","8.18556","0.36015"
"122.90000","8.19199","0.35843"
"123.00000","8.19856","0.35717"
"123.10000","8.20518","0.35583"
"123.20000","8.21204","0.35422"
"123.30000","8.21854","0.35223"
"123.40000","8.22521","0.35150"
"123.50000","8.23187","0.34976"
"123.60000","8.23843","0.34838"
"123.70000","8.24524","0.34647"
"123.80000","8.25231","0.34539"
"123.90000","8.25888","0.34364"
"124.00000","8.26528","0.34203"
"124.10000","8.27162","0.34068"
"124.20000","8.27828","0.33936"
"124.30000","8.28560","0.33813"
"124.40000","8.29218","0.33647"
"124.50000","8.29847","0.33463"
"124.60000","8.30505","0.33370"
"124.70000","8.31221","0.33233"
"124.80000","8.31912","0.33055"
"124.90000","8.32532","0.32922"
"125.00000","8.33148","0.32762"
"125.10000","8.33828","0.32649"
"125.20000","8.34544","0.32575"
"125.30000","8.35217","0.32417"
"125.40000","8.35873","0.32325"
"125.50000","8.36522","0.32144"
"125.60000","8.37197","0.32022"
"125.70000","8.37866","0.31931"
"125.80000","8.38521","0.31780"
"125.90000","8.39207","0.31694"
"126.00000","8.39849","0.31573"
"126.10000","8.40508","0.31472"
"126.20000","8.41189","0.31361"
"126.30000","8.41911","0.31235"
"126.40000","8.42576","0.31019"
"126.50000","8.43170","0.30798"
"126.60000","8.43810","0.30609"
"126.70000","8.44529","0.30469"
"126.80000","8.45236","0.30325"
"126.90000","8.45885","0.30164"
"127.00000","8.46490","0.30044"
"127.10000","8.47192","0.29875"
"127.20000","8.47900","0.29741"
"127.30000","8.48545","0.29533"
"127.40000","8.49176","0.29358"
"127.50000","8.49823","0.29250"
"127.60000","8.50509","0.29184"
"127.70000","8.51202","0.29099"
"127.80000","8.51863","0.28926"
"127.90000","8.52569","0.28826"
"128.00000","8.53195","0.28648"
"128.10000","8.53845","0.28556"
"128.20000","8.54511","0.28462"
"128.30000","8.55199","0.28334"
"128.40000","8.55888","0.28150"
"128.50000","8.56514","0.28026"
"128.60000","8.57158","0.27924"
"128.70000","8.57874","0.27940"
"128.80000","8.58598","0.27780"
"128.90000","8.59222","0.27687"
"129.00000","8.59824","0.27554"
"129.10000","8.60471","0.27453"
"129.20000","8.61211","0.27429"
"129.30000","8.61905","0.27267"
"129.40000","8.62531","0.27114"
"129.50000","8.63173","0.26989"
"129.60000","8.63859","0.26866"
"129.70000","8.64561","0.26743"
"129.80000","8.65205","0.26616"
"129.90000","8.65837","0.26496"
"130.00000","8.66499","0.26510"
"130.10000","8.67184","0.26408"
"130.20000","8.67880","0.26327"
"130.30000","8.68555","0.26246"
"130.40000","8.69233","0.26107"
"130.50000","8.69873","0.25935"
"130.60000","8.70496","0.25836"
"130.70000","8.71165","0.25747"
"130.80000","8.71883","0.25678"
"130.90000","8.72550","0.25497"
"131.00000","8.73195","0.25337"
"131.10000","8.73831","0.25207"
"131.20000","8.74563","0.25120"
"131.30000","8.75248","0.24977"
"131.40000","8.75874","0.24859"
"131.50000","8.76495","0.24726"
"131.60000","8.77151","0.24659"
"131.70000","8.77869","0.24533"
"131.80000","8.78554","0.24431"
"131.90000","8.79193","0.24315"
"132.00000","8.79862","0.24125"
"132.10000","8.80517","0.23988"
"132.20000","8.81205","0.23882"
"132.30000","8.81861","0.23674"
"132.40000","8.82518","0.23590"
"132.50000","8.83186","0.23445"
"132.60000","8.83840","0.23328"
"132.70000","8.84528","0.23208"
"132.80000","8.85230","0.23106"
"132.90000","8.85895","0.22999"
"133.00000","8.86546","0.22803"
"133.10000","8.87157","0.22704"
"133.20000","8.87825","0.22635"
"133.30000","8.88551","0.22533"
"133.40000","8.89213","0.22390"
"133.50000","8.89864","0.22205"
"133.60000","8.90515","0.22145"
"133.70000","8.91217","0.22123"
"133.80000","8.91903","0.21987"
"133.90000","8.92519","0.21882"
"134.00000","8.93155","0.21768"
"134.10000","8.93837","0.21718"
"134.20000","8.94547","0.21581"
"134.30000","8.95207","0.21507"
"134.40000","8.95864","0.21426"
"134.50000","8.96547","0.21345"
"134.60000","8.97199","0.21242"
"134.70000","8.97859","0.21163"
"134.80000","8.98508","0.21074"
"134.90000","8.99195","0.21014"
"135.00000","8.99870","0.20879"
"135.10000","9.00521","0.20763"
"135.20000","9.01188","0.20753"
"135.30000","9.01899","0.20654"
"135.40000","9.02563","0.20556"
"135.50000","9.03181","0.20491"
"135.60000","9.03815","0.20431"
"135.70000","9.04531","0.20453"
"135.80000","9.05231","0.20418"
"135.90000","9.05881","0.20312"
"136.00000","9.06522","0.20199"
"136.10000","9.07191","0.20156"
"136.20000","9.07896","0.20094"
"136.30000","9.08546","0.19954"
"136.40000","9.09173","0.19871"
"136.50000","9.09834","0.19788"
"136.60000","9.10515","0.19781"
"136.70000","9.11189","0.19665"
"136.80000","9.11862","0.19594"
"136.90000","9.12542","0.19542"
"137.00000","9.13204","0.19469"
"137.10000","9.13852","0.19341"
"137.20000","9.14513","0.19229"
"137.30000","9.15193","0.19165"
"137.40000","9.15873","0.19080"
"137.50000","9.16534","0.19008"
"137.60000","9.17166","0.18856"
"137.70000","9.17870","0.18788"
"137.80000","9.18581","0.18714"
"137.90000","9.19211","0.18564"
"138.00000","9.19845","0.18496"
"138.10000","9.20489","0.18411"
"138.20000","9.21208","0.18324"
"138.30000","9.21881","0.18255"
"138.40000","9.22523","0.18156"
"138.50000","9.23196","0.18100"
"138.60000","9.23865","0.18017"
"138.70000","9.24553","0.17909"
"138.80000","9.25199","0.17800"
"138.90000","9.25835","0.17771"
"139.00000","9.26527","0.17755"
"139.10000","9.27189","0.17676"
"139.20000","9.27867","0.17625"
"139.30000","9.28539","0.17571"
"139.40000","9.29227","0.17538"
"139.50000","9.29890","0.17432"
"139.60000","9.30505","0.17293"
"139.70000","9.31171","0.17204"
"139.80000","9.31870","0.17171"
"139.90000","9.32540","0.17060"
"140.00000","9.33198","0.16943"
"140.10000","9.33839","0.16877"
"140.20000","9.34560","0.16769"
"140.30000","9.35234","0.16662"
"140.40000","9.35867","0.16516"
"140.50000","9.36501","0.16427"
"140.60000","9.37167","0.16337"
"140.70000","9.37872","0.16298"
"140.80000","9.38547","0.16210"
"140.90000","9.39182","0.16166"
"141.00000","9.39877","0.16079"
"141.10000","9.40540","0.15968"
"141.20000","9.41201","0.15847"
"141.30000","9.41843","0.15780"
"141.40000","9.42508","0.15699"
"141.50000","9.43190","0.15636"
"141.60000","9.43854","0.15568"
"141.70000","9.44528","0.15463"
"141.80000","9.45213","0.15414"
"141.90000","9.45879","0.15242"
"142.00000","9.46545","0.15174"
"142.10000","9.47169","0.15057"
"142.20000","9.47820","0.14949"
"142.30000","9.48547","0.14907"
"142.40000","9.49210","0.14771"
"142.50000","9.49868","0.14650"
"142.60000","9.50516","0.14623"
"142.70000","9.51216","0.14563"
"142.80000","9.51897","0.14466"
"142.90000","9.52521","0.14302"
"143.00000","9.53167","0.14208"
"143.10000","9.53856","0.14189"
"143.20000","9.54550","0.14176"
"143.30000","9.55203","0.14049"
"143.40000","9.55853","0.13975"
"143.50000","9.56545","0.13914"
"143.60000","9.57209","0.13877"
"143.70000","9.57861","0.13724"
"143.80000","9.58508","0.13590"
"143.90000","9.59188","0.13496"
"144.00000","9.59860","0.13437"
"144.10000","9.60525","0.13358"
"144.20000","9.61191","0.13293"
"144.30000","9.61900","0.13242"
"144.40000","9.62546","0.13108"
"144.50000","9.63191","0.12967"
"144.60000","9.63826","0.12775"
"144.70000","9.64527","0.12727"
"144.80000","9.65222","0.12667"
"144.90000","9.65871","0.12566"
"145.00000","9.66519","0.12538"
"145.10000","9.67204","0.12449"
"145.20000","9.67893","0.12287"
"145.30000","9.68539","0.12215"
"145.40000","9.69164","0.12097"
"145.50000","9.69844","0.12074"
"145.60000","9.70527","0.12036"
"145.70000","9.71198","0.11979"
"145.80000","9.71856","0.11903"
"145.90000","9.72543","0.11859"
"146.00000","9.73202","0.11788"
"146.10000","9.73865","0.11692"
"146.20000","9.74507","0.11641"
"146.30000","9.75173","0.11593"
"146.40000","9.75873","0.11560"
"146.50000","9.76536","0.11482"
"146.60000","9.77174","0.11486"
"146.70000","9.77866","0.11523"
"146.80000","9.78571","0.11508"
"146.90000","9.79223","0.11452"
"147.00000","9.79839","0.11405"
"147.10000","9.80486","0.11377"
"147.20000","9.81200","0.11393"
"147.30000","9.81886","0.11329"
"147.40000","9.82533","0.11253"
"147.50000","9.83189","0.11208"
"147.60000","9.83857","0.11102"
"147.70000","9.84561","0.11054"
"147.80000","9.85195","0.10978"
"147.90000","9.85824","0.10927"
"148.00000","9.86522","0.10887"
"148.10000","9.87194","0.10885"
"148.20000","9.87876","0.10821"
"148.30000","9.88536","0.10738"
"148.40000","9.89229","0.10617"
"148.50000","9.89881","0.10557"
"148.60000","9.90508","0.10441"
"148.70000","9.91173","0.10423"
"148.80000","9.91866","0.10384"
"148.83900","9.92144","0.10365"