File: 20.12.09/1Layer_1.is_flex_RawData/Specimen_RawData_1.csv
Specimen properties : Thickness,"2.70000",mm
Specimen properties : Width,"10.50000",mm
Specimen properties : Support span,"43.20000",mm

Time,Extension,Load
(s),(mm),(kgf)
"0.00000","0.00000","-0.00136"
"0.10000","0.00082","-0.00075"
"0.20000","0.00581","0.00324"
"0.30000","0.01702","0.01093"
"0.40000","0.02482","0.01558"
"0.50000","0.03161","0.02006"
"0.60000","0.03855","0.02500"
"0.70000","0.04519","0.02820"
"0.80000","0.05190","0.03276"
"0.90000","0.05849","0.03673"
"1.00000","0.06520","0.04036"
"1.10000","0.07179","0.04463"
"1.20000","0.07851","0.04875"
"1.30000","0.08522","0.05241"
"1.40000","0.09219","0.05650"
"1.50000","0.09893","0.06062"
"1.60000","0.10530","0.06369"
"1.70000","0.11157","0.06780"
"1.80000","0.11831","0.07114"
"1.90000","0.12548","0.07549"
"2.00000","0.13219","0.07866"
"2.10000","0.13852","0.08251"
"2.20000","0.14513","0.08651"
"2.30000","0.15222","0.08999"
"2.40000","0.15893","0.09372"
"2.50000","0.16525","0.09702"
"2.60000","0.17149","0.10039"
"2.70000","0.17843","0.10433"
"2.80000","0.18551","0.10774"
"2.90000","0.19205","0.11143"
"3.00000","0.19874","0.11348"
"3.10000","0.20531","0.11551"
"3.20000","0.21200","0.11619"
"3.30000","0.21862","0.11813"
"3.40000","0.22508","0.11965"
"3.50000","0.23205","0.12043"
"3.60000","0.23849","0.12425"
"3.70000","0.24514","0.12719"
"3.80000","0.25197","0.13081"
"3.90000","0.25910","0.13440"
"4.00000","0.26575","0.13738"
"4.10000","0.27175","0.14013"
"4.20000","0.27817","0.14363"
"4.30000","0.28533","0.14718"
"4.40000","0.29228","0.15020"
"4.50000","0.29883","0.15352"
"4.60000","0.30508","0.15613"
"4.70000","0.31187","0.16000"
"4.80000","0.31889","0.16324"
"4.90000","0.32542","0.16659"
"5.00000","0.33186","0.16955"
"5.10000","0.33828","0.17273"
"5.20000","0.34515","0.17660"
"5.30000","0.35195","0.18006"
"5.40000","0.35854","0.18274"
"5.50000","0.36557","0.18631"
"5.60000","0.37190","0.18933"
"5.70000","0.37852","0.19247"
"5.80000","0.38514","0.19556"
"5.90000","0.39189","0.19913"
"6.00000","0.39884","0.20219"
"6.10000","0.40510","0.20503"
"6.20000","0.41165","0.20775"
"6.30000","0.41879","0.21189"
"6.40000","0.42595","0.21537"
"6.50000","0.43226","0.21784"
"6.60000","0.43824","0.22017"
"6.70000","0.44479","0.22390"
"6.80000","0.45205","0.22700"
"6.90000","0.45898","0.23042"
"7.00000","0.46541","0.23356"
"7.10000","0.47177","0.23637"
"7.20000","0.47856","0.23940"
"7.30000","0.48562","0.24214"
"7.40000","0.49204","0.24506"
"7.50000","0.49850","0.24815"
"7.60000","0.50509","0.25134"
"7.70000","0.51187","0.25414"
"7.80000","0.51869","0.25709"
"7.90000","0.52550","0.26050"
"8.00000","0.53238","0.26351"
"8.10000","0.53860","0.26615"
"8.20000","0.54503","0.26887"
"8.30000","0.55167","0.27195"
"8.40000","0.55883","0.27502"
"8.50000","0.56556","0.27797"
"8.60000","0.57179","0.28071"
"8.70000","0.57840","0.28376"
"8.80000","0.58561","0.28671"
"8.90000","0.59244","0.28975"
"9.00000","0.59872","0.29256"
"9.10000","0.60487","0.29545"
"9.20000","0.61162","0.29788"
"9.30000","0.61876","0.30117"
"9.40000","0.62556","0.30446"
"9.50000","0.63198","0.30700"
"9.60000","0.63854","0.30984"
"9.70000","0.64519","0.31269"
"9.80000","0.65200","0.31594"
"9.90000","0.65853","0.31819"
"10.00000","0.66523","0.32129"
"10.10000","0.67177","0.32435"
"10.20000","0.67847","0.32732"
"10.30000","0.68527","0.32965"
"10.40000","0.69226","0.33330"
"10.50000","0.69894","0.33614"
"10.60000","0.70528","0.33864"
"10.70000","0.71161","0.34108"
"10.80000","0.71829","0.34427"
"10.90000","0.72564","0.34766"
"11.00000","0.73220","0.35036"
"11.10000","0.73850","0.35263"
"11.20000","0.74503","0.35519"
"11.30000","0.75223","0.35881"
"11.40000","0.75900","0.36153"
"11.50000","0.76527","0.36388"
"11.60000","0.77150","0.36631"
"11.70000","0.77835","0.36933"
"11.80000","0.78556","0.37263"
"11.90000","0.79210","0.37521"
"12.00000","0.79867","0.37768"
"12.10000","0.80538","0.38023"
"12.20000","0.81198","0.38325"
"12.30000","0.81860","0.38625"
"12.40000","0.82514","0.38819"
"12.50000","0.83202","0.39105"
"12.60000","0.83860","0.39402"
"12.70000","0.84509","0.39638"
"12.80000","0.85194","0.39944"
"12.90000","0.85899","0.40226"
"13.00000","0.86563","0.40480"
"13.10000","0.87184","0.40723"
"13.20000","0.87815","0.40974"
"13.30000","0.88539","0.41331"
"13.40000","0.89232","0.41570"
"13.50000","0.89872","0.41814"
"13.60000","0.90508","0.42025"
"13.70000","0.91191","0.42338"
"13.80000","0.91898","0.42610"
"13.90000","0.92537","0.42860"
"14.00000","0.93172","0.43105"
"14.10000","0.93840","0.43333"
"14.20000","0.94521","0.43635"
"14.30000","0.95198","0.43884"
"14.40000","0.95858","0.44173"
"14.50000","0.96552","0.44432"
"14.60000","0.97203","0.44675"
"14.70000","0.97851","0.44934"
"14.80000","0.98517","0.45190"
"14.90000","0.99189","0.45450"
"15.00000","0.99880","0.45717"
"15.10000","1.00525","0.45943"
"15.20000","1.01154","0.46215"
"15.30000","1.01879","0.46477"
"15.40000","1.02581","0.46744"
"15.50000","1.03219","0.46943"
"15.60000","1.03827","0.47161"
"15.70000","1.04484","0.47437"
"15.80000","1.05207","0.47744"
"15.90000","1.05887","0.48002"
"16.00000","1.06534","0.48166"
"16.10000","1.07173","0.48430"
"16.20000","1.07866","0.48718"
"16.30000","1.08560","0.48993"
"16.40000","1.09191","0.49179"
"16.50000","1.09843","0.49410"
"16.60000","1.10514","0.49669"
"16.70000","1.11184","0.49909"
"16.80000","1.11871","0.50140"
"16.90000","1.12546","0.50381"
"17.00000","1.13243","0.50639"
"17.10000","1.13865","0.50864"
"17.20000","1.14501","0.51115"
"17.30000","1.15173","0.51310"
"17.40000","1.15874","0.51545"
"17.50000","1.16551","0.51804"
"17.60000","1.17190","0.51996"
"17.70000","1.17840","0.52280"
"17.80000","1.18560","0.52539"
"17.90000","1.19246","0.52750"
"18.00000","1.19874","0.52959"
"18.10000","1.20485","0.53156"
"18.20000","1.21164","0.53408"
"18.30000","1.21869","0.53659"
"18.40000","1.22550","0.53946"
"18.50000","1.23195","0.54081"
"18.60000","1.23863","0.54311"
"18.70000","1.24523","0.54558"
"18.80000","1.25208","0.54797"
"18.90000","1.25853","0.54987"
"19.00000","1.26529","0.55212"
"19.10000","1.27182","0.55446"
"19.20000","1.27845","0.55649"
"19.30000","1.28525","0.55889"
"19.40000","1.29229","0.56116"
"19.50000","1.29890","0.56332"
"19.60000","1.30529","0.56520"
"19.70000","1.31158","0.56735"
"19.80000","1.31831","0.56966"
"19.90000","1.32555","0.57198"
"20.00000","1.33214","0.57397"
"20.10000","1.33840","0.57594"
"20.20000","1.34507","0.57819"
"20.30000","1.35231","0.58075"
"20.40000","1.35902","0.58231"
"20.50000","1.36517","0.58398"
"20.60000","1.37146","0.58568"
"20.70000","1.37828","0.58821"
"20.80000","1.38546","0.59058"
"20.90000","1.39209","0.59247"
"21.00000","1.39875","0.59496"
"21.10000","1.40535","0.59642"
"21.20000","1.41195","0.59837"
"21.30000","1.41865","0.60056"
"21.40000","1.42510","0.60212"
"21.50000","1.43208","0.60460"
"21.60000","1.43851","0.60614"
"21.70000","1.44514","0.60812"
"21.80000","1.45195","0.60996"
"21.90000","1.45914","0.61207"
"22.00000","1.46568","0.61380"
"22.10000","1.47169","0.61539"
"22.20000","1.47819","0.61659"
"22.30000","1.48528","0.61900"
"22.40000","1.49229","0.62126"
"22.50000","1.49877","0.62230"
"22.60000","1.50503","0.62343"
"22.70000","1.51182","0.62562"
"22.80000","1.51893","0.62769"
"22.90000","1.52551","0.62913"
"23.00000","1.53182","0.63005"
"23.10000","1.53815","0.63181"
"23.20000","1.54513","0.63407"
"23.30000","1.55205","0.63579"
"23.40000","1.55872","0.63695"
"23.50000","1.56570","0.63911"
"23.60000","1.57191","0.64000"
"23.70000","1.57846","0.64173"
"23.80000","1.58510","0.64324"
"23.90000","1.59191","0.64502"
"24.00000","1.59890","0.64645"
"24.10000","1.60508","0.64788"
"24.20000","1.61168","0.64959"
"24.30000","1.61873","0.65078"
"24.40000","1.62597","0.65262"
"24.50000","1.63233","0.65377"
"24.60000","1.63829","0.65470"
"24.70000","1.64477","0.65608"
"24.80000","1.65211","0.65787"
"24.90000","1.65900","0.65928"
"25.00000","1.66539","0.66038"
"25.10000","1.67176","0.66167"
"25.20000","1.67852","0.66333"
"25.30000","1.68559","0.66472"
"25.40000","1.69202","0.66608"
"25.50000","1.69846","0.66720"
"25.60000","1.70506","0.66837"
"25.70000","1.71186","0.66987"
"25.80000","1.71875","0.67137"
"25.90000","1.72550","0.67258"
"26.00000","1.73239","0.67390"
"26.10000","1.73869","0.67463"
"26.20000","1.74498","0.67597"
"26.30000","1.75157","0.67712"
"26.40000","1.75887","0.67894"
"26.50000","1.76548","0.68022"
"26.60000","1.77181","0.68073"
"26.70000","1.77833","0.68200"
"26.80000","1.78564","0.68388"
"26.90000","1.79255","0.68495"
"27.00000","1.79878","0.68547"
"27.10000","1.80479","0.68645"
"27.20000","1.81146","0.68799"
"27.30000","1.81877","0.68928"
"27.40000","1.82564","0.69072"
"27.50000","1.83197","0.69126"
"27.60000","1.83851","0.69236"
"27.70000","1.84523","0.69355"
"27.80000","1.85205","0.69470"
"27.90000","1.85862","0.69545"
"28.00000","1.86522","0.69702"
"28.10000","1.87162","0.69773"
"28.20000","1.87850","0.69884"
"28.30000","1.88523","0.69991"
"28.40000","1.89237","0.70128"
"28.50000","1.89900","0.70212"
"28.60000","1.90517","0.70294"
"28.70000","1.91151","0.70381"
"28.80000","1.91829","0.70500"
"28.90000","1.92562","0.70603"
"29.00000","1.93229","0.70774"
"29.10000","1.93843","0.70806"
"29.20000","1.94507","0.70918"
"29.30000","1.95230","0.71095"
"29.40000","1.95898","0.71166"
"29.50000","1.96528","0.71207"
"29.60000","1.97143","0.71299"
"29.70000","1.97844","0.71430"
"29.80000","1.98551","0.71547"
"29.90000","1.99216","0.71607"
"30.00000","1.99874","0.71680"
"30.10000","2.00519","0.71771"
"30.20000","2.01189","0.71897"
"30.30000","2.01858","0.72023"
"30.40000","2.02513","0.72080"
"30.50000","2.03217","0.72205"
"30.60000","2.03848","0.72263"
"30.70000","2.04502","0.72329"
"30.80000","2.05193","0.72473"
"30.90000","2.05919","0.72626"
"31.00000","2.06576","0.72668"
"31.10000","2.07172","0.72722"
"31.20000","2.07816","0.72825"
"31.30000","2.08543","0.72957"
"31.40000","2.09229","0.73068"
"31.50000","2.09878","0.73131"
"31.60000","2.10500","0.73211"
"31.70000","2.11187","0.73313"
"31.80000","2.11895","0.73441"
"31.90000","2.12551","0.73508"
"32.00000","2.13181","0.73571"
"32.10000","2.13822","0.73643"
"32.20000","2.14504","0.73729"
"32.30000","2.15201","0.73888"
"32.40000","2.15876","0.73968"
"32.50000","2.16558","0.74046"
"32.60000","2.17193","0.74123"
"32.70000","2.17840","0.74205"
"32.80000","2.18507","0.74293"
"32.90000","2.19188","0.74377"
"33.00000","2.19883","0.74492"
"33.10000","2.20513","0.74550"
"33.20000","2.21168","0.74686"
"33.30000","2.21876","0.74758"
"33.40000","2.22597","0.74900"
"33.50000","2.23218","0.74917"
"33.60000","2.23839","0.74977"
"33.70000","2.24476","0.75038"
"33.80000","2.25196","0.75231"
"33.90000","2.25896","0.75273"
"34.00000","2.26537","0.75384"
"34.10000","2.27189","0.75470"
"34.20000","2.27860","0.75529"
"34.30000","2.28563","0.75664"
"34.40000","2.29197","0.75692"
"34.50000","2.29838","0.75751"
"34.60000","2.30515","0.75858"
"34.70000","2.31182","0.75961"
"34.80000","2.31866","0.76069"
"34.90000","2.32544","0.76117"
"35.00000","2.33235","0.76248"
"35.10000","2.33883","0.76259"
"35.20000","2.34496","0.76370"
"35.30000","2.35169","0.76398"
"35.40000","2.35880","0.76540"
"35.50000","2.36549","0.76620"
"35.60000","2.37199","0.76661"
"35.70000","2.37831","0.76719"
"35.80000","2.38565","0.76850"
"35.90000","2.39247","0.76935"
"36.00000","2.39872","0.76965"
"36.10000","2.40496","0.77018"
"36.20000","2.41157","0.77111"
"36.30000","2.41870","0.77250"
"36.40000","2.42553","0.77305"
"36.50000","2.43191","0.77328"
"36.60000","2.43870","0.77453"
"36.70000","2.44524","0.77509"
"36.80000","2.45202","0.77566"
"36.90000","2.45845","0.77608"
"37.00000","2.46512","0.77727"
"37.10000","2.47195","0.77780"
"37.20000","2.47848","0.77857"
"37.30000","2.48521","0.77883"
"37.40000","2.49226","0.78053"
"37.50000","2.49887","0.78104"
"37.60000","2.50540","0.78133"
"37.70000","2.51160","0.78167"
"37.80000","2.51832","0.78259"
"37.90000","2.52553","0.78400"
"38.00000","2.53205","0.78477"
"38.10000","2.53864","0.78498"
"38.20000","2.54522","0.78617"
"38.30000","2.55223","0.78692"
"38.40000","2.55894","0.78737"
"38.50000","2.56522","0.78811"
"38.60000","2.57163","0.78835"
"38.70000","2.57842","0.78928"
"38.80000","2.58543","0.79034"
"38.90000","2.59204","0.79108"
"39.00000","2.59866","0.79165"
"39.10000","2.60539","0.79271"
"39.20000","2.61207","0.79377"
"39.30000","2.61862","0.79437"
"39.40000","2.62506","0.79485"
"39.50000","2.63194","0.79594"
"39.60000","2.63867","0.79659"
"39.70000","2.64523","0.79777"
"39.80000","2.65198","0.79889"
"39.90000","2.65903","0.79934"
"40.00000","2.66554","0.80030"
"40.10000","2.67192","0.80069"
"40.20000","2.67827","0.80126"
"40.30000","2.68527","0.80265"
"40.40000","2.69225","0.80322"
"40.50000","2.69870","0.80408"
"40.60000","2.70514","0.80449"
"40.70000","2.71195","0.80521"
"40.80000","2.71889","0.80650"
"40.90000","2.72539","0.80711"
"41.00000","2.73168","0.80744"
"41.10000","2.73848","0.80833"
"41.20000","2.74520","0.80901"
"41.30000","2.75188","0.81007"
"41.40000","2.75858","0.81072"
"41.50000","2.76546","0.81178"
"41.60000","2.77213","0.81219"
"41.70000","2.77859","0.81330"
"41.80000","2.78511","0.81382"
"41.90000","2.79185","0.81405"
"42.00000","2.79873","0.81493"
"42.10000","2.80537","0.81578"
"42.20000","2.81182","0.81611"
"42.30000","2.81875","0.81722"
"42.40000","2.82567","0.81777"
"42.50000","2.83211","0.81819"
"42.60000","2.83845","0.81873"
"42.70000","2.84496","0.81949"
"42.80000","2.85196","0.82009"
"42.90000","2.85879","0.82040"
"43.00000","2.86526","0.82105"
"43.10000","2.87199","0.82175"
"43.20000","2.87871","0.82254"
"43.30000","2.88555","0.82352"
"43.40000","2.89188","0.82300"
"43.50000","2.89832","0.82378"
"43.60000","2.90526","0.82489"
"43.70000","2.91205","0.82515"
"43.80000","2.91874","0.82578"
"43.90000","2.92540","0.82647"
"44.00000","2.93224","0.82720"
"44.10000","2.93886","0.82751"
"44.20000","2.94508","0.82754"
"44.30000","2.95163","0.82827"
"44.40000","2.95863","0.82960"
"44.50000","2.96539","0.82986"
"44.60000","2.97206","0.83047"
"44.70000","2.97853","0.83095"
"44.80000","2.98559","0.83192"
"44.90000","2.99236","0.83231"
"45.00000","2.99864","0.83238"
"45.10000","3.00497","0.83231"
"45.20000","3.01167","0.83315"
"45.30000","3.01873","0.83408"
"45.40000","3.02542","0.83442"
"45.50000","3.03182","0.83491"
"45.60000","3.03878","0.83576"
"45.70000","3.04534","0.83602"
"45.80000","3.05198","0.83669"
"45.90000","3.05846","0.83665"
"46.00000","3.06511","0.83781"
"46.10000","3.07196","0.83839"
"46.20000","3.07862","0.83881"
"46.30000","3.08514","0.83904"
"46.40000","3.09212","0.83981"
"46.50000","3.09890","0.84056"
"46.60000","3.10543","0.84085"
"46.70000","3.11177","0.84068"
"46.80000","3.11831","0.84151"
"46.90000","3.12538","0.84245"
"47.00000","3.13203","0.84264"
"47.10000","3.13869","0.84336"
"47.20000","3.14530","0.84363"
"47.30000","3.15231","0.84397"
"47.40000","3.15886","0.84496"
"47.50000","3.16509","0.84494"
"47.60000","3.17159","0.84554"
"47.70000","3.17853","0.84603"
"47.80000","3.18542","0.84706"
"47.90000","3.19200","0.84728"
"48.00000","3.19860","0.84780"
"48.10000","3.20549","0.84819"
"48.20000","3.21212","0.84911"
"48.30000","3.21858","0.84887"
"48.40000","3.22506","0.84971"
"48.50000","3.23192","0.84991"
"48.60000","3.23860","0.85053"
"48.70000","3.24517","0.85091"
"48.80000","3.25187","0.85162"
"48.90000","3.25905","0.85230"
"49.00000","3.26562","0.85223"
"49.10000","3.27195","0.85277"
"49.20000","3.27828","0.85281"
"49.30000","3.28527","0.85374"
"49.40000","3.29221","0.85359"
"49.50000","3.29873","0.85396"
"49.60000","3.30512","0.85426"
"49.70000","3.31198","0.85466"
"49.80000","3.31886","0.85541"
"49.90000","3.32541","0.85523"
"50.00000","3.33176","0.85538"
"50.10000","3.33844","0.85576"
"50.20000","3.34517","0.85569"
"50.30000","3.35191","0.85677"
"50.40000","3.35854","0.85639"
"50.50000","3.36543","0.85726"
"50.60000","3.37210","0.85761"
"50.70000","3.37856","0.85785"
"50.80000","3.38505","0.85785"
"50.90000","3.39182","0.85823"
"51.00000","3.39876","0.85879"
"51.10000","3.40531","0.85912"
"51.20000","3.41178","0.85952"
"51.30000","3.41868","0.86023"
"51.40000","3.42572","0.86062"
"51.50000","3.43216","0.86065"
"51.60000","3.43840","0.86072"
"51.70000","3.44498","0.86131"
"51.80000","3.45203","0.86214"
"51.90000","3.45877","0.86256"
"52.00000","3.46524","0.86264"
"52.10000","3.47194","0.86301"
"52.20000","3.47872","0.86353"
"52.30000","3.48567","0.86376"
"52.40000","3.49197","0.86399"
"52.50000","3.49830","0.86416"
"52.60000","3.50519","0.86470"
"52.70000","3.51192","0.86490"
"52.80000","3.51865","0.86572"
"52.90000","3.52530","0.86600"
"53.00000","3.53222","0.86630"
"53.10000","3.53878","0.86636"
"53.20000","3.54511","0.86676"
"53.30000","3.55169","0.86732"
"53.40000","3.55864","0.86801"
"53.50000","3.56540","0.86801"
"53.60000","3.57197","0.86798"
"53.70000","3.57855","0.86923"
"53.80000","3.58554","0.86948"
"53.90000","3.59241","0.86945"
"54.00000","3.59870","0.86939"
"54.10000","3.60487","0.86920"
"54.20000","3.61173","0.86967"
"54.30000","3.61864","0.86948"
"54.40000","3.62542","0.87004"
"54.50000","3.63197","0.87000"
"54.60000","3.63859","0.86974"
"54.70000","3.64527","0.87030"
"54.80000","3.65199","0.87025"
"54.90000","3.65848","0.87070"
"55.00000","3.66516","0.87072"
"55.10000","3.67178","0.87104"
"55.20000","3.67858","0.87125"
"55.30000","3.68527","0.87123"
"55.40000","3.69218","0.87211"
"55.50000","3.69891","0.87178"
"55.60000","3.70531","0.87174"
"55.70000","3.71163","0.87141"
"55.80000","3.71832","0.87224"
"55.90000","3.72562","0.87233"
"56.00000","3.73208","0.87247"
"56.10000","3.73839","0.87199"
"56.20000","3.74513","0.87279"
"56.30000","3.75230","0.87326"
"56.40000","3.75895","0.87319"
"56.50000","3.76520","0.87296"
"56.60000","3.77154","0.87331"
"56.70000","3.77846","0.87346"
"56.80000","3.78551","0.87397"
"56.90000","3.79210","0.87366"
"57.00000","3.79857","0.87384"
"57.10000","3.80525","0.87396"
"57.20000","3.81205","0.87412"
"57.30000","3.81866","0.87452"
"57.40000","3.82515","0.87461"
"57.50000","3.83207","0.87479"
"57.60000","3.83836","0.87462"
"57.70000","3.84514","0.87503"
"57.80000","3.85197","0.87537"
"57.90000","3.85910","0.87559"
"58.00000","3.86560","0.87532"
"58.10000","3.87174","0.87494"
"58.20000","3.87809","0.87508"
"58.30000","3.88531","0.87572"
"58.40000","3.89235","0.87621"
"58.50000","3.89879","0.87584"
"58.60000","3.90504","0.87591"
"58.70000","3.91198","0.87647"
"58.80000","3.91904","0.87628"
"58.90000","3.92553","0.87616"
"59.00000","3.93172","0.87594"
"59.10000","3.93822","0.87591"
"59.20000","3.94518","0.87663"
"59.30000","3.95207","0.87735"
"59.40000","3.95872","0.87708"
"59.50000","3.96552","0.87776"
"59.60000","3.97189","0.87777"
"59.70000","3.97845","0.87762"
"59.80000","3.98509","0.87773"
"59.90000","3.99196","0.87810"
"60.00000","3.99888","0.87792"
"60.10000","4.00511","0.87780"
"60.20000","4.01168","0.87789"
"60.30000","4.01871","0.87785"
"60.40000","4.02590","0.87781"
"60.50000","4.03219","0.87744"
"60.60000","4.03831","0.87689"
"60.70000","4.04484","0.87703"
"60.80000","4.05208","0.87705"
"60.90000","4.05894","0.87681"
"61.00000","4.06533","0.87623"
"61.10000","4.07179","0.87590"
"61.20000","4.07864","0.87628"
"61.30000","4.08563","0.87679"
"61.40000","4.09200","0.87614"
"61.50000","4.09836","0.87612"
"61.60000","4.10514","0.87596"
"61.70000","4.11187","0.87628"
"61.80000","4.11865","0.87626"
"61.90000","4.12546","0.87622"
"62.00000","4.13244","0.87616"
"62.10000","4.13872","0.87577"
"62.20000","4.14500","0.87548"
"62.30000","4.15170","0.87558"
"62.40000","4.15883","0.87568"
"62.50000","4.16542","0.87551"
"62.60000","4.17195","0.87541"
"62.70000","4.17843","0.87560"
"62.80000","4.18566","0.87583"
"62.90000","4.19242","0.87580"
"63.00000","4.19874","0.87544"
"63.10000","4.20493","0.87521"
"63.20000","4.21162","0.87556"
"63.30000","4.21871","0.87600"
"63.40000","4.22554","0.87576"
"63.50000","4.23196","0.87580"
"63.60000","4.23852","0.87559"
"63.70000","4.24523","0.87561"
"63.80000","4.25210","0.87575"
"63.90000","4.25861","0.87550"
"64.00000","4.26514","0.87554"
"64.10000","4.27180","0.87557"
"64.20000","4.27846","0.87586"
"64.30000","4.28526","0.87577"
"64.40000","4.29227","0.87580"
"64.50000","4.29886","0.87593"
"64.60000","4.30534","0.87525"
"64.70000","4.31162","0.87533"
"64.80000","4.31831","0.87559"
"64.90000","4.32555","0.87577"
"65.00000","4.33214","0.87554"
"65.10000","4.33852","0.87520"
"65.20000","4.34516","0.87531"
"65.30000","4.35234","0.87599"
"65.40000","4.35894","0.87532"
"65.50000","4.36516","0.87476"
"65.60000","4.37158","0.87464"
"65.70000","4.37842","0.87469"
"65.80000","4.38547","0.87497"
"65.90000","4.39208","0.87434"
"66.00000","4.39864","0.87444"
"66.10000","4.40543","0.87383"
"66.20000","4.41205","0.87359"
"66.30000","4.41863","0.87251"
"66.40000","4.42519","0.87230"
"66.50000","4.43196","0.87222"
"66.60000","4.43857","0.87116"
"66.70000","4.44517","0.87115"
"66.80000","4.45192","0.87089"
"66.90000","4.45903","0.87096"
"67.00000","4.46564","0.87080"
"67.10000","4.47181","0.86990"
"67.20000","4.47824","0.86953"
"67.30000","4.48531","0.87020"
"67.40000","4.49226","0.86998"
"67.50000","4.49870","0.86950"
"67.60000","4.50512","0.86904"
"67.70000","4.51190","0.86905"
"67.80000","4.51894","0.86912"
"67.90000","4.52545","0.86841"
"68.00000","4.53178","0.86817"
"68.10000","4.53831","0.86759"
"68.20000","4.54516","0.86792"
"68.30000","4.55202","0.86807"
"68.40000","4.55867","0.86798"
"68.50000","4.56545","0.86735"
"68.60000","4.57199","0.86729"
"68.70000","4.57856","0.86720"
"68.80000","4.58518","0.86726"
"68.90000","4.59185","0.86687"
"69.00000","4.59869","0.86695"
"69.10000","4.60517","0.86676"
"69.20000","4.61171","0.86599"
"69.30000","4.61874","0.86658"
"69.40000","4.62581","0.86642"
"69.50000","4.63224","0.86583"
"69.60000","4.63833","0.86506"
"69.70000","4.64481","0.86501"
"69.80000","4.65210","0.86492"
"69.90000","4.65891","0.86479"
"70.00000","4.66528","0.86424"
"70.10000","4.67189","0.86503"
"70.20000","4.67864","0.86448"
"70.30000","4.68559","0.86471"
"70.40000","4.69194","0.86433"
"70.50000","4.69838","0.86348"
"70.60000","4.70510","0.86317"
"70.70000","4.71192","0.86347"
"70.80000","4.71863","0.86302"
"70.90000","4.72539","0.86318"
"71.00000","4.73231","0.86280"
"71.10000","4.73884","0.86241"
"71.20000","4.74502","0.86230"
"71.30000","4.75167","0.86237"
"71.40000","4.75872","0.86203"
"71.50000","4.76537","0.86100"
"71.60000","4.77197","0.86103"
"71.70000","4.77840","0.86097"
"71.80000","4.78563","0.86105"
"71.90000","4.79246","0.86069"
"72.00000","4.79868","0.86011"
"72.10000","4.80492","0.85941"
"72.20000","4.81164","0.85977"
"72.30000","4.81873","0.85961"
"72.40000","4.82552","0.85949"
"72.50000","4.83196","0.85919"
"72.60000","4.83864","0.85920"
"72.70000","4.84538","0.85948"
"72.80000","4.85200","0.85918"
"72.90000","4.85846","0.85872"
"73.00000","4.86515","0.85893"
"73.10000","4.87178","0.85807"
"73.20000","4.87842","0.85755"
"73.30000","4.88526","0.85651"
"73.40000","4.89228","0.85705"
"73.50000","4.89890","0.85618"
"73.60000","4.90533","0.85560"
"73.70000","4.91158","0.85538"
"73.80000","4.91835","0.85477"
"73.90000","4.92558","0.85434"
"74.00000","4.93210","0.85390"
"74.10000","4.93851","0.85360"
"74.20000","4.94519","0.85349"
"74.30000","4.95233","0.85284"
"74.40000","4.95896","0.85222"
"74.50000","4.96522","0.85223"
"74.60000","4.97152","0.85108"
"74.70000","4.97831","0.85188"
"74.80000","4.98545","0.85163"
"74.90000","4.99209","0.85122"
"75.00000","4.99867","0.85036"
"75.10000","5.00537","0.85044"
"75.20000","5.01210","0.84982"
"75.30000","5.01863","0.84918"
"75.40000","5.02509","0.84846"
"75.50000","5.03207","0.84813"
"75.60000","5.03859","0.84752"
"75.70000","5.04512","0.84694"
"75.80000","5.05195","0.84746"
"75.90000","5.05903","0.84707"
"76.00000","5.06562","0.84679"
"76.10000","5.07180","0.84630"
"76.20000","5.07818","0.84579"
"76.30000","5.08535","0.84638"
"76.40000","5.09234","0.84610"
"76.50000","5.09882","0.84514"
"76.60000","5.10507","0.84448"
"76.70000","5.11184","0.84429"
"76.80000","5.11892","0.84447"
"76.90000","5.12545","0.84322"
"77.00000","5.13181","0.84221"
"77.10000","5.13830","0.84191"
"77.20000","5.14509","0.84162"
"77.30000","5.15204","0.84104"
"77.40000","5.15867","0.84068"
"77.50000","5.16561","0.84032"
"77.60000","5.17207","0.83920"
"77.70000","5.17843","0.83889"
"77.80000","5.18512","0.83889"
"77.90000","5.19189","0.83808"
"78.00000","5.19884","0.83715"
"78.10000","5.20521","0.83640"
"78.20000","5.21159","0.83536"
"78.30000","5.21872","0.83568"
"78.40000","5.22581","0.83519"
"78.50000","5.23221","0.83413"
"78.60000","5.23844","0.83287"
"78.70000","5.24481","0.83303"
"78.80000","5.25202","0.83239"
"78.90000","5.25889","0.83207"
"79.00000","5.26540","0.83131"
"79.10000","5.27190","0.83047"
"79.20000","5.27853","0.83007"
"79.30000","5.28556","0.82982"
"79.40000","5.29202","0.82929"
"79.50000","5.29843","0.82869"
"79.60000","5.30518","0.82858"
"79.70000","5.31179","0.82831"
"79.80000","5.31870","0.82797"
"79.90000","5.32543","0.82716"
"80.00000","5.33231","0.82757"
"80.10000","5.33873","0.82644"
"80.20000","5.34501","0.82660"
"80.30000","5.35177","0.82597"
"80.40000","5.35875","0.82579"
"80.50000","5.36549","0.82512"
"80.60000","5.37192","0.82403"
"80.70000","5.37838","0.82344"
"80.80000","5.38564","0.82332"
"80.90000","5.39241","0.82305"
"81.00000","5.39871","0.82144"
"81.10000","5.40493","0.82077"
"81.20000","5.41156","0.82076"
"81.30000","5.41867","0.81984"
"81.40000","5.42554","0.81949"
"81.50000","5.43195","0.81831"
"81.60000","5.43848","0.81714"
"81.70000","5.44517","0.81658"
"81.80000","5.45193","0.81572"
"81.90000","5.45850","0.81486"
"82.00000","5.46523","0.81425"
"82.10000","5.47178","0.81309"
"82.20000","5.47845","0.81270"
"82.30000","5.48526","0.81183"
"82.40000","5.49221","0.81156"
"82.50000","5.49892","0.81064"
"82.60000","5.50539","0.80979"
"82.70000","5.51153","0.80882"
"82.80000","5.51829","0.80844"
"82.90000","5.52556","0.80772"
"83.00000","5.53217","0.80716"
"83.10000","5.53853","0.80543"
"83.20000","5.54502","0.80474"
"83.30000","5.55228","0.80437"
"83.40000","5.55909","0.80277"
"83.50000","5.56532","0.80210"
"83.60000","5.57157","0.80052"
"83.70000","5.57832","0.80037"
"83.80000","5.58548","0.79947"
"83.90000","5.59209","0.79826"
"84.00000","5.59874","0.79748"
"84.10000","5.60529","0.79671"
"84.20000","5.61195","0.79574"
"84.30000","5.61861","0.79492"
"84.40000","5.62511","0.79404"
"84.50000","5.63209","0.79369"
"84.60000","5.63851","0.79236"
"84.70000","5.64504","0.79196"
"84.80000","5.65200","0.79160"
"84.90000","5.65909","0.79062"
"85.00000","5.66574","0.78951"
"85.10000","5.67178","0.78832"
"85.20000","5.67814","0.78765"
"85.30000","5.68537","0.78732"
"85.40000","5.69232","0.78605"
"85.50000","5.69878","0.78467"
"85.60000","5.70498","0.78328"
"85.70000","5.71181","0.78262"
"85.80000","5.71902","0.78193"
"85.90000","5.72542","0.78106"
"86.00000","5.73181","0.78017"
"86.10000","5.73819","0.77952"
"86.20000","5.74510","0.77915"
"86.30000","5.75202","0.77829"
"86.40000","5.75872","0.77706"
"86.50000","5.76555","0.77632"
"86.60000","5.77199","0.77529"
"86.70000","5.77846","0.77433"
"86.80000","5.78510","0.77368"
"86.90000","5.79193","0.77261"
"87.00000","5.79892","0.77206"
"87.10000","5.80513","0.77048"
"87.20000","5.81158","0.76956"
"87.30000","5.81879","0.76944"
"87.40000","5.82582","0.76815"
"87.50000","5.83228","0.76693"
"87.60000","5.83828","0.76544"
"87.70000","5.84473","0.76446"
"87.80000","5.85219","0.76394"
"87.90000","5.85894","0.76234"
"88.00000","5.86528","0.76041"
"88.10000","5.87176","0.75953"
"88.20000","5.87858","0.75796"
"88.30000","5.88556","0.75729"
"88.40000","5.89203","0.75572"
"88.50000","5.89849","0.75401"
"88.60000","5.90517","0.75292"
"88.70000","5.91184","0.75233"
"88.80000","5.91864","0.75162"
"88.90000","5.92542","0.75027"
"89.00000","5.93240","0.74975"
"89.10000","5.93870","0.74849"
"89.20000","5.94498","0.74733"
"89.30000","5.95175","0.74660"
"89.40000","5.95883","0.74555"
"89.50000","5.96545","0.74419"
"89.60000","5.97185","0.74345"
"89.70000","5.97838","0.74235"
"89.80000","5.98560","0.74152"
"89.90000","5.99253","0.74055"
"90.00000","5.99875","0.73883"
"90.10000","6.00490","0.73730"
"90.20000","6.01160","0.73672"
"90.30000","6.01875","0.73571"
"90.40000","6.02556","0.73477"
"90.50000","6.03196","0.73336"
"90.60000","6.03868","0.73242"
"90.70000","6.04516","0.73094"
"90.80000","6.05199","0.72948"
"90.90000","6.05851","0.72830"
"91.00000","6.06530","0.72697"
"91.10000","6.07184","0.72573"
"91.20000","6.07844","0.72486"
"91.30000","6.08524","0.72361"
"91.40000","6.09233","0.72288"
"91.50000","6.09894","0.72136"
"91.60000","6.10526","0.72038"
"91.70000","6.11156","0.71945"
"91.80000","6.11835","0.71833"
"91.90000","6.12552","0.71772"
"92.00000","6.13212","0.71655"
"92.10000","6.13857","0.71548"
"92.20000","6.14507","0.71490"
"92.30000","6.15226","0.71465"
"92.40000","6.15902","0.71356"
"92.50000","6.16527","0.71262"
"92.60000","6.17143","0.71128"
"92.70000","6.17831","0.71084"
"92.80000","6.18556","0.70967"
"92.90000","6.19204","0.70882"
"93.00000","6.19870","0.70729"
"93.10000","6.20532","0.70621"
"93.20000","6.21203","0.70563"
"93.30000","6.21867","0.70455"
"93.40000","6.22510","0.70326"
"93.50000","6.23200","0.70233"
"93.60000","6.23850","0.70078"
"93.70000","6.24514","0.69999"
"93.80000","6.25197","0.69881"
"93.90000","6.25907","0.69790"
"94.00000","6.26574","0.69624"
"94.10000","6.27178","0.69435"
"94.20000","6.27813","0.69316"
"94.30000","6.28525","0.69189"
"94.40000","6.29230","0.69086"
"94.50000","6.29892","0.68933"
"94.60000","6.30507","0.68800"
"94.70000","6.31184","0.68691"
"94.80000","6.31899","0.68645"
"94.90000","6.32543","0.68448"
"95.00000","6.33181","0.68317"
"95.10000","6.33834","0.68185"
"95.20000","6.34513","0.68062"
"95.30000","6.35193","0.67937"
"95.40000","6.35860","0.67845"
"95.50000","6.36555","0.67765"
"95.60000","6.37200","0.67641"
"95.70000","6.37847","0.67477"
"95.80000","6.38509","0.67327"
"95.90000","6.39181","0.67245"
"96.00000","6.39884","0.67150"
"96.10000","6.40517","0.66979"
"96.20000","6.41167","0.66898"
"96.30000","6.41886","0.66811"
"96.40000","6.42584","0.66678"
"96.50000","6.43218","0.66551"
"96.60000","6.43832","0.66338"
"96.70000","6.44475","0.66223"
"96.80000","6.45213","0.66163"
"96.90000","6.45896","0.65975"
"97.00000","6.46533","0.65868"
"97.10000","6.47196","0.65776"
"97.20000","6.47858","0.65644"
"97.30000","6.48556","0.65512"
"97.40000","6.49193","0.65307"
"97.50000","6.49836","0.65223"
"97.60000","6.50522","0.65032"
"97.70000","6.51183","0.64925"
"97.80000","6.51873","0.64742"
"97.90000","6.52543","0.64663"
"98.00000","6.53235","0.64446"
"98.10000","6.53869","0.64270"
"98.20000","6.54499","0.64153"
"98.30000","6.55171","0.63979"
"98.40000","6.55872","0.63895"
"98.50000","6.56541","0.63728"
"98.60000","6.57196","0.63595"
"98.70000","6.57841","0.63510"
"98.80000","6.58567","0.63436"
"98.90000","6.59241","0.63280"
"99.00000","6.59870","0.63107"
"99.10000","6.60498","0.62924"
"99.20000","6.61161","0.62836"
"99.30000","6.61874","0.62667"
"99.40000","6.62550","0.62548"
"99.50000","6.63197","0.62415"
"99.60000","6.63864","0.62303"
"99.70000","6.64521","0.62142"
"99.80000","6.65203","0.61952"
"99.90000","6.65847","0.61830"
"100.00000","6.66520","0.61673"
"100.10000","6.67184","0.61545"
"100.20000","6.67855","0.61466"
"100.30000","6.68528","0.61367"
"100.40000","6.69215","0.61242"
"100.50000","6.69891","0.61101"
"100.60000","6.70533","0.60936"
"100.70000","6.71157","0.60791"
"100.80000","6.71835","0.60677"
"100.90000","6.72553","0.60531"
"101.00000","6.73209","0.60411"
"101.10000","6.73858","0.60145"
"101.20000","6.74517","0.60051"
"101.30000","6.75222","0.59867"
"101.40000","6.75900","0.59733"
"101.50000","6.76523","0.59520"
"101.60000","6.77157","0.59331"
"101.70000","6.77847","0.59221"
"101.80000","6.78548","0.59066"
"101.90000","6.79207","0.58847"
"102.00000","6.79873","0.58597"
"102.10000","6.80533","0.58390"
"102.20000","6.81200","0.58176"
"102.30000","6.81865","0.58010"
"102.40000","6.82512","0.57788"
"102.50000","6.83207","0.57606"
"102.60000","6.83857","0.57413"
"102.70000","6.84516","0.57254"
"102.80000","6.85186","0.57039"
"102.90000","6.85899","0.56895"
"103.00000","6.86563","0.56675"
"103.10000","6.87180","0.56395"
"103.20000","6.87820","0.56164"
"103.30000","6.88533","0.55893"
"103.40000","6.89223","0.55552"
"103.50000","6.89874","0.55244"
"103.60000","6.90515","0.54909"
"103.70000","6.91191","0.54582"
"103.80000","6.91886","0.54323"
"103.90000","6.92545","0.53999"
"104.00000","6.93190","0.53642"
"104.10000","6.93831","0.53351"
"104.20000","6.94520","0.53051"
"104.30000","6.95203","0.52785"
"104.40000","6.95863","0.52509"
"104.50000","6.96553","0.52243"
"104.60000","6.97198","0.51918"
"104.70000","6.97839","0.51562"
"104.80000","6.98512","0.51292"
"104.90000","6.99195","0.51010"
"105.00000","6.99885","0.50731"
"105.10000","7.00514","0.50403"
"105.20000","7.01162","0.50124"
"105.30000","7.01878","0.49898"
"105.40000","7.02578","0.49604"
"105.50000","7.03227","0.49224"
"105.60000","7.03829","0.48910"
"105.70000","7.04474","0.48634"
"105.80000","7.05208","0.48331"
"105.90000","7.05890","0.47988"
"106.00000","7.06540","0.47667"
"106.10000","7.07181","0.47412"
"106.20000","7.07851","0.47165"
"106.30000","7.08561","0.46936"
"106.40000","7.09201","0.46696"
"106.50000","7.09848","0.46396"
"106.60000","7.10505","0.46099"
"106.70000","7.11181","0.45858"
"106.80000","7.11869","0.45561"
"106.90000","7.12544","0.45308"
"107.00000","7.13243","0.45034"
"107.10000","7.13868","0.44787"
"107.20000","7.14496","0.44533"
"107.30000","7.15173","0.44263"
"107.40000","7.15880","0.44029"
"107.50000","7.16563","0.43874"
"107.60000","7.17187","0.43588"
"107.70000","7.17830","0.43293"
"107.80000","7.18560","0.43064"
"107.90000","7.19244","0.42836"
"108.00000","7.19876","0.42457"
"108.10000","7.20487","0.42151"
"108.20000","7.21159","0.41929"
"108.30000","7.21876","0.41731"
"108.40000","7.22555","0.41481"
"108.50000","7.23198","0.41239"
"108.60000","7.23856","0.40977"
"108.70000","7.24525","0.40775"
"108.80000","7.25207","0.40585"
"108.90000","7.25856","0.40444"
"109.00000","7.26529","0.40211"
"109.10000","7.27163","0.40086"
"109.20000","7.27842","0.39868"
"109.30000","7.28527","0.39731"
"109.40000","7.29231","0.39554"
"109.50000","7.29897","0.39334"
"109.60000","7.30521","0.39158"
"109.70000","7.31157","0.38948"
"109.80000","7.31836","0.38826"
"109.90000","7.32550","0.38698"
"110.00000","7.33214","0.38518"
"110.10000","7.33850","0.38335"
"110.20000","7.34517","0.38162"
"110.30000","7.35226","0.37990"
"110.40000","7.35902","0.37720"
"110.50000","7.36529","0.37512"
"110.60000","7.37148","0.37342"
"110.70000","7.37836","0.37194"
"110.80000","7.38540","0.36992"
"110.90000","7.39203","0.36809"
"111.00000","7.39873","0.36635"
"111.10000","7.40540","0.36408"
"111.20000","7.41202","0.36240"
"111.30000","7.41866","0.35944"
"111.40000","7.42514","0.35761"
"111.50000","7.43213","0.35585"
"111.60000","7.43855","0.35400"
"111.70000","7.44506","0.35218"
"111.80000","7.45197","0.35013"
"111.90000","7.45906","0.34780"
"112.00000","7.46566","0.34565"
"112.10000","7.47183","0.34391"
"112.20000","7.47819","0.34168"
"112.30000","7.48526","0.34064"
"112.40000","7.49228","0.33874"
"112.50000","7.49882","0.33677"
"112.60000","7.50516","0.33392"
"112.70000","7.51183","0.33277"
"112.80000","7.51896","0.33141"
"112.90000","7.52541","0.32983"
"113.00000","7.53181","0.32665"
"113.10000","7.53835","0.32659"
"113.20000","7.54508","0.32536"
"113.30000","7.55194","0.32436"
"113.40000","7.55863","0.32302"
"113.50000","7.56559","0.32265"
"113.60000","7.57198","0.32110"
"113.70000","7.57841","0.32065"
"113.80000","7.58513","0.31989"
"113.90000","7.59188","0.31950"
"114.00000","7.59878","0.31846"
"114.10000","7.60528","0.31719"
"114.20000","7.61167","0.31594"
"114.30000","7.61879","0.31507"
"114.40000","7.62573","0.31416"
"114.50000","7.63219","0.31271"
"114.60000","7.63845","0.31097"
"114.70000","7.64489","0.30974"
"114.80000","7.65205","0.30854"
"114.90000","7.65880","0.30741"
"115.00000","7.66536","0.30617"
"115.10000","7.67192","0.30472"
"115.20000","7.67856","0.30367"
"115.30000","7.68561","0.30222"
"115.40000","7.69198","0.30062"
"115.50000","7.69839","0.29913"
"115.60000","7.70518","0.29798"
"115.70000","7.71183","0.29657"
"115.80000","7.71862","0.29509"
"115.90000","7.72534","0.29398"
"116.00000","7.73239","0.29278"
"116.10000","7.73885","0.29183"
"116.20000","7.74500","0.29079"
"116.30000","7.75165","0.28953"
"116.40000","7.75870","0.28859"
"116.50000","7.76551","0.28787"
"116.60000","7.77191","0.28646"
"116.70000","7.77842","0.28518"
"116.80000","7.78552","0.28418"
"116.90000","7.79243","0.28247"
"117.00000","7.79875","0.28123"
"117.10000","7.80488","0.27973"
"117.20000","7.81163","0.27915"
"117.30000","7.81870","0.27856"
"117.40000","7.82557","0.27731"
"117.50000","7.83199","0.27573"
"117.60000","7.83868","0.27449"
"117.70000","7.84522","0.27328"
"117.80000","7.85205","0.27204"
"117.90000","7.85847","0.27099"
"118.00000","7.86517","0.27023"
"118.10000","7.87181","0.26869"
"118.20000","7.87852","0.26807"
"118.30000","7.88527","0.26704"
"118.40000","7.89214","0.26657"
"118.50000","7.89895","0.26458"
"118.60000","7.90531","0.26378"
"118.70000","7.91164","0.26297"
"118.80000","7.91839","0.26192"
"118.90000","7.92550","0.26111"
"119.00000","7.93224","0.26096"
"119.10000","7.93854","0.25989"
"119.20000","7.94515","0.25997"
"119.30000","7.95225","0.25886"
"119.40000","7.95893","0.25818"
"119.50000","7.96519","0.25765"
"119.60000","7.97153","0.25686"
"119.70000","7.97844","0.25595"
"119.80000","7.98547","0.25550"
"119.90000","7.99207","0.25510"
"120.00000","7.99880","0.25453"
"120.10000","8.00538","0.25380"
"120.20000","8.01193","0.25268"
"120.30000","8.01855","0.25177"
"120.40000","8.02507","0.25097"
"120.50000","8.03202","0.25040"
"120.60000","8.03861","0.24998"
"120.70000","8.04514","0.24982"
"120.80000","8.05199","0.24870"
"120.90000","8.05902","0.24765"
"121.00000","8.06564","0.24705"
"121.10000","8.07177","0.24583"
"121.20000","8.07816","0.24505"
"121.30000","8.08529","0.24491"
"121.40000","8.09231","0.24355"
"121.50000","8.09882","0.24299"
"121.60000","8.10506","0.24191"
"121.70000","8.11184","0.24146"
"121.80000","8.11896","0.24026"
"121.90000","8.12541","0.23933"
"122.00000","8.13177","0.23875"
"122.10000","8.13831","0.23792"
"122.20000","8.14517","0.23713"
"122.30000","8.15196","0.23659"
"122.40000","8.15861","0.23579"
"122.50000","8.16562","0.23513"
"122.60000","8.17197","0.23420"
"122.70000","8.17846","0.23314"
"122.80000","8.18513","0.23217"
"122.90000","8.19188","0.23139"
"123.00000","8.19877","0.23051"
"123.10000","8.20505","0.22974"
"123.20000","8.21160","0.22916"
"123.30000","8.21874","0.22908"
"123.40000","8.22585","0.22842"
"123.50000","8.23228","0.22754"
"123.60000","8.23830","0.22726"
"123.70000","8.24471","0.22719"
"123.80000","8.25206","0.22595"
"123.90000","8.25892","0.22537"
"124.00000","8.26542","0.22482"
"124.10000","8.27180","0.22414"
"124.20000","8.27858","0.22360"
"124.30000","8.28560","0.22294"
"124.40000","8.29209","0.22228"
"124.50000","8.29847","0.22168"
"124.60000","8.30504","0.22106"
"124.70000","8.31175","0.22089"
"124.80000","8.31865","0.22030"
"124.90000","8.32546","0.21971"
"125.00000","8.33246","0.21906"
"125.10000","8.33865","0.21807"
"125.20000","8.34494","0.21773"
"125.30000","8.35165","0.21764"
"125.40000","8.35882","0.21695"
"125.50000","8.36554","0.21649"
"125.60000","8.37190","0.21640"
"125.70000","8.37841","0.21604"
"125.80000","8.38568","0.21572"
"125.90000","8.39249","0.21518"
"126.00000","8.39873","0.21457"
"126.10000","8.40484","0.21398"
"126.20000","8.41156","0.21372"
"126.30000","8.41871","0.21349"
"126.40000","8.42553","0.21257"
"126.50000","8.43198","0.21183"
"126.60000","8.43856","0.21169"
"126.70000","8.44520","0.21121"
"126.80000","8.45200","0.20993"
"126.90000","8.45851","0.20963"
"127.00000","8.46530","0.20921"
"127.10000","8.47180","0.20845"
"127.20000","8.47838","0.20820"
"127.30000","8.48529","0.20776"
"127.40000","8.49238","0.20711"
"127.50000","8.49893","0.20689"
"127.60000","8.50521","0.20644"
"127.70000","8.51153","0.20628"
"127.80000","8.51831","0.20638"
"127.90000","8.52561","0.20635"
"128.00000","8.53221","0.20585"
"128.10000","8.53848","0.20493"
"128.20000","8.54506","0.20499"
"128.30000","8.55229","0.20486"
"128.40000","8.55906","0.20475"
"128.50000","8.56529","0.20346"
"128.60000","8.57143","0.20341"
"128.70000","8.57837","0.20288"
"128.80000","8.58549","0.20268"
"128.90000","8.59207","0.20205"
"129.00000","8.59872","0.20159"
"129.10000","8.60529","0.20090"
"129.20000","8.61194","0.20049"
"129.30000","8.61862","0.19961"
"129.40000","8.62511","0.19884"
"129.50000","8.63213","0.19766"
"129.60000","8.63852","0.19645"
"129.70000","8.64513","0.19613"
"129.80000","8.65192","0.19601"
"129.90000","8.65907","0.19483"
"130.00000","8.66574","0.19431"
"130.10000","8.67170","0.19331"
"130.20000","8.67812","0.19290"
"130.30000","8.68530","0.19298"
"130.40000","8.69234","0.19262"
"130.50000","8.69887","0.19152"
"130.60000","8.70495","0.19078"
"130.70000","8.71184","0.19049"
"130.80000","8.71898","0.18977"
"130.90000","8.72546","0.18919"
"131.00000","8.73183","0.18835"
"131.10000","8.73821","0.18769"
"131.20000","8.74512","0.18774"
"131.30000","8.75195","0.18651"
"131.40000","8.75866","0.18632"
"131.50000","8.76570","0.18593"
"131.60000","8.77194","0.18506"
"131.70000","8.77847","0.18416"
"131.80000","8.78513","0.18373"
"131.90000","8.79194","0.18362"
"132.00000","8.79880","0.18273"
"132.10000","8.80506","0.18241"
"132.20000","8.81163","0.18239"
"132.30000","8.81878","0.18225"
"132.40000","8.82600","0.18171"
"132.50000","8.83221","0.18128"
"132.60000","8.83825","0.18072"
"132.70000","8.84474","0.18078"
"132.80000","8.85208","0.18022"
"132.90000","8.85898","0.17952"
"133.00000","8.86533","0.17913"
"133.10000","8.87175","0.17876"
"133.20000","8.87856","0.17835"
"133.30000","8.88564","0.17784"
"133.40000","8.89204","0.17702"
"133.50000","8.89832","0.17647"
"133.60000","8.90498","0.17580"
"133.70000","8.91192","0.17579"
"133.80000","8.91872","0.17540"
"133.90000","8.92549","0.17495"
"134.00000","8.93238","0.17476"
"134.10000","8.93873","0.17366"
"134.20000","8.94498","0.17387"
"134.30000","8.95171","0.17349"
"134.40000","8.95885","0.17318"
"134.50000","8.96550","0.17292"
"134.60000","8.97192","0.17226"
"134.70000","8.97832","0.17179"
"134.80000","8.98562","0.17194"
"134.90000","8.99250","0.17159"
"135.00000","8.99873","0.17114"
"135.10000","9.00488","0.17026"
"135.20000","9.01159","0.17032"
"135.30000","9.01870","0.16998"
"135.40000","9.02554","0.16916"
"135.50000","9.03189","0.16836"
"135.60000","9.03865","0.16801"
"135.70000","9.04517","0.16784"
"135.80000","9.05204","0.16747"
"135.90000","9.05862","0.16661"
"136.00000","9.06522","0.16663"
"136.10000","9.07185","0.16598"
"136.20000","9.07843","0.16627"
"136.30000","9.08528","0.16575"
"136.40000","9.09230","0.16566"
"136.50000","9.09888","0.16519"
"136.60000","9.10536","0.16442"
"136.70000","9.11156","0.16345"
"136.80000","9.11833","0.16342"
"136.90000","9.12556","0.16277"
"136.92500","9.12719","0.16260"