File: 20.12.09/1Layer_4.is_flex_RawData/Specimen_RawData_1.csv
Specimen properties : Thickness,"3.64000",mm
Specimen properties : Width,"5.38000",mm
Specimen properties : Support span,"58.24000",mm

Time,Extension,Load
(s),(mm),(kgf)
"0.00000","0.00000","-0.00089"
"0.20000","0.00527","0.00287"
"0.40000","0.02488","0.01249"
"0.60000","0.03859","0.01956"
"0.80000","0.05168","0.02546"
"1.00000","0.06519","0.03208"
"1.20000","0.07904","0.03832"
"1.40000","0.09177","0.04434"
"1.60000","0.10522","0.05075"
"1.80000","0.11877","0.05706"
"2.00000","0.13216","0.06297"
"2.20000","0.14552","0.06877"
"2.40000","0.15814","0.07457"
"2.60000","0.17222","0.08068"
"2.80000","0.18531","0.08616"
"3.00000","0.19876","0.09211"
"3.20000","0.21182","0.09762"
"3.40000","0.22506","0.10347"
"3.60000","0.23876","0.10888"
"3.80000","0.25211","0.11438"
"4.00000","0.26488","0.11985"
"4.20000","0.27890","0.12569"
"4.40000","0.29163","0.13097"
"4.60000","0.30571","0.13625"
"4.80000","0.31819","0.14157"
"5.00000","0.33209","0.14736"
"5.20000","0.34539","0.15261"
"5.40000","0.35863","0.15758"
"5.60000","0.37187","0.16293"
"5.80000","0.38525","0.16822"
"6.00000","0.39847","0.17309"
"6.20000","0.41242","0.17855"
"6.40000","0.42488","0.18333"
"6.60000","0.43901","0.18906"
"6.80000","0.45184","0.19369"
"7.00000","0.46548","0.16731"
"7.20000","0.47858","0.17929"
"7.40000","0.49165","0.18556"
"7.60000","0.50542","0.19073"
"7.80000","0.51879","0.19557"
"8.00000","0.53165","0.20023"
"8.20000","0.54556","0.20455"
"8.40000","0.55823","0.20808"
"8.60000","0.57257","0.21192"
"8.80000","0.58500","0.21585"
"9.00000","0.59859","0.22101"
"9.20000","0.61209","0.22546"
"9.40000","0.62517","0.23051"
"9.60000","0.63880","0.23508"
"9.80000","0.65180","0.23993"
"10.00000","0.66532","0.24504"
"10.20000","0.67910","0.24992"
"10.40000","0.69174","0.25447"
"10.60000","0.70527","0.25886"
"10.80000","0.71857","0.26322"
"11.00000","0.73209","0.26830"
"11.20000","0.74554","0.27327"
"11.40000","0.75808","0.27698"
"11.60000","0.77227","0.28188"
"11.80000","0.78513","0.28637"
"12.00000","0.79883","0.29087"
"12.20000","0.81175","0.29476"
"12.40000","0.82501","0.29887"
"12.60000","0.83875","0.30358"
"12.80000","0.85205","0.30760"
"13.00000","0.86488","0.31164"
"13.20000","0.87891","0.31590"
"13.40000","0.89162","0.32013"
"13.60000","0.90587","0.32443"
"13.80000","0.91820","0.32776"
"14.00000","0.93206","0.33208"
"14.20000","0.94538","0.33585"
"14.40000","0.95856","0.33967"
"14.60000","0.97182","0.34348"
"14.80000","0.98536","0.34810"
"15.00000","0.99853","0.35161"
"15.20000","1.01247","0.35559"
"15.40000","1.02481","0.35901"
"15.60000","1.03902","0.36351"
"15.80000","1.05184","0.36637"
"16.00000","1.06554","0.37061"
"16.20000","1.07855","0.37392"
"16.40000","1.09171","0.37731"
"16.60000","1.10533","0.38149"
"16.80000","1.11879","0.38516"
"17.00000","1.13174","0.38806"
"17.20000","1.14552","0.39167"
"17.40000","1.15833","0.39504"
"17.60000","1.17242","0.39884"
"17.80000","1.18516","0.40157"
"18.00000","1.19858","0.40524"
"18.20000","1.21212","0.40845"
"18.40000","1.22520","0.41179"
"18.60000","1.23874","0.41523"
"18.80000","1.25179","0.41823"
"19.00000","1.26533","0.42169"
"19.20000","1.27913","0.42521"
"19.40000","1.29165","0.42801"
"19.60000","1.30531","0.43112"
"19.80000","1.31872","0.43408"
"20.00000","1.33220","0.43755"
"20.20000","1.34552","0.44027"
"20.40000","1.35806","0.44270"
"20.60000","1.37226","0.44635"
"20.80000","1.38536","0.44908"
"21.00000","1.39873","0.45202"
"21.20000","1.41182","0.45499"
"21.40000","1.42498","0.45747"
"21.60000","1.43884","0.46070"
"21.80000","1.45209","0.46323"
"22.00000","1.46487","0.46613"
"22.20000","1.47888","0.46913"
"22.40000","1.49165","0.47195"
"22.60000","1.50570","0.47491"
"22.80000","1.51825","0.47713"
"23.00000","1.53210","0.48012"
"23.20000","1.54539","0.48293"
"23.40000","1.55854","0.48490"
"23.60000","1.57184","0.48772"
"23.80000","1.58525","0.49052"
"24.00000","1.59850","0.49322"
"24.20000","1.61247","0.49592"
"24.40000","1.62492","0.49797"
"24.60000","1.63897","0.50107"
"24.80000","1.65183","0.50352"
"25.00000","1.66546","0.50612"
"25.20000","1.67863","0.50855"
"25.40000","1.69168","0.51037"
"25.60000","1.70531","0.51331"
"25.80000","1.71870","0.51576"
"26.00000","1.73171","0.51800"
"26.20000","1.74565","0.52061"
"26.40000","1.75823","0.52264"
"26.60000","1.77261","0.52581"
"26.80000","1.78504","0.52753"
"27.00000","1.79862","0.52961"
"27.20000","1.81212","0.53188"
"27.40000","1.82518","0.53458"
"27.60000","1.83882","0.53647"
"27.80000","1.85173","0.53866"
"28.00000","1.86537","0.54103"
"28.20000","1.87910","0.54346"
"28.40000","1.89171","0.54530"
"28.60000","1.90533","0.54758"
"28.80000","1.91858","0.54942"
"29.00000","1.93209","0.55197"
"29.20000","1.94552","0.55360"
"29.40000","1.95824","0.55563"
"29.60000","1.97225","0.55770"
"29.80000","1.98519","0.55947"
"30.00000","1.99872","0.56202"
"30.20000","2.01185","0.56423"
"30.40000","2.02505","0.56615"
"30.60000","2.03879","0.56796"
"30.80000","2.05212","0.56983"
"31.00000","2.06484","0.57186"
"31.20000","2.07887","0.57373"
"31.40000","2.09163","0.57560"
"31.60000","2.10570","0.57811"
"31.80000","2.11831","0.57910"
"32.00000","2.13200","0.58135"
"32.20000","2.14537","0.58291"
"32.40000","2.15861","0.58520"
"32.60000","2.17183","0.58690"
"32.80000","2.18530","0.58854"
"33.00000","2.19850","0.59057"
"33.20000","2.21238","0.59229"
"33.40000","2.22491","0.59391"
"33.60000","2.23891","0.59555"
"33.80000","2.25189","0.59706"
"34.00000","2.26541","0.59900"
"34.20000","2.27862","0.60071"
"34.40000","2.29170","0.60230"
"34.60000","2.30541","0.60405"
"34.80000","2.31870","0.60590"
"35.00000","2.33179","0.60782"
"35.20000","2.34552","0.60939"
"35.40000","2.35832","0.61060"
"35.60000","2.37244","0.61281"
"35.80000","2.38509","0.61378"
"36.00000","2.39859","0.61608"
"36.20000","2.41207","0.61745"
"36.40000","2.42531","0.61873"
"36.60000","2.43866","0.62066"
"36.80000","2.45182","0.62264"
"37.00000","2.46535","0.62403"
"37.20000","2.47916","0.62554"
"37.40000","2.49169","0.62675"
"37.60000","2.50528","0.62881"
"37.80000","2.51869","0.63021"
"38.00000","2.53219","0.63192"
"38.20000","2.54551","0.63333"
"38.40000","2.55803","0.63464"
"38.60000","2.57222","0.63615"
"38.80000","2.58530","0.63746"
"39.00000","2.59880","0.63923"
"39.20000","2.61182","0.64081"
"39.40000","2.62497","0.64243"
"39.60000","2.63890","0.64403"
"39.80000","2.65204","0.64541"
"40.00000","2.66484","0.64653"
"40.20000","2.67893","0.64859"
"40.40000","2.69164","0.64980"
"40.60000","2.70575","0.65171"
"40.80000","2.71815","0.65255"
"41.00000","2.73203","0.65421"
"41.20000","2.74536","0.65594"
"41.40000","2.75858","0.65754"
"41.60000","2.77190","0.65919"
"41.80000","2.78532","0.66008"
"42.00000","2.79858","0.66186"
"42.20000","2.81239","0.66324"
"42.40000","2.82480","0.66370"
"42.60000","2.83896","0.66570"
"42.80000","2.85174","0.66723"
"43.00000","2.86552","0.66877"
"43.20000","2.87857","0.66970"
"43.40000","2.89177","0.67138"
"43.60000","2.90534","0.67250"
"43.80000","2.91866","0.67414"
"44.00000","2.93170","0.67513"
"44.20000","2.94563","0.67655"
"44.40000","2.95825","0.67775"
"44.60000","2.97263","0.67939"
"44.80000","2.98514","0.68032"
"45.00000","2.99855","0.68138"
"45.20000","3.01213","0.68289"
"45.40000","3.02523","0.68444"
"45.60000","3.03879","0.68548"
"45.80000","3.05181","0.68652"
"46.00000","3.06534","0.68799"
"46.20000","3.07908","0.68909"
"46.40000","3.09165","0.69041"
"46.60000","3.10535","0.69119"
"46.80000","3.11856","0.69258"
"47.00000","3.13217","0.69371"
"47.20000","3.14555","0.69492"
"47.40000","3.15810","0.69571"
"47.60000","3.17230","0.69751"
"47.80000","3.18519","0.69845"
"48.00000","3.19871","0.69956"
"48.20000","3.21183","0.70072"
"48.40000","3.22508","0.70174"
"48.60000","3.23878","0.70351"
"48.80000","3.25199","0.70415"
"49.00000","3.26490","0.70499"
"49.20000","3.27889","0.70694"
"49.40000","3.29163","0.70736"
"49.60000","3.30583","0.70924"
"49.80000","3.31814","0.70923"
"50.00000","3.33204","0.71098"
"50.20000","3.34536","0.71193"
"50.40000","3.35858","0.71308"
"50.60000","3.37187","0.71390"
"50.80000","3.38526","0.71480"
"51.00000","3.39849","0.71593"
"51.20000","3.41255","0.71732"
"51.40000","3.42488","0.71771"
"51.60000","3.43895","0.71942"
"51.80000","3.45188","0.71967"
"52.00000","3.46564","0.72156"
"52.20000","3.47849","0.72209"
"52.40000","3.49166","0.72286"
"52.60000","3.50538","0.72367"
"52.80000","3.51868","0.72509"
"53.00000","3.53170","0.72596"
"53.20000","3.54548","0.72691"
"53.40000","3.55833","0.72755"
"53.60000","3.57252","0.72918"
"53.80000","3.58516","0.72963"
"54.00000","3.59866","0.73071"
"54.20000","3.61214","0.73125"
"54.40000","3.62517","0.73247"
"54.60000","3.63881","0.73327"
"54.80000","3.65184","0.73386"
"55.00000","3.66527","0.73502"
"55.20000","3.67909","0.73610"
"55.40000","3.69175","0.73682"
"55.60000","3.70532","0.73782"
"55.80000","3.71874","0.73825"
"56.00000","3.73214","0.73953"
"56.20000","3.74554","0.74025"
"56.40000","3.75814","0.74052"
"56.60000","3.77218","0.74176"
"56.80000","3.78532","0.74276"
"57.00000","3.79864","0.74316"
"57.20000","3.81171","0.74435"
"57.40000","3.82509","0.74529"
"57.60000","3.83874","0.74619"
"57.80000","3.85207","0.74671"
"58.00000","3.86491","0.74720"
"58.20000","3.87878","0.74855"
"58.40000","3.89176","0.74947"
"58.60000","3.90574","0.75032"
"58.80000","3.91826","0.75098"
"59.00000","3.93205","0.75187"
"59.20000","3.94530","0.75229"
"59.40000","3.95872","0.75318"
"59.60000","3.97178","0.75400"
"59.80000","3.98532","0.75482"
"60.00000","3.99848","0.75583"
"60.20000","4.01234","0.75634"
"60.40000","4.02498","0.75723"
"60.60000","4.03885","0.75833"
"60.80000","4.05189","0.75925"
"61.00000","4.06551","0.75993"
"61.20000","4.07849","0.76011"
"61.40000","4.09189","0.76094"
"61.60000","4.10525","0.76175"
"61.80000","4.11875","0.76270"
"62.00000","4.13178","0.76331"
"62.20000","4.14548","0.76393"
"62.40000","4.15844","0.76506"
"62.60000","4.17233","0.76587"
"62.80000","4.18525","0.76642"
"63.00000","4.19856","0.76698"
"63.20000","4.21200","0.76729"
"63.40000","4.22537","0.76792"
"63.60000","4.23865","0.76928"
"63.80000","4.25192","0.77003"
"64.00000","4.26520","0.77071"
"64.20000","4.27889","0.77127"
"64.40000","4.29187","0.77190"
"64.60000","4.30519","0.77263"
"64.80000","4.31873","0.77345"
"65.00000","4.33210","0.77348"
"65.20000","4.34549","0.77399"
"65.40000","4.35828","0.77478"
"65.60000","4.37208","0.77591"
"65.80000","4.38533","0.77653"
"66.00000","4.39868","0.77674"
"66.20000","4.41179","0.77753"
"66.40000","4.42520","0.77782"
"66.60000","4.43875","0.77856"
"66.80000","4.45217","0.77889"
"67.00000","4.46489","0.77938"
"67.20000","4.47869","0.78006"
"67.40000","4.49188","0.78035"
"67.60000","4.50564","0.78142"
"67.80000","4.51828","0.78167"
"68.00000","4.53204","0.78272"
"68.20000","4.54524","0.78271"
"68.40000","4.55881","0.78343"
"68.60000","4.57174","0.78414"
"68.80000","4.58536","0.78463"
"69.00000","4.59847","0.78517"
"69.20000","4.61234","0.78578"
"69.40000","4.62505","0.78578"
"69.60000","4.63884","0.78696"
"69.80000","4.65182","0.78731"
"70.00000","4.66553","0.78748"
"70.20000","4.67857","0.78843"
"70.40000","4.69179","0.78894"
"70.60000","4.70523","0.78956"
"70.80000","4.71883","0.79006"
"71.00000","4.73172","0.79013"
"71.20000","4.74550","0.79111"
"71.40000","4.75839","0.79155"
"71.60000","4.77245","0.79222"
"71.80000","4.78514","0.79196"
"72.00000","4.79865","0.79317"
"72.20000","4.81201","0.79363"
"72.40000","4.82537","0.79406"
"72.60000","4.83865","0.79438"
"72.80000","4.85191","0.79473"
"73.00000","4.86530","0.79572"
"73.20000","4.87890","0.79624"
"73.40000","4.89181","0.79668"
"73.60000","4.90520","0.79683"
"73.80000","4.91870","0.79745"
"74.00000","4.93213","0.79810"
"74.20000","4.94550","0.79827"
"74.40000","4.95824","0.79833"
"74.60000","4.97219","0.79905"
"74.80000","4.98519","0.79942"
"75.00000","4.99869","0.79956"
"75.20000","5.01179","0.79968"
"75.40000","5.02517","0.80047"
"75.60000","5.03870","0.80077"
"75.80000","5.05214","0.80060"
"76.00000","5.06493","0.80107"
"76.20000","5.07880","0.80135"
"76.40000","5.09163","0.80138"
"76.60000","5.10576","0.80177"
"76.80000","5.11824","0.80126"
"77.00000","5.13209","0.80174"
"77.20000","5.14532","0.80190"
"77.40000","5.15861","0.80217"
"77.60000","5.17185","0.80205"
"77.80000","5.18507","0.80125"
"78.00000","5.19854","0.80172"
"78.20000","5.21243","0.80230"
"78.40000","5.22486","0.80209"
"78.60000","5.23907","0.80270"
"78.80000","5.25187","0.80149"
"79.00000","5.26539","0.80255"
"79.20000","5.27863","0.80273"
"79.40000","5.29172","0.80286"
"79.60000","5.30538","0.80285"
"79.80000","5.31861","0.80305"
"80.00000","5.33170","0.80313"
"80.20000","5.34552","0.80313"
"80.40000","5.35832","0.80329"
"80.60000","5.37253","0.80423"
"80.80000","5.38511","0.80375"
"81.00000","5.39862","0.80421"
"81.20000","5.41212","0.80404"
"81.40000","5.42516","0.80422"
"81.60000","5.43877","0.80462"
"81.80000","5.45184","0.80446"
"82.00000","5.46532","0.80478"
"82.20000","5.47899","0.80490"
"82.40000","5.49175","0.80448"
"82.60000","5.50537","0.80522"
"82.80000","5.51870","0.80485"
"83.00000","5.53222","0.80515"
"83.20000","5.54550","0.80487"
"83.40000","5.55819","0.80441"
"83.60000","5.57225","0.80529"
"83.80000","5.58528","0.80471"
"84.00000","5.59865","0.80497"
"84.20000","5.61178","0.80500"
"84.40000","5.62508","0.80491"
"84.60000","5.63869","0.80517"
"84.80000","5.65217","0.80475"
"85.00000","5.66487","0.80455"
"85.20000","5.67883","0.80463"
"85.40000","5.69172","0.80423"
"85.60000","5.70567","0.80392"
"85.80000","5.71829","0.80378"
"86.00000","5.73218","0.80402"
"86.20000","5.74532","0.80348"
"86.40000","5.75864","0.80338"
"86.60000","5.77196","0.80333"
"86.80000","5.78524","0.80351"
"87.00000","5.79854","0.80335"
"87.20000","5.81231","0.80305"
"87.40000","5.82495","0.80244"
"87.60000","5.83889","0.80244"
"87.80000","5.85186","0.80168"
"88.00000","5.86545","0.80208"
"88.20000","5.87847","0.80137"
"88.40000","5.89180","0.80167"
"88.60000","5.90538","0.80055"
"88.80000","5.91870","0.80107"
"89.00000","5.93177","0.80090"
"89.20000","5.94543","0.80035"
"89.40000","5.95827","0.79951"
"89.60000","5.97250","0.79976"
"89.80000","5.98516","0.79881"
"90.00000","5.99863","0.79858"
"90.20000","6.01204","0.79837"
"90.40000","6.02522","0.79861"
"90.60000","6.03868","0.79798"
"90.80000","6.05178","0.79766"
"91.00000","6.06528","0.79764"
"91.20000","6.07907","0.79708"
"91.40000","6.09175","0.79639"
"91.60000","6.10530","0.79608"
"91.80000","6.11877","0.79585"
"92.00000","6.13224","0.79544"
"92.20000","6.14545","0.79522"
"92.40000","6.15822","0.79443"
"92.60000","6.17219","0.79363"
"92.80000","6.18539","0.79304"
"93.00000","6.19868","0.79233"
"93.20000","6.21173","0.79115"
"93.40000","6.22502","0.79066"
"93.60000","6.23881","0.79025"
"93.80000","6.25211","0.78958"
"94.00000","6.26490","0.78866"
"94.20000","6.27886","0.78816"
"94.40000","6.29166","0.78718"
"94.60000","6.30568","0.78663"
"94.80000","6.31832","0.78573"
"95.00000","6.33200","0.78573"
"95.20000","6.34535","0.78475"
"95.40000","6.35866","0.78406"
"95.60000","6.37181","0.78372"
"95.80000","6.38530","0.78291"
"96.00000","6.39851","0.78210"
"96.20000","6.41238","0.78134"
"96.40000","6.42493","0.77990"
"96.60000","6.43894","0.77908"
"96.80000","6.45190","0.77758"
"97.00000","6.46553","0.77627"
"97.20000","6.47858","0.77460"
"97.40000","6.49170","0.77263"
"97.60000","6.50540","0.77024"
"97.80000","6.51879","0.76812"
"98.00000","6.53176","0.76644"
"98.20000","6.54554","0.76353"
"98.40000","6.55835","0.75961"
"98.60000","6.57242","0.75543"
"98.80000","6.58522","0.75128"
"99.00000","6.59860","0.74726"
"99.20000","6.61207","0.74361"
"99.40000","6.62521","0.73875"
"99.60000","6.63871","0.73461"
"99.80000","6.65185","0.72936"
"100.00000","6.66530","0.72461"
"100.20000","6.67901","0.71966"
"100.40000","6.69173","0.71380"
"100.60000","6.70532","0.70787"
"100.80000","6.71866","0.70252"
"101.00000","6.73219","0.69804"
"101.20000","6.74547","0.69311"
"101.40000","6.75813","0.68813"
"101.60000","6.77216","0.68335"
"101.80000","6.78519","0.67829"
"102.00000","6.79863","0.67241"
"102.20000","6.81188","0.66519"
"102.40000","6.82500","0.65869"
"102.60000","6.83880","0.65392"
"102.80000","6.85211","0.64907"
"103.00000","6.86485","0.64417"
"103.20000","6.87887","0.63956"
"103.40000","6.89163","0.63517"
"103.60000","6.90577","0.63108"
"103.80000","6.91832","0.62668"
"104.00000","6.93206","0.62396"
"104.20000","6.94540","0.61918"
"104.40000","6.95858","0.61616"
"104.60000","6.97187","0.61053"
"104.80000","6.98528","0.60571"
"105.00000","6.99857","0.59963"
"105.20000","7.01247","0.59188"
"105.40000","7.02487","0.58370"
"105.60000","7.03899","0.57744"
"105.80000","7.05190","0.57031"
"106.00000","7.06548","0.56375"
"106.20000","7.07862","0.55716"
"106.40000","7.09168","0.55195"
"106.60000","7.10538","0.54572"
"106.80000","7.11871","0.53986"
"107.00000","7.13171","0.53465"
"107.20000","7.14559","0.52949"
"107.40000","7.15831","0.52304"
"107.60000","7.17247","0.51754"
"107.80000","7.18507","0.51223"
"108.00000","7.19868","0.50876"
"108.20000","7.21203","0.50391"
"108.40000","7.22523","0.50045"
"108.60000","7.23874","0.49594"
"108.80000","7.25192","0.49237"
"109.00000","7.26527","0.48952"
"109.20000","7.27908","0.48675"
"109.40000","7.29174","0.48298"
"109.60000","7.30530","0.48123"
"109.80000","7.31860","0.47843"
"110.00000","7.33215","0.47589"
"110.20000","7.34552","0.47129"
"110.40000","7.35815","0.46939"
"110.60000","7.37220","0.46653"
"110.80000","7.38527","0.46460"
"111.00000","7.39875","0.46232"
"111.20000","7.41187","0.46005"
"111.40000","7.42503","0.45819"
"111.60000","7.43877","0.45645"
"111.80000","7.45207","0.45479"
"112.00000","7.46480","0.45371"
"112.20000","7.47889","0.45144"
"112.40000","7.49158","0.44982"
"112.60000","7.50569","0.44849"
"112.80000","7.51823","0.44605"
"113.00000","7.53201","0.44509"
"113.20000","7.54531","0.44340"
"113.40000","7.55862","0.44154"
"113.60000","7.57183","0.43919"
"113.80000","7.58526","0.43832"
"114.00000","7.59847","0.43710"
"114.20000","7.61248","0.43537"
"114.40000","7.62484","0.43267"
"114.60000","7.63902","0.43149"
"114.80000","7.65188","0.42999"
"115.00000","7.66549","0.42804"
"115.20000","7.67857","0.42537"
"115.40000","7.69176","0.42348"
"115.60000","7.70528","0.42061"
"115.80000","7.71874","0.41799"
"116.00000","7.73172","0.41526"
"116.20000","7.74554","0.41188"
"116.40000","7.75834","0.40863"
"116.60000","7.77250","0.40546"
"116.80000","7.78517","0.40129"
"117.00000","7.79866","0.39762"
"117.20000","7.81207","0.39401"
"117.40000","7.82519","0.39065"
"117.60000","7.83870","0.38760"
"117.80000","7.85191","0.38490"
"118.00000","7.86537","0.38275"
"118.20000","7.87897","0.37981"
"118.40000","7.89176","0.37719"
"118.60000","7.90526","0.37312"
"118.80000","7.91871","0.37030"
"119.00000","7.93215","0.36750"
"119.20000","7.94550","0.36368"
"119.40000","7.95818","0.36051"
"119.60000","7.97221","0.35845"
"119.80000","7.98535","0.35594"
"120.00000","7.99871","0.35406"
"120.20000","8.01177","0.35187"
"120.40000","8.02515","0.35058"
"120.60000","8.03874","0.34947"
"120.80000","8.05210","0.34782"
"121.00000","8.06491","0.34639"
"121.20000","8.07881","0.34456"
"121.40000","8.09175","0.34254"
"121.60000","8.10566","0.34049"
"121.80000","8.11828","0.33925"
"122.00000","8.13210","0.33821"
"122.20000","8.14532","0.33666"
"122.40000","8.15862","0.33489"
"122.60000","8.17181","0.33371"
"122.80000","8.18535","0.33266"
"123.00000","8.19854","0.33181"
"123.20000","8.21232","0.33038"
"123.40000","8.22489","0.32937"
"123.60000","8.23890","0.32913"
"123.80000","8.25191","0.32752"
"124.00000","8.26541","0.32758"
"124.20000","8.27863","0.32661"
"124.40000","8.29174","0.32523"
"124.60000","8.30533","0.32443"
"124.80000","8.31865","0.32300"
"125.00000","8.33178","0.32233"
"125.20000","8.34546","0.32118"
"125.40000","8.35834","0.31994"
"125.60000","8.37243","0.31903"
"125.80000","8.38508","0.31710"
"126.00000","8.39867","0.31598"
"126.20000","8.41209","0.31427"
"126.40000","8.42523","0.31183"
"126.60000","8.43874","0.31043"
"126.80000","8.45175","0.30810"
"127.00000","8.46530","0.30698"
"127.20000","8.47907","0.30530"
"127.40000","8.49172","0.30371"
"127.60000","8.50538","0.30278"
"127.80000","8.51867","0.30150"
"128.00000","8.53198","0.30069"
"128.20000","8.54563","0.29969"
"128.40000","8.55812","0.29952"
"128.60000","8.57230","0.29864"
"128.80000","8.58536","0.29758"
"129.00000","8.59869","0.29614"
"129.20000","8.61187","0.29535"
"129.40000","8.62510","0.29482"
"129.60000","8.63878","0.29297"
"129.80000","8.65201","0.29218"
"130.00000","8.66495","0.29077"
"130.20000","8.67879","0.28912"
"130.40000","8.69174","0.28769"
"130.60000","8.70575","0.28629"
"130.80000","8.71824","0.28488"
"131.00000","8.73200","0.28414"
"131.20000","8.74537","0.28202"
"131.40000","8.75867","0.28044"
"131.60000","8.77180","0.27894"
"131.80000","8.78532","0.27747"
"132.00000","8.79849","0.27617"
"132.20000","8.81241","0.27452"
"132.40000","8.82487","0.27327"
"132.60000","8.83897","0.27204"
"132.80000","8.85191","0.27062"
"133.00000","8.86554","0.26896"
"133.20000","8.87861","0.26736"
"133.40000","8.89163","0.26571"
"133.60000","8.90531","0.26495"
"133.80000","8.91873","0.26297"
"134.00000","8.93182","0.26186"
"134.20000","8.94545","0.26061"
"134.40000","8.95836","0.25882"
"134.60000","8.97243","0.25717"
"134.80000","8.98522","0.25416"
"135.00000","8.99864","0.25203"
"135.20000","9.01212","0.24923"
"135.40000","9.02520","0.24626"
"135.60000","9.03874","0.24357"
"135.80000","9.05179","0.23973"
"136.00000","9.06530","0.23638"
"136.20000","9.07903","0.23214"
"136.40000","9.09177","0.22787"
"136.60000","9.10520","0.22618"
"136.80000","9.11869","0.22326"
"137.00000","9.13216","0.22086"
"137.20000","9.14552","0.21794"
"137.40000","9.15807","0.21480"
"137.60000","9.17207","0.21291"
"137.80000","9.18533","0.21067"
"138.00000","9.19885","0.20898"
"138.20000","9.21185","0.20762"
"138.40000","9.22504","0.20639"
"138.60000","9.23870","0.20558"
"138.80000","9.25216","0.20388"
"139.00000","9.26483","0.20196"
"139.20000","9.27893","0.20054"
"139.40000","9.29164","0.19908"
"139.60000","9.30563","0.19786"
"139.80000","9.31830","0.19487"
"140.00000","9.33215","0.19370"
"140.20000","9.34537","0.19275"
"140.40000","9.35858","0.19124"
"140.60000","9.37180","0.18960"
"140.80000","9.38532","0.18828"
"141.00000","9.39855","0.18685"
"141.20000","9.41245","0.18523"
"141.40000","9.42489","0.18318"
"141.60000","9.43893","0.18207"
"141.80000","9.45187","0.18096"
"142.00000","9.46549","0.18012"
"142.20000","9.47858","0.17885"
"142.40000","9.49174","0.17864"
"142.60000","9.50535","0.17753"
"142.80000","9.51886","0.17628"
"143.00000","9.53174","0.17586"
"143.20000","9.54554","0.17488"
"143.40000","9.55823","0.17375"
"143.60000","9.57254","0.17400"
"143.80000","9.58511","0.17246"
"144.00000","9.59857","0.17210"
"144.20000","9.61213","0.17152"
"144.40000","9.62521","0.17106"
"144.60000","9.63878","0.17045"
"144.80000","9.65173","0.16992"
"145.00000","9.66536","0.16947"
"145.20000","9.67907","0.16879"
"145.40000","9.69170","0.16803"
"145.60000","9.70526","0.16785"
"145.80000","9.71874","0.16682"
"146.00000","9.73216","0.16674"
"146.20000","9.74558","0.16610"
"146.40000","9.75812","0.16539"
"146.60000","9.77224","0.16554"
"146.80000","9.78529","0.16493"
"147.00000","9.79871","0.16444"
"147.20000","9.81188","0.16394"
"147.40000","9.82510","0.16309"
"147.60000","9.83886","0.16285"
"147.80000","9.85199","0.16221"
"148.00000","9.86489","0.16109"
"148.20000","9.87885","0.16058"
"148.40000","9.89167","0.15996"
"148.60000","9.90577","0.15930"
"148.80000","9.91818","0.15825"
"149.00000","9.93209","0.15772"
"149.20000","9.94534","0.15698"
"149.40000","9.95856","0.15656"
"149.60000","9.97183","0.15632"
"149.80000","9.98523","0.15557"
"150.00000","9.99839","0.15534"
"150.20000","10.01249","0.15459"
"150.40000","10.02490","0.15338"
"150.60000","10.03893","0.15350"
"150.80000","10.05175","0.15336"
"151.00000","10.06542","0.15259"
"151.20000","10.07861","0.15204"
"151.40000","10.09168","0.15106"
"151.60000","10.10538","0.15049"
"151.80000","10.11872","0.14935"
"152.00000","10.13169","0.14871"
"152.20000","10.14554","0.14801"
"152.40000","10.15828","0.14666"
"152.60000","10.17255","0.14687"
"152.80000","10.18511","0.14611"
"153.00000","10.19865","0.14600"
"153.20000","10.21208","0.14546"
"153.40000","10.22517","0.14498"
"153.60000","10.23871","0.14343"
"153.80000","10.25169","0.14230"
"154.00000","10.26531","0.14086"
"154.20000","10.27904","0.13977"
"154.40000","10.29174","0.13838"
"154.60000","10.30535","0.13763"
"154.80000","10.31869","0.13712"
"155.00000","10.33215","0.13602"
"155.20000","10.34556","0.13545"
"155.40000","10.35813","0.13498"
"155.60000","10.37217","0.13444"
"155.80000","10.38533","0.13372"
"156.00000","10.39866","0.13291"
"156.20000","10.41186","0.13188"
"156.40000","10.42504","0.13076"
"156.60000","10.43872","0.13049"
"156.80000","10.45224","0.12968"
"157.00000","10.46488","0.12884"
"157.20000","10.47886","0.12851"
"157.40000","10.49168","0.12797"
"157.60000","10.50566","0.12761"
"157.80000","10.51834","0.12674"
"158.00000","10.53190","0.12637"
"158.20000","10.54531","0.12597"
"158.40000","10.55868","0.12515"
"158.60000","10.57177","0.12468"
"158.80000","10.58540","0.12437"
"159.00000","10.59847","0.12351"
"159.20000","10.61228","0.12234"
"159.40000","10.62498","0.12171"
"159.60000","10.63892","0.12114"
"159.80000","10.65193","0.12052"
"160.00000","10.66549","0.12027"
"160.20000","10.67844","0.12001"
"160.40000","10.69179","0.11949"
"160.60000","10.70522","0.11967"
"160.80000","10.71879","0.11935"
"161.00000","10.73174","0.11912"
"161.20000","10.74536","0.11876"
"161.40000","10.75833","0.11829"
"161.60000","10.77247","0.11778"
"161.80000","10.78521","0.11754"
"162.00000","10.79861","0.11722"
"162.20000","10.81204","0.11664"
"162.40000","10.82529","0.11648"
"162.60000","10.83868","0.11593"
"162.80000","10.85184","0.11607"
"163.00000","10.86540","0.11577"
"163.20000","10.87899","0.11538"
"163.40000","10.89180","0.11455"
"163.60000","10.90516","0.11428"
"163.80000","10.91878","0.11372"
"164.00000","10.93220","0.11318"
"164.20000","10.94547","0.11270"
"164.40000","10.95824","0.11248"
"164.60000","10.97215","0.11158"
"164.80000","10.98537","0.11102"
"165.00000","10.99872","0.11093"
"165.20000","11.01168","0.11024"
"165.40000","11.02518","0.11019"
"165.60000","11.03875","0.10998"
"165.80000","11.05207","0.10867"
"166.00000","11.06485","0.10827"
"166.20000","11.07878","0.10862"
"166.40000","11.09175","0.10845"
"166.60000","11.10561","0.10842"
"166.80000","11.11835","0.10775"
"167.00000","11.13209","0.10788"
"167.20000","11.14521","0.10751"
"167.40000","11.15874","0.10715"
"167.60000","11.17176","0.10697"
"167.80000","11.18535","0.10661"
"168.00000","11.19846","0.10672"
"168.20000","11.21230","0.10651"
"168.40000","11.22498","0.10588"
"168.60000","11.23892","0.10579"
"168.80000","11.25187","0.10548"
"169.00000","11.26550","0.10539"
"169.20000","11.27846","0.10517"
"169.40000","11.29190","0.10467"
"169.60000","11.30531","0.10495"
"169.80000","11.31872","0.10465"
"170.00000","11.33174","0.10429"
"170.20000","11.34545","0.10374"
"170.40000","11.35842","0.10286"
"170.60000","11.37242","0.10289"
"170.80000","11.38509","0.10238"
"171.00000","11.39871","0.10217"
"171.20000","11.41204","0.10200"
"171.40000","11.42526","0.10145"
"171.60000","11.43868","0.10048"
"171.80000","11.45183","0.09982"
"172.00000","11.46539","0.10001"
"172.20000","11.47893","0.09955"
"172.40000","11.49177","0.09958"
"172.60000","11.50525","0.09953"
"172.80000","11.51870","0.09898"
"173.00000","11.53221","0.09903"
"173.20000","11.54545","0.09814"
"173.40000","11.55818","0.09786"
"173.60000","11.57218","0.09770"
"173.75100","11.58195","0.09713"