File: 20.12.09/1Layer_8.is_flex_RawData/Specimen_RawData_1.csv
Specimen properties : Thickness,"4.00000",mm
Specimen properties : Width,"10.30000",mm
Specimen properties : Support span,"64.00000",mm

Time,Extension,Load
(s),(mm),(kgf)
"0.00000","0.00000","-0.00644"
"0.10000","0.00087","-0.00629"
"0.20000","0.00653","-0.00289"
"0.30000","0.01668","0.00158"
"0.40000","0.02443","0.00501"
"0.50000","0.03176","0.00829"
"0.60000","0.03863","0.01066"
"0.70000","0.04493","0.01242"
"0.80000","0.05189","0.01586"
"0.90000","0.05899","0.01836"
"1.00000","0.06555","0.02049"
"1.10000","0.07182","0.02276"
"1.20000","0.07815","0.02511"
"1.30000","0.08520","0.02742"
"1.40000","0.09218","0.03003"
"1.50000","0.09874","0.03251"
"1.60000","0.10545","0.03450"
"1.70000","0.11196","0.03644"
"1.80000","0.11868","0.03939"
"1.90000","0.12530","0.04101"
"2.00000","0.13188","0.04332"
"2.10000","0.13878","0.04557"
"2.20000","0.14516","0.04750"
"2.30000","0.15175","0.04969"
"2.40000","0.15881","0.05198"
"2.50000","0.16576","0.05424"
"2.60000","0.17218","0.05610"
"2.70000","0.17825","0.05792"
"2.80000","0.18480","0.05994"
"2.90000","0.19221","0.06199"
"3.00000","0.19896","0.06405"
"3.10000","0.20532","0.06579"
"3.20000","0.21164","0.06755"
"3.30000","0.21863","0.07002"
"3.40000","0.22572","0.07194"
"3.50000","0.23202","0.07294"
"3.60000","0.23828","0.07511"
"3.70000","0.24506","0.07693"
"3.80000","0.25188","0.07912"
"3.90000","0.25869","0.08062"
"4.00000","0.26536","0.08258"
"4.10000","0.27221","0.08426"
"4.20000","0.27864","0.08588"
"4.30000","0.28515","0.08804"
"4.40000","0.29170","0.08941"
"4.50000","0.29873","0.09122"
"4.60000","0.30545","0.09307"
"4.70000","0.31172","0.09458"
"4.80000","0.31830","0.09603"
"4.90000","0.32572","0.09814"
"5.00000","0.33247","0.09991"
"5.10000","0.33869","0.10135"
"5.20000","0.34482","0.10209"
"5.30000","0.35172","0.10402"
"5.40000","0.35887","0.10570"
"5.50000","0.36539","0.10736"
"5.60000","0.37189","0.10864"
"5.70000","0.37859","0.11046"
"5.80000","0.38531","0.11218"
"5.90000","0.39216","0.11376"
"6.00000","0.39859","0.11515"
"6.10000","0.40515","0.11681"
"6.20000","0.41172","0.11825"
"6.30000","0.41860","0.11954"
"6.40000","0.42539","0.12116"
"6.50000","0.43223","0.12287"
"6.60000","0.43901","0.12401"
"6.70000","0.44523","0.12567"
"6.80000","0.45164","0.12722"
"6.90000","0.45848","0.12826"
"7.00000","0.46552","0.12998"
"7.10000","0.47214","0.13135"
"7.20000","0.47848","0.13270"
"7.30000","0.48522","0.13396"
"7.40000","0.49231","0.13597"
"7.50000","0.49901","0.13699"
"7.60000","0.50522","0.13848"
"7.70000","0.51143","0.13972"
"7.80000","0.51857","0.14139"
"7.90000","0.52545","0.14281"
"8.00000","0.53213","0.14413"
"8.10000","0.53864","0.14537"
"8.20000","0.54532","0.14693"
"8.30000","0.55204","0.14813"
"8.40000","0.55858","0.14921"
"8.50000","0.56509","0.15086"
"8.60000","0.57190","0.15254"
"8.70000","0.57841","0.15333"
"8.80000","0.58523","0.15486"
"8.90000","0.59198","0.15641"
"9.00000","0.59902","0.15780"
"9.10000","0.60550","0.15909"
"9.20000","0.61174","0.16011"
"9.30000","0.61822","0.16151"
"9.40000","0.62522","0.16322"
"9.50000","0.63215","0.16439"
"9.60000","0.63880","0.16576"
"9.70000","0.64499","0.16667"
"9.80000","0.65211","0.16793"
"9.90000","0.65904","0.16958"
"10.00000","0.66552","0.17078"
"10.10000","0.67181","0.17175"
"10.20000","0.67815","0.17289"
"10.30000","0.68526","0.17432"
"10.40000","0.69219","0.17598"
"10.50000","0.69873","0.17688"
"10.60000","0.70549","0.17819"
"10.70000","0.71190","0.17895"
"10.80000","0.71856","0.18083"
"10.90000","0.72520","0.18191"
"11.00000","0.73189","0.18285"
"11.10000","0.73868","0.18418"
"11.20000","0.74516","0.18577"
"11.30000","0.75178","0.18687"
"11.40000","0.75886","0.18878"
"11.50000","0.76573","0.18931"
"11.60000","0.77222","0.19044"
"11.70000","0.77831","0.19149"
"11.80000","0.78489","0.19245"
"11.90000","0.79214","0.19463"
"12.00000","0.79895","0.19530"
"12.10000","0.80535","0.19662"
"12.20000","0.81162","0.19782"
"12.30000","0.81861","0.19915"
"12.40000","0.82571","0.20026"
"12.50000","0.83200","0.20147"
"12.60000","0.83836","0.20194"
"12.70000","0.84498","0.20357"
"12.80000","0.85189","0.20474"
"12.90000","0.85870","0.20612"
"13.00000","0.86528","0.20696"
"13.10000","0.87218","0.20808"
"13.20000","0.87852","0.20918"
"13.30000","0.88510","0.21034"
"13.40000","0.89173","0.21137"
"13.50000","0.89881","0.21272"
"13.60000","0.90545","0.21385"
"13.70000","0.91172","0.21481"
"13.80000","0.91830","0.21634"
"13.90000","0.92575","0.21774"
"14.00000","0.93257","0.21808"
"14.10000","0.93874","0.21935"
"14.20000","0.94478","0.21993"
"14.30000","0.95170","0.22142"
"14.40000","0.95887","0.22268"
"14.50000","0.96550","0.22413"
"14.60000","0.97189","0.22473"
"14.70000","0.97859","0.22571"
"14.80000","0.98535","0.22688"
"14.90000","0.99224","0.22835"
"15.00000","0.99870","0.22931"
"15.10000","1.00512","0.23004"
"15.20000","1.01172","0.23093"
"15.30000","1.01855","0.23246"
"15.40000","1.02543","0.23362"
"15.50000","1.03225","0.23471"
"15.60000","1.03888","0.23522"
"15.70000","1.04525","0.23638"
"15.80000","1.05159","0.23759"
"15.90000","1.05853","0.23872"
"16.00000","1.06559","0.23980"
"16.10000","1.07208","0.24050"
"16.20000","1.07837","0.24140"
"16.30000","1.08521","0.24302"
"16.40000","1.09241","0.24422"
"16.50000","1.09908","0.24475"
"16.60000","1.10521","0.24557"
"16.70000","1.11141","0.24662"
"16.80000","1.11849","0.24746"
"16.90000","1.12550","0.24897"
"17.00000","1.13213","0.24992"
"17.10000","1.13852","0.25078"
"17.20000","1.14521","0.25224"
"17.30000","1.15196","0.25269"
"17.40000","1.15872","0.25383"
"17.50000","1.16519","0.25465"
"17.60000","1.17192","0.25551"
"17.70000","1.17842","0.25669"
"17.80000","1.18514","0.25793"
"17.90000","1.19193","0.25897"
"18.00000","1.19905","0.25948"
"18.10000","1.20554","0.26088"
"18.20000","1.21173","0.26124"
"18.30000","1.21822","0.26266"
"18.40000","1.22529","0.26351"
"18.50000","1.23216","0.26439"
"18.60000","1.23878","0.26522"
"18.70000","1.24507","0.26616"
"18.80000","1.25196","0.26748"
"18.90000","1.25899","0.26813"
"19.00000","1.26554","0.26893"
"19.10000","1.27187","0.26979"
"19.20000","1.27820","0.27069"
"19.30000","1.28514","0.27180"
"19.40000","1.29216","0.27298"
"19.50000","1.29875","0.27377"
"19.60000","1.30548","0.27482"
"19.70000","1.31193","0.27534"
"19.80000","1.31855","0.27633"
"19.90000","1.32519","0.27720"
"20.00000","1.33182","0.27794"
"20.10000","1.33877","0.27916"
"20.20000","1.34511","0.27969"
"20.30000","1.35174","0.28076"
"20.40000","1.35883","0.28166"
"20.50000","1.36577","0.28290"
"20.60000","1.37219","0.28333"
"20.70000","1.37832","0.28415"
"20.80000","1.38477","0.28472"
"20.90000","1.39215","0.28607"
"21.00000","1.39892","0.28693"
"21.10000","1.40533","0.28762"
"21.20000","1.41172","0.28844"
"21.30000","1.41868","0.28930"
"21.40000","1.42568","0.29049"
"21.50000","1.43195","0.29142"
"21.60000","1.43829","0.29201"
"21.70000","1.44509","0.29267"
"21.80000","1.45194","0.29381"
"21.90000","1.45860","0.29428"
"22.00000","1.46523","0.29497"
"22.10000","1.47225","0.29607"
"22.20000","1.47865","0.29693"
"22.30000","1.48512","0.29751"
"22.40000","1.49167","0.29816"
"22.50000","1.49873","0.29890"
"22.60000","1.50549","0.29970"
"22.70000","1.51179","0.30068"
"22.80000","1.51829","0.30166"
"22.90000","1.52574","0.30287"
"23.00000","1.53243","0.30369"
"23.10000","1.53869","0.30416"
"23.20000","1.54478","0.30491"
"23.30000","1.55169","0.30585"
"23.40000","1.55888","0.30674"
"23.50000","1.56549","0.30732"
"23.60000","1.57189","0.30802"
"23.70000","1.57857","0.30886"
"23.80000","1.58528","0.30989"
"23.90000","1.59213","0.31078"
"24.00000","1.59866","0.31126"
"24.10000","1.60521","0.31181"
"24.20000","1.61170","0.31263"
"24.30000","1.61865","0.31330"
"24.40000","1.62541","0.31420"
"24.50000","1.63225","0.31540"
"24.60000","1.63893","0.31577"
"24.70000","1.64516","0.31658"
"24.80000","1.65166","0.31665"
"24.90000","1.65844","0.31782"
"25.00000","1.66561","0.31834"
"25.10000","1.67211","0.31966"
"25.20000","1.67849","0.31970"
"25.30000","1.68524","0.32069"
"25.40000","1.69240","0.32159"
"25.50000","1.69906","0.32255"
"25.60000","1.70525","0.32236"
"25.70000","1.71135","0.32322"
"25.80000","1.71841","0.32435"
"25.90000","1.72555","0.32475"
"26.00000","1.73221","0.32576"
"26.10000","1.73866","0.32566"
"26.20000","1.74524","0.32648"
"26.30000","1.75200","0.32760"
"26.40000","1.75865","0.32824"
"26.50000","1.76508","0.32881"
"26.60000","1.77195","0.32932"
"26.70000","1.77839","0.32985"
"26.80000","1.78518","0.33036"
"26.90000","1.79196","0.33138"
"27.00000","1.79911","0.33208"
"27.10000","1.80554","0.33272"
"27.20000","1.81174","0.33357"
"27.30000","1.81815","0.33393"
"27.40000","1.82528","0.33517"
"27.50000","1.83224","0.33637"
"27.60000","1.83877","0.33661"
"27.70000","1.84496","0.33692"
"27.80000","1.85197","0.33800"
"27.90000","1.85904","0.33829"
"28.00000","1.86555","0.33900"
"28.10000","1.87178","0.33935"
"28.20000","1.87810","0.33999"
"28.30000","1.88511","0.34112"
"28.40000","1.89221","0.34209"
"28.50000","1.89874","0.34250"
"28.60000","1.90543","0.34326"
"28.70000","1.91190","0.34401"
"28.80000","1.91863","0.34425"
"28.90000","1.92533","0.34480"
"29.00000","1.93188","0.34588"
"29.10000","1.93878","0.34648"
"29.20000","1.94518","0.34714"
"29.30000","1.95179","0.34769"
"29.40000","1.95885","0.34845"
"29.50000","1.96578","0.34907"
"29.60000","1.97213","0.35000"
"29.70000","1.97825","0.34991"
"29.80000","1.98482","0.35046"
"29.90000","1.99218","0.35161"
"30.00000","1.99906","0.35219"
"30.10000","2.00530","0.35277"
"30.20000","2.01164","0.35325"
"30.30000","2.01863","0.35399"
"30.40000","2.02565","0.35472"
"30.50000","2.03196","0.35527"
"30.60000","2.03831","0.35562"
"30.70000","2.04497","0.35578"
"30.80000","2.05194","0.35636"
"30.90000","2.05868","0.35745"
"31.00000","2.06543","0.35800"
"31.10000","2.07226","0.35818"
"31.20000","2.07852","0.35901"
"31.30000","2.08511","0.35916"
"31.40000","2.09178","0.35955"
"31.50000","2.09881","0.36073"
"31.60000","2.10538","0.36129"
"31.70000","2.11166","0.36133"
"31.80000","2.11830","0.36190"
"31.90000","2.12576","0.36279"
"32.00000","2.13253","0.36387"
"32.10000","2.13871","0.36424"
"32.20000","2.14478","0.36477"
"32.30000","2.15167","0.36517"
"32.40000","2.15894","0.36569"
"32.50000","2.16556","0.36636"
"32.60000","2.17194","0.36698"
"32.70000","2.17849","0.36751"
"32.80000","2.18526","0.36856"
"32.90000","2.19215","0.36887"
"33.00000","2.19870","0.36948"
"33.10000","2.20514","0.37005"
"33.20000","2.21173","0.37072"
"33.30000","2.21850","0.37152"
"33.40000","2.22541","0.37228"
"33.50000","2.23225","0.37291"
"33.60000","2.23899","0.37312"
"33.70000","2.24528","0.37377"
"33.80000","2.25166","0.37418"
"33.90000","2.25843","0.37512"
"34.00000","2.26556","0.37565"
"34.10000","2.27208","0.37614"
"34.20000","2.27842","0.37627"
"34.30000","2.28523","0.37730"
"34.40000","2.29240","0.37826"
"34.50000","2.29909","0.37840"
"34.60000","2.30525","0.37885"
"34.70000","2.31135","0.37951"
"34.80000","2.31842","0.38032"
"34.90000","2.32556","0.38128"
"35.00000","2.33221","0.38159"
"35.10000","2.33862","0.38190"
"35.20000","2.34521","0.38240"
"35.30000","2.35199","0.38334"
"35.40000","2.35867","0.38374"
"35.50000","2.36514","0.38425"
"35.60000","2.37190","0.38475"
"35.70000","2.37840","0.38527"
"35.80000","2.38522","0.38606"
"35.90000","2.39197","0.38662"
"36.00000","2.39910","0.38738"
"36.10000","2.40553","0.38796"
"36.20000","2.41172","0.38819"
"36.30000","2.41815","0.38863"
"36.40000","2.42525","0.38998"
"36.50000","2.43225","0.38997"
"36.60000","2.43883","0.39052"
"36.70000","2.44501","0.39100"
"36.80000","2.45198","0.39162"
"36.90000","2.45906","0.39227"
"37.00000","2.46553","0.39304"
"37.10000","2.47180","0.39305"
"37.20000","2.47816","0.39348"
"37.30000","2.48522","0.39382"
"37.40000","2.49214","0.39461"
"37.50000","2.49875","0.39505"
"37.60000","2.50549","0.39550"
"37.70000","2.51186","0.39593"
"37.80000","2.51851","0.39699"
"37.90000","2.52528","0.39710"
"38.00000","2.53192","0.39779"
"38.10000","2.53880","0.39807"
"38.20000","2.54509","0.39866"
"38.30000","2.55179","0.39850"
"38.40000","2.55884","0.39933"
"38.50000","2.56574","0.40005"
"38.60000","2.57220","0.40043"
"38.70000","2.57831","0.40027"
"38.80000","2.58486","0.40121"
"38.90000","2.59217","0.40191"
"39.00000","2.59901","0.40201"
"39.10000","2.60532","0.40252"
"39.20000","2.61163","0.40248"
"39.30000","2.61868","0.40389"
"39.40000","2.62567","0.40449"
"39.50000","2.63197","0.40456"
"39.60000","2.63835","0.40498"
"39.70000","2.64495","0.40584"
"39.80000","2.65184","0.40569"
"39.90000","2.65874","0.40730"
"40.00000","2.66535","0.40728"
"40.10000","2.67218","0.40782"
"40.20000","2.67856","0.40837"
"40.30000","2.68506","0.40835"
"40.40000","2.69173","0.40942"
"40.50000","2.69880","0.40961"
"40.60000","2.70540","0.40992"
"40.70000","2.71171","0.41049"
"40.80000","2.71826","0.41100"
"40.90000","2.72571","0.41176"
"41.00000","2.73253","0.41186"
"41.10000","2.73871","0.41240"
"41.20000","2.74478","0.41216"
"41.30000","2.75166","0.41298"
"41.40000","2.75891","0.41376"
"41.50000","2.76554","0.41368"
"41.60000","2.77196","0.41458"
"41.70000","2.77857","0.41447"
"41.80000","2.78529","0.41522"
"41.90000","2.79224","0.41611"
"42.00000","2.79863","0.41603"
"42.10000","2.80510","0.41629"
"42.20000","2.81179","0.41704"
"42.30000","2.81851","0.41726"
"42.40000","2.82536","0.41799"
"42.50000","2.83219","0.41827"
"42.60000","2.83895","0.41883"
"42.70000","2.84529","0.41916"
"42.80000","2.85168","0.41938"
"42.90000","2.85857","0.42003"
"43.00000","2.86553","0.42082"
"43.10000","2.87211","0.42094"
"43.20000","2.87854","0.42160"
"43.30000","2.88506","0.42197"
"43.40000","2.89237","0.42310"
"43.50000","2.89901","0.42309"
"43.60000","2.90522","0.42318"
"43.70000","2.91150","0.42340"
"43.80000","2.91848","0.42432"
"43.90000","2.92550","0.42510"
"44.00000","2.93204","0.42496"
"44.10000","2.93857","0.42538"
"44.20000","2.94539","0.42648"
"44.30000","2.95196","0.42651"
"44.40000","2.95854","0.42700"
"44.50000","2.96508","0.42725"
"44.60000","2.97189","0.42771"
"44.70000","2.97849","0.42830"
"44.80000","2.98522","0.42848"
"44.90000","2.99194","0.42902"
"45.00000","2.99896","0.42938"
"45.10000","3.00550","0.42950"
"45.20000","3.01185","0.43012"
"45.30000","3.01823","0.43049"
"45.40000","3.02517","0.43108"
"45.50000","3.03215","0.43165"
"45.60000","3.03877","0.43225"
"45.70000","3.04518","0.43196"
"45.80000","3.05209","0.43260"
"45.90000","3.05897","0.43328"
"46.00000","3.06541","0.43306"
"46.10000","3.07180","0.43388"
"46.20000","3.07829","0.43412"
"46.30000","3.08526","0.43448"
"46.40000","3.09210","0.43506"
"46.50000","3.09868","0.43499"
"46.60000","3.10540","0.43619"
"46.70000","3.11203","0.43663"
"46.80000","3.11876","0.43644"
"46.90000","3.12520","0.43700"
"47.00000","3.13179","0.43762"
"47.10000","3.13873","0.43749"
"47.20000","3.14528","0.43796"
"47.30000","3.15177","0.43833"
"47.40000","3.15879","0.43882"
"47.50000","3.16571","0.43961"
"47.60000","3.17212","0.43952"
"47.70000","3.17842","0.44012"
"47.80000","3.18485","0.44025"
"47.90000","3.19211","0.44096"
"48.00000","3.19894","0.44138"
"48.10000","3.20529","0.44112"
"48.20000","3.21174","0.44197"
"48.30000","3.21875","0.44228"
"48.40000","3.22555","0.44281"
"48.50000","3.23194","0.44290"
"48.60000","3.23828","0.44338"
"48.70000","3.24513","0.44342"
"48.80000","3.25190","0.44335"
"48.90000","3.25860","0.44434"
"49.00000","3.26523","0.44465"
"49.10000","3.27213","0.44479"
"49.20000","3.27875","0.44537"
"49.30000","3.28521","0.44557"
"49.40000","3.29169","0.44563"
"49.50000","3.29863","0.44608"
"49.60000","3.30537","0.44666"
"49.70000","3.31200","0.44695"
"49.80000","3.31850","0.44720"
"49.90000","3.32555","0.44816"
"50.00000","3.33231","0.44854"
"50.10000","3.33866","0.44809"
"50.20000","3.34495","0.44852"
"50.30000","3.35183","0.44929"
"50.40000","3.35870","0.44964"
"50.50000","3.36533","0.44976"
"50.60000","3.37183","0.45059"
"50.70000","3.37877","0.45074"
"50.80000","3.38542","0.45074"
"50.90000","3.39206","0.45128"
"51.00000","3.39843","0.45087"
"51.10000","3.40509","0.45123"
"51.20000","3.41209","0.45209"
"51.30000","3.41865","0.45223"
"51.40000","3.42540","0.45247"
"51.50000","3.43214","0.45254"
"51.60000","3.43889","0.45362"
"51.70000","3.44536","0.45388"
"51.80000","3.45173","0.45359"
"51.90000","3.45840","0.45400"
"52.00000","3.46543","0.45439"
"52.10000","3.47204","0.45470"
"52.20000","3.47864","0.45550"
"52.30000","3.48528","0.45551"
"52.40000","3.49225","0.45597"
"52.50000","3.49893","0.45650"
"52.60000","3.50524","0.45628"
"52.70000","3.51161","0.45671"
"52.80000","3.51853","0.45670"
"52.90000","3.52539","0.45741"
"53.00000","3.53200","0.45771"
"53.10000","3.53855","0.45793"
"53.20000","3.54552","0.45832"
"53.30000","3.55203","0.45898"
"53.40000","3.55857","0.45915"
"53.50000","3.56503","0.45917"
"53.60000","3.57186","0.45947"
"53.70000","3.57853","0.46039"
"53.80000","3.58523","0.46031"
"53.90000","3.59186","0.46073"
"54.00000","3.59888","0.46133"
"54.10000","3.60555","0.46143"
"54.20000","3.61197","0.46155"
"54.30000","3.61826","0.46144"
"54.40000","3.62516","0.46261"
"54.50000","3.63208","0.46257"
"54.60000","3.63873","0.46295"
"54.70000","3.64526","0.46318"
"54.80000","3.65210","0.46385"
"54.90000","3.65899","0.46392"
"55.00000","3.66536","0.46430"
"55.10000","3.67167","0.46455"
"55.20000","3.67837","0.46519"
"55.30000","3.68533","0.46581"
"55.40000","3.69207","0.46598"
"55.50000","3.69870","0.46657"
"55.60000","3.70546","0.46687"
"55.70000","3.71211","0.46694"
"55.80000","3.71866","0.46743"
"55.90000","3.72516","0.46716"
"56.00000","3.73180","0.46822"
"56.10000","3.73860","0.46855"
"56.20000","3.74536","0.46833"
"56.30000","3.75186","0.46911"
"56.40000","3.75869","0.46961"
"56.50000","3.76568","0.46989"
"56.60000","3.77212","0.47021"
"56.70000","3.77848","0.47017"
"56.80000","3.78496","0.47055"
"56.90000","3.79213","0.47116"
"57.00000","3.79884","0.47163"
"57.10000","3.80530","0.47166"
"57.20000","3.81174","0.47230"
"57.30000","3.81870","0.47260"
"57.40000","3.82556","0.47271"
"57.50000","3.83199","0.47354"
"57.60000","3.83831","0.47356"
"57.70000","3.84510","0.47399"
"57.80000","3.85191","0.47402"
"57.90000","3.85854","0.47487"
"58.00000","3.86524","0.47511"
"58.10000","3.87219","0.47523"
"58.20000","3.87868","0.47589"
"58.30000","3.88515","0.47615"
"58.40000","3.89168","0.47623"
"58.50000","3.89865","0.47690"
"58.60000","3.90539","0.47706"
"58.70000","3.91178","0.47722"
"58.80000","3.91839","0.47722"
"58.90000","3.92566","0.47807"
"59.00000","3.93238","0.47844"
"59.10000","3.93871","0.47816"
"59.20000","3.94489","0.47840"
"59.30000","3.95179","0.47874"
"59.40000","3.95878","0.47942"
"59.50000","3.96537","0.47935"
"59.60000","3.97188","0.47976"
"59.70000","3.97874","0.47949"
"59.80000","3.98541","0.48008"
"59.90000","3.99216","0.48065"
"60.00000","3.99853","0.48057"
"60.10000","4.00509","0.48126"
"60.20000","4.01186","0.48169"
"60.30000","4.01858","0.48210"
"60.40000","4.02527","0.48231"
"60.50000","4.03218","0.48259"
"60.60000","4.03895","0.48281"
"60.70000","4.04527","0.48253"
"60.80000","4.05170","0.48284"
"60.90000","4.05843","0.48382"
"61.00000","4.06546","0.48400"
"61.10000","4.07202","0.48399"
"61.20000","4.07858","0.48432"
"61.30000","4.08528","0.48471"
"61.40000","4.09226","0.48541"
"61.50000","4.09900","0.48512"
"61.60000","4.10518","0.48518"
"61.70000","4.11137","0.48515"
"61.80000","4.11861","0.48598"
"61.90000","4.12542","0.48642"
"62.00000","4.13211","0.48624"
"62.10000","4.13856","0.48656"
"62.20000","4.14527","0.48654"
"62.30000","4.15201","0.48676"
"62.40000","4.15861","0.48683"
"62.50000","4.16504","0.48674"
"62.60000","4.17189","0.48729"
"62.70000","4.17840","0.48728"
"62.80000","4.18528","0.48754"
"62.90000","4.19189","0.48809"
"63.00000","4.19903","0.48821"
"63.10000","4.20551","0.48818"
"63.20000","4.21174","0.48864"
"63.30000","4.21827","0.48866"
"63.40000","4.22523","0.48918"
"63.50000","4.23223","0.48949"
"63.60000","4.23870","0.48929"
"63.70000","4.24491","0.48952"
"63.80000","4.25210","0.48985"
"63.90000","4.25913","0.49013"
"64.00000","4.26557","0.49011"
"64.10000","4.27175","0.49024"
"64.20000","4.27814","0.48977"
"64.30000","4.28525","0.49095"
"64.40000","4.29218","0.49088"
"64.50000","4.29875","0.49077"
"64.60000","4.30543","0.49096"
"64.70000","4.31192","0.49090"
"64.80000","4.31859","0.49113"
"64.90000","4.32530","0.49155"
"65.00000","4.33190","0.49226"
"65.10000","4.33868","0.49201"
"65.20000","4.34512","0.49237"
"65.30000","4.35180","0.49233"
"65.40000","4.35892","0.49306"
"65.50000","4.36572","0.49287"
"65.60000","4.37211","0.49277"
"65.70000","4.37823","0.49290"
"65.80000","4.38483","0.49348"
"65.90000","4.39227","0.49357"
"66.00000","4.39891","0.49369"
"66.10000","4.40534","0.49392"
"66.20000","4.41171","0.49409"
"66.30000","4.41876","0.49433"
"66.40000","4.42570","0.49474"
"66.50000","4.43198","0.49439"
"66.60000","4.43829","0.49458"
"66.70000","4.44497","0.49473"
"66.80000","4.45192","0.49558"
"66.90000","4.45875","0.49483"
"67.00000","4.46535","0.49549"
"67.10000","4.47213","0.49562"
"67.20000","4.47860","0.49548"
"67.30000","4.48512","0.49573"
"67.40000","4.49170","0.49588"
"67.50000","4.49883","0.49626"
"67.60000","4.50541","0.49607"
"67.70000","4.51165","0.49604"
"67.80000","4.51823","0.49624"
"67.90000","4.52557","0.49667"
"68.00000","4.53249","0.49673"
"68.10000","4.53873","0.49645"
"68.20000","4.54483","0.49653"
"68.30000","4.55173","0.49717"
"68.40000","4.55892","0.49750"
"68.50000","4.56556","0.49766"
"68.60000","4.57184","0.49716"
"68.70000","4.57846","0.49748"
"68.80000","4.58536","0.49755"
"68.90000","4.59227","0.49779"
"69.00000","4.59870","0.49788"
"69.10000","4.60516","0.49786"
"69.20000","4.61172","0.49765"
"69.30000","4.61855","0.49811"
"69.40000","4.62535","0.49846"
"69.50000","4.63227","0.49866"
"69.60000","4.63893","0.49865"
"69.70000","4.64523","0.49851"
"69.80000","4.65169","0.49866"
"69.90000","4.65849","0.49866"
"70.00000","4.66555","0.49931"
"70.10000","4.67207","0.49866"
"70.20000","4.67847","0.49856"
"70.30000","4.68514","0.49877"
"70.40000","4.69239","0.49943"
"70.50000","4.69910","0.49939"
"70.60000","4.70530","0.49852"
"70.70000","4.71146","0.49838"
"70.80000","4.71847","0.49851"
"70.90000","4.72549","0.49900"
"71.00000","4.73217","0.49904"
"71.10000","4.73853","0.49890"
"71.20000","4.74520","0.49929"
"71.30000","4.75199","0.49942"
"71.40000","4.75868","0.49929"
"71.50000","4.76510","0.49946"
"71.60000","4.77190","0.49995"
"71.70000","4.77839","0.49949"
"71.80000","4.78518","0.49999"
"71.90000","4.79195","0.49991"
"72.00000","4.79905","0.50032"
"72.10000","4.80560","0.50040"
"72.20000","4.81178","0.50019"
"72.30000","4.81819","0.50010"
"72.40000","4.82524","0.50051"
"72.50000","4.83222","0.50099"
"72.60000","4.83872","0.50064"
"72.70000","4.84497","0.50074"
"72.80000","4.85214","0.50107"
"72.90000","4.85912","0.50155"
"73.00000","4.86546","0.50113"
"73.10000","4.87169","0.50093"
"73.20000","4.87824","0.50124"
"73.30000","4.88533","0.50193"
"73.40000","4.89220","0.50176"
"73.50000","4.89870","0.50147"
"73.60000","4.90537","0.50208"
"73.70000","4.91192","0.50187"
"73.80000","4.91861","0.50191"
"73.90000","4.92526","0.50182"
"74.00000","4.93184","0.50129"
"74.10000","4.93870","0.50198"
"74.20000","4.94527","0.50198"
"74.30000","4.95179","0.50142"
"74.40000","4.95876","0.50201"
"74.50000","4.96575","0.50196"
"74.60000","4.97217","0.50155"
"74.70000","4.97838","0.50129"
"74.80000","4.98491","0.50121"
"74.90000","4.99213","0.50213"
"75.00000","4.99890","0.50128"
"75.10000","5.00529","0.50143"
"75.20000","5.01165","0.50142"
"75.30000","5.01868","0.50154"
"75.40000","5.02565","0.50163"
"75.50000","5.03194","0.50162"
"75.60000","5.03826","0.50149"
"75.70000","5.04508","0.50109"
"75.80000","5.05196","0.50135"
"75.90000","5.05870","0.50145"
"76.00000","5.06530","0.50156"
"76.10000","5.07219","0.50129"
"76.20000","5.07861","0.50170"
"76.30000","5.08510","0.50146"
"76.40000","5.09171","0.50132"
"76.50000","5.09873","0.50100"
"76.60000","5.10536","0.50133"
"76.70000","5.11173","0.50078"
"76.80000","5.11837","0.50078"
"76.90000","5.12576","0.50095"
"77.00000","5.13240","0.50049"
"77.10000","5.13861","0.50012"
"77.20000","5.14485","0.50006"
"77.30000","5.15177","0.50049"
"77.40000","5.15890","0.50020"
"77.50000","5.16546","0.49996"
"77.60000","5.17189","0.49950"
"77.70000","5.17858","0.50011"
"77.80000","5.18535","0.49933"
"77.90000","5.19216","0.49948"
"78.00000","5.19862","0.49931"
"78.10000","5.20507","0.49888"
"78.20000","5.21177","0.49843"
"78.30000","5.21858","0.49848"
"78.40000","5.22532","0.49820"
"78.50000","5.23223","0.49788"
"78.60000","5.23903","0.49763"
"78.70000","5.24525","0.49719"
"78.80000","5.25156","0.49734"
"78.90000","5.25840","0.49709"
"79.00000","5.26556","0.49724"
"79.10000","5.27210","0.49700"
"79.20000","5.27858","0.49621"
"79.30000","5.28523","0.49665"
"79.40000","5.29235","0.49659"
"79.50000","5.29904","0.49621"
"79.60000","5.30523","0.49613"
"79.70000","5.31147","0.49614"
"79.80000","5.31848","0.49623"
"79.90000","5.32550","0.49654"
"80.00000","5.33215","0.49595"
"80.10000","5.33857","0.49594"
"80.20000","5.34523","0.49573"
"80.30000","5.35205","0.49594"
"80.40000","5.35869","0.49536"
"80.50000","5.36505","0.49540"
"80.60000","5.37183","0.49529"
"80.70000","5.37841","0.49506"
"80.80000","5.38522","0.49505"
"80.90000","5.39193","0.49491"
"81.00000","5.39899","0.49486"
"81.10000","5.40549","0.49487"
"81.20000","5.41182","0.49393"
"81.30000","5.41824","0.49380"
"81.40000","5.42520","0.49387"
"81.50000","5.43217","0.49375"
"81.60000","5.43876","0.49333"
"81.70000","5.44504","0.49328"
"81.80000","5.45210","0.49298"
"81.90000","5.45902","0.49311"
"82.00000","5.46553","0.49261"
"82.10000","5.47178","0.49201"
"82.20000","5.47817","0.49235"
"82.30000","5.48520","0.49206"
"82.40000","5.49220","0.49137"
"82.50000","5.49872","0.49139"
"82.60000","5.50544","0.49141"
"82.70000","5.51197","0.49121"
"82.80000","5.51871","0.49087"
"82.90000","5.52527","0.49034"
"83.00000","5.53187","0.49035"
"83.10000","5.53876","0.48982"
"83.20000","5.54517","0.48976"
"83.30000","5.55169","0.48927"
"83.40000","5.55881","0.48959"
"83.50000","5.56579","0.48927"
"83.60000","5.57221","0.48864"
"83.70000","5.57829","0.48865"
"83.80000","5.58487","0.48792"
"83.90000","5.59211","0.48802"
"84.00000","5.59898","0.48749"
"84.10000","5.60536","0.48685"
"84.20000","5.61164","0.48599"
"84.30000","5.61865","0.48568"
"84.40000","5.62564","0.48560"
"84.50000","5.63200","0.48485"
"84.60000","5.63833","0.48496"
"84.70000","5.64503","0.48447"
"84.80000","5.65186","0.48479"
"84.90000","5.65871","0.48410"
"85.00000","5.66538","0.48324"
"85.10000","5.67222","0.48319"
"85.20000","5.67863","0.48285"
"85.30000","5.68510","0.48285"
"85.40000","5.69171","0.48216"
"85.50000","5.69877","0.48199"
"85.60000","5.70544","0.48182"
"85.70000","5.71167","0.48099"
"85.80000","5.71821","0.48073"
"85.90000","5.72566","0.48110"
"86.00000","5.73250","0.47992"
"86.10000","5.73876","0.47993"
"86.20000","5.74488","0.47939"
"86.30000","5.75177","0.47906"
"86.40000","5.75884","0.47932"
"86.50000","5.76547","0.47917"
"86.60000","5.77197","0.47834"
"86.70000","5.77856","0.47835"
"86.80000","5.78527","0.47843"
"86.90000","5.79216","0.47762"
"87.00000","5.79865","0.47762"
"87.10000","5.80510","0.47689"
"87.20000","5.81175","0.47649"
"87.30000","5.81863","0.47629"
"87.40000","5.82542","0.47570"
"87.50000","5.83217","0.47580"
"87.60000","5.83896","0.47556"
"87.70000","5.84526","0.47494"
"87.80000","5.85162","0.47421"
"87.90000","5.85850","0.47442"
"88.00000","5.86567","0.47429"
"88.10000","5.87213","0.47369"
"88.20000","5.87848","0.47357"
"88.30000","5.88516","0.47330"
"88.40000","5.89234","0.47330"
"88.50000","5.89902","0.47320"
"88.60000","5.90530","0.47260"
"88.70000","5.91138","0.47235"
"88.80000","5.91839","0.47191"
"88.90000","5.92547","0.47227"
"89.00000","5.93217","0.47164"
"89.10000","5.93861","0.47115"
"89.20000","5.94519","0.47123"
"89.30000","5.95192","0.47087"
"89.40000","5.95859","0.47064"
"89.50000","5.96511","0.47014"
"89.60000","5.97190","0.47019"
"89.70000","5.97837","0.46967"
"89.80000","5.98523","0.46925"
"89.90000","5.99197","0.46909"
"90.00000","5.99906","0.46870"
"90.10000","6.00555","0.46843"
"90.20000","6.01178","0.46778"
"90.30000","6.01811","0.46719"
"90.40000","6.02519","0.46767"
"90.50000","6.03228","0.46763"
"90.60000","6.03878","0.46677"
"90.70000","6.04499","0.46675"
"90.80000","6.05201","0.46716"
"90.90000","6.05907","0.46689"
"91.00000","6.06558","0.46661"
"91.10000","6.07178","0.46591"
"91.20000","6.07827","0.46586"
"91.30000","6.08522","0.46529"
"91.40000","6.09215","0.46513"
"91.50000","6.09873","0.46445"
"91.60000","6.10538","0.46410"
"91.70000","6.11185","0.46392"
"91.80000","6.11858","0.46367"
"91.90000","6.12526","0.46323"
"92.00000","6.13193","0.46278"
"92.10000","6.13878","0.46156"
"92.20000","6.14518","0.46158"
"92.30000","6.15177","0.46113"
"92.40000","6.15880","0.46102"
"92.50000","6.16579","0.46050"
"92.60000","6.17220","0.45973"
"92.70000","6.17827","0.45916"
"92.80000","6.18485","0.45839"
"92.90000","6.19214","0.45870"
"93.00000","6.19893","0.45788"
"93.10000","6.20536","0.45742"
"93.20000","6.21166","0.45704"
"93.30000","6.21867","0.45700"
"93.40000","6.22575","0.45662"
"93.50000","6.23199","0.45577"
"93.60000","6.23824","0.45500"
"93.70000","6.24490","0.45494"
"93.80000","6.25194","0.45433"
"93.90000","6.25868","0.45394"
"94.00000","6.26535","0.45350"
"94.10000","6.27217","0.45312"
"94.20000","6.27863","0.45305"
"94.30000","6.28510","0.45233"
"94.40000","6.29175","0.45151"
"94.50000","6.29876","0.45169"
"94.60000","6.30545","0.45089"
"94.70000","6.31170","0.45022"
"94.80000","6.31834","0.45035"
"94.90000","6.32569","0.45004"
"95.00000","6.33248","0.44918"
"95.10000","6.33867","0.44863"
"95.20000","6.34477","0.44785"
"95.30000","6.35172","0.44763"
"95.40000","6.35894","0.44787"
"95.50000","6.36556","0.44678"
"95.60000","6.37193","0.44629"
"95.70000","6.37850","0.44616"
"95.80000","6.38528","0.44565"
"95.90000","6.39215","0.44539"
"96.00000","6.39869","0.44443"
"96.10000","6.40518","0.44412"
"96.20000","6.41175","0.44388"
"96.30000","6.41859","0.44327"
"96.40000","6.42540","0.44264"
"96.50000","6.43224","0.44232"
"96.60000","6.43897","0.44175"
"96.70000","6.44512","0.44086"
"96.80000","6.45163","0.44016"
"96.90000","6.45859","0.43985"
"97.00000","6.46559","0.43903"
"97.10000","6.47207","0.43842"
"97.20000","6.47846","0.43808"
"97.30000","6.48517","0.43748"
"97.40000","6.49233","0.43720"
"97.50000","6.49902","0.43651"
"97.60000","6.50529","0.43587"
"97.70000","6.51144","0.43534"
"97.80000","6.51845","0.43544"
"97.90000","6.52546","0.43456"
"98.00000","6.53222","0.43405"
"98.10000","6.53865","0.43335"
"98.20000","6.54529","0.43324"
"98.30000","6.55188","0.43321"
"98.40000","6.55866","0.43230"
"98.50000","6.56519","0.43176"
"98.60000","6.57193","0.43148"
"98.70000","6.57839","0.43044"
"98.80000","6.58515","0.43055"
"98.90000","6.59194","0.42999"
"99.00000","6.59904","0.42976"
"99.10000","6.60548","0.42925"
"99.20000","6.61176","0.42816"
"99.30000","6.61819","0.42814"
"99.40000","6.62525","0.42781"
"99.50000","6.63225","0.42762"
"99.60000","6.63879","0.42685"
"99.70000","6.64508","0.42633"
"99.80000","6.65199","0.42626"
"99.90000","6.65904","0.42611"
"100.00000","6.66546","0.42566"
"100.10000","6.67177","0.42498"
"100.20000","6.67816","0.42448"
"100.30000","6.68523","0.42496"
"100.40000","6.69216","0.42405"
"100.50000","6.69871","0.42388"
"100.60000","6.70544","0.42351"
"100.70000","6.71197","0.42351"
"100.80000","6.71860","0.42269"
"100.90000","6.72524","0.42227"
"101.00000","6.73186","0.42169"
"101.10000","6.73875","0.42081"
"101.20000","6.74515","0.42068"
"101.30000","6.75175","0.41988"
"101.40000","6.75879","0.42037"
"101.50000","6.76570","0.41909"
"101.60000","6.77227","0.41890"
"101.70000","6.77829","0.41823"
"101.80000","6.78489","0.41833"
"101.90000","6.79210","0.41801"
"102.00000","6.79889","0.41784"
"102.10000","6.80542","0.41717"
"102.20000","6.81170","0.41699"
"102.30000","6.81872","0.41653"
"102.40000","6.82569","0.41686"
"102.50000","6.83199","0.41634"
"102.60000","6.83833","0.41585"
"102.70000","6.84504","0.41584"
"102.80000","6.85182","0.41518"
"102.90000","6.85864","0.41564"
"103.00000","6.86534","0.41495"
"103.10000","6.87225","0.41446"
"103.20000","6.87852","0.41429"
"103.30000","6.88509","0.41379"
"103.40000","6.89166","0.41338"
"103.50000","6.89878","0.41349"
"103.60000","6.90548","0.41297"
"103.70000","6.91175","0.41254"
"103.80000","6.91836","0.41208"
"103.90000","6.92571","0.41168"
"104.00000","6.93251","0.41100"
"104.10000","6.93869","0.41035"
"104.20000","6.94479","0.40969"
"104.30000","6.95166","0.40938"
"104.40000","6.95896","0.40883"
"104.50000","6.96552","0.40806"
"104.60000","6.97191","0.40758"
"104.70000","6.97855","0.40729"
"104.80000","6.98528","0.40689"
"104.90000","6.99219","0.40592"
"105.00000","6.99870","0.40536"
"105.10000","7.00511","0.40468"
"105.20000","7.01180","0.40415"
"105.30000","7.01855","0.40375"
"105.40000","7.02539","0.40312"
"105.50000","7.03218","0.40266"
"105.60000","7.03902","0.40233"
"105.70000","7.04525","0.40203"
"105.80000","7.05159","0.40156"
"105.90000","7.05851","0.40108"
"106.00000","7.06554","0.40055"
"106.10000","7.07203","0.40003"
"106.20000","7.07847","0.39930"
"106.30000","7.08517","0.39912"
"106.40000","7.09239","0.39910"
"106.50000","7.09905","0.39823"
"106.60000","7.10522","0.39747"
"106.70000","7.11146","0.39672"
"106.80000","7.11848","0.39620"
"106.90000","7.12542","0.39591"
"107.00000","7.13214","0.39493"
"107.10000","7.13866","0.39441"
"107.20000","7.14531","0.39365"
"107.30000","7.15196","0.39325"
"107.40000","7.15864","0.39232"
"107.50000","7.16503","0.39247"
"107.60000","7.17191","0.39152"
"107.70000","7.17842","0.39068"
"107.80000","7.18522","0.39049"
"107.90000","7.19193","0.39023"
"108.00000","7.19901","0.38943"
"108.10000","7.20560","0.38879"
"108.20000","7.21174","0.38814"
"108.30000","7.21821","0.38766"
"108.40000","7.22522","0.38668"
"108.50000","7.23221","0.38595"
"108.60000","7.23874","0.38506"
"108.70000","7.24507","0.38460"
"108.80000","7.25204","0.38426"
"108.90000","7.25904","0.38364"
"109.00000","7.26550","0.38212"
"109.10000","7.27180","0.38136"
"109.20000","7.27823","0.38002"
"109.30000","7.28527","0.38000"
"109.40000","7.29214","0.37911"
"109.50000","7.29871","0.37809"
"109.60000","7.30549","0.37764"
"109.70000","7.31188","0.37646"
"109.80000","7.31861","0.37597"
"109.90000","7.32523","0.37456"
"110.00000","7.33189","0.37366"
"110.10000","7.33878","0.37283"
"110.20000","7.34517","0.37151"
"110.30000","7.35188","0.37028"
"110.40000","7.35873","0.36974"
"110.50000","7.36571","0.36858"
"110.60000","7.37215","0.36751"
"110.70000","7.37830","0.36647"
"110.80000","7.38488","0.36631"
"110.90000","7.39215","0.36542"
"111.00000","7.39891","0.36464"
"111.10000","7.40535","0.36351"
"111.20000","7.41168","0.36231"
"111.30000","7.41874","0.36202"
"111.40000","7.42562","0.36101"
"111.50000","7.43197","0.36025"
"111.60000","7.43834","0.35991"
"111.70000","7.44499","0.35888"
"111.80000","7.45196","0.35907"
"111.90000","7.45874","0.35805"
"112.00000","7.46533","0.35735"
"112.10000","7.47217","0.35666"
"112.20000","7.47847","0.35586"
"112.30000","7.48506","0.35488"
"112.40000","7.49178","0.35407"
"112.50000","7.49880","0.35331"
"112.60000","7.50547","0.35165"
"112.70000","7.51171","0.35078"
"112.80000","7.51827","0.35018"
"112.90000","7.52572","0.34945"
"113.00000","7.53249","0.34833"
"113.10000","7.53871","0.34751"
"113.20000","7.54474","0.34657"
"113.30000","7.55171","0.34632"
"113.40000","7.55884","0.34537"
"113.50000","7.56553","0.34463"
"113.60000","7.57195","0.34358"
"113.70000","7.57849","0.34329"
"113.80000","7.58532","0.34301"
"113.90000","7.59219","0.34196"
"114.00000","7.59865","0.34131"
"114.10000","7.60514","0.34097"
"114.20000","7.61172","0.34038"
"114.30000","7.61857","0.33982"
"114.40000","7.62544","0.33957"
"114.50000","7.63224","0.33841"
"114.60000","7.63895","0.33757"
"114.70000","7.64518","0.33668"
"114.80000","7.65162","0.33564"
"114.90000","7.65848","0.33505"
"115.00000","7.66555","0.33438"
"115.10000","7.67211","0.33331"
"115.20000","7.67845","0.33223"
"115.30000","7.68520","0.33150"
"115.40000","7.69235","0.33092"
"115.50000","7.69912","0.32999"
"115.60000","7.70526","0.32917"
"115.70000","7.71136","0.32840"
"115.80000","7.71837","0.32793"
"115.90000","7.72550","0.32741"
"116.00000","7.73226","0.32652"
"116.10000","7.73865","0.32563"
"116.20000","7.74529","0.32524"
"116.30000","7.75201","0.32404"
"116.40000","7.75868","0.32378"
"116.50000","7.76516","0.32269"
"116.60000","7.77184","0.32173"
"116.70000","7.77834","0.32112"
"116.80000","7.78519","0.32033"
"116.90000","7.79199","0.31941"
"117.00000","7.79901","0.31865"
"117.10000","7.80555","0.31728"
"117.20000","7.81177","0.31613"
"117.30000","7.81812","0.31503"
"117.40000","7.82518","0.31491"
"117.50000","7.83226","0.31432"
"117.60000","7.83882","0.31325"
"117.70000","7.84504","0.31208"
"117.80000","7.85202","0.31137"
"117.90000","7.85905","0.31037"
"118.00000","7.86550","0.30907"
"118.10000","7.87178","0.30803"
"118.20000","7.87819","0.30723"
"118.30000","7.88523","0.30618"
"118.40000","7.89219","0.30521"
"118.50000","7.89871","0.30385"
"118.60000","7.90543","0.30246"
"118.70000","7.91185","0.30100"
"118.80000","7.91858","0.29997"
"118.90000","7.92521","0.29822"
"119.00000","7.93187","0.29700"
"119.10000","7.93878","0.29469"
"119.20000","7.94520","0.29315"
"119.30000","7.95178","0.29082"
"119.40000","7.95891","0.28953"
"119.50000","7.96578","0.28746"
"119.60000","7.97220","0.28545"
"119.70000","7.97837","0.28326"
"119.80000","7.98482","0.28061"
"119.90000","7.99212","0.27898"
"120.00000","7.99893","0.27616"
"120.10000","8.00533","0.27420"
"120.20000","8.01168","0.27097"
"120.30000","8.01863","0.26883"
"120.40000","8.02569","0.26564"
"120.50000","8.03201","0.26166"
"120.60000","8.03838","0.25778"
"120.70000","8.04501","0.25384"
"120.80000","8.05183","0.25017"
"120.90000","8.05860","0.24557"
"121.00000","8.06529","0.24169"
"121.10000","8.07224","0.23639"
"121.20000","8.07866","0.23088"
"121.30000","8.08513","0.22507"
"121.40000","8.09171","0.21985"
"121.50000","8.09875","0.21449"
"121.60000","8.10535","0.20851"
"121.70000","8.11180","0.20191"
"121.80000","8.11827","0.19375"
"121.90000","8.12567","0.18724"
"122.00000","8.13246","0.18113"
"122.10000","8.13867","0.17491"
"122.20000","8.14487","0.16941"
"122.30000","8.15180","0.16492"
"122.40000","8.15887","0.16009"
"122.50000","8.16553","0.15482"
"122.60000","8.17192","0.15020"
"122.70000","8.17854","0.14545"
"122.80000","8.18532","0.14060"
"122.90000","8.19219","0.13695"
"123.00000","8.19861","0.13322"
"123.10000","8.20508","0.12956"
"123.20000","8.21181","0.12569"
"123.30000","8.21861","0.12287"
"123.40000","8.22534","0.12040"
"123.50000","8.23215","0.11749"
"123.60000","8.23899","0.11487"
"123.70000","8.24529","0.11216"
"123.80000","8.25168","0.10987"
"123.90000","8.25844","0.10772"
"124.00000","8.26548","0.10593"
"124.10000","8.27211","0.10408"
"124.20000","8.27846","0.10198"
"124.30000","8.28522","0.10046"
"124.40000","8.29237","0.09843"
"124.50000","8.29904","0.09675"
"124.60000","8.30521","0.09495"
"124.70000","8.31141","0.09329"
"124.80000","8.31846","0.09155"
"124.90000","8.32543","0.09005"
"125.00000","8.33208","0.08817"
"125.10000","8.33867","0.08643"
"125.20000","8.34536","0.08496"
"125.30000","8.35201","0.08329"
"125.40000","8.35858","0.08170"
"125.50000","8.36506","0.08033"
"125.60000","8.37193","0.07914"
"125.70000","8.37838","0.07721"
"125.80000","8.38531","0.07603"
"125.90000","8.39205","0.07391"
"126.00000","8.39896","0.07237"
"126.10000","8.40556","0.07122"
"126.20000","8.41178","0.06963"
"126.30000","8.41821","0.06816"
"126.40000","8.42525","0.06644"
"126.50000","8.43217","0.06480"
"126.60000","8.43886","0.06355"
"126.70000","8.44502","0.06262"
"126.80000","8.45210","0.06149"
"126.90000","8.45906","0.06055"
"127.00000","8.46547","0.05927"
"127.06100","8.46931","0.05838"