File: 20.12.09/1Layer_9.is_flex_RawData/Specimen_RawData_1.csv
Specimen properties : Thickness,"3.30000",mm
Specimen properties : Width,"12.80000",mm
Specimen properties : Support span,"52.80000",mm

Time,Extension,Load
(s),(mm),(kgf)
"0.00000","0.00000","-0.00497"
"0.20000","0.00552","-0.00192"
"0.40000","0.02510","0.00933"
"0.60000","0.03825","0.01583"
"0.80000","0.05199","0.02191"
"1.00000","0.06509","0.02783"
"1.20000","0.07895","0.03431"
"1.40000","0.09212","0.04015"
"1.60000","0.10492","0.04575"
"1.80000","0.11897","0.05125"
"2.00000","0.13175","0.05606"
"2.20000","0.14565","0.06222"
"2.40000","0.15843","0.06685"
"2.60000","0.17186","0.07248"
"2.80000","0.18559","0.07773"
"3.00000","0.19861","0.08228"
"3.20000","0.21171","0.08672"
"3.40000","0.22547","0.09197"
"3.60000","0.23846","0.09666"
"3.80000","0.25246","0.10125"
"4.00000","0.26476","0.10522"
"4.20000","0.27875","0.10958"
"4.40000","0.29189","0.11383"
"4.60000","0.30527","0.11849"
"4.80000","0.31851","0.12235"
"5.00000","0.33178","0.12605"
"5.20000","0.34520","0.13039"
"5.40000","0.35892","0.13420"
"5.60000","0.37158","0.13843"
"5.80000","0.38556","0.14265"
"6.00000","0.39846","0.14616"
"6.20000","0.41226","0.15018"
"6.40000","0.42529","0.15382"
"6.60000","0.43846","0.15772"
"6.80000","0.45204","0.16151"
"7.00000","0.46530","0.16531"
"7.20000","0.47853","0.16878"
"7.40000","0.49206","0.17256"
"7.60000","0.50506","0.17621"
"7.80000","0.51909","0.17996"
"8.00000","0.53177","0.18240"
"8.20000","0.54540","0.18695"
"8.40000","0.55869","0.19040"
"8.60000","0.57199","0.19346"
"8.80000","0.58536","0.19735"
"9.00000","0.59835","0.20065"
"9.20000","0.61205","0.20433"
"9.40000","0.62548","0.20728"
"9.60000","0.63850","0.21076"
"9.80000","0.65199","0.21414"
"10.00000","0.66518","0.21692"
"10.20000","0.67893","0.22057"
"10.40000","0.69211","0.22388"
"10.60000","0.70491","0.22626"
"10.80000","0.71882","0.22964"
"11.00000","0.73181","0.23289"
"11.20000","0.74556","0.23637"
"11.40000","0.75848","0.23903"
"11.60000","0.77194","0.24198"
"11.80000","0.78552","0.24456"
"12.00000","0.79852","0.24788"
"12.20000","0.81177","0.25046"
"12.40000","0.82544","0.25346"
"12.60000","0.83848","0.25602"
"12.80000","0.85245","0.25913"
"13.00000","0.86473","0.26097"
"13.20000","0.87876","0.26449"
"13.40000","0.89193","0.26695"
"13.60000","0.90528","0.26970"
"13.80000","0.91850","0.27186"
"14.00000","0.93177","0.27458"
"14.20000","0.94528","0.27725"
"14.40000","0.95894","0.27988"
"14.60000","0.97152","0.28200"
"14.80000","0.98561","0.28441"
"15.00000","0.99839","0.28706"
"15.20000","1.01226","0.28967"
"15.40000","1.02521","0.29147"
"15.60000","1.03833","0.29386"
"15.80000","1.05209","0.29663"
"16.00000","1.06525","0.29895"
"16.20000","1.07868","0.30101"
"16.40000","1.09208","0.30351"
"16.60000","1.10516","0.30561"
"16.80000","1.11910","0.30822"
"17.00000","1.13158","0.30992"
"17.20000","1.14542","0.31269"
"17.40000","1.15873","0.31446"
"17.60000","1.17190","0.31668"
"17.80000","1.18539","0.31834"
"18.00000","1.19822","0.32043"
"18.20000","1.21202","0.32294"
"18.40000","1.22566","0.32495"
"18.60000","1.23843","0.32669"
"18.80000","1.25205","0.32918"
"19.00000","1.26511","0.33086"
"19.20000","1.27892","0.33353"
"19.40000","1.29218","0.33553"
"19.60000","1.30487","0.33685"
"19.80000","1.31899","0.33916"
"20.00000","1.33183","0.34065"
"20.20000","1.34549","0.34309"
"20.40000","1.35846","0.34429"
"20.60000","1.37184","0.34647"
"20.80000","1.38558","0.34860"
"21.00000","1.39862","0.35033"
"21.20000","1.41168","0.35182"
"21.40000","1.42550","0.35388"
"21.60000","1.43845","0.35570"
"21.80000","1.45246","0.35793"
"22.00000","1.46476","0.35902"
"22.20000","1.47877","0.36117"
"22.40000","1.49196","0.36308"
"22.60000","1.50527","0.36453"
"22.80000","1.51860","0.36619"
"23.00000","1.53168","0.36809"
"23.20000","1.54524","0.36986"
"23.40000","1.55894","0.37148"
"23.60000","1.57146","0.37274"
"23.80000","1.58566","0.37489"
"24.00000","1.59836","0.37599"
"24.20000","1.61233","0.37842"
"24.40000","1.62521","0.37905"
"24.60000","1.63852","0.38076"
"24.80000","1.65213","0.38255"
"25.00000","1.66515","0.38399"
"25.20000","1.67856","0.38563"
"25.40000","1.69222","0.38730"
"25.60000","1.70511","0.38835"
"25.80000","1.71906","0.39006"
"26.00000","1.73169","0.39115"
"26.20000","1.74551","0.39299"
"26.40000","1.75867","0.39415"
"26.60000","1.77192","0.39600"
"26.80000","1.78545","0.39745"
"27.00000","1.79827","0.39851"
"27.20000","1.81196","0.40013"
"27.40000","1.82560","0.40155"
"27.60000","1.83839","0.40297"
"27.80000","1.85201","0.40464"
"28.00000","1.86512","0.40563"
"28.20000","1.87884","0.40749"
"28.40000","1.89209","0.40859"
"28.60000","1.90496","0.40996"
"28.80000","1.91881","0.41094"
"29.00000","1.93190","0.41243"
"29.20000","1.94567","0.41402"
"29.40000","1.95838","0.41479"
"29.60000","1.97182","0.41630"
"29.80000","1.98551","0.41765"
"30.00000","1.99867","0.41877"
"30.20000","2.01180","0.42012"
"30.40000","2.02546","0.42153"
"30.60000","2.03833","0.42260"
"30.80000","2.05239","0.42423"
"31.00000","2.06486","0.42482"
"31.20000","2.07873","0.42626"
"31.40000","2.09195","0.42727"
"31.60000","2.10523","0.42903"
"31.80000","2.11842","0.42986"
"32.00000","2.13185","0.43113"
"32.20000","2.14525","0.43211"
"32.40000","2.15886","0.43333"
"32.60000","2.17152","0.43414"
"32.80000","2.18552","0.43576"
"33.00000","2.19850","0.43670"
"33.20000","2.21233","0.43800"
"33.40000","2.22517","0.43885"
"33.60000","2.23853","0.44040"
"33.80000","2.25201","0.44122"
"34.00000","2.26544","0.44246"
"34.20000","2.27859","0.44347"
"34.40000","2.29199","0.44468"
"34.60000","2.30516","0.44559"
"34.80000","2.31902","0.44690"
"35.00000","2.33182","0.44757"
"35.20000","2.34538","0.44882"
"35.40000","2.35860","0.44996"
"35.60000","2.37205","0.45100"
"35.80000","2.38530","0.45189"
"36.00000","2.39851","0.45291"
"36.20000","2.41188","0.45367"
"36.40000","2.42551","0.45501"
"36.60000","2.43859","0.45601"
"36.80000","2.45182","0.45742"
"37.00000","2.46537","0.45823"
"37.20000","2.47884","0.45925"
"37.40000","2.49198","0.45999"
"37.60000","2.50499","0.46109"
"37.80000","2.51877","0.46182"
"38.00000","2.53207","0.46286"
"38.20000","2.54551","0.46391"
"38.40000","2.55830","0.46504"
"38.60000","2.57205","0.46611"
"38.80000","2.58544","0.46732"
"39.00000","2.59874","0.46801"
"39.20000","2.61167","0.46859"
"39.40000","2.62528","0.46964"
"39.60000","2.63861","0.47058"
"39.80000","2.65232","0.47123"
"40.00000","2.66491","0.47196"
"40.20000","2.67869","0.47327"
"40.40000","2.69189","0.47379"
"40.60000","2.70536","0.47442"
"40.80000","2.71842","0.47512"
"41.00000","2.73186","0.47595"
"41.20000","2.74523","0.47694"
"41.40000","2.75875","0.47798"
"41.60000","2.77173","0.47876"
"41.80000","2.78542","0.47993"
"42.00000","2.79868","0.48041"
"42.20000","2.81227","0.48143"
"42.40000","2.82510","0.48219"
"42.60000","2.83859","0.48342"
"42.80000","2.85201","0.48406"
"43.00000","2.86549","0.48474"
"43.20000","2.87855","0.48500"
"43.40000","2.89202","0.48624"
"43.60000","2.90521","0.48609"
"43.80000","2.91900","0.48731"
"44.00000","2.93185","0.48792"
"44.20000","2.94543","0.48865"
"44.40000","2.95863","0.48919"
"44.60000","2.97198","0.49016"
"44.80000","2.98536","0.49075"
"45.00000","2.99842","0.49147"
"45.20000","3.01189","0.49251"
"45.40000","3.02547","0.49263"
"45.60000","3.03857","0.49345"
"45.80000","3.05191","0.49438"
"46.00000","3.06518","0.49476"
"46.20000","3.07888","0.49600"
"46.40000","3.09206","0.49587"
"46.60000","3.10508","0.49705"
"46.80000","3.11883","0.49725"
"47.00000","3.13196","0.49799"
"47.20000","3.14554","0.49866"
"47.40000","3.15839","0.49905"
"47.60000","3.17187","0.49968"
"47.80000","3.18550","0.50075"
"48.00000","3.19873","0.50127"
"48.20000","3.21167","0.50176"
"48.40000","3.22542","0.50235"
"48.60000","3.23855","0.50332"
"48.80000","3.25241","0.50460"
"49.00000","3.26481","0.50413"
"49.20000","3.27877","0.50526"
"49.40000","3.29187","0.50533"
"49.60000","3.30539","0.50575"
"49.80000","3.31839","0.50601"
"50.00000","3.33179","0.50642"
"50.20000","3.34513","0.50736"
"50.40000","3.35889","0.50799"
"50.60000","3.37164","0.50838"
"50.80000","3.38560","0.50949"
"51.00000","3.39835","0.50934"
"51.20000","3.41243","0.51028"
"51.40000","3.42515","0.50976"
"51.60000","3.43845","0.51086"
"51.80000","3.45213","0.51123"
"52.00000","3.46527","0.51114"
"52.20000","3.47868","0.51218"
"52.40000","3.49207","0.51279"
"52.60000","3.50512","0.51313"
"52.80000","3.51906","0.51383"
"53.00000","3.53163","0.51398"
"53.20000","3.54546","0.51503"
"53.40000","3.55867","0.51528"
"53.60000","3.57200","0.51552"
"53.80000","3.58545","0.51599"
"54.00000","3.59829","0.51625"
"54.20000","3.61206","0.51704"
"54.40000","3.62546","0.51762"
"54.60000","3.63849","0.51794"
"54.80000","3.65206","0.51850"
"55.00000","3.66506","0.51905"
"55.20000","3.67882","0.52023"
"55.40000","3.69213","0.52007"
"55.60000","3.70489","0.52049"
"55.80000","3.71899","0.52120"
"56.00000","3.73178","0.52092"
"56.20000","3.74563","0.52108"
"56.40000","3.75845","0.52116"
"56.60000","3.77185","0.52124"
"56.80000","3.78553","0.52187"
"57.00000","3.79865","0.52205"
"57.20000","3.81173","0.52231"
"57.40000","3.82539","0.52294"
"57.60000","3.83844","0.52330"
"57.80000","3.85251","0.52356"
"58.00000","3.86481","0.52332"
"58.20000","3.87881","0.52410"
"58.40000","3.89185","0.52416"
"58.60000","3.90526","0.52492"
"58.80000","3.91847","0.52460"
"59.00000","3.93177","0.52489"
"59.20000","3.94524","0.52518"
"59.40000","3.95889","0.52557"
"59.60000","3.97164","0.52583"
"59.80000","3.98554","0.52650"
"60.00000","3.99834","0.52700"
"60.20000","4.01240","0.52742"
"60.40000","4.02509","0.52787"
"60.60000","4.03853","0.52802"
"60.80000","4.05208","0.52825"
"61.00000","4.06534","0.52829"
"61.20000","4.07857","0.52861"
"61.40000","4.09203","0.52937"
"61.60000","4.10514","0.52922"
"61.80000","4.11908","0.52958"
"62.00000","4.13170","0.52946"
"62.20000","4.14541","0.52968"
"62.40000","4.15864","0.52985"
"62.60000","4.17201","0.53016"
"62.80000","4.18535","0.53091"
"63.00000","4.19839","0.53076"
"63.20000","4.21200","0.53162"
"63.40000","4.22550","0.53246"
"63.60000","4.23848","0.53227"
"63.80000","4.25201","0.53246"
"64.00000","4.26511","0.53265"
"64.20000","4.27891","0.53330"
"64.40000","4.29209","0.53307"
"64.60000","4.30495","0.53356"
"64.80000","4.31887","0.53373"
"65.00000","4.33186","0.53361"
"65.20000","4.34558","0.53419"
"65.40000","4.35837","0.53386"
"65.60000","4.37186","0.53397"
"65.80000","4.38549","0.53412"
"66.00000","4.39868","0.53416"
"66.20000","4.41168","0.53469"
"66.40000","4.42538","0.53501"
"66.60000","4.43847","0.53499"
"66.80000","4.45247","0.53462"
"67.00000","4.46480","0.53467"
"67.20000","4.47876","0.53555"
"67.40000","4.49190","0.53607"
"67.60000","4.50535","0.53654"
"67.80000","4.51838","0.53661"
"68.00000","4.53174","0.53705"
"68.20000","4.54523","0.53685"
"68.40000","4.55887","0.53728"
"68.60000","4.57160","0.53712"
"68.80000","4.58556","0.53756"
"69.00000","4.59840","0.53760"
"69.20000","4.61230","0.53904"
"69.40000","4.62522","0.53887"
"69.60000","4.63842","0.53982"
"69.80000","4.65208","0.54026"
"70.00000","4.66534","0.54135"
"70.20000","4.67863","0.54283"
"70.40000","4.69208","0.54370"
"70.60000","4.70505","0.54477"
"70.80000","4.71913","0.54597"
"71.00000","4.73172","0.54664"
"71.20000","4.74542","0.54799"
"71.40000","4.75868","0.54882"
"71.60000","4.77195","0.54993"
"71.80000","4.78540","0.55023"
"72.00000","4.79831","0.54951"
"72.20000","4.81203","0.54970"
"72.40000","4.82561","0.55020"
"72.60000","4.83849","0.55012"
"72.80000","4.85201","0.55074"
"73.00000","4.86508","0.55054"
"73.20000","4.87893","0.55111"
"73.40000","4.89216","0.55126"
"73.60000","4.90494","0.55211"
"73.80000","4.91883","0.55269"
"74.00000","4.93193","0.55260"
"74.20000","4.94550","0.55313"
"74.40000","4.95841","0.55332"
"74.60000","4.97186","0.55337"
"74.80000","4.98547","0.55365"
"75.00000","4.99864","0.55351"
"75.20000","5.01171","0.55417"
"75.40000","5.02546","0.55354"
"75.60000","5.03842","0.55372"
"75.80000","5.05243","0.55395"
"76.00000","5.06479","0.55380"
"76.20000","5.07869","0.55449"
"76.40000","5.09191","0.55462"
"76.60000","5.10522","0.55472"
"76.80000","5.11843","0.55467"
"77.00000","5.13176","0.55475"
"77.20000","5.14525","0.55492"
"77.40000","5.15890","0.55480"
"77.60000","5.17149","0.55485"
"77.80000","5.18562","0.55523"
"78.00000","5.19838","0.55480"
"78.20000","5.21244","0.55560"
"78.40000","5.22518","0.55545"
"78.60000","5.23844","0.55530"
"78.80000","5.25213","0.55538"
"79.00000","5.26517","0.55538"
"79.20000","5.27863","0.55532"
"79.40000","5.29213","0.55564"
"79.60000","5.30503","0.55590"
"79.80000","5.31918","0.55524"
"80.00000","5.33165","0.55541"
"80.20000","5.34541","0.55663"
"80.40000","5.35877","0.55684"
"80.60000","5.37195","0.55681"
"80.80000","5.38536","0.55720"
"81.00000","5.39822","0.55719"
"81.20000","5.41195","0.55655"
"81.40000","5.42554","0.55666"
"81.60000","5.43848","0.55647"
"81.80000","5.45204","0.55669"
"82.00000","5.46510","0.55637"
"82.20000","5.47878","0.55637"
"82.40000","5.49214","0.55622"
"82.60000","5.50490","0.55650"
"82.80000","5.51900","0.55657"
"83.00000","5.53177","0.55644"
"83.20000","5.54563","0.55719"
"83.40000","5.55853","0.55734"
"83.60000","5.57178","0.55715"
"83.80000","5.58559","0.55692"
"84.00000","5.59859","0.55682"
"84.20000","5.61183","0.55684"
"84.40000","5.62542","0.55691"
"84.60000","5.63840","0.55678"
"84.80000","5.65248","0.55688"
"85.00000","5.66479","0.55627"
"85.20000","5.67878","0.55620"
"85.40000","5.69196","0.55573"
"85.60000","5.70515","0.55559"
"85.80000","5.71859","0.55508"
"86.00000","5.73174","0.55489"
"86.20000","5.74525","0.55550"
"86.40000","5.75896","0.55555"
"86.60000","5.77153","0.55455"
"86.80000","5.78562","0.55520"
"87.00000","5.79846","0.55491"
"87.20000","5.81233","0.55508"
"87.40000","5.82523","0.55469"
"87.60000","5.83844","0.55458"
"87.80000","5.85208","0.55393"
"88.00000","5.86526","0.55309"
"88.20000","5.87854","0.55296"
"88.40000","5.89212","0.55262"
"88.60000","5.90506","0.55189"
"88.80000","5.91905","0.55223"
"89.00000","5.93163","0.55151"
"89.20000","5.94542","0.55190"
"89.40000","5.95883","0.55100"
"89.60000","5.97196","0.55118"
"89.80000","5.98535","0.55089"
"90.00000","5.99832","0.55119"
"90.20000","6.01194","0.55093"
"90.40000","6.02566","0.55093"
"90.60000","6.03836","0.55017"
"90.80000","6.05205","0.55007"
"91.00000","6.06508","0.54943"
"91.20000","6.07893","0.54950"
"91.40000","6.09212","0.54971"
"91.60000","6.10482","0.54957"
"91.80000","6.11893","0.54950"
"92.00000","6.13188","0.54953"
"92.20000","6.14554","0.54920"
"92.40000","6.15850","0.54838"
"92.60000","6.17191","0.54886"
"92.80000","6.18548","0.54835"
"93.00000","6.19861","0.54797"
"93.20000","6.21174","0.54751"
"93.40000","6.22542","0.54801"
"93.60000","6.23840","0.54701"
"93.80000","6.25243","0.54768"
"94.00000","6.26488","0.54699"
"94.20000","6.27876","0.54782"
"94.40000","6.29199","0.54756"
"94.60000","6.30526","0.54765"
"94.80000","6.31838","0.54700"
"95.00000","6.33179","0.54698"
"95.20000","6.34520","0.54734"
"95.40000","6.35888","0.54722"
"95.60000","6.37160","0.54631"
"95.80000","6.38558","0.54665"
"96.00000","6.39844","0.54644"
"96.20000","6.41230","0.54672"
"96.40000","6.42521","0.54586"
"96.60000","6.43855","0.54553"
"96.80000","6.45202","0.54588"
"97.00000","6.46529","0.54559"
"97.20000","6.47852","0.54529"
"97.40000","6.49210","0.54560"
"97.60000","6.50519","0.54569"
"97.80000","6.51897","0.54564"
"98.00000","6.53171","0.54443"
"98.20000","6.54538","0.54495"
"98.40000","6.55876","0.54451"
"98.60000","6.57199","0.54457"
"98.80000","6.58537","0.54408"
"99.00000","6.59828","0.54402"
"99.20000","6.61198","0.54409"
"99.40000","6.62558","0.54410"
"99.60000","6.63844","0.54403"
"99.80000","6.65199","0.54417"
"100.00000","6.66509","0.54375"
"100.20000","6.67898","0.54397"
"100.40000","6.69216","0.54333"
"100.60000","6.70484","0.54311"
"100.80000","6.71889","0.54254"
"101.00000","6.73177","0.54142"
"101.20000","6.74559","0.54159"
"101.40000","6.75844","0.54084"
"101.60000","6.77190","0.54063"
"101.80000","6.78551","0.54038"
"102.00000","6.79859","0.53976"
"102.20000","6.81177","0.53940"
"102.40000","6.82547","0.53948"
"102.60000","6.83843","0.53897"
"102.80000","6.85243","0.53902"
"103.00000","6.86477","0.53820"
"103.20000","6.87880","0.53831"
"103.40000","6.89204","0.53765"
"103.60000","6.90521","0.53745"
"103.80000","6.91848","0.53617"
"104.00000","6.93172","0.53589"
"104.20000","6.94524","0.53561"
"104.40000","6.95894","0.53502"
"104.60000","6.97155","0.53533"
"104.80000","6.98552","0.53467"
"105.00000","6.99845","0.53406"
"105.20000","7.01232","0.53426"
"105.40000","7.02519","0.53389"
"105.60000","7.03849","0.53366"
"105.80000","7.05205","0.53304"
"106.00000","7.06524","0.53252"
"106.20000","7.07855","0.53221"
"106.40000","7.09213","0.53198"
"106.60000","7.10511","0.53132"
"106.80000","7.11913","0.53102"
"107.00000","7.13172","0.53016"
"107.20000","7.14540","0.53028"
"107.40000","7.15868","0.52949"
"107.60000","7.17191","0.52961"
"107.80000","7.18539","0.52849"
"108.00000","7.19834","0.52788"
"108.20000","7.21197","0.52763"
"108.40000","7.22563","0.52715"
"108.60000","7.23845","0.52571"
"108.80000","7.25203","0.52577"
"109.00000","7.26520","0.52456"
"109.20000","7.27888","0.52459"
"109.40000","7.29209","0.52310"
"109.60000","7.30501","0.52292"
"109.80000","7.31885","0.52163"
"110.00000","7.33188","0.52110"
"110.20000","7.34559","0.52109"
"110.40000","7.35834","0.51951"
"110.60000","7.37191","0.51943"
"110.80000","7.38540","0.51935"
"111.00000","7.39875","0.51911"
"111.20000","7.41171","0.51876"
"111.40000","7.42542","0.51884"
"111.60000","7.43854","0.51815"
"111.80000","7.45239","0.51730"
"112.00000","7.46478","0.51649"
"112.20000","7.47871","0.51607"
"112.40000","7.49199","0.51509"
"112.60000","7.50536","0.51518"
"112.80000","7.51840","0.51434"
"113.00000","7.53174","0.51322"
"113.20000","7.54527","0.51296"
"113.40000","7.55893","0.51176"
"113.60000","7.57160","0.51057"
"113.80000","7.58556","0.51023"
"114.00000","7.59838","0.50940"
"114.20000","7.61233","0.50935"
"114.40000","7.62529","0.50872"
"114.60000","7.63847","0.50824"
"114.80000","7.65203","0.50777"
"115.00000","7.66536","0.50745"
"115.20000","7.67863","0.50693"
"115.40000","7.69206","0.50593"
"115.60000","7.70515","0.50583"
"115.80000","7.71908","0.50560"
"116.00000","7.73167","0.50464"
"116.20000","7.74540","0.50427"
"116.40000","7.75869","0.50327"
"116.60000","7.77205","0.50343"
"116.80000","7.78535","0.50274"
"117.00000","7.79830","0.50202"
"117.20000","7.81205","0.50180"
"117.40000","7.82564","0.50173"
"117.60000","7.83842","0.50105"
"117.80000","7.85202","0.50109"
"118.00000","7.86501","0.50005"
"118.20000","7.87887","0.50022"
"118.40000","7.89216","0.49920"
"118.60000","7.90488","0.49857"
"118.80000","7.91890","0.49808"
"119.00000","7.93182","0.49786"
"119.20000","7.94562","0.49760"
"119.40000","7.95847","0.49718"
"119.60000","7.97179","0.49739"
"119.80000","7.98551","0.49812"
"120.00000","7.99863","0.49730"
"120.20000","8.01165","0.49658"
"120.40000","8.02546","0.49620"
"120.60000","8.03847","0.49542"
"120.80000","8.05244","0.49474"
"121.00000","8.06474","0.49387"
"121.20000","8.07878","0.49323"
"121.40000","8.09193","0.49225"
"121.60000","8.10526","0.49222"
"121.80000","8.11841","0.49153"
"122.00000","8.13180","0.49132"
"122.20000","8.14526","0.49039"
"122.40000","8.15887","0.48926"
"122.60000","8.17157","0.48840"
"122.80000","8.18561","0.48774"
"123.00000","8.19835","0.48646"
"123.20000","8.21237","0.48627"
"123.40000","8.22519","0.48568"
"123.60000","8.23851","0.48584"
"123.80000","8.25211","0.48529"
"124.00000","8.26519","0.48495"
"124.20000","8.27861","0.48448"
"124.40000","8.29218","0.48370"
"124.60000","8.30506","0.48244"
"124.80000","8.31909","0.48232"
"125.00000","8.33163","0.48119"
"125.20000","8.34546","0.48114"
"125.40000","8.35876","0.47988"
"125.60000","8.37187","0.47989"
"125.80000","8.38543","0.47921"
"126.00000","8.39821","0.47832"
"126.20000","8.41200","0.47769"
"126.40000","8.42571","0.47687"
"126.60000","8.43846","0.47542"
"126.80000","8.45205","0.47503"
"127.00000","8.46507","0.47481"
"127.20000","8.47894","0.47529"
"127.40000","8.49214","0.47475"
"127.60000","8.50495","0.47444"
"127.80000","8.51894","0.47349"
"128.00000","8.53181","0.47247"
"128.20000","8.54555","0.47114"
"128.40000","8.55836","0.47003"
"128.60000","8.57188","0.46945"
"128.80000","8.58556","0.46918"
"129.00000","8.59862","0.46832"
"129.20000","8.61172","0.46782"
"129.40000","8.62546","0.46689"
"129.60000","8.63839","0.46588"
"129.80000","8.65247","0.46472"
"130.00000","8.66477","0.46351"
"130.20000","8.67885","0.46316"
"130.40000","8.69185","0.46276"
"130.60000","8.70519","0.46198"
"130.80000","8.71848","0.46097"
"131.00000","8.73178","0.46082"
"131.20000","8.74537","0.45980"
"131.40000","8.75883","0.45939"
"131.60000","8.77155","0.45877"
"131.80000","8.78556","0.45829"
"132.00000","8.79848","0.45731"
"132.20000","8.81227","0.45720"
"132.40000","8.82519","0.45629"
"132.60000","8.83842","0.45519"
"132.80000","8.85205","0.45406"
"133.00000","8.86539","0.45341"
"133.20000","8.87859","0.45256"
"133.40000","8.89191","0.45169"
"133.60000","8.90522","0.45122"
"133.80000","8.91899","0.45025"
"134.00000","8.93173","0.44913"
"134.20000","8.94541","0.44836"
"134.40000","8.95869","0.44679"
"134.60000","8.97199","0.44601"
"134.80000","8.98534","0.44471"
"135.00000","8.99842","0.44368"
"135.20000","9.01196","0.44206"
"135.40000","9.02547","0.44108"
"135.60000","9.03855","0.43979"
"135.80000","9.05198","0.43925"
"136.00000","9.06513","0.43777"
"136.20000","9.07893","0.43740"
"136.40000","9.09206","0.43615"
"136.60000","9.10493","0.43474"
"136.80000","9.11887","0.43238"
"137.00000","9.13194","0.43134"
"137.20000","9.14554","0.43004"
"137.40000","9.15828","0.42944"
"137.60000","9.17199","0.42842"
"137.80000","9.18545","0.42762"
"138.00000","9.19878","0.42653"
"138.20000","9.21165","0.42485"
"138.40000","9.22540","0.42334"
"138.60000","9.23846","0.42231"
"138.80000","9.25233","0.42008"
"139.00000","9.26489","0.41874"
"139.20000","9.27878","0.41792"
"139.40000","9.29184","0.41676"
"139.60000","9.30541","0.41499"
"139.80000","9.31833","0.41286"
"140.00000","9.33187","0.41137"
"140.20000","9.34522","0.41078"
"140.40000","9.35877","0.40953"
"140.60000","9.37165","0.40792"
"140.80000","9.38549","0.40743"
"141.00000","9.39850","0.40565"
"141.20000","9.41231","0.40421"
"141.40000","9.42514","0.40253"
"141.60000","9.43859","0.40137"
"141.80000","9.45204","0.39973"
"142.00000","9.46543","0.39750"
"142.20000","9.47848","0.39616"
"142.40000","9.49205","0.39452"
"142.60000","9.50520","0.39260"
"142.80000","9.51893","0.39023"
"143.00000","9.53184","0.38739"
"143.20000","9.54541","0.38603"
"143.40000","9.55863","0.38297"
"143.60000","9.57207","0.38069"
"143.80000","9.58536","0.37835"
"144.00000","9.59845","0.37576"
"144.20000","9.61198","0.37297"
"144.40000","9.62546","0.37043"
"144.60000","9.63859","0.36703"
"144.80000","9.65186","0.36454"
"145.00000","9.66525","0.36220"
"145.20000","9.67883","0.36062"
"145.40000","9.69205","0.35717"
"145.60000","9.70501","0.35487"
"145.80000","9.71891","0.35217"
"146.00000","9.73194","0.35002"
"146.20000","9.74554","0.34790"
"146.40000","9.75829","0.34637"
"146.60000","9.77200","0.34415"
"146.80000","9.78542","0.34236"
"147.00000","9.79869","0.33877"
"147.20000","9.81174","0.33746"
"147.40000","9.82538","0.33603"
"147.60000","9.83848","0.33445"
"147.80000","9.85237","0.33217"
"148.00000","9.86488","0.32961"
"148.20000","9.87876","0.32768"
"148.40000","9.89190","0.32613"
"148.60000","9.90529","0.32445"
"148.80000","9.91841","0.32233"
"149.00000","9.93184","0.32029"
"149.20000","9.94513","0.31803"
"149.40000","9.95884","0.31607"
"149.60000","9.97168","0.31390"
"149.80000","9.98556","0.31204"
"150.00000","9.99833","0.30870"
"150.20000","10.01239","0.30615"
"150.40000","10.02516","0.30334"
"150.60000","10.03850","0.30099"
"150.80000","10.05203","0.29870"
"151.00000","10.06530","0.29562"
"151.20000","10.07856","0.29381"
"151.40000","10.09210","0.29116"
"151.60000","10.10515","0.28915"
"151.80000","10.11912","0.28705"
"152.00000","10.13164","0.28554"
"152.20000","10.14549","0.28338"
"152.40000","10.15866","0.28139"
"152.60000","10.17202","0.27897"
"152.80000","10.18538","0.27645"
"153.00000","10.19826","0.27444"
"153.20000","10.21197","0.27283"
"153.40000","10.22561","0.27153"
"153.60000","10.23848","0.27024"
"153.80000","10.25208","0.26898"
"154.00000","10.26506","0.26662"
"154.20000","10.27890","0.26413"
"154.40000","10.29218","0.26114"
"154.60000","10.30495","0.25999"
"154.80000","10.31894","0.25820"
"155.00000","10.33183","0.25601"
"155.20000","10.34555","0.25365"
"155.40000","10.35844","0.25325"
"155.60000","10.37187","0.25095"
"155.80000","10.38556","0.25066"
"156.00000","10.39862","0.24798"
"156.20000","10.41173","0.24580"
"156.40000","10.42544","0.24383"
"156.60000","10.43842","0.24264"
"156.80000","10.45250","0.24103"
"157.00000","10.46477","0.23942"
"157.20000","10.47879","0.23852"
"157.40000","10.49194","0.23668"
"157.60000","10.50524","0.23597"
"157.80000","10.51844","0.23414"
"158.00000","10.53175","0.23313"
"158.20000","10.54527","0.23185"
"158.40000","10.55887","0.23006"
"158.60000","10.57152","0.22836"
"158.80000","10.58565","0.22795"
"159.00000","10.59843","0.22669"
"159.20000","10.61238","0.22500"
"159.40000","10.62516","0.22328"
"159.60000","10.63844","0.22239"
"159.80000","10.65205","0.22092"
"160.00000","10.66528","0.21927"
"160.20000","10.67866","0.21809"
"160.40000","10.69194","0.21732"
"160.60000","10.70512","0.21605"
"160.80000","10.71908","0.21479"
"161.00000","10.73166","0.21249"
"161.20000","10.74544","0.21149"
"161.40000","10.75865","0.20965"
"161.60000","10.77207","0.20756"
"161.80000","10.78536","0.20569"
"162.00000","10.79829","0.20418"
"162.20000","10.81202","0.20361"
"162.40000","10.82556","0.20222"
"162.60000","10.83847","0.20040"
"162.80000","10.85199","0.19950"
"163.00000","10.86518","0.19817"
"163.20000","10.87889","0.19732"
"163.40000","10.89207","0.19509"
"163.60000","10.90495","0.19414"
"163.80000","10.91886","0.19236"
"164.00000","10.93204","0.19100"
"164.20000","10.94553","0.18895"
"164.40000","10.95836","0.18675"
"164.60000","10.97187","0.18653"
"164.80000","10.98550","0.18602"
"165.00000","10.99863","0.18435"
"165.20000","11.01171","0.18302"
"165.40000","11.02537","0.18086"
"165.60000","11.03846","0.17891"
"165.80000","11.05239","0.17774"
"166.00000","11.06480","0.17674"
"166.20000","11.07877","0.17553"
"166.40000","11.09197","0.17370"
"166.60000","11.10538","0.17177"
"166.80000","11.11841","0.16955"
"167.00000","11.13180","0.16695"
"167.20000","11.14527","0.16622"
"167.40000","11.15884","0.16496"
"167.60000","11.17158","0.16402"
"167.80000","11.18556","0.16320"
"168.00000","11.19849","0.16177"
"168.20000","11.21227","0.16050"
"168.40000","11.22518","0.15960"
"168.60000","11.23858","0.15812"
"168.80000","11.25203","0.15532"
"169.00000","11.26534","0.15382"
"169.20000","11.27859","0.15306"
"169.40000","11.29207","0.15119"
"169.60000","11.30512","0.15006"
"169.80000","11.31910","0.14877"
"170.00000","11.33171","0.14613"
"170.20000","11.34541","0.14461"
"170.40000","11.35871","0.14304"
"170.60000","11.37193","0.14182"
"170.80000","11.38539","0.13993"
"171.00000","11.39833","0.13848"
"171.20000","11.41196","0.13780"
"171.40000","11.42554","0.13682"
"171.60000","11.43848","0.13579"
"171.80000","11.45200","0.13371"
"172.00000","11.46509","0.13198"
"172.20000","11.47890","0.13092"
"172.40000","11.49217","0.12933"
"172.60000","11.50486","0.12851"
"172.80000","11.51891","0.12688"
"173.00000","11.53181","0.12584"
"173.20000","11.54557","0.12393"
"173.40000","11.55844","0.12277"
"173.60000","11.57186","0.12022"
"173.80000","11.58546","0.11857"
"174.00000","11.59863","0.11672"
"174.20000","11.61166","0.11503"
"174.40000","11.62556","0.11376"
"174.60000","11.63845","0.11293"
"174.80000","11.65237","0.11127"
"175.00000","11.66487","0.10979"
"175.20000","11.67872","0.10855"
"175.40000","11.69187","0.10653"
"175.60000","11.70527","0.10442"
"175.80000","11.71842","0.10254"
"176.00000","11.73179","0.10154"
"176.20000","11.74522","0.09983"
"176.40000","11.75891","0.09862"
"176.60000","11.77160","0.09668"
"176.80000","11.78546","0.09562"
"177.00000","11.79844","0.09385"
"177.20000","11.81221","0.09321"
"177.40000","11.82524","0.09192"
"177.60000","11.83844","0.09142"
"177.80000","11.85206","0.08971"
"178.00000","11.86527","0.08801"
"178.20000","11.87854","0.08666"
"178.40000","11.89211","0.08607"
"178.60000","11.90506","0.08451"
"178.80000","11.91910","0.08333"
"179.00000","11.93169","0.08185"
"179.20000","11.94547","0.08075"
"179.40000","11.95875","0.07926"
"179.60000","11.97198","0.07827"
"179.80000","11.98534","0.07738"
"180.00000","11.99822","0.07621"
"180.20000","12.01205","0.07516"
"180.40000","12.02555","0.07336"
"180.60000","12.03848","0.07286"
"180.80000","12.05198","0.07153"
"181.00000","12.06513","0.07036"
"181.20000","12.07891","0.06834"
"181.40000","12.09218","0.06591"
"181.60000","12.10488","0.06411"
"181.80000","12.11891","0.06189"
"182.00000","12.13177","0.06058"
"182.20000","12.14561","0.05859"
"182.40000","12.15839","0.05689"
"182.60000","12.17184","0.05539"
"182.80000","12.18553","0.05412"
"183.00000","12.19865","0.05302"
"183.20000","12.21175","0.05191"
"183.40000","12.22549","0.05052"
"183.60000","12.23840","0.04925"
"183.80000","12.25240","0.04881"
"184.00000","12.26472","0.04742"
"184.20000","12.27880","0.04655"
"184.40000","12.29195","0.04479"
"184.60000","12.30522","0.04330"
"184.80000","12.31844","0.04116"
"185.00000","12.33174","0.03994"
"185.20000","12.34533","0.03948"
"185.40000","12.35889","0.03800"
"185.60000","12.37148","0.03679"
"185.80000","12.38560","0.03499"
"186.00000","12.39845","0.03309"
"186.20000","12.41225","0.03231"
"186.40000","12.42526","0.03000"
"186.60000","12.43849","0.02853"
"186.80000","12.45204","0.02682"
"187.00000","12.46531","0.02486"
"187.20000","12.47865","0.02248"
"187.40000","12.49213","0.02028"
"187.60000","12.50509","0.01803"
"187.80000","12.51901","0.01558"
"188.00000","12.53175","0.01341"
"188.20000","12.54538","0.01167"
"188.40000","12.55872","0.00956"
"188.60000","12.57197","0.00767"
"188.80000","12.58536","0.00606"
"189.00000","12.59827","0.00457"
"189.20000","12.61201","0.00254"
"189.30900","12.61924","0.00197"