File: 20.12.09/1Layer_11.is_flex_RawData/Specimen_RawData_1.csv
Specimen properties : Thickness,"2.70000",mm
Specimen properties : Width,"11.70000",mm
Specimen properties : Support span,"43.20000",mm

Time,Extension,Load
(s),(mm),(kgf)
"0.00000","0.00000","-0.00515"
"0.10000","0.00087","-0.00463"
"0.20000","0.00601","-0.00052"
"0.30000","0.01626","0.00814"
"0.40000","0.02452","0.01345"
"0.50000","0.03202","0.01790"
"0.60000","0.03866","0.02229"
"0.70000","0.04500","0.02597"
"0.80000","0.05187","0.02974"
"0.90000","0.05902","0.03334"
"1.00000","0.06542","0.03715"
"1.10000","0.07177","0.04035"
"1.20000","0.07832","0.04431"
"1.30000","0.08523","0.04786"
"1.40000","0.09205","0.05154"
"1.50000","0.09875","0.05513"
"1.60000","0.10570","0.05832"
"1.70000","0.11203","0.06163"
"1.80000","0.11838","0.06483"
"1.90000","0.12490","0.06837"
"2.00000","0.13211","0.07218"
"2.10000","0.13889","0.07534"
"2.20000","0.14515","0.07827"
"2.30000","0.15168","0.08155"
"2.40000","0.15896","0.08496"
"2.50000","0.16583","0.08828"
"2.60000","0.17212","0.09098"
"2.70000","0.17824","0.09393"
"2.80000","0.18488","0.09648"
"2.90000","0.19197","0.09926"
"3.00000","0.19893","0.10261"
"3.10000","0.20531","0.10518"
"3.20000","0.21193","0.10805"
"3.30000","0.21851","0.11085"
"3.40000","0.22532","0.11370"
"3.50000","0.23196","0.11618"
"3.60000","0.23856","0.11899"
"3.70000","0.24511","0.12178"
"3.80000","0.25182","0.12406"
"3.90000","0.25856","0.12682"
"4.00000","0.26559","0.12960"
"4.10000","0.27228","0.13189"
"4.20000","0.27863","0.13477"
"4.30000","0.28492","0.13694"
"4.40000","0.29162","0.13942"
"4.50000","0.29893","0.14225"
"4.60000","0.30548","0.14433"
"4.70000","0.31188","0.14657"
"4.80000","0.31844","0.14891"
"4.90000","0.32551","0.15146"
"5.00000","0.33238","0.15432"
"5.10000","0.33864","0.15624"
"5.20000","0.34482","0.15842"
"5.30000","0.35171","0.16061"
"5.40000","0.35881","0.16361"
"5.50000","0.36544","0.16545"
"5.60000","0.37204","0.16740"
"5.70000","0.37867","0.16995"
"5.80000","0.38522","0.17203"
"5.90000","0.39192","0.17422"
"6.00000","0.39847","0.17669"
"6.10000","0.40543","0.17923"
"6.20000","0.41185","0.18101"
"6.30000","0.41843","0.18344"
"6.40000","0.42523","0.18530"
"6.50000","0.43236","0.18782"
"6.60000","0.43901","0.18989"
"6.70000","0.44524","0.19163"
"6.80000","0.45147","0.19379"
"6.90000","0.45861","0.19620"
"7.00000","0.46567","0.19829"
"7.10000","0.47211","0.20004"
"7.20000","0.47841","0.20229"
"7.30000","0.48519","0.20425"
"7.40000","0.49225","0.20702"
"7.50000","0.49877","0.20857"
"7.60000","0.50511","0.21007"
"7.70000","0.51169","0.21225"
"7.80000","0.51847","0.21475"
"7.90000","0.52535","0.21688"
"8.00000","0.53202","0.21853"
"8.10000","0.53889","0.22060"
"8.20000","0.54529","0.22191"
"8.30000","0.55183","0.22442"
"8.40000","0.55846","0.22651"
"8.50000","0.56517","0.22822"
"8.60000","0.57213","0.23030"
"8.70000","0.57864","0.23186"
"8.80000","0.58499","0.23375"
"8.90000","0.59208","0.23604"
"9.00000","0.59912","0.23811"
"9.10000","0.60560","0.23970"
"9.20000","0.61162","0.24130"
"9.30000","0.61810","0.24299"
"9.40000","0.62536","0.24555"
"9.50000","0.63222","0.24729"
"9.60000","0.63871","0.24903"
"9.70000","0.64515","0.25029"
"9.80000","0.65184","0.25225"
"9.90000","0.65893","0.25444"
"10.00000","0.66533","0.25591"
"10.10000","0.67173","0.25754"
"10.20000","0.67846","0.25927"
"10.30000","0.68527","0.26110"
"10.40000","0.69202","0.26309"
"10.50000","0.69876","0.26493"
"10.60000","0.70572","0.26672"
"10.70000","0.71202","0.26831"
"10.80000","0.71831","0.26952"
"10.90000","0.72507","0.27160"
"11.00000","0.73210","0.27340"
"11.10000","0.73883","0.27510"
"11.20000","0.74524","0.27661"
"11.30000","0.75177","0.27798"
"11.40000","0.75892","0.28059"
"11.50000","0.76579","0.28169"
"11.60000","0.77211","0.28336"
"11.70000","0.77825","0.28439"
"11.80000","0.78495","0.28622"
"11.90000","0.79202","0.28830"
"12.00000","0.79884","0.28983"
"12.10000","0.80529","0.29122"
"12.20000","0.81191","0.29303"
"12.30000","0.81856","0.29442"
"12.40000","0.82537","0.29611"
"12.50000","0.83192","0.29763"
"12.60000","0.83861","0.29909"
"12.70000","0.84519","0.30090"
"12.80000","0.85177","0.30205"
"12.90000","0.85859","0.30393"
"13.00000","0.86556","0.30584"
"13.10000","0.87230","0.30733"
"13.20000","0.87869","0.30819"
"13.30000","0.88492","0.30995"
"13.40000","0.89166","0.31137"
"13.50000","0.89890","0.31318"
"13.60000","0.90549","0.31480"
"13.70000","0.91175","0.31612"
"13.80000","0.91842","0.31748"
"13.90000","0.92558","0.31984"
"14.00000","0.93235","0.32100"
"14.10000","0.93857","0.32215"
"14.20000","0.94483","0.32328"
"14.30000","0.95162","0.32499"
"14.40000","0.95877","0.32627"
"14.50000","0.96539","0.32782"
"14.60000","0.97200","0.32938"
"14.70000","0.97870","0.33096"
"14.80000","0.98530","0.33239"
"14.90000","0.99200","0.33385"
"15.00000","0.99866","0.33493"
"15.10000","1.00546","0.33660"
"15.20000","1.01182","0.33762"
"15.30000","1.01841","0.33902"
"15.40000","1.02528","0.34060"
"15.50000","1.03243","0.34260"
"15.60000","1.03905","0.34362"
"15.70000","1.04502","0.34461"
"15.80000","1.05145","0.34558"
"15.90000","1.05860","0.34750"
"16.00000","1.06566","0.34881"
"16.10000","1.07218","0.35050"
"16.20000","1.07835","0.35124"
"16.30000","1.08515","0.35268"
"16.40000","1.09222","0.35455"
"16.50000","1.09886","0.35579"
"16.60000","1.10524","0.35656"
"16.70000","1.11154","0.35812"
"16.80000","1.11842","0.35964"
"16.90000","1.12533","0.36100"
"17.00000","1.13207","0.36203"
"17.10000","1.13900","0.36337"
"17.20000","1.14517","0.36399"
"17.30000","1.15184","0.36579"
"17.40000","1.15842","0.36706"
"17.50000","1.16532","0.36849"
"17.60000","1.17223","0.37026"
"17.70000","1.17848","0.37098"
"17.80000","1.18495","0.37226"
"17.90000","1.19199","0.37361"
"18.00000","1.19922","0.37535"
"18.10000","1.20558","0.37643"
"18.20000","1.21161","0.37734"
"18.30000","1.21813","0.37874"
"18.40000","1.22541","0.38001"
"18.50000","1.23232","0.38154"
"18.60000","1.23869","0.38262"
"18.70000","1.24508","0.38336"
"18.80000","1.25191","0.38518"
"18.90000","1.25895","0.38625"
"19.00000","1.26537","0.38768"
"19.10000","1.27178","0.38829"
"19.20000","1.27844","0.38978"
"19.30000","1.28522","0.39081"
"19.40000","1.29199","0.39232"
"19.50000","1.29877","0.39386"
"19.60000","1.30575","0.39526"
"19.70000","1.31207","0.39569"
"19.80000","1.31834","0.39697"
"19.90000","1.32500","0.39797"
"20.00000","1.33212","0.39984"
"20.10000","1.33882","0.40043"
"20.20000","1.34514","0.40195"
"20.30000","1.35180","0.40294"
"20.40000","1.35893","0.40442"
"20.50000","1.36577","0.40583"
"20.60000","1.37213","0.40653"
"20.70000","1.37821","0.40725"
"20.80000","1.38493","0.40876"
"20.90000","1.39197","0.41026"
"21.00000","1.39893","0.41128"
"21.10000","1.40529","0.41186"
"21.20000","1.41186","0.41300"
"21.30000","1.41855","0.41438"
"21.40000","1.42539","0.41573"
"21.50000","1.43195","0.41682"
"21.60000","1.43855","0.41749"
"21.70000","1.44505","0.41876"
"21.80000","1.45182","0.41954"
"21.90000","1.45855","0.42116"
"22.00000","1.46558","0.42230"
"22.10000","1.47238","0.42361"
"22.20000","1.47862","0.42401"
"22.30000","1.48491","0.42510"
"22.40000","1.49161","0.42632"
"22.50000","1.49893","0.42737"
"22.60000","1.50559","0.42902"
"22.70000","1.51178","0.42919"
"22.80000","1.51839","0.43093"
"22.90000","1.52553","0.43218"
"23.00000","1.53237","0.43302"
"23.10000","1.53862","0.43342"
"23.20000","1.54473","0.43407"
"23.30000","1.55174","0.43583"
"23.40000","1.55882","0.43693"
"23.50000","1.56550","0.43814"
"23.60000","1.57208","0.43899"
"23.70000","1.57859","0.43958"
"23.80000","1.58524","0.44119"
"23.90000","1.59188","0.44186"
"24.00000","1.59851","0.44296"
"24.10000","1.60552","0.44391"
"24.20000","1.61184","0.44497"
"24.30000","1.61839","0.44546"
"24.40000","1.62522","0.44685"
"24.50000","1.63245","0.44798"
"24.60000","1.63902","0.44886"
"24.70000","1.64509","0.44951"
"24.80000","1.65145","0.45042"
"24.90000","1.65864","0.45181"
"25.00000","1.66573","0.45288"
"25.10000","1.67213","0.45364"
"25.20000","1.67843","0.45416"
"25.30000","1.68518","0.45571"
"25.40000","1.69227","0.45672"
"25.50000","1.69886","0.45766"
"25.60000","1.70511","0.45846"
"25.70000","1.71161","0.45907"
"25.80000","1.71843","0.46001"
"25.90000","1.72531","0.46134"
"26.00000","1.73204","0.46225"
"26.10000","1.73893","0.46288"
"26.20000","1.74526","0.46392"
"26.30000","1.75178","0.46478"
"26.40000","1.75841","0.46593"
"26.50000","1.76526","0.46659"
"26.60000","1.77214","0.46770"
"26.70000","1.77853","0.46839"
"26.80000","1.78495","0.46934"
"26.90000","1.79193","0.47029"
"27.00000","1.79921","0.47215"
"27.10000","1.80558","0.47226"
"27.20000","1.81170","0.47278"
"27.30000","1.81810","0.47367"
"27.40000","1.82533","0.47521"
"27.50000","1.83227","0.47601"
"27.60000","1.83873","0.47669"
"27.70000","1.84520","0.47748"
"27.80000","1.85189","0.47874"
"27.90000","1.85892","0.47979"
"28.00000","1.86539","0.47995"
"28.10000","1.87177","0.48085"
"28.20000","1.87851","0.48182"
"28.30000","1.88519","0.48270"
"28.40000","1.89194","0.48357"
"28.50000","1.89869","0.48422"
"28.60000","1.90567","0.48495"
"28.70000","1.91216","0.48606"
"28.80000","1.91836","0.48676"
"28.90000","1.92503","0.48804"
"29.00000","1.93205","0.48864"
"29.10000","1.93881","0.48939"
"29.20000","1.94542","0.49006"
"29.30000","1.95167","0.49071"
"29.40000","1.95889","0.49173"
"29.50000","1.96574","0.49315"
"29.60000","1.97208","0.49345"
"29.70000","1.97829","0.49361"
"29.80000","1.98485","0.49457"
"29.90000","1.99205","0.49547"
"30.00000","1.99888","0.49684"
"30.10000","2.00526","0.49705"
"30.20000","2.01209","0.49781"
"30.30000","2.01855","0.49891"
"30.40000","2.02526","0.49952"
"30.50000","2.03182","0.50022"
"30.60000","2.03846","0.50063"
"30.70000","2.04527","0.50150"
"30.80000","2.05180","0.50260"
"30.90000","2.05854","0.50334"
"31.00000","2.06553","0.50469"
"31.10000","2.07223","0.50531"
"31.20000","2.07876","0.50604"
"31.30000","2.08499","0.50584"
"31.40000","2.09163","0.50695"
"31.50000","2.09875","0.50795"
"31.60000","2.10542","0.50888"
"31.70000","2.11198","0.50923"
"31.80000","2.11857","0.51003"
"31.90000","2.12552","0.51106"
"32.00000","2.13228","0.51204"
"32.10000","2.13857","0.51212"
"32.20000","2.14492","0.51264"
"32.30000","2.15178","0.51360"
"32.40000","2.15877","0.51464"
"32.50000","2.16531","0.51526"
"32.60000","2.17189","0.51553"
"32.70000","2.17881","0.51677"
"32.80000","2.18541","0.51677"
"32.90000","2.19193","0.51762"
"33.00000","2.19842","0.51844"
"33.10000","2.20532","0.51916"
"33.20000","2.21203","0.51962"
"33.30000","2.21854","0.52067"
"33.40000","2.22517","0.52112"
"33.50000","2.23231","0.52207"
"33.60000","2.23895","0.52274"
"33.70000","2.24524","0.52338"
"33.80000","2.25155","0.52340"
"33.90000","2.25858","0.52444"
"34.00000","2.26560","0.52536"
"34.10000","2.27206","0.52593"
"34.20000","2.27847","0.52615"
"34.30000","2.28524","0.52701"
"34.40000","2.29221","0.52814"
"34.50000","2.29875","0.52850"
"34.60000","2.30510","0.52906"
"34.70000","2.31178","0.52937"
"34.80000","2.31856","0.53037"
"34.90000","2.32521","0.53127"
"35.00000","2.33189","0.53166"
"35.10000","2.33871","0.53237"
"35.20000","2.34545","0.53295"
"35.30000","2.35196","0.53323"
"35.40000","2.35844","0.53419"
"35.50000","2.36516","0.53490"
"35.60000","2.37205","0.53537"
"35.70000","2.37872","0.53624"
"35.80000","2.38509","0.53652"
"35.90000","2.39205","0.53765"
"36.00000","2.39906","0.53883"
"36.10000","2.40550","0.53909"
"36.20000","2.41178","0.53941"
"36.30000","2.41825","0.53987"
"36.40000","2.42532","0.54071"
"36.50000","2.43208","0.54151"
"36.60000","2.43862","0.54188"
"36.70000","2.44528","0.54231"
"36.80000","2.45202","0.54323"
"36.90000","2.45890","0.54420"
"37.00000","2.46524","0.54465"
"37.10000","2.47168","0.54441"
"37.20000","2.47859","0.54570"
"37.30000","2.48540","0.54624"
"37.40000","2.49201","0.54661"
"37.50000","2.49871","0.54738"
"37.60000","2.50555","0.54793"
"37.70000","2.51213","0.54846"
"37.80000","2.51846","0.54857"
"37.90000","2.52498","0.54962"
"38.00000","2.53200","0.55009"
"38.10000","2.53872","0.55084"
"38.20000","2.54536","0.55134"
"38.30000","2.55183","0.55182"
"38.40000","2.55881","0.55262"
"38.50000","2.56569","0.55343"
"38.60000","2.57204","0.55353"
"38.70000","2.57838","0.55402"
"38.80000","2.58499","0.55456"
"38.90000","2.59204","0.55523"
"39.00000","2.59880","0.55572"
"39.10000","2.60515","0.55635"
"39.20000","2.61210","0.55761"
"39.30000","2.61872","0.55760"
"39.40000","2.62527","0.55823"
"39.50000","2.63178","0.55887"
"39.60000","2.63839","0.55956"
"39.70000","2.64525","0.56009"
"39.80000","2.65191","0.56054"
"39.90000","2.65851","0.56078"
"40.00000","2.66547","0.56217"
"40.10000","2.67214","0.56213"
"40.20000","2.67879","0.56262"
"40.30000","2.68508","0.56287"
"40.40000","2.69166","0.56369"
"40.50000","2.69876","0.56452"
"40.60000","2.70535","0.56506"
"40.70000","2.71202","0.56564"
"40.80000","2.71866","0.56616"
"40.90000","2.72559","0.56684"
"41.00000","2.73223","0.56692"
"41.10000","2.73846","0.56723"
"41.20000","2.74492","0.56776"
"41.30000","2.75186","0.56831"
"41.40000","2.75875","0.56901"
"41.50000","2.76535","0.56923"
"41.60000","2.77192","0.56978"
"41.70000","2.77883","0.57005"
"41.80000","2.78546","0.57056"
"41.90000","2.79196","0.57080"
"42.00000","2.79838","0.57106"
"42.10000","2.80523","0.57202"
"42.20000","2.81194","0.57189"
"42.30000","2.81857","0.57279"
"42.40000","2.82522","0.57319"
"42.50000","2.83232","0.57396"
"42.60000","2.83892","0.57413"
"42.70000","2.84523","0.57468"
"42.80000","2.85159","0.57467"
"42.90000","2.85864","0.57552"
"43.00000","2.86566","0.57615"
"43.10000","2.87206","0.57623"
"43.20000","2.87840","0.57686"
"43.30000","2.88524","0.57772"
"43.40000","2.89221","0.57810"
"43.50000","2.89875","0.57838"
"43.60000","2.90509","0.57854"
"43.70000","2.91171","0.57905"
"43.80000","2.91857","0.57976"
"43.90000","2.92528","0.58060"
"44.00000","2.93185","0.58064"
"44.10000","2.93869","0.58173"
"44.20000","2.94543","0.58225"
"44.30000","2.95196","0.58237"
"44.40000","2.95846","0.58280"
"44.50000","2.96520","0.58377"
"44.60000","2.97205","0.58390"
"44.70000","2.97862","0.58444"
"44.80000","2.98506","0.58470"
"44.90000","2.99195","0.58533"
"45.00000","2.99902","0.58627"
"45.10000","3.00553","0.58606"
"45.20000","3.01181","0.58609"
"45.30000","3.01827","0.58664"
"45.40000","3.02533","0.58784"
"45.50000","3.03217","0.58811"
"45.60000","3.03864","0.58814"
"45.70000","3.04524","0.58833"
"45.80000","3.05192","0.58888"
"45.90000","3.05894","0.58940"
"46.00000","3.06533","0.58995"
"46.10000","3.07167","0.58986"
"46.20000","3.07850","0.59060"
"46.30000","3.08525","0.59108"
"46.40000","3.09204","0.59163"
"46.50000","3.09873","0.59188"
"46.60000","3.10565","0.59206"
"46.70000","3.11211","0.59262"
"46.80000","3.11837","0.59249"
"46.90000","3.12501","0.59298"
"47.00000","3.13205","0.59397"
"47.10000","3.13878","0.59388"
"47.20000","3.14530","0.59419"
"47.30000","3.15180","0.59469"
"47.40000","3.15893","0.59539"
"47.50000","3.16570","0.59587"
"47.60000","3.17200","0.59596"
"47.70000","3.17823","0.59582"
"47.80000","3.18498","0.59698"
"47.90000","3.19199","0.59702"
"48.00000","3.19880","0.59759"
"48.10000","3.20529","0.59804"
"48.20000","3.21187","0.59836"
"48.30000","3.21861","0.59865"
"48.40000","3.22535","0.59937"
"48.50000","3.23183","0.59966"
"48.60000","3.23846","0.59997"
"48.70000","3.24512","0.60068"
"48.80000","3.25187","0.60110"
"48.90000","3.25858","0.60136"
"49.00000","3.26553","0.60212"
"49.10000","3.27226","0.60214"
"49.20000","3.27868","0.60196"
"49.30000","3.28490","0.60237"
"49.40000","3.29162","0.60278"
"49.50000","3.29886","0.60349"
"49.60000","3.30550","0.60362"
"49.70000","3.31182","0.60374"
"49.80000","3.31845","0.60467"
"49.90000","3.32558","0.60493"
"50.00000","3.33243","0.60518"
"50.10000","3.33854","0.60535"
"50.20000","3.34485","0.60544"
"50.30000","3.35178","0.60635"
"50.40000","3.35882","0.60739"
"50.50000","3.36541","0.60735"
"50.60000","3.37196","0.60779"
"50.70000","3.37868","0.60781"
"50.80000","3.38530","0.60880"
"50.90000","3.39202","0.60865"
"51.00000","3.39844","0.60873"
"51.10000","3.40540","0.60957"
"51.20000","3.41183","0.60961"
"51.30000","3.41845","0.61049"
"51.40000","3.42526","0.61066"
"51.50000","3.43247","0.61119"
"51.60000","3.43893","0.61128"
"51.70000","3.44502","0.61097"
"51.80000","3.45145","0.61117"
"51.90000","3.45857","0.61262"
"52.00000","3.46578","0.61277"
"52.10000","3.47216","0.61269"
"52.20000","3.47834","0.61266"
"52.30000","3.48527","0.61334"
"52.40000","3.49228","0.61400"
"52.50000","3.49887","0.61364"
"52.60000","3.50513","0.61371"
"52.70000","3.51163","0.61418"
"52.80000","3.51843","0.61441"
"52.90000","3.52540","0.61511"
"53.00000","3.53205","0.61535"
"53.10000","3.53891","0.61566"
"53.20000","3.54529","0.61593"
"53.30000","3.55195","0.61643"
"53.40000","3.55842","0.61688"
"53.50000","3.56522","0.61718"
"53.60000","3.57217","0.61723"
"53.70000","3.57849","0.61724"
"53.80000","3.58495","0.61751"
"53.90000","3.59203","0.61807"
"54.00000","3.59921","0.61909"
"54.10000","3.60544","0.61811"
"54.20000","3.61170","0.61836"
"54.30000","3.61811","0.61882"
"54.40000","3.62537","0.61963"
"54.50000","3.63241","0.61983"
"54.60000","3.63867","0.62003"
"54.70000","3.64514","0.62043"
"54.80000","3.65185","0.62035"
"54.90000","3.65895","0.62069"
"55.00000","3.66538","0.62075"
"55.10000","3.67172","0.62051"
"55.20000","3.67845","0.62121"
"55.30000","3.68521","0.62185"
"55.40000","3.69195","0.62204"
"55.50000","3.69882","0.62243"
"55.60000","3.70569","0.62269"
"55.70000","3.71203","0.62206"
"55.80000","3.71831","0.62217"
"55.90000","3.72498","0.62280"
"56.00000","3.73218","0.62320"
"56.10000","3.73880","0.62375"
"56.20000","3.74525","0.62395"
"56.30000","3.75167","0.62454"
"56.40000","3.75904","0.62538"
"56.50000","3.76581","0.62530"
"56.60000","3.77207","0.62517"
"56.70000","3.77826","0.62489"
"56.80000","3.78495","0.62557"
"56.90000","3.79206","0.62602"
"57.00000","3.79888","0.62643"
"57.10000","3.80529","0.62620"
"57.20000","3.81192","0.62642"
"57.30000","3.81853","0.62669"
"57.40000","3.82538","0.62708"
"57.50000","3.83188","0.62721"
"57.60000","3.83850","0.62709"
"57.70000","3.84515","0.62733"
"57.80000","3.85171","0.62745"
"57.90000","3.85858","0.62781"
"58.00000","3.86561","0.62799"
"58.10000","3.87223","0.62783"
"58.20000","3.87875","0.62769"
"58.30000","3.88499","0.62811"
"58.40000","3.89162","0.62824"
"58.50000","3.89892","0.62888"
"58.60000","3.90546","0.62862"
"58.70000","3.91179","0.62872"
"58.80000","3.91846","0.62934"
"58.90000","3.92565","0.62971"
"59.00000","3.93234","0.62955"
"59.10000","3.93846","0.62953"
"59.20000","3.94489","0.62989"
"59.30000","3.95175","0.63015"
"59.40000","3.95888","0.63042"
"59.50000","3.96540","0.63029"
"59.60000","3.97199","0.63053"
"59.70000","3.97877","0.63114"
"59.80000","3.98539","0.63147"
"59.90000","3.99188","0.63096"
"60.00000","3.99844","0.63134"
"60.10000","4.00531","0.63141"
"60.20000","4.01201","0.63171"
"60.30000","4.01853","0.63193"
"60.40000","4.02528","0.63202"
"60.50000","4.03239","0.63220"
"60.60000","4.03892","0.63233"
"60.70000","4.04516","0.63234"
"60.80000","4.05157","0.63246"
"60.90000","4.05864","0.63314"
"61.00000","4.06564","0.63333"
"61.10000","4.07207","0.63329"
"61.20000","4.07838","0.63277"
"61.30000","4.08520","0.63385"
"61.40000","4.09230","0.63387"
"61.50000","4.09880","0.63369"
"61.60000","4.10507","0.63365"
"61.70000","4.11169","0.63367"
"61.80000","4.11853","0.63414"
"61.90000","4.12532","0.63411"
"62.00000","4.13195","0.63431"
"62.10000","4.13878","0.63529"
"62.20000","4.14535","0.63466"
"62.30000","4.15185","0.63481"
"62.40000","4.15841","0.63484"
"62.50000","4.16516","0.63544"
"62.60000","4.17213","0.63561"
"62.70000","4.17860","0.63541"
"62.80000","4.18496","0.63569"
"62.90000","4.19203","0.63614"
"63.00000","4.19916","0.63624"
"63.10000","4.20558","0.63587"
"63.20000","4.21168","0.63579"
"63.30000","4.21811","0.63594"
"63.40000","4.22545","0.63643"
"63.50000","4.23221","0.63630"
"63.60000","4.23861","0.63645"
"63.70000","4.24522","0.63647"
"63.80000","4.25190","0.63680"
"63.90000","4.25891","0.63723"
"64.00000","4.26535","0.63662"
"64.10000","4.27176","0.63643"
"64.20000","4.27845","0.63689"
"64.30000","4.28524","0.63710"
"64.40000","4.29190","0.63653"
"64.50000","4.29862","0.63644"
"64.60000","4.30568","0.63651"
"64.70000","4.31218","0.63636"
"64.80000","4.31835","0.63609"
"64.90000","4.32500","0.63608"
"65.00000","4.33204","0.63692"
"65.10000","4.33869","0.63643"
"65.20000","4.34531","0.63646"
"65.30000","4.35170","0.63608"
"65.40000","4.35900","0.63710"
"65.50000","4.36586","0.63674"
"65.60000","4.37209","0.63577"
"65.70000","4.37828","0.63548"
"65.80000","4.38491","0.63564"
"65.90000","4.39203","0.63596"
"66.00000","4.39887","0.63615"
"66.10000","4.40535","0.63538"
"66.20000","4.41203","0.63518"
"66.30000","4.41856","0.63512"
"66.40000","4.42540","0.63495"
"66.50000","4.43187","0.63448"
"66.60000","4.43846","0.63492"
"66.70000","4.44515","0.63462"
"66.80000","4.45169","0.63415"
"66.90000","4.45856","0.63437"
"67.00000","4.46568","0.63451"
"67.10000","4.47228","0.63428"
"67.20000","4.47866","0.63344"
"67.30000","4.48494","0.63303"
"67.40000","4.49165","0.63327"
"67.50000","4.49895","0.63371"
"67.60000","4.50543","0.63364"
"67.70000","4.51182","0.63294"
"67.80000","4.51845","0.63342"
"67.90000","4.52559","0.63325"
"68.00000","4.53233","0.63319"
"68.10000","4.53861","0.63296"
"68.20000","4.54488","0.63266"
"68.30000","4.55167","0.63291"
"68.40000","4.55879","0.63364"
"68.50000","4.56548","0.63288"
"68.60000","4.57197","0.63335"
"68.70000","4.57870","0.63289"
"68.80000","4.58535","0.63246"
"68.90000","4.59199","0.63294"
"69.00000","4.59848","0.63266"
"69.10000","4.60544","0.63255"
"69.20000","4.61193","0.63210"
"69.30000","4.61843","0.63197"
"69.40000","4.62523","0.63245"
"69.50000","4.63236","0.63259"
"69.60000","4.63906","0.63260"
"69.70000","4.64516","0.63210"
"69.80000","4.65148","0.63220"
"69.90000","4.65862","0.63217"
"70.00000","4.66564","0.63198"
"70.10000","4.67215","0.63183"
"70.20000","4.67845","0.63157"
"70.30000","4.68514","0.63178"
"70.40000","4.69217","0.63220"
"70.50000","4.69883","0.63155"
"70.60000","4.70512","0.63143"
"70.70000","4.71162","0.63127"
"70.80000","4.71848","0.63173"
"70.90000","4.72540","0.63176"
"71.00000","4.73203","0.63159"
"71.10000","4.73899","0.63191"
"71.20000","4.74523","0.63174"
"71.30000","4.75180","0.63131"
"71.40000","4.75848","0.63123"
"71.50000","4.76520","0.63119"
"71.60000","4.77213","0.63106"
"71.70000","4.77853","0.63093"
"71.80000","4.78494","0.63048"
"71.90000","4.79205","0.63090"
"72.00000","4.79918","0.63086"
"72.10000","4.80560","0.63076"
"72.20000","4.81174","0.63013"
"72.30000","4.81810","0.63030"
"72.40000","4.82536","0.63056"
"72.50000","4.83222","0.63056"
"72.60000","4.83869","0.63050"
"72.70000","4.84525","0.63042"
"72.80000","4.85187","0.63001"
"72.90000","4.85887","0.63060"
"73.00000","4.86535","0.62977"
"73.10000","4.87175","0.62960"
"73.20000","4.87843","0.62950"
"73.30000","4.88517","0.62965"
"73.40000","4.89204","0.62965"
"73.50000","4.89876","0.62933"
"73.60000","4.90577","0.62936"
"73.70000","4.91207","0.62901"
"73.80000","4.91827","0.62890"
"73.90000","4.92502","0.62894"
"74.00000","4.93213","0.62924"
"74.10000","4.93878","0.62858"
"74.20000","4.94524","0.62857"
"74.30000","4.95173","0.62826"
"74.40000","4.95897","0.62898"
"74.50000","4.96584","0.62878"
"74.60000","4.97205","0.62797"
"74.70000","4.97816","0.62760"
"74.80000","4.98486","0.62778"
"74.90000","4.99208","0.62784"
"75.00000","4.99889","0.62806"
"75.10000","5.00525","0.62754"
"75.20000","5.01185","0.62752"
"75.30000","5.01854","0.62712"
"75.40000","5.02538","0.62694"
"75.50000","5.03187","0.62693"
"75.60000","5.03850","0.62680"
"75.70000","5.04513","0.62605"
"75.80000","5.05175","0.62649"
"75.90000","5.05856","0.62588"
"76.00000","5.06562","0.62580"
"76.10000","5.07225","0.62563"
"76.20000","5.07870","0.62540"
"76.30000","5.08492","0.62502"
"76.40000","5.09166","0.62498"
"76.50000","5.09885","0.62483"
"76.60000","5.10553","0.62444"
"76.70000","5.11189","0.62385"
"76.80000","5.11834","0.62389"
"76.90000","5.12561","0.62339"
"77.00000","5.13241","0.62311"
"77.10000","5.13859","0.62242"
"77.20000","5.14491","0.62211"
"77.30000","5.15164","0.62158"
"77.40000","5.15886","0.62180"
"77.50000","5.16543","0.62050"
"77.60000","5.17205","0.62058"
"77.70000","5.17864","0.61929"
"77.80000","5.18525","0.61971"
"77.90000","5.19194","0.61901"
"78.00000","5.19847","0.61753"
"78.10000","5.20539","0.61742"
"78.20000","5.21195","0.61677"
"78.30000","5.21850","0.61601"
"78.40000","5.22521","0.61576"
"78.50000","5.23240","0.61564"
"78.60000","5.23909","0.61501"
"78.70000","5.24510","0.61404"
"78.80000","5.25153","0.61373"
"78.90000","5.25864","0.61329"
"79.00000","5.26556","0.61320"
"79.10000","5.27209","0.61242"
"79.20000","5.27836","0.61188"
"79.30000","5.28523","0.61134"
"79.40000","5.29227","0.61119"
"79.50000","5.29885","0.61030"
"79.60000","5.30522","0.60994"
"79.70000","5.31149","0.60899"
"79.80000","5.31834","0.60890"
"79.90000","5.32537","0.60876"
"80.00000","5.33203","0.60808"
"80.10000","5.33882","0.60765"
"80.20000","5.34532","0.60664"
"80.30000","5.35186","0.60646"
"80.40000","5.35844","0.60615"
"80.50000","5.36524","0.60553"
"80.60000","5.37221","0.60526"
"80.70000","5.37848","0.60448"
"80.80000","5.38495","0.60444"
"80.90000","5.39205","0.60466"
"81.00000","5.39920","0.60424"
"81.10000","5.40559","0.60356"
"81.20000","5.41163","0.60287"
"81.30000","5.41807","0.60254"
"81.40000","5.42537","0.60242"
"81.50000","5.43238","0.60208"
"81.60000","5.43870","0.60089"
"81.70000","5.44512","0.60086"
"81.80000","5.45182","0.60034"
"81.90000","5.45890","0.59998"
"82.00000","5.46538","0.59959"
"82.10000","5.47184","0.59871"
"82.20000","5.47847","0.59828"
"82.30000","5.48517","0.59828"
"82.40000","5.49199","0.59803"
"82.50000","5.49882","0.59761"
"82.60000","5.50570","0.59688"
"82.70000","5.51201","0.59612"
"82.80000","5.51835","0.59601"
"82.90000","5.52507","0.59579"
"83.00000","5.53208","0.59591"
"83.10000","5.53882","0.59563"
"83.20000","5.54519","0.59558"
"83.30000","5.55166","0.59559"
"83.40000","5.55892","0.59593"
"83.50000","5.56583","0.59560"
"83.60000","5.57215","0.59463"
"83.70000","5.57830","0.59443"
"83.80000","5.58498","0.59412"
"83.90000","5.59205","0.59410"
"84.00000","5.59887","0.59360"
"84.10000","5.60527","0.59328"
"84.20000","5.61198","0.59280"
"84.30000","5.61846","0.59233"
"84.40000","5.62532","0.59203"
"84.50000","5.63190","0.59140"
"84.60000","5.63865","0.59114"
"84.70000","5.64517","0.59027"
"84.80000","5.65180","0.59007"
"84.90000","5.65856","0.58961"
"85.00000","5.66555","0.58883"
"85.10000","5.67236","0.58848"
"85.20000","5.67862","0.58733"
"85.30000","5.68491","0.58683"
"85.40000","5.69165","0.58688"
"85.50000","5.69893","0.58624"
"85.60000","5.70545","0.58568"
"85.70000","5.71188","0.58509"
"85.80000","5.71837","0.58504"
"85.90000","5.72558","0.58446"
"86.00000","5.73242","0.58414"
"86.10000","5.73866","0.58355"
"86.20000","5.74485","0.58259"
"86.30000","5.75163","0.58300"
"86.40000","5.75879","0.58259"
"86.50000","5.76540","0.58202"
"86.60000","5.77206","0.58168"
"86.70000","5.77863","0.58124"
"86.80000","5.78524","0.58075"
"86.90000","5.79189","0.58047"
"87.00000","5.79845","0.57982"
"87.10000","5.80544","0.57891"
"87.20000","5.81190","0.57868"
"87.30000","5.81846","0.57818"
"87.40000","5.82520","0.57737"
"87.50000","5.83245","0.57721"
"87.60000","5.83911","0.57680"
"87.70000","5.84508","0.57567"
"87.80000","5.85142","0.57466"
"87.90000","5.85860","0.57512"
"88.00000","5.86564","0.57439"
"88.10000","5.87223","0.57390"
"88.20000","5.87845","0.57273"
"88.30000","5.88525","0.57275"
"88.40000","5.89230","0.57257"
"88.50000","5.89879","0.57157"
"88.60000","5.90513","0.57079"
"88.70000","5.91167","0.57071"
"88.80000","5.91842","0.57044"
"88.90000","5.92530","0.56942"
"89.00000","5.93190","0.56912"
"89.10000","5.93890","0.56861"
"89.20000","5.94532","0.56775"
"89.30000","5.95180","0.56714"
"89.40000","5.95846","0.56679"
"89.50000","5.96516","0.56651"
"89.60000","5.97224","0.56553"
"89.70000","5.97851","0.56482"
"89.80000","5.98496","0.56431"
"89.90000","5.99209","0.56429"
"90.00000","5.99921","0.56354"
"90.10000","6.00559","0.56310"
"90.20000","6.01169","0.56193"
"90.30000","6.01801","0.56150"
"90.40000","6.02529","0.56137"
"90.50000","6.03234","0.56048"
"90.60000","6.03870","0.55978"
"90.70000","6.04523","0.55916"
"90.80000","6.05189","0.55900"
"90.90000","6.05890","0.55814"
"91.00000","6.06538","0.55736"
"91.10000","6.07177","0.55631"
"91.20000","6.07850","0.55631"
"91.30000","6.08518","0.55567"
"91.40000","6.09201","0.55512"
"91.50000","6.09878","0.55463"
"91.60000","6.10568","0.55372"
"91.70000","6.11204","0.55284"
"91.80000","6.11830","0.55215"
"91.90000","6.12499","0.55195"
"92.00000","6.13205","0.55140"
"92.10000","6.13880","0.55005"
"92.20000","6.14529","0.54979"
"92.30000","6.15171","0.54908"
"92.40000","6.15901","0.54896"
"92.50000","6.16578","0.54843"
"92.60000","6.17208","0.54799"
"92.70000","6.17838","0.54689"
"92.80000","6.18487","0.54696"
"92.90000","6.19209","0.54665"
"93.00000","6.19893","0.54659"
"93.10000","6.20527","0.54584"
"93.20000","6.21190","0.54544"
"93.30000","6.21851","0.54476"
"93.40000","6.22541","0.54464"
"93.50000","6.23186","0.54374"
"93.60000","6.23850","0.54362"
"93.70000","6.24511","0.54326"
"93.80000","6.25177","0.54344"
"93.90000","6.25857","0.54304"
"94.00000","6.26553","0.54320"
"94.10000","6.27234","0.54295"
"94.20000","6.27870","0.54199"
"94.30000","6.28493","0.54206"
"94.40000","6.29164","0.54139"
"94.50000","6.29887","0.54156"
"94.60000","6.30545","0.54166"
"94.70000","6.31188","0.54076"
"94.80000","6.31848","0.54062"
"94.90000","6.32556","0.54041"
"95.00000","6.33232","0.53958"
"95.10000","6.33862","0.53931"
"95.20000","6.34493","0.53875"
"95.30000","6.35176","0.53886"
"95.40000","6.35876","0.53818"
"95.50000","6.36537","0.53756"
"95.60000","6.37206","0.53686"
"95.70000","6.37868","0.53681"
"95.80000","6.38525","0.53565"
"95.90000","6.39195","0.53515"
"96.00000","6.39846","0.53443"
"96.10000","6.40544","0.53375"
"96.20000","6.41197","0.53268"
"96.30000","6.41846","0.53227"
"96.40000","6.42524","0.53151"
"96.50000","6.43238","0.53142"
"96.60000","6.43898","0.53062"
"96.70000","6.44515","0.52951"
"96.80000","6.45148","0.52900"
"96.90000","6.45858","0.52872"
"97.00000","6.46566","0.52833"
"97.10000","6.47214","0.52714"
"97.20000","6.47846","0.52609"
"97.30000","6.48519","0.52601"
"97.40000","6.49227","0.52553"
"97.50000","6.49879","0.52483"
"97.60000","6.50515","0.52374"
"97.70000","6.51160","0.52278"
"97.80000","6.51851","0.52258"
"97.90000","6.52540","0.52172"
"98.00000","6.53191","0.52089"
"98.10000","6.53888","0.52106"
"98.20000","6.54527","0.51973"
"98.30000","6.55176","0.51890"
"98.40000","6.55844","0.51856"
"98.50000","6.56523","0.51805"
"98.60000","6.57216","0.51793"
"98.70000","6.57849","0.51664"
"98.80000","6.58494","0.51628"
"98.90000","6.59210","0.51632"
"99.00000","6.59920","0.51540"
"99.10000","6.60561","0.51439"
"99.20000","6.61163","0.51349"
"99.30000","6.61808","0.51367"
"99.40000","6.62532","0.51303"
"99.50000","6.63221","0.51241"
"99.60000","6.63873","0.51138"
"99.70000","6.64514","0.51096"
"99.80000","6.65191","0.51040"
"99.90000","6.65887","0.51054"
"100.00000","6.66535","0.50992"
"100.10000","6.67185","0.50875"
"100.20000","6.67833","0.50838"
"100.30000","6.68513","0.50823"
"100.40000","6.69205","0.50824"
"100.50000","6.69879","0.50721"
"100.60000","6.70579","0.50695"
"100.70000","6.71199","0.50589"
"100.80000","6.71825","0.50569"
"100.90000","6.72501","0.50516"
"101.00000","6.73215","0.50476"
"101.10000","6.73893","0.50425"
"101.20000","6.74523","0.50291"
"101.30000","6.75167","0.50259"
"101.40000","6.75887","0.50239"
"101.50000","6.76576","0.50215"
"101.60000","6.77209","0.50079"
"101.70000","6.77823","0.49940"
"101.80000","6.78489","0.49909"
"101.90000","6.79209","0.49868"
"102.00000","6.79890","0.49781"
"102.10000","6.80533","0.49654"
"102.20000","6.81195","0.49564"
"102.30000","6.81854","0.49490"
"102.40000","6.82542","0.49414"
"102.50000","6.83191","0.49256"
"102.60000","6.83856","0.49251"
"102.70000","6.84508","0.49101"
"102.80000","6.85173","0.48991"
"102.90000","6.85849","0.48866"
"103.00000","6.86566","0.48796"
"103.10000","6.87237","0.48680"
"103.20000","6.87860","0.48543"
"103.30000","6.88489","0.48453"
"103.40000","6.89161","0.48392"
"103.50000","6.89899","0.48342"
"103.60000","6.90549","0.48214"
"103.70000","6.91180","0.48065"
"103.80000","6.91836","0.48031"
"103.90000","6.92565","0.47975"
"104.00000","6.93242","0.47762"
"104.10000","6.93863","0.47657"
"104.20000","6.94482","0.47533"
"104.30000","6.95166","0.47478"
"104.40000","6.95876","0.47356"
"104.50000","6.96540","0.47215"
"104.60000","6.97197","0.47092"
"104.70000","6.97867","0.46954"
"104.80000","6.98532","0.46908"
"104.90000","6.99199","0.46796"
"105.00000","6.99848","0.46631"
"105.10000","7.00549","0.46585"
"105.20000","7.01195","0.46383"
"105.30000","7.01844","0.46313"
"105.40000","7.02527","0.46186"
"105.50000","7.03243","0.46071"
"105.60000","7.03908","0.45930"
"105.70000","7.04518","0.45766"
"105.80000","7.05145","0.45607"
"105.90000","7.05857","0.45493"
"106.00000","7.06566","0.45398"
"106.10000","7.07218","0.45265"
"106.20000","7.07840","0.45145"
"106.30000","7.08522","0.45036"
"106.40000","7.09230","0.44928"
"106.50000","7.09878","0.44750"
"106.60000","7.10517","0.44612"
"106.70000","7.11170","0.44503"
"106.80000","7.11842","0.44362"
"106.90000","7.12530","0.44236"
"107.00000","7.13197","0.44151"
"107.10000","7.13883","0.44034"
"107.20000","7.14530","0.43872"
"107.30000","7.15175","0.43725"
"107.40000","7.15844","0.43627"
"107.50000","7.16526","0.43439"
"107.60000","7.17211","0.43322"
"107.70000","7.17866","0.43176"
"107.80000","7.18495","0.43079"
"107.90000","7.19202","0.42994"
"108.00000","7.19913","0.42928"
"108.10000","7.20554","0.42748"
"108.20000","7.21176","0.42645"
"108.30000","7.21808","0.42590"
"108.40000","7.22544","0.42523"
"108.50000","7.23223","0.42382"
"108.60000","7.23866","0.42272"
"108.70000","7.24523","0.42146"
"108.80000","7.25191","0.42076"
"108.90000","7.25894","0.41983"
"109.00000","7.26530","0.41857"
"109.10000","7.27176","0.41728"
"109.20000","7.27849","0.41646"
"109.30000","7.28517","0.41495"
"109.40000","7.29193","0.41374"
"109.50000","7.29859","0.41271"
"109.60000","7.30570","0.41155"
"109.70000","7.31224","0.41021"
"109.80000","7.31833","0.40900"
"109.90000","7.32509","0.40785"
"110.00000","7.33200","0.40703"
"110.10000","7.33884","0.40598"
"110.20000","7.34522","0.40491"
"110.30000","7.35172","0.40440"
"110.40000","7.35884","0.40356"
"110.50000","7.36578","0.40261"
"110.60000","7.37214","0.40065"
"110.70000","7.37821","0.39970"
"110.80000","7.38487","0.39926"
"110.90000","7.39202","0.39872"
"111.00000","7.39886","0.39784"
"111.10000","7.40535","0.39681"
"111.20000","7.41175","0.39572"
"111.30000","7.41859","0.39483"
"111.40000","7.42536","0.39297"
"111.50000","7.43182","0.39195"
"111.60000","7.43861","0.39139"
"111.70000","7.44517","0.39009"
"111.80000","7.45186","0.38900"
"111.90000","7.45871","0.38814"
"112.00000","7.46553","0.38695"
"112.10000","7.47232","0.38625"
"112.20000","7.47863","0.38480"
"112.30000","7.48490","0.38400"
"112.40000","7.49160","0.38345"
"112.50000","7.49895","0.38244"
"112.60000","7.50557","0.38175"
"112.70000","7.51185","0.38010"
"112.80000","7.51842","0.37962"
"112.90000","7.52562","0.37853"
"113.00000","7.53232","0.37700"
"113.10000","7.53858","0.37628"
"113.20000","7.54480","0.37489"
"113.30000","7.55171","0.37397"
"113.40000","7.55880","0.37312"
"113.50000","7.56542","0.37207"
"113.60000","7.57206","0.37094"
"113.70000","7.57877","0.36987"
"113.80000","7.58534","0.36926"
"113.90000","7.59201","0.36825"
"114.00000","7.59847","0.36690"
"114.10000","7.60535","0.36622"
"114.20000","7.61192","0.36491"
"114.30000","7.61850","0.36446"
"114.40000","7.62529","0.36342"
"114.50000","7.63239","0.36256"
"114.60000","7.63900","0.36120"
"114.70000","7.64509","0.35990"
"114.80000","7.65149","0.35854"
"114.90000","7.65862","0.35773"
"115.00000","7.66560","0.35707"
"115.10000","7.67217","0.35538"
"115.20000","7.67842","0.35422"
"115.30000","7.68519","0.35398"
"115.40000","7.69230","0.35299"
"115.50000","7.69881","0.35236"
"115.60000","7.70511","0.35098"
"115.70000","7.71159","0.35045"
"115.80000","7.71845","0.34968"
"115.90000","7.72537","0.34796"
"116.00000","7.73205","0.34693"
"116.10000","7.73896","0.34562"
"116.20000","7.74530","0.34396"
"116.30000","7.75176","0.34234"
"116.40000","7.75849","0.34052"
"116.50000","7.76524","0.33911"
"116.60000","7.77210","0.33728"
"116.70000","7.77846","0.33591"
"116.80000","7.78492","0.33419"
"116.90000","7.79201","0.33344"
"117.00000","7.79916","0.33151"
"117.10000","7.80558","0.32989"
"117.20000","7.81166","0.32839"
"117.30000","7.81803","0.32760"
"117.40000","7.82547","0.32613"
"117.50000","7.83233","0.32405"
"117.60000","7.83871","0.32212"
"117.70000","7.84509","0.32049"
"117.80000","7.85183","0.31948"
"117.90000","7.85896","0.31787"
"118.00000","7.86541","0.31607"
"118.10000","7.87181","0.31522"
"118.20000","7.87838","0.31403"
"118.30000","7.88513","0.31282"
"118.40000","7.89196","0.31191"
"118.50000","7.89878","0.31099"
"118.60000","7.90581","0.31010"
"118.70000","7.91198","0.30815"
"118.80000","7.91828","0.30681"
"118.90000","7.92497","0.30532"
"119.00000","7.93212","0.30449"
"119.10000","7.93888","0.30290"
"119.20000","7.94524","0.30105"
"119.30000","7.95172","0.30008"
"119.40000","7.95895","0.29853"
"119.50000","7.96578","0.29736"
"119.60000","7.97210","0.29555"
"119.70000","7.97821","0.29426"
"119.80000","7.98491","0.29357"
"119.90000","7.99207","0.29222"
"120.00000","7.99885","0.29116"
"120.10000","8.00535","0.28993"
"120.20000","8.01189","0.28837"
"120.30000","8.01852","0.28717"
"120.40000","8.02540","0.28532"
"120.50000","8.03189","0.28356"
"120.60000","8.03855","0.28272"
"120.70000","8.04510","0.28137"
"120.80000","8.05169","0.27972"
"120.90000","8.05860","0.27856"
"121.00000","8.06572","0.27647"
"121.10000","8.07231","0.27429"
"121.20000","8.07860","0.27237"
"121.30000","8.08492","0.27110"
"121.40000","8.09157","0.26978"
"121.50000","8.09897","0.26856"
"121.60000","8.10554","0.26728"
"121.70000","8.11179","0.26537"
"121.80000","8.11837","0.26486"
"121.90000","8.12556","0.26317"
"122.00000","8.13235","0.26220"
"122.10000","8.13864","0.26079"
"122.20000","8.14477","0.25955"
"122.30000","8.15169","0.25821"
"122.40000","8.15890","0.25730"
"122.50000","8.16553","0.25553"
"122.60000","8.17204","0.25478"
"122.70000","8.17854","0.25393"
"122.80000","8.18527","0.25338"
"122.90000","8.19189","0.25192"
"123.00000","8.19855","0.25077"
"123.10000","8.20552","0.25016"
"123.20000","8.21182","0.24915"
"123.30000","8.21840","0.24885"
"123.40000","8.22518","0.24797"
"123.50000","8.23243","0.24721"
"123.60000","8.23913","0.24627"
"123.70000","8.24503","0.24504"
"123.80000","8.25149","0.24406"
"123.90000","8.25867","0.24348"
"124.00000","8.26567","0.24238"
"124.10000","8.27219","0.24106"
"124.20000","8.27830","0.24016"
"124.30000","8.28518","0.23965"
"124.40000","8.29222","0.23875"
"124.50000","8.29888","0.23768"
"124.60000","8.30520","0.23661"
"124.70000","8.31155","0.23576"
"124.80000","8.31841","0.23476"
"124.90000","8.32525","0.23362"
"125.00000","8.33194","0.23290"
"125.10000","8.33909","0.23275"
"125.20000","8.34529","0.23098"
"125.30000","8.35182","0.23030"
"125.40000","8.35843","0.22993"
"125.50000","8.36526","0.22881"
"125.60000","8.37216","0.22862"
"125.70000","8.37843","0.22752"
"125.80000","8.38498","0.22695"
"125.90000","8.39219","0.22636"
"126.00000","8.39933","0.22571"
"126.10000","8.40558","0.22427"
"126.20000","8.41159","0.22308"
"126.30000","8.41802","0.22328"
"126.40000","8.42539","0.22235"
"126.50000","8.43229","0.22187"
"126.60000","8.43862","0.22048"
"126.70000","8.44507","0.21915"
"126.80000","8.45193","0.21942"
"126.90000","8.45896","0.21843"
"127.00000","8.46536","0.21694"
"127.10000","8.47174","0.21567"
"127.20000","8.47838","0.21371"
"127.30000","8.48520","0.21278"
"127.40000","8.49196","0.21149"
"127.50000","8.49874","0.21019"
"127.60000","8.50575","0.20851"
"127.70000","8.51210","0.20694"
"127.80000","8.51832","0.20543"
"127.90000","8.52498","0.20429"
"128.00000","8.53211","0.20306"
"128.10000","8.53885","0.20151"
"128.20000","8.54531","0.20053"
"128.30000","8.55168","0.19966"
"128.40000","8.55899","0.19822"
"128.50000","8.56585","0.19731"
"128.60000","8.57204","0.19614"
"128.70000","8.57824","0.19500"
"128.80000","8.58491","0.19404"
"128.90000","8.59204","0.19256"
"129.00000","8.59884","0.19153"
"129.10000","8.60522","0.18977"
"129.20000","8.61202","0.18879"
"129.30000","8.61863","0.18732"
"129.40000","8.62539","0.18622"
"129.50000","8.63187","0.18501"
"129.60000","8.63848","0.18434"
"129.70000","8.64517","0.18334"
"129.80000","8.65174","0.18260"
"129.90000","8.65858","0.18231"
"130.00000","8.66566","0.18158"
"130.10000","8.67232","0.18027"
"130.20000","8.67879","0.17950"
"130.30000","8.68486","0.17831"
"130.40000","8.69163","0.17784"
"130.50000","8.69894","0.17780"
"130.60000","8.70545","0.17695"
"130.70000","8.71190","0.17616"
"130.80000","8.71838","0.17552"
"130.90000","8.72555","0.17504"
"131.00000","8.73231","0.17408"
"131.10000","8.73855","0.17374"
"131.20000","8.74504","0.17317"
"131.30000","8.75170","0.17268"
"131.40000","8.75877","0.17214"
"131.50000","8.76534","0.17159"
"131.60000","8.77197","0.17009"
"131.70000","8.77880","0.16950"
"131.80000","8.78532","0.16827"
"131.90000","8.79199","0.16678"
"132.00000","8.79844","0.16603"
"132.10000","8.80526","0.16500"
"132.20000","8.81194","0.16401"
"132.30000","8.81847","0.16375"
"132.40000","8.82524","0.16324"
"132.50000","8.83243","0.16183"
"132.60000","8.83895","0.16135"
"132.70000","8.84519","0.16035"
"132.80000","8.85149","0.16000"
"132.90000","8.85859","0.15957"
"133.00000","8.86569","0.15906"
"133.10000","8.87217","0.15851"
"133.20000","8.87851","0.15742"
"133.30000","8.88523","0.15730"
"133.40000","8.89223","0.15669"
"133.50000","8.89878","0.15575"
"133.60000","8.90508","0.15492"
"133.70000","8.91171","0.15447"
"133.80000","8.91845","0.15404"
"133.90000","8.92528","0.15355"
"134.00000","8.93201","0.15369"
"134.10000","8.93880","0.15327"
"134.20000","8.94538","0.15214"
"134.30000","8.95191","0.15186"
"134.40000","8.95846","0.15168"
"134.50000","8.96514","0.15126"
"134.60000","8.97202","0.15052"
"134.70000","8.97871","0.14966"
"134.80000","8.98500","0.14954"
"134.82700","8.98683","0.14952"