File: 20.12.09/1Layer_15.is_flex_RawData/Specimen_RawData_1.csv
Specimen properties : Thickness,"3.60000",mm
Specimen properties : Width,"9.50000",mm
Specimen properties : Support span,"57.60000",mm

Time,Extension,Load
(s),(mm),(kgf)
"0.00000","0.00000","-0.00409"
"0.10000","0.00145","-0.00280"
"0.20000","0.01155","0.00414"
"0.30000","0.01836","0.00723"
"0.40000","0.02465","0.01144"
"0.50000","0.03143","0.01495"
"0.60000","0.03857","0.01888"
"0.70000","0.04538","0.02244"
"0.80000","0.05201","0.02536"
"0.90000","0.05832","0.02884"
"1.00000","0.06550","0.03160"
"1.10000","0.07238","0.03519"
"1.20000","0.07877","0.03780"
"1.30000","0.08484","0.04095"
"1.40000","0.09143","0.04373"
"1.50000","0.09859","0.04710"
"1.60000","0.10545","0.04984"
"1.70000","0.11193","0.05281"
"1.80000","0.11862","0.05556"
"1.90000","0.12516","0.05871"
"2.00000","0.13193","0.06163"
"2.10000","0.13847","0.06443"
"2.20000","0.14513","0.06705"
"2.30000","0.15170","0.06920"
"2.40000","0.15841","0.07204"
"2.50000","0.16524","0.07512"
"2.60000","0.17212","0.07754"
"2.70000","0.17894","0.08036"
"2.80000","0.18535","0.08271"
"2.90000","0.19156","0.08544"
"3.00000","0.19825","0.08799"
"3.10000","0.20552","0.09077"
"3.20000","0.21221","0.09294"
"3.30000","0.21852","0.09514"
"3.40000","0.22506","0.09770"
"3.50000","0.23224","0.10038"
"3.60000","0.23898","0.10229"
"3.70000","0.24527","0.10455"
"3.80000","0.25153","0.10675"
"3.90000","0.25837","0.10908"
"4.00000","0.26544","0.11161"
"4.10000","0.27211","0.11342"
"4.20000","0.27871","0.11565"
"4.30000","0.28537","0.11780"
"4.40000","0.29194","0.11974"
"4.50000","0.29869","0.12215"
"4.60000","0.30514","0.12396"
"4.70000","0.31204","0.12624"
"4.80000","0.31852","0.12773"
"4.90000","0.32511","0.13005"
"5.00000","0.33191","0.13177"
"5.10000","0.33912","0.13432"
"5.20000","0.34578","0.13594"
"5.30000","0.35183","0.13731"
"5.40000","0.35815","0.13922"
"5.50000","0.36524","0.14108"
"5.60000","0.37235","0.14332"
"5.70000","0.37888","0.14503"
"5.80000","0.38503","0.14604"
"5.90000","0.39182","0.14783"
"6.00000","0.39893","0.15015"
"6.10000","0.40550","0.15118"
"6.20000","0.41192","0.15306"
"6.30000","0.41824","0.15422"
"6.40000","0.42509","0.15610"
"6.50000","0.43200","0.15785"
"6.60000","0.43871","0.15907"
"6.70000","0.44550","0.16084"
"6.80000","0.45191","0.16172"
"6.90000","0.45853","0.16366"
"7.00000","0.46510","0.16497"
"7.10000","0.47193","0.16620"
"7.20000","0.47888","0.16805"
"7.30000","0.48516","0.16889"
"7.40000","0.49161","0.17051"
"7.50000","0.49866","0.17170"
"7.60000","0.50591","0.17348"
"7.70000","0.51228","0.17411"
"7.80000","0.51827","0.17536"
"7.90000","0.52475","0.17660"
"8.00000","0.53195","0.17788"
"8.10000","0.53894","0.17948"
"8.20000","0.54537","0.18053"
"8.30000","0.55178","0.18179"
"8.40000","0.55860","0.18185"
"8.50000","0.56553","0.18446"
"8.60000","0.57210","0.18485"
"8.70000","0.57851","0.18612"
"8.80000","0.58507","0.18718"
"8.90000","0.59192","0.18871"
"9.00000","0.59860","0.18965"
"9.10000","0.60546","0.19123"
"9.20000","0.61238","0.19168"
"9.30000","0.61866","0.19269"
"9.40000","0.62495","0.19390"
"9.50000","0.63164","0.19511"
"9.60000","0.63877","0.19613"
"9.70000","0.64560","0.19772"
"9.80000","0.65187","0.19827"
"9.90000","0.65835","0.19915"
"10.00000","0.66555","0.20058"
"10.10000","0.67255","0.20174"
"10.20000","0.67873","0.20213"
"10.30000","0.68493","0.20327"
"10.40000","0.69156","0.20441"
"10.50000","0.69867","0.20552"
"10.60000","0.70565","0.20674"
"10.70000","0.71197","0.20750"
"10.80000","0.71856","0.20796"
"10.90000","0.72517","0.20931"
"11.00000","0.73204","0.21069"
"11.10000","0.73864","0.21151"
"11.20000","0.74521","0.21231"
"11.30000","0.75183","0.21276"
"11.40000","0.75844","0.21396"
"11.50000","0.76515","0.21530"
"11.60000","0.77225","0.21620"
"11.70000","0.77893","0.21698"
"11.80000","0.78538","0.21810"
"11.90000","0.79161","0.21885"
"12.00000","0.79827","0.21979"
"12.10000","0.80556","0.22118"
"12.20000","0.81213","0.22174"
"12.30000","0.81863","0.22246"
"12.40000","0.82505","0.22349"
"12.50000","0.83212","0.22459"
"12.60000","0.83911","0.22576"
"12.70000","0.84533","0.22637"
"12.80000","0.85151","0.22714"
"12.90000","0.85833","0.22799"
"13.00000","0.86545","0.22911"
"13.10000","0.87211","0.22992"
"13.20000","0.87872","0.23111"
"13.30000","0.88541","0.23180"
"13.40000","0.89194","0.23259"
"13.50000","0.89856","0.23386"
"13.60000","0.90512","0.23417"
"13.70000","0.91201","0.23544"
"13.80000","0.91858","0.23604"
"13.90000","0.92508","0.23712"
"14.00000","0.93187","0.23799"
"14.10000","0.93909","0.23893"
"14.20000","0.94574","0.23967"
"14.30000","0.95190","0.24039"
"14.40000","0.95816","0.24087"
"14.50000","0.96520","0.24244"
"14.60000","0.97226","0.24327"
"14.70000","0.97882","0.24407"
"14.80000","0.98520","0.24471"
"14.90000","0.99181","0.24527"
"15.00000","0.99881","0.24663"
"15.10000","1.00555","0.24727"
"15.20000","1.01183","0.24765"
"15.30000","1.01830","0.24894"
"15.40000","1.02509","0.25007"
"15.50000","1.03192","0.25043"
"15.60000","1.03865","0.25142"
"15.70000","1.04561","0.25236"
"15.80000","1.05197","0.25288"
"15.90000","1.05850","0.25416"
"16.00000","1.06515","0.25472"
"16.10000","1.07188","0.25576"
"16.20000","1.07879","0.25622"
"16.30000","1.08529","0.25676"
"16.40000","1.09156","0.25774"
"16.50000","1.09865","0.25914"
"16.60000","1.10582","0.26020"
"16.70000","1.11228","0.26043"
"16.80000","1.11834","0.26113"
"16.90000","1.12473","0.26182"
"17.00000","1.13204","0.26290"
"17.10000","1.13890","0.26375"
"17.20000","1.14542","0.26461"
"17.30000","1.15178","0.26517"
"17.40000","1.15857","0.26593"
"17.50000","1.16559","0.26685"
"17.60000","1.17198","0.26743"
"17.70000","1.17843","0.26829"
"17.80000","1.18511","0.26886"
"17.90000","1.19184","0.27001"
"18.00000","1.19860","0.27088"
"18.10000","1.20542","0.27121"
"18.20000","1.21253","0.27235"
"18.30000","1.21868","0.27316"
"18.40000","1.22501","0.27350"
"18.50000","1.23170","0.27453"
"18.60000","1.23877","0.27523"
"18.70000","1.24554","0.27586"
"18.80000","1.25194","0.27619"
"18.90000","1.25830","0.27714"
"19.00000","1.26561","0.27811"
"19.10000","1.27250","0.27928"
"19.20000","1.27883","0.27921"
"19.30000","1.28491","0.28030"
"19.40000","1.29152","0.28120"
"19.50000","1.29867","0.28208"
"19.60000","1.30551","0.28314"
"19.70000","1.31199","0.28346"
"19.80000","1.31866","0.28377"
"19.90000","1.32520","0.28419"
"20.00000","1.33205","0.28496"
"20.10000","1.33870","0.28649"
"20.20000","1.34537","0.28715"
"20.30000","1.35184","0.28761"
"20.40000","1.35842","0.28843"
"20.50000","1.36525","0.28935"
"20.60000","1.37226","0.28974"
"20.70000","1.37893","0.29066"
"20.80000","1.38536","0.29092"
"20.90000","1.39157","0.29168"
"21.00000","1.39834","0.29247"
"21.10000","1.40552","0.29358"
"21.20000","1.41215","0.29431"
"21.30000","1.41844","0.29447"
"21.40000","1.42508","0.29526"
"21.50000","1.43217","0.29642"
"21.60000","1.43906","0.29681"
"21.70000","1.44528","0.29759"
"21.80000","1.45147","0.29759"
"21.90000","1.45837","0.29864"
"22.00000","1.46537","0.29958"
"22.10000","1.47213","0.30027"
"22.20000","1.47869","0.30080"
"22.30000","1.48534","0.30158"
"22.40000","1.49193","0.30252"
"22.50000","1.49863","0.30263"
"22.60000","1.50516","0.30314"
"22.70000","1.51209","0.30428"
"22.80000","1.51860","0.30451"
"22.90000","1.52513","0.30519"
"23.00000","1.53191","0.30601"
"23.10000","1.53906","0.30655"
"23.20000","1.54569","0.30766"
"23.30000","1.55170","0.30776"
"23.40000","1.55819","0.30809"
"23.50000","1.56528","0.30912"
"23.60000","1.57237","0.31009"
"23.70000","1.57885","0.31041"
"23.80000","1.58505","0.31114"
"23.90000","1.59181","0.31156"
"24.00000","1.59880","0.31220"
"24.10000","1.60553","0.31269"
"24.20000","1.61192","0.31336"
"24.30000","1.61822","0.31376"
"24.40000","1.62511","0.31488"
"24.50000","1.63202","0.31558"
"24.60000","1.63876","0.31624"
"24.70000","1.64556","0.31677"
"24.80000","1.65189","0.31713"
"24.90000","1.65851","0.31789"
"25.00000","1.66507","0.31796"
"25.10000","1.67192","0.31926"
"25.20000","1.67890","0.31958"
"25.30000","1.68515","0.32009"
"25.40000","1.69166","0.32037"
"25.50000","1.69866","0.32111"
"25.60000","1.70593","0.32231"
"25.70000","1.71229","0.32256"
"25.80000","1.71835","0.32273"
"25.90000","1.72476","0.32315"
"26.00000","1.73199","0.32443"
"26.10000","1.73893","0.32503"
"26.20000","1.74542","0.32565"
"26.30000","1.75180","0.32607"
"26.40000","1.75854","0.32642"
"26.50000","1.76552","0.32747"
"26.60000","1.77206","0.32805"
"26.70000","1.77853","0.32822"
"26.80000","1.78510","0.32895"
"26.90000","1.79183","0.32952"
"27.00000","1.79872","0.33031"
"27.10000","1.80545","0.33054"
"27.20000","1.81238","0.33136"
"27.30000","1.81872","0.33181"
"27.40000","1.82501","0.33231"
"27.50000","1.83166","0.33273"
"27.60000","1.83878","0.33346"
"27.70000","1.84560","0.33407"
"27.80000","1.85183","0.33417"
"27.90000","1.85834","0.33504"
"28.00000","1.86553","0.33601"
"28.10000","1.87251","0.33660"
"28.20000","1.87880","0.33715"
"28.30000","1.88489","0.33717"
"28.40000","1.89154","0.33795"
"28.50000","1.89865","0.33893"
"28.60000","1.90562","0.33917"
"28.70000","1.91203","0.33995"
"28.80000","1.91853","0.34007"
"28.90000","1.92520","0.34071"
"29.00000","1.93207","0.34165"
"29.10000","1.93863","0.34171"
"29.20000","1.94518","0.34288"
"29.30000","1.95175","0.34296"
"29.40000","1.95846","0.34335"
"29.50000","1.96524","0.34403"
"29.60000","1.97219","0.34497"
"29.70000","1.97898","0.34576"
"29.80000","1.98529","0.34583"
"29.90000","1.99162","0.34664"
"30.00000","1.99826","0.34742"
"30.10000","2.00561","0.34755"
"30.20000","2.01224","0.34841"
"30.30000","2.01847","0.34848"
"30.40000","2.02509","0.34950"
"30.50000","2.03219","0.34982"
"30.60000","2.03908","0.35034"
"30.70000","2.04532","0.35121"
"30.80000","2.05143","0.35149"
"30.90000","2.05836","0.35207"
"31.00000","2.06543","0.35269"
"31.10000","2.07207","0.35342"
"31.20000","2.07872","0.35377"
"31.30000","2.08535","0.35415"
"31.40000","2.09192","0.35473"
"31.50000","2.09855","0.35538"
"31.60000","2.10510","0.35543"
"31.70000","2.11213","0.35668"
"31.80000","2.11861","0.35661"
"31.90000","2.12506","0.35690"
"32.00000","2.13187","0.35798"
"32.10000","2.13915","0.35849"
"32.20000","2.14572","0.35875"
"32.30000","2.15182","0.35864"
"32.40000","2.15817","0.35974"
"32.50000","2.16526","0.36035"
"32.60000","2.17241","0.36094"
"32.70000","2.17881","0.36126"
"32.80000","2.18504","0.36169"
"32.90000","2.19177","0.36216"
"33.00000","2.19891","0.36266"
"33.10000","2.20555","0.36296"
"33.20000","2.21187","0.36357"
"33.30000","2.21827","0.36386"
"33.40000","2.22500","0.36432"
"33.50000","2.23196","0.36484"
"33.60000","2.23876","0.36578"
"33.70000","2.24556","0.36595"
"33.80000","2.25194","0.36620"
"33.90000","2.25845","0.36664"
"34.00000","2.26511","0.36704"
"34.10000","2.27189","0.36760"
"34.20000","2.27877","0.36838"
"34.30000","2.28522","0.36847"
"34.40000","2.29157","0.36901"
"34.50000","2.29868","0.36969"
"34.60000","2.30591","0.37058"
"34.70000","2.31223","0.37055"
"34.80000","2.31840","0.37075"
"34.90000","2.32478","0.37107"
"35.00000","2.33197","0.37185"
"35.10000","2.33890","0.37263"
"35.20000","2.34538","0.37245"
"35.30000","2.35187","0.37300"
"35.40000","2.35856","0.37384"
"35.50000","2.36555","0.37461"
"35.60000","2.37200","0.37455"
"35.70000","2.37842","0.37481"
"35.80000","2.38519","0.37531"
"35.90000","2.39186","0.37595"
"36.00000","2.39862","0.37593"
"36.10000","2.40540","0.37675"
"36.20000","2.41234","0.37710"
"36.30000","2.41882","0.37727"
"36.40000","2.42502","0.37795"
"36.50000","2.43173","0.37776"
"36.60000","2.43870","0.37884"
"36.70000","2.44542","0.37912"
"36.80000","2.45206","0.37923"
"36.90000","2.45837","0.37952"
"37.00000","2.46556","0.38066"
"37.10000","2.47238","0.38077"
"37.20000","2.47882","0.38099"
"37.30000","2.48503","0.38107"
"37.40000","2.49157","0.38185"
"37.50000","2.49868","0.38233"
"37.60000","2.50553","0.38296"
"37.70000","2.51190","0.38272"
"37.80000","2.51869","0.38317"
"37.90000","2.52525","0.38409"
"38.00000","2.53201","0.38413"
"38.10000","2.53861","0.38486"
"38.20000","2.54515","0.38463"
"38.30000","2.55188","0.38521"
"38.40000","2.55848","0.38586"
"38.50000","2.56517","0.38627"
"38.60000","2.57213","0.38709"
"38.70000","2.57895","0.38719"
"38.80000","2.58546","0.38708"
"38.90000","2.59165","0.38754"
"39.00000","2.59832","0.38802"
"39.10000","2.60541","0.38848"
"39.20000","2.61206","0.38908"
"39.30000","2.61873","0.38921"
"39.40000","2.62517","0.38968"
"39.50000","2.63219","0.38994"
"39.60000","2.63896","0.39044"
"39.70000","2.64523","0.39078"
"39.80000","2.65160","0.39090"
"39.90000","2.65840","0.39144"
"40.00000","2.66541","0.39196"
"40.10000","2.67208","0.39214"
"40.20000","2.67856","0.39229"
"40.30000","2.68544","0.39314"
"40.40000","2.69204","0.39367"
"40.50000","2.69861","0.39342"
"40.60000","2.70510","0.39391"
"40.70000","2.71194","0.39460"
"40.80000","2.71868","0.39499"
"40.90000","2.72524","0.39503"
"41.00000","2.73193","0.39586"
"41.10000","2.73901","0.39594"
"41.20000","2.74558","0.39622"
"41.30000","2.75192","0.39658"
"41.40000","2.75823","0.39750"
"41.50000","2.76520","0.39741"
"41.60000","2.77229","0.39773"
"41.70000","2.77869","0.39776"
"41.80000","2.78513","0.39819"
"41.90000","2.79191","0.39871"
"42.00000","2.79891","0.39903"
"42.10000","2.80539","0.39970"
"42.20000","2.81170","0.39975"
"42.30000","2.81841","0.40030"
"42.40000","2.82524","0.40046"
"42.50000","2.83194","0.40086"
"42.60000","2.83860","0.40089"
"42.70000","2.84543","0.40165"
"42.80000","2.85209","0.40199"
"42.90000","2.85864","0.40202"
"43.00000","2.86508","0.40225"
"43.10000","2.87175","0.40288"
"43.20000","2.87864","0.40331"
"43.30000","2.88533","0.40349"
"43.40000","2.89170","0.40382"
"43.50000","2.89844","0.40401"
"43.60000","2.90579","0.40463"
"43.70000","2.91217","0.40475"
"43.80000","2.91838","0.40511"
"43.90000","2.92484","0.40530"
"44.00000","2.93205","0.40562"
"44.10000","2.93885","0.40628"
"44.20000","2.94520","0.40634"
"44.30000","2.95202","0.40687"
"44.40000","2.95870","0.40686"
"44.50000","2.96556","0.40760"
"44.60000","2.97191","0.40761"
"44.70000","2.97826","0.40778"
"44.80000","2.98531","0.40833"
"44.90000","2.99216","0.40892"
"45.00000","2.99868","0.40893"
"45.10000","3.00538","0.40942"
"45.20000","3.01224","0.40955"
"45.30000","3.01890","0.40983"
"45.40000","3.02512","0.41040"
"45.50000","3.03168","0.41053"
"45.60000","3.03857","0.41089"
"45.70000","3.04535","0.41115"
"45.80000","3.05211","0.41148"
"45.90000","3.05863","0.41196"
"46.00000","3.06558","0.41228"
"46.10000","3.07236","0.41267"
"46.20000","3.07871","0.41236"
"46.30000","3.08507","0.41273"
"46.40000","3.09162","0.41320"
"46.50000","3.09865","0.41344"
"46.60000","3.10548","0.41387"
"46.70000","3.11192","0.41390"
"46.80000","3.11873","0.41416"
"46.90000","3.12536","0.41479"
"47.00000","3.13200","0.41474"
"47.10000","3.13849","0.41524"
"47.20000","3.14506","0.41528"
"47.30000","3.15195","0.41576"
"47.40000","3.15859","0.41595"
"47.50000","3.16516","0.41630"
"47.60000","3.17207","0.41656"
"47.70000","3.17881","0.41738"
"47.80000","3.18556","0.41712"
"47.90000","3.19169","0.41694"
"48.00000","3.19822","0.41765"
"48.10000","3.20546","0.41818"
"48.20000","3.21204","0.41836"
"48.30000","3.21871","0.41850"
"48.40000","3.22528","0.41843"
"48.50000","3.23215","0.41873"
"48.60000","3.23894","0.41927"
"48.70000","3.24522","0.41963"
"48.80000","3.25159","0.41955"
"48.90000","3.25846","0.41997"
"49.00000","3.26537","0.42061"
"49.10000","3.27204","0.42042"
"49.20000","3.27864","0.42090"
"49.30000","3.28552","0.42093"
"49.40000","3.29210","0.42122"
"49.50000","3.29859","0.42145"
"49.60000","3.30504","0.42199"
"49.70000","3.31193","0.42208"
"49.80000","3.31861","0.42262"
"49.90000","3.32525","0.42238"
"50.00000","3.33190","0.42270"
"50.10000","3.33898","0.42314"
"50.20000","3.34561","0.42334"
"50.30000","3.35192","0.42371"
"50.40000","3.35828","0.42338"
"50.50000","3.36523","0.42392"
"50.60000","3.37228","0.42464"
"50.70000","3.37878","0.42424"
"50.80000","3.38511","0.42475"
"50.90000","3.39193","0.42496"
"51.00000","3.39886","0.42525"
"51.10000","3.40536","0.42562"
"51.20000","3.41178","0.42534"
"51.30000","3.41839","0.42596"
"51.40000","3.42518","0.42607"
"51.50000","3.43195","0.42686"
"51.60000","3.43855","0.42667"
"51.70000","3.44539","0.42756"
"51.80000","3.45217","0.42742"
"51.90000","3.45862","0.42785"
"52.00000","3.46503","0.42759"
"52.10000","3.47176","0.42776"
"52.20000","3.47872","0.42860"
"52.30000","3.48532","0.42838"
"52.40000","3.49171","0.42834"
"52.50000","3.49872","0.42902"
"52.60000","3.50572","0.42955"
"52.70000","3.51215","0.42935"
"52.80000","3.51844","0.42960"
"52.90000","3.52482","0.42954"
"53.00000","3.53204","0.43006"
"53.10000","3.53880","0.43002"
"53.20000","3.54531","0.43015"
"53.30000","3.55198","0.43038"
"53.40000","3.55863","0.43099"
"53.50000","3.56562","0.43161"
"53.60000","3.57202","0.43129"
"53.70000","3.57836","0.43155"
"53.80000","3.58520","0.43183"
"53.90000","3.59191","0.43194"
"54.00000","3.59864","0.43240"
"54.10000","3.60526","0.43257"
"54.20000","3.61226","0.43316"
"54.30000","3.61887","0.43330"
"54.40000","3.62514","0.43305"
"54.50000","3.63167","0.43278"
"54.60000","3.63863","0.43407"
"54.70000","3.64544","0.43389"
"54.80000","3.65199","0.43403"
"54.90000","3.65851","0.43452"
"55.00000","3.66556","0.43481"
"55.10000","3.67240","0.43491"
"55.20000","3.67881","0.43496"
"55.30000","3.68498","0.43520"
"55.40000","3.69156","0.43530"
"55.50000","3.69863","0.43578"
"55.60000","3.70550","0.43593"
"55.70000","3.71201","0.43608"
"55.80000","3.71863","0.43620"
"55.90000","3.72524","0.43658"
"56.00000","3.73202","0.43701"
"56.10000","3.73849","0.43673"
"56.20000","3.74515","0.43717"
"56.30000","3.75183","0.43709"
"56.40000","3.75846","0.43745"
"56.50000","3.76524","0.43804"
"56.60000","3.77217","0.43810"
"56.70000","3.77896","0.43847"
"56.80000","3.78536","0.43847"
"56.90000","3.79159","0.43834"
"57.00000","3.79820","0.43903"
"57.10000","3.80559","0.43935"
"57.20000","3.81222","0.43965"
"57.30000","3.81849","0.43920"
"57.40000","3.82501","0.43984"
"57.50000","3.83228","0.43983"
"57.60000","3.83909","0.44030"
"57.70000","3.84527","0.43999"
"57.80000","3.85153","0.44007"
"57.90000","3.85835","0.44039"
"58.00000","3.86555","0.44080"
"58.10000","3.87209","0.44113"
"58.20000","3.87865","0.44079"
"58.30000","3.88533","0.44127"
"58.40000","3.89195","0.44125"
"58.50000","3.89868","0.44215"
"58.60000","3.90525","0.44211"
"58.70000","3.91199","0.44193"
"58.80000","3.91849","0.44219"
"58.90000","3.92506","0.44203"
"59.00000","3.93190","0.44259"
"59.10000","3.93912","0.44303"
"59.20000","3.94575","0.44281"
"59.30000","3.95174","0.44292"
"59.40000","3.95816","0.44284"
"59.50000","3.96525","0.44342"
"59.60000","3.97233","0.44412"
"59.70000","3.97887","0.44381"
"59.80000","3.98509","0.44348"
"59.90000","3.99190","0.44409"
"60.00000","3.99888","0.44368"
"60.10000","4.00559","0.44474"
"60.20000","4.01183","0.44412"
"60.30000","4.01823","0.44419"
"60.40000","4.02510","0.44457"
"60.50000","4.03195","0.44557"
"60.60000","4.03870","0.44510"
"60.70000","4.04555","0.44514"
"60.80000","4.05194","0.44562"
"60.90000","4.05851","0.44570"
"61.00000","4.06502","0.44601"
"61.10000","4.07184","0.44590"
"61.20000","4.07892","0.44643"
"61.30000","4.08525","0.44615"
"61.40000","4.09159","0.44638"
"61.50000","4.09861","0.44684"
"61.60000","4.10590","0.44756"
"61.70000","4.11227","0.44687"
"61.80000","4.11834","0.44661"
"61.90000","4.12469","0.44728"
"62.00000","4.13198","0.44747"
"62.10000","4.13895","0.44765"
"62.20000","4.14541","0.44786"
"62.30000","4.15185","0.44798"
"62.40000","4.15856","0.44804"
"62.50000","4.16558","0.44847"
"62.60000","4.17200","0.44850"
"62.70000","4.17839","0.44839"
"62.80000","4.18517","0.44878"
"62.90000","4.19184","0.44876"
"63.00000","4.19863","0.44953"
"63.10000","4.20543","0.44962"
"63.20000","4.21238","0.44995"
"63.30000","4.21876","0.45011"
"63.40000","4.22501","0.44999"
"63.50000","4.23166","0.45036"
"63.60000","4.23879","0.45047"
"63.70000","4.24547","0.45043"
"63.80000","4.25193","0.45031"
"63.90000","4.25837","0.45035"
"64.00000","4.26560","0.45086"
"64.10000","4.27246","0.45142"
"64.20000","4.27878","0.45077"
"64.30000","4.28499","0.45116"
"64.40000","4.29157","0.45105"
"64.50000","4.29875","0.45179"
"64.60000","4.30558","0.45186"
"64.70000","4.31193","0.45155"
"64.80000","4.31855","0.45188"
"64.90000","4.32517","0.45168"
"65.00000","4.33206","0.45246"
"65.10000","4.33863","0.45218"
"65.20000","4.34522","0.45206"
"65.30000","4.35183","0.45198"
"65.40000","4.35832","0.45216"
"65.50000","4.36517","0.45273"
"65.60000","4.37228","0.45264"
"65.70000","4.37886","0.45253"
"65.80000","4.38541","0.45264"
"65.90000","4.39159","0.45239"
"66.00000","4.39825","0.45261"
"66.10000","4.40560","0.45255"
"66.20000","4.41218","0.45236"
"66.30000","4.41857","0.45241"
"66.40000","4.42511","0.45258"
"66.50000","4.43218","0.45280"
"66.60000","4.43898","0.45280"
"66.70000","4.44519","0.45288"
"66.80000","4.45160","0.45304"
"66.90000","4.45837","0.45360"
"67.00000","4.46553","0.45387"
"67.10000","4.47210","0.45360"
"67.20000","4.47863","0.45418"
"67.30000","4.48547","0.45404"
"67.40000","4.49199","0.45413"
"67.50000","4.49864","0.45464"
"67.60000","4.50514","0.45472"
"67.70000","4.51193","0.45460"
"67.80000","4.51861","0.45429"
"67.90000","4.52519","0.45460"
"68.00000","4.53189","0.45465"
"68.10000","4.53904","0.45488"
"68.20000","4.54567","0.45498"
"68.30000","4.55185","0.45483"
"68.40000","4.55822","0.45459"
"68.50000","4.56526","0.45548"
"68.60000","4.57227","0.45545"
"68.70000","4.57874","0.45468"
"68.80000","4.58513","0.45516"
"68.90000","4.59191","0.45489"
"69.00000","4.59887","0.45563"
"69.10000","4.60547","0.45524"
"69.20000","4.61173","0.45559"
"69.30000","4.61839","0.45513"
"69.40000","4.62520","0.45557"
"69.50000","4.63201","0.45550"
"69.60000","4.63857","0.45535"
"69.70000","4.64547","0.45604"
"69.80000","4.65198","0.45552"
"69.90000","4.65852","0.45554"
"70.00000","4.66515","0.45590"
"70.10000","4.67184","0.45582"
"70.20000","4.67875","0.45580"
"70.30000","4.68521","0.45606"
"70.40000","4.69169","0.45552"
"70.50000","4.69867","0.45644"
"70.60000","4.70584","0.45629"
"70.70000","4.71217","0.45639"
"70.80000","4.71837","0.45624"
"70.90000","4.72479","0.45598"
"71.00000","4.73206","0.45644"
"71.10000","4.73894","0.45684"
"71.20000","4.74533","0.45657"
"71.30000","4.75186","0.45638"
"71.40000","4.75864","0.45673"
"71.50000","4.76559","0.45699"
"71.60000","4.77198","0.45626"
"71.70000","4.77832","0.45603"
"71.80000","4.78512","0.45658"
"71.90000","4.79193","0.45626"
"72.00000","4.79863","0.45645"
"72.10000","4.80539","0.45659"
"72.20000","4.81241","0.45667"
"72.30000","4.81884","0.45627"
"72.40000","4.82503","0.45650"
"72.50000","4.83162","0.45640"
"72.60000","4.83870","0.45687"
"72.70000","4.84545","0.45636"
"72.80000","4.85200","0.45674"
"72.90000","4.85840","0.45679"
"73.00000","4.86560","0.45714"
"73.10000","4.87246","0.45725"
"73.20000","4.87875","0.45707"
"73.30000","4.88497","0.45684"
"73.40000","4.89158","0.45699"
"73.50000","4.89875","0.45754"
"73.60000","4.90552","0.45717"
"73.70000","4.91202","0.45720"
"73.80000","4.91859","0.45753"
"73.90000","4.92519","0.45715"
"74.00000","4.93210","0.45732"
"74.10000","4.93850","0.45726"
"74.20000","4.94515","0.45736"
"74.30000","4.95184","0.45766"
"74.40000","4.95841","0.45743"
"74.50000","4.96522","0.45739"
"74.60000","4.97219","0.45760"
"74.70000","4.97890","0.45730"
"74.80000","4.98543","0.45748"
"74.90000","4.99163","0.45740"
"75.00000","4.99821","0.45726"
"75.10000","5.00565","0.45764"
"75.20000","5.01212","0.45742"
"75.30000","5.01855","0.45700"
"75.40000","5.02505","0.45710"
"75.50000","5.03226","0.45716"
"75.60000","5.03907","0.45742"
"75.70000","5.04526","0.45698"
"75.80000","5.05156","0.45618"
"75.90000","5.05837","0.45647"
"76.00000","5.06540","0.45744"
"76.10000","5.07211","0.45710"
"76.20000","5.07866","0.45694"
"76.30000","5.08536","0.45653"
"76.40000","5.09193","0.45687"
"76.50000","5.09863","0.45637"
"76.60000","5.10517","0.45681"
"76.70000","5.11206","0.45639"
"76.80000","5.11864","0.45641"
"76.90000","5.12511","0.45653"
"77.00000","5.13185","0.45662"
"77.10000","5.13908","0.45668"
"77.20000","5.14574","0.45659"
"77.30000","5.15183","0.45625"
"77.40000","5.15818","0.45572"
"77.50000","5.16527","0.45648"
"77.60000","5.17232","0.45634"
"77.70000","5.17881","0.45587"
"77.80000","5.18512","0.45529"
"77.90000","5.19182","0.45597"
"78.00000","5.19886","0.45566"
"78.10000","5.20545","0.45565"
"78.20000","5.21184","0.45525"
"78.30000","5.21833","0.45537"
"78.40000","5.22513","0.45529"
"78.50000","5.23194","0.45501"
"78.60000","5.23863","0.45519"
"78.70000","5.24565","0.45516"
"78.80000","5.25206","0.45474"
"78.90000","5.25847","0.45499"
"79.00000","5.26510","0.45506"
"79.10000","5.27189","0.45491"
"79.20000","5.27883","0.45522"
"79.30000","5.28523","0.45480"
"79.40000","5.29157","0.45471"
"79.50000","5.29861","0.45480"
"79.60000","5.30585","0.45487"
"79.70000","5.31227","0.45454"
"79.80000","5.31840","0.45424"
"79.90000","5.32479","0.45418"
"80.00000","5.33199","0.45439"
"80.10000","5.33891","0.45427"
"80.20000","5.34539","0.45421"
"80.30000","5.35190","0.45383"
"80.40000","5.35853","0.45393"
"80.50000","5.36552","0.45400"
"80.60000","5.37202","0.45405"
"80.70000","5.37847","0.45324"
"80.80000","5.38512","0.45301"
"80.90000","5.39185","0.45356"
"81.00000","5.39867","0.45357"
"81.10000","5.40539","0.45301"
"81.20000","5.41235","0.45276"
"81.30000","5.41881","0.45248"
"81.40000","5.42499","0.45219"
"81.50000","5.43170","0.45214"
"81.60000","5.43879","0.45230"
"81.70000","5.44554","0.45220"
"81.80000","5.45190","0.45175"
"81.90000","5.45836","0.45198"
"82.00000","5.46558","0.45129"
"82.10000","5.47251","0.45127"
"82.20000","5.47880","0.45090"
"82.30000","5.48495","0.44999"
"82.40000","5.49152","0.45001"
"82.50000","5.49877","0.44990"
"82.60000","5.50549","0.45005"
"82.70000","5.51188","0.44905"
"82.80000","5.51859","0.44932"
"82.90000","5.52518","0.44898"
"83.00000","5.53198","0.44911"
"83.10000","5.53855","0.44837"
"83.20000","5.54521","0.44904"
"83.30000","5.55182","0.44859"
"83.40000","5.55838","0.44798"
"83.50000","5.56524","0.44802"
"83.60000","5.57224","0.44808"
"83.70000","5.57898","0.44798"
"83.80000","5.58540","0.44743"
"83.90000","5.59154","0.44660"
"84.00000","5.59825","0.44695"
"84.10000","5.60556","0.44689"
"84.20000","5.61211","0.44638"
"84.30000","5.61861","0.44622"
"84.40000","5.62512","0.44569"
"84.50000","5.63216","0.44566"
"84.60000","5.63908","0.44499"
"84.70000","5.64530","0.44479"
"84.80000","5.65155","0.44410"
"84.90000","5.65834","0.44390"
"85.00000","5.66543","0.44383"
"85.10000","5.67215","0.44388"
"85.20000","5.67869","0.44328"
"85.30000","5.68529","0.44317"
"85.40000","5.69192","0.44297"
"85.50000","5.69862","0.44280"
"85.60000","5.70517","0.44246"
"85.70000","5.71204","0.44224"
"85.80000","5.71862","0.44205"
"85.90000","5.72505","0.44166"
"86.00000","5.73190","0.44156"
"86.10000","5.73909","0.44093"
"86.20000","5.74578","0.44081"
"86.30000","5.75183","0.44017"
"86.40000","5.75810","0.43942"
"86.50000","5.76524","0.43973"
"86.60000","5.77229","0.43920"
"86.70000","5.77889","0.43865"
"86.80000","5.78508","0.43813"
"86.90000","5.79186","0.43755"
"87.00000","5.79894","0.43791"
"87.10000","5.80547","0.43681"
"87.20000","5.81189","0.43613"
"87.30000","5.81812","0.43570"
"87.40000","5.82504","0.43578"
"87.50000","5.83194","0.43544"
"87.60000","5.83868","0.43507"
"87.70000","5.84560","0.43439"
"87.80000","5.85203","0.43361"
"87.90000","5.85849","0.43343"
"88.00000","5.86501","0.43226"
"88.10000","5.87178","0.43190"
"88.20000","5.87888","0.43138"
"88.30000","5.88524","0.43051"
"88.40000","5.89160","0.43000"
"88.50000","5.89870","0.42939"
"88.60000","5.90590","0.42929"
"88.70000","5.91230","0.42830"
"88.80000","5.91831","0.42717"
"88.90000","5.92468","0.42652"
"89.00000","5.93199","0.42622"
"89.10000","5.93902","0.42578"
"89.20000","5.94539","0.42442"
"89.30000","5.95183","0.42385"
"89.40000","5.95857","0.42363"
"89.50000","5.96556","0.42306"
"89.60000","5.97205","0.42213"
"89.70000","5.97845","0.42088"
"89.80000","5.98511","0.42024"
"89.90000","5.99177","0.42021"
"90.00000","5.99864","0.41931"
"90.10000","6.00552","0.41883"
"90.20000","6.01243","0.41837"
"90.30000","6.01870","0.41728"
"90.40000","6.02503","0.41651"
"90.50000","6.03170","0.41594"
"90.60000","6.03871","0.41602"
"90.70000","6.04549","0.41507"
"90.80000","6.05192","0.41448"
"90.90000","6.05833","0.41361"
"91.00000","6.06557","0.41363"
"91.10000","6.07242","0.41285"
"91.20000","6.07879","0.41200"
"91.30000","6.08499","0.41153"
"91.40000","6.09156","0.41099"
"91.50000","6.09872","0.41053"
"91.60000","6.10555","0.40969"
"91.70000","6.11194","0.40844"
"91.80000","6.11862","0.40768"
"91.90000","6.12514","0.40720"
"92.00000","6.13203","0.40621"
"92.10000","6.13861","0.40537"
"92.20000","6.14526","0.40480"
"92.30000","6.15177","0.40380"
"92.40000","6.15839","0.40375"
"92.50000","6.16526","0.40274"
"92.60000","6.17231","0.40323"
"92.70000","6.17898","0.40168"
"92.80000","6.18535","0.40125"
"92.90000","6.19156","0.40004"
"93.00000","6.19820","0.40007"
"93.10000","6.20547","0.39935"
"93.20000","6.21219","0.39864"
"93.30000","6.21862","0.39796"
"93.40000","6.22504","0.39717"
"93.50000","6.23226","0.39690"
"93.60000","6.23906","0.39610"
"93.70000","6.24529","0.39511"
"93.80000","6.25149","0.39393"
"93.90000","6.25830","0.39375"
"94.00000","6.26548","0.39356"
"94.10000","6.27210","0.39241"
"94.20000","6.27865","0.39158"
"94.30000","6.28536","0.39069"
"94.40000","6.29190","0.39023"
"94.50000","6.29854","0.38921"
"94.60000","6.30509","0.38870"
"94.70000","6.31206","0.38803"
"94.80000","6.31856","0.38722"
"94.90000","6.32514","0.38595"
"95.00000","6.33193","0.38593"
"95.10000","6.33917","0.38503"
"95.20000","6.34578","0.38393"
"95.30000","6.35175","0.38315"
"95.40000","6.35813","0.38260"
"95.50000","6.36523","0.38252"
"95.60000","6.37235","0.38175"
"95.70000","6.37883","0.38134"
"95.80000","6.38515","0.37995"
"95.90000","6.39193","0.38000"
"96.00000","6.39884","0.37947"
"96.10000","6.40544","0.37857"
"96.20000","6.41179","0.37750"
"96.30000","6.41831","0.37687"
"96.40000","6.42507","0.37690"
"96.50000","6.43207","0.37632"
"96.60000","6.43870","0.37566"
"96.70000","6.44562","0.37512"
"96.80000","6.45198","0.37442"
"96.90000","6.45846","0.37366"
"97.00000","6.46507","0.37285"
"97.10000","6.47193","0.37246"
"97.20000","6.47888","0.37174"
"97.30000","6.48526","0.37089"
"97.40000","6.49162","0.37062"
"97.50000","6.49867","0.37032"
"97.60000","6.50590","0.36958"
"97.70000","6.51228","0.36839"
"97.80000","6.51836","0.36716"
"97.90000","6.52467","0.36677"
"98.00000","6.53202","0.36651"
"98.10000","6.53900","0.36535"
"98.20000","6.54539","0.36485"
"98.30000","6.55193","0.36387"
"98.40000","6.55849","0.36342"
"98.50000","6.56554","0.36289"
"98.60000","6.57201","0.36153"
"98.70000","6.57844","0.36115"
"98.80000","6.58520","0.35978"
"98.90000","6.59187","0.35973"
"99.00000","6.59870","0.35895"
"99.10000","6.60539","0.35845"
"99.20000","6.61231","0.35784"
"99.30000","6.61880","0.35702"
"99.40000","6.62500","0.35657"
"99.50000","6.63168","0.35577"
"99.60000","6.63873","0.35559"
"99.70000","6.64553","0.35454"
"99.80000","6.65196","0.35375"
"99.90000","6.65830","0.35316"
"100.00000","6.66559","0.35322"
"100.10000","6.67253","0.35234"
"100.20000","6.67883","0.35173"
"100.30000","6.68504","0.35109"
"100.40000","6.69154","0.35018"
"100.50000","6.69876","0.34999"
"100.60000","6.70557","0.34905"
"100.70000","6.71194","0.34830"
"100.80000","6.71863","0.34793"
"100.90000","6.72514","0.34696"
"101.00000","6.73205","0.34651"
"101.10000","6.73857","0.34577"
"101.20000","6.74513","0.34502"
"101.30000","6.75185","0.34409"
"101.40000","6.75850","0.34375"
"101.50000","6.76535","0.34306"
"101.60000","6.77219","0.34227"
"101.70000","6.77889","0.34143"
"101.80000","6.78540","0.34091"
"101.90000","6.79155","0.33993"
"102.00000","6.79831","0.33896"
"102.10000","6.80550","0.33858"
"102.20000","6.81212","0.33804"
"102.30000","6.81863","0.33713"
"102.40000","6.82510","0.33678"
"102.50000","6.83223","0.33593"
"102.60000","6.83902","0.33532"
"102.70000","6.84523","0.33409"
"102.80000","6.85156","0.33421"
"102.90000","6.85842","0.33374"
"103.00000","6.86545","0.33334"
"103.10000","6.87208","0.33306"
"103.20000","6.87874","0.33220"
"103.30000","6.88538","0.33169"
"103.40000","6.89190","0.33088"
"103.50000","6.89857","0.33098"
"103.60000","6.90510","0.33022"
"103.70000","6.91210","0.33010"
"103.80000","6.91864","0.32923"
"103.90000","6.92513","0.32848"
"104.00000","6.93194","0.32791"
"104.10000","6.93894","0.32783"
"104.20000","6.94567","0.32683"
"104.30000","6.95184","0.32630"
"104.40000","6.95815","0.32554"
"104.50000","6.96528","0.32519"
"104.60000","6.97226","0.32465"
"104.70000","6.97880","0.32436"
"104.80000","6.98514","0.32318"
"104.90000","6.99183","0.32276"
"105.00000","6.99890","0.32279"
"105.10000","7.00545","0.32166"
"105.20000","7.01190","0.32128"
"105.30000","7.01823","0.32070"
"105.40000","7.02511","0.32030"
"105.50000","7.03211","0.31986"
"105.60000","7.03867","0.31969"
"105.70000","7.04543","0.31969"
"105.80000","7.05194","0.31822"
"105.90000","7.05851","0.31797"
"106.00000","7.06511","0.31780"
"106.10000","7.07181","0.31761"
"106.20000","7.07888","0.31678"
"106.30000","7.08523","0.31633"
"106.40000","7.09163","0.31539"
"106.50000","7.09867","0.31553"
"106.60000","7.10583","0.31477"
"106.70000","7.11231","0.31421"
"106.80000","7.11831","0.31299"
"106.90000","7.12476","0.31290"
"107.00000","7.13203","0.31268"
"107.10000","7.13886","0.31189"
"107.20000","7.14540","0.31095"
"107.30000","7.15182","0.31049"
"107.40000","7.15856","0.30992"
"107.50000","7.16558","0.30984"
"107.60000","7.17202","0.30949"
"107.70000","7.17855","0.30895"
"107.80000","7.18509","0.30849"
"107.90000","7.19175","0.30818"
"108.00000","7.19862","0.30802"
"108.10000","7.20546","0.30736"
"108.20000","7.21239","0.30741"
"108.30000","7.21872","0.30661"
"108.40000","7.22501","0.30603"
"108.50000","7.23176","0.30556"
"108.60000","7.23876","0.30576"
"108.70000","7.24563","0.30536"
"108.80000","7.25192","0.30472"
"108.90000","7.25832","0.30412"
"109.00000","7.26550","0.30443"
"109.10000","7.27240","0.30373"
"109.20000","7.27880","0.30257"
"109.30000","7.28495","0.30201"
"109.40000","7.29154","0.30231"
"109.50000","7.29873","0.30240"
"109.60000","7.30554","0.30140"
"109.70000","7.31204","0.30126"
"109.80000","7.31862","0.30072"
"109.90000","7.32521","0.30024"
"110.00000","7.33209","0.29988"
"110.10000","7.33859","0.29916"
"110.20000","7.34525","0.29897"
"110.30000","7.35175","0.29836"
"110.40000","7.35843","0.29795"
"110.50000","7.36523","0.29721"
"110.60000","7.37217","0.29685"
"110.70000","7.37902","0.29604"
"110.80000","7.38530","0.29487"
"110.90000","7.39156","0.29421"
"111.00000","7.39836","0.29369"
"111.10000","7.40549","0.29342"
"111.20000","7.41217","0.29237"
"111.30000","7.41854","0.29169"
"111.40000","7.42509","0.29121"
"111.50000","7.43220","0.29093"
"111.60000","7.43905","0.28946"
"111.70000","7.44530","0.28922"
"111.80000","7.45152","0.28794"
"111.90000","7.45832","0.28794"
"112.00000","7.46535","0.28705"
"112.10000","7.47210","0.28642"
"112.20000","7.47872","0.28553"
"112.30000","7.48541","0.28476"
"112.40000","7.49188","0.28402"
"112.50000","7.49855","0.28351"
"112.60000","7.50516","0.28264"
"112.70000","7.51211","0.28229"
"112.80000","7.51862","0.28052"
"112.90000","7.52518","0.28036"
"113.00000","7.53191","0.27987"
"113.10000","7.53900","0.27899"
"113.20000","7.54570","0.27792"
"113.30000","7.55190","0.27678"
"113.40000","7.55819","0.27635"
"113.50000","7.56517","0.27618"
"113.60000","7.57232","0.27498"
"113.70000","7.57885","0.27377"
"113.80000","7.58515","0.27286"
"113.90000","7.59181","0.27206"
"114.00000","7.59889","0.27129"
"114.10000","7.60546","0.27025"
"114.20000","7.61183","0.26883"
"114.30000","7.61835","0.26817"
"114.40000","7.62511","0.26741"
"114.50000","7.63203","0.26631"
"114.60000","7.63866","0.26586"
"114.70000","7.64549","0.26465"
"114.80000","7.65197","0.26362"
"114.90000","7.65846","0.26269"
"115.00000","7.66517","0.26130"
"115.10000","7.67186","0.26009"
"115.20000","7.67878","0.25909"
"115.30000","7.68530","0.25737"
"115.40000","7.69160","0.25636"
"115.50000","7.69865","0.25532"
"115.60000","7.70581","0.25381"
"115.70000","7.71225","0.25146"
"115.80000","7.71842","0.24995"
"115.90000","7.72475","0.24853"
"116.00000","7.73208","0.24682"
"116.10000","7.73886","0.24437"
"116.20000","7.74534","0.24230"
"116.30000","7.75187","0.23965"
"116.40000","7.75857","0.23744"
"116.50000","7.76564","0.23529"
"116.60000","7.77201","0.23293"
"116.70000","7.77838","0.22999"
"116.80000","7.78514","0.22807"
"116.90000","7.79183","0.22610"
"117.00000","7.79862","0.22389"
"117.10000","7.80540","0.22211"
"117.20000","7.81244","0.21971"
"117.30000","7.81887","0.21693"
"117.40000","7.82498","0.21410"
"117.50000","7.83163","0.21137"
"117.60000","7.83875","0.20938"
"117.70000","7.84549","0.20608"
"117.80000","7.85193","0.20340"
"117.90000","7.85836","0.20015"
"118.00000","7.86562","0.19735"
"118.10000","7.87242","0.19449"
"118.20000","7.87878","0.19108"
"118.30000","7.88489","0.18814"
"118.40000","7.89151","0.18588"
"118.50000","7.89874","0.18349"
"118.60000","7.90551","0.18068"
"118.70000","7.91201","0.17864"
"118.80000","7.91874","0.17542"
"118.90000","7.92522","0.17321"
"119.00000","7.93210","0.17041"
"119.10000","7.93846","0.16775"
"119.20000","7.94517","0.16568"
"119.30000","7.95177","0.16356"
"119.40000","7.95845","0.16163"
"119.50000","7.96527","0.15980"
"119.60000","7.97214","0.15800"
"119.70000","7.97900","0.15546"
"119.80000","7.98533","0.15347"
"119.90000","7.99159","0.15213"
"120.00000","7.99830","0.14996"
"120.09800","8.00551","0.14874"