File: 20.12.09/1Layer_5.is_flex_RawData/Specimen_RawData_1.csv
Specimen properties : Thickness,"3.20000",mm
Specimen properties : Width,"19.20000",mm
Specimen properties : Support span,"51.20000",mm

Time,Extension,Load
(s),(mm),(kgf)
"0.00000","0.00000","-0.00158"
"0.20000","0.00479","0.00146"
"0.40000","0.02543","0.01295"
"0.60000","0.03847","0.01983"
"0.80000","0.05179","0.02683"
"1.00000","0.06537","0.03363"
"1.20000","0.07864","0.03770"
"1.40000","0.09197","0.04174"
"1.60000","0.10540","0.04843"
"1.80000","0.11844","0.05560"
"2.00000","0.13241","0.06231"
"2.20000","0.14496","0.06940"
"2.40000","0.15876","0.07640"
"2.60000","0.17216","0.08286"
"2.80000","0.18528","0.08950"
"3.00000","0.19871","0.09612"
"3.20000","0.21155","0.10197"
"3.40000","0.22543","0.10879"
"3.60000","0.23891","0.11480"
"3.80000","0.25178","0.12103"
"4.00000","0.26538","0.12748"
"4.20000","0.27846","0.13275"
"4.40000","0.29224","0.13928"
"4.60000","0.30546","0.14517"
"4.80000","0.31823","0.15080"
"5.00000","0.33233","0.15670"
"5.20000","0.34513","0.16210"
"5.40000","0.35895","0.16824"
"5.60000","0.37181","0.17326"
"5.80000","0.38522","0.17916"
"6.00000","0.39890","0.18467"
"6.20000","0.41191","0.19002"
"6.40000","0.42505","0.19542"
"6.60000","0.43880","0.20099"
"6.80000","0.45179","0.20647"
"7.00000","0.46578","0.21182"
"7.20000","0.47810","0.21679"
"7.40000","0.49213","0.22293"
"7.60000","0.50527","0.22774"
"7.80000","0.51858","0.23335"
"8.00000","0.53185","0.23821"
"8.20000","0.54511","0.24376"
"8.40000","0.55858","0.24909"
"8.60000","0.57223","0.25393"
"8.80000","0.58488","0.25843"
"9.00000","0.59890","0.26452"
"9.20000","0.61178","0.26896"
"9.40000","0.62558","0.27427"
"9.60000","0.63858","0.27904"
"9.80000","0.65181","0.28416"
"10.00000","0.66537","0.28884"
"10.20000","0.67869","0.29368"
"10.40000","0.69189","0.29865"
"10.60000","0.70550","0.30345"
"10.80000","0.71836","0.30811"
"11.00000","0.73242","0.31326"
"11.20000","0.74507","0.31735"
"11.40000","0.75882","0.32250"
"11.60000","0.77202","0.32694"
"11.80000","0.78532","0.33245"
"12.00000","0.79867","0.33626"
"12.20000","0.81168","0.34047"
"12.40000","0.82533","0.34558"
"12.60000","0.83891","0.34985"
"12.80000","0.85185","0.35417"
"13.00000","0.86531","0.35840"
"13.20000","0.87853","0.36286"
"13.40000","0.89222","0.36762"
"13.60000","0.90546","0.37126"
"13.80000","0.91835","0.37591"
"14.00000","0.93217","0.38064"
"14.20000","0.94512","0.38433"
"14.40000","0.95886","0.38890"
"14.60000","0.97180","0.39249"
"14.80000","0.98526","0.39676"
"15.00000","0.99885","0.40104"
"15.20000","1.01197","0.40487"
"15.40000","1.02510","0.40904"
"15.60000","1.03883","0.41314"
"15.80000","1.05176","0.41683"
"16.00000","1.06576","0.42135"
"16.20000","1.07811","0.42431"
"16.40000","1.09217","0.42878"
"16.60000","1.10521","0.43280"
"16.80000","1.11866","0.43647"
"17.00000","1.13181","0.44024"
"17.20000","1.14513","0.44372"
"17.40000","1.15853","0.44763"
"17.60000","1.17225","0.45124"
"17.80000","1.18479","0.45432"
"18.00000","1.19897","0.45869"
"18.20000","1.21162","0.46181"
"18.40000","1.22573","0.46595"
"18.60000","1.23845","0.46886"
"18.80000","1.25172","0.47243"
"19.00000","1.26539","0.47632"
"19.20000","1.27868","0.47942"
"19.40000","1.29199","0.48284"
"19.60000","1.30545","0.48664"
"19.80000","1.31846","0.48978"
"20.00000","1.33243","0.49346"
"20.20000","1.34497","0.49610"
"20.40000","1.35876","0.49953"
"20.60000","1.37204","0.50287"
"20.80000","1.38522","0.50573"
"21.00000","1.39879","0.50894"
"21.20000","1.41159","0.51186"
"21.40000","1.42537","0.51518"
"21.60000","1.43900","0.51852"
"21.80000","1.45176","0.52129"
"22.00000","1.46541","0.52490"
"22.20000","1.47844","0.52727"
"22.40000","1.49225","0.53079"
"22.60000","1.50548","0.53387"
"22.80000","1.51827","0.53659"
"23.00000","1.53228","0.53948"
"23.20000","1.54510","0.54211"
"23.40000","1.55893","0.54565"
"23.60000","1.57176","0.54745"
"23.80000","1.58522","0.55077"
"24.00000","1.59889","0.55399"
"24.20000","1.61195","0.55630"
"24.40000","1.62509","0.55882"
"24.60000","1.63877","0.56222"
"24.80000","1.65178","0.56448"
"25.00000","1.66581","0.56773"
"25.20000","1.67807","0.57007"
"25.40000","1.69217","0.57282"
"25.60000","1.70532","0.57542"
"25.80000","1.71861","0.57785"
"26.00000","1.73189","0.58041"
"26.20000","1.74499","0.58324"
"26.40000","1.75861","0.58625"
"26.60000","1.77225","0.58838"
"26.80000","1.78484","0.59079"
"27.00000","1.79890","0.59359"
"27.20000","1.81163","0.59534"
"27.40000","1.82576","0.59898"
"27.60000","1.83857","0.60075"
"27.80000","1.85174","0.60294"
"28.00000","1.86543","0.60540"
"28.20000","1.87856","0.60784"
"28.40000","1.89187","0.61050"
"28.60000","1.90552","0.61222"
"28.80000","1.91839","0.61501"
"29.00000","1.93250","0.61771"
"29.20000","1.94500","0.61939"
"29.40000","1.95881","0.62240"
"29.60000","1.97203","0.62416"
"29.80000","1.98532","0.62646"
"30.00000","1.99872","0.62864"
"30.20000","2.01156","0.63055"
"30.40000","2.02534","0.63270"
"30.60000","2.03892","0.63527"
"30.80000","2.05174","0.63705"
"31.00000","2.06530","0.63954"
"31.20000","2.07848","0.64156"
"31.40000","2.09218","0.64378"
"31.60000","2.10544","0.64591"
"31.80000","2.11823","0.64778"
"32.00000","2.13223","0.64995"
"32.20000","2.14520","0.65195"
"32.40000","2.15892","0.65393"
"32.60000","2.17170","0.65625"
"32.80000","2.18522","0.65811"
"33.00000","2.19884","0.66028"
"33.20000","2.21197","0.66217"
"33.40000","2.22511","0.66380"
"33.60000","2.23879","0.66647"
"33.80000","2.25169","0.66779"
"34.00000","2.26578","0.67031"
"34.20000","2.27815","0.67127"
"34.40000","2.29216","0.67373"
"34.60000","2.30521","0.67543"
"34.80000","2.31859","0.67780"
"35.00000","2.33176","0.67921"
"35.20000","2.34522","0.68122"
"35.40000","2.35853","0.68266"
"35.60000","2.37227","0.68496"
"35.80000","2.38486","0.68593"
"36.00000","2.39890","0.68843"
"36.20000","2.41192","0.69002"
"36.40000","2.42558","0.69234"
"36.60000","2.43851","0.69392"
"36.80000","2.45187","0.69555"
"37.00000","2.46533","0.69741"
"37.20000","2.47870","0.69904"
"37.40000","2.49192","0.70059"
"37.60000","2.50536","0.70246"
"37.80000","2.51855","0.70407"
"38.00000","2.53232","0.70580"
"38.20000","2.54515","0.70724"
"38.40000","2.55870","0.70888"
"38.60000","2.57202","0.71006"
"38.80000","2.58528","0.71219"
"39.00000","2.59857","0.71306"
"39.20000","2.61187","0.71477"
"39.40000","2.62524","0.71620"
"39.60000","2.63883","0.71837"
"39.80000","2.65192","0.71925"
"40.00000","2.66523","0.72123"
"40.20000","2.67865","0.72269"
"40.40000","2.69218","0.72437"
"40.60000","2.70535","0.72561"
"40.80000","2.71837","0.72745"
"41.00000","2.73211","0.72971"
"41.20000","2.74533","0.73073"
"41.40000","2.75883","0.73211"
"41.60000","2.77166","0.73348"
"41.80000","2.78537","0.73535"
"42.00000","2.79872","0.73656"
"42.20000","2.81211","0.73807"
"42.40000","2.82496","0.73905"
"42.60000","2.83870","0.74083"
"42.80000","2.85194","0.74198"
"43.00000","2.86570","0.74364"
"43.20000","2.87829","0.74450"
"43.40000","2.89207","0.74648"
"43.60000","2.90517","0.74801"
"43.80000","2.91872","0.74894"
"44.00000","2.93165","0.74969"
"44.20000","2.94524","0.75145"
"44.40000","2.95854","0.75252"
"44.60000","2.97216","0.75402"
"44.80000","2.98501","0.75518"
"45.00000","2.99872","0.75702"
"45.20000","3.01191","0.75770"
"45.40000","3.02559","0.75977"
"45.60000","3.03843","0.76055"
"45.80000","3.05192","0.76247"
"46.00000","3.06537","0.76359"
"46.20000","3.07879","0.76476"
"46.40000","3.09190","0.76620"
"46.60000","3.10532","0.76732"
"46.80000","3.11852","0.76865"
"47.00000","3.13235","0.76995"
"47.20000","3.14520","0.77105"
"47.40000","3.15867","0.77277"
"47.60000","3.17200","0.77316"
"47.80000","3.18535","0.77453"
"48.00000","3.19867","0.77565"
"48.20000","3.21174","0.77682"
"48.40000","3.22527","0.77825"
"48.60000","3.23880","0.77944"
"48.80000","3.25191","0.77999"
"49.00000","3.26521","0.78150"
"49.20000","3.27853","0.78281"
"49.40000","3.29224","0.78436"
"49.60000","3.30546","0.78537"
"49.80000","3.31835","0.78606"
"50.00000","3.33211","0.78759"
"50.20000","3.34533","0.78850"
"50.40000","3.35889","0.78953"
"50.60000","3.37172","0.79020"
"50.80000","3.38527","0.79126"
"51.00000","3.39878","0.79227"
"51.20000","3.41199","0.79276"
"51.40000","3.42507","0.79424"
"51.60000","3.43870","0.79505"
"51.80000","3.45195","0.79626"
"52.00000","3.46567","0.79699"
"52.20000","3.47811","0.79733"
"52.40000","3.49201","0.79887"
"52.60000","3.50525","0.79965"
"52.80000","3.51864","0.80067"
"53.00000","3.53173","0.80186"
"53.20000","3.54510","0.80233"
"53.40000","3.55849","0.80363"
"53.60000","3.57227","0.80490"
"53.80000","3.58494","0.80532"
"54.00000","3.59894","0.80683"
"54.20000","3.61173","0.80782"
"54.40000","3.62564","0.80930"
"54.60000","3.63851","0.81000"
"54.80000","3.65188","0.81122"
"55.00000","3.66539","0.81225"
"55.20000","3.67860","0.81317"
"55.40000","3.69196","0.81448"
"55.60000","3.70533","0.81549"
"55.80000","3.71851","0.81595"
"56.00000","3.73236","0.81808"
"56.20000","3.74497","0.81881"
"56.40000","3.75880","0.82051"
"56.60000","3.77203","0.82206"
"56.80000","3.78532","0.82376"
"57.00000","3.79873","0.82498"
"57.20000","3.81168","0.82597"
"57.40000","3.82525","0.82802"
"57.60000","3.83883","0.82956"
"57.80000","3.85183","0.83116"
"58.00000","3.86535","0.83280"
"58.20000","3.87833","0.83413"
"58.40000","3.89231","0.83591"
"58.60000","3.90543","0.83702"
"58.80000","3.91819","0.83838"
"59.00000","3.93227","0.84031"
"59.20000","3.94517","0.84144"
"59.40000","3.95887","0.84238"
"59.60000","3.97176","0.84321"
"59.80000","3.98523","0.84442"
"60.00000","3.99885","0.84532"
"60.20000","4.01198","0.84614"
"60.40000","4.02511","0.84688"
"60.60000","4.03870","0.84735"
"60.80000","4.05177","0.84823"
"61.00000","4.06580","0.84920"
"61.20000","4.07816","0.84916"
"61.40000","4.09207","0.85124"
"61.60000","4.10524","0.85236"
"61.80000","4.11855","0.85331"
"62.00000","4.13184","0.85410"
"62.20000","4.14514","0.85506"
"62.40000","4.15855","0.85576"
"62.60000","4.17225","0.85639"
"62.80000","4.18491","0.85669"
"63.00000","4.19886","0.85862"
"63.20000","4.21172","0.85837"
"63.40000","4.22579","0.85977"
"63.60000","4.23847","0.85977"
"63.80000","4.25187","0.86110"
"64.00000","4.26539","0.86221"
"64.20000","4.27869","0.86207"
"64.40000","4.29193","0.86285"
"64.60000","4.30531","0.86378"
"64.80000","4.31850","0.86547"
"65.00000","4.33237","0.86644"
"65.20000","4.34507","0.86665"
"65.40000","4.35880","0.86791"
"65.60000","4.37197","0.86833"
"65.80000","4.38527","0.86901"
"66.00000","4.39873","0.86907"
"66.20000","4.41172","0.86909"
"66.40000","4.42534","0.86996"
"66.60000","4.43886","0.87087"
"66.80000","4.45179","0.87077"
"67.00000","4.46532","0.87213"
"67.20000","4.47847","0.87295"
"67.40000","4.49218","0.87411"
"67.60000","4.50543","0.87469"
"67.80000","4.51838","0.87594"
"68.00000","4.53217","0.87657"
"68.20000","4.54519","0.87658"
"68.40000","4.55892","0.87723"
"68.60000","4.57176","0.87784"
"68.80000","4.58518","0.87810"
"69.00000","4.59881","0.87880"
"69.20000","4.61207","0.87921"
"69.40000","4.62505","0.88011"
"69.60000","4.63871","0.88105"
"69.80000","4.65182","0.88182"
"70.00000","4.66574","0.88201"
"70.20000","4.67817","0.88198"
"70.40000","4.69209","0.88283"
"70.60000","4.70526","0.88284"
"70.80000","4.71863","0.88308"
"71.00000","4.73183","0.88289"
"71.20000","4.74508","0.88364"
"71.40000","4.75858","0.88428"
"71.60000","4.77219","0.88503"
"71.80000","4.78496","0.88537"
"72.00000","4.79887","0.88613"
"72.20000","4.81175","0.88638"
"72.40000","4.82562","0.88770"
"72.60000","4.83855","0.88809"
"72.80000","4.85176","0.88855"
"73.00000","4.86538","0.88803"
"73.20000","4.87864","0.88864"
"73.40000","4.89200","0.88953"
"73.60000","4.90541","0.89019"
"73.80000","4.91845","0.89118"
"74.00000","4.93239","0.89267"
"74.20000","4.94507","0.89313"
"74.40000","4.95876","0.89380"
"74.60000","4.97206","0.89443"
"74.80000","4.98522","0.89479"
"75.00000","4.99870","0.89451"
"75.20000","5.01163","0.89507"
"75.40000","5.02532","0.89550"
"75.60000","5.03895","0.89612"
"75.80000","5.05180","0.89652"
"76.00000","5.06534","0.89712"
"76.20000","5.07843","0.89681"
"76.40000","5.09226","0.89847"
"76.60000","5.10540","0.89811"
"76.80000","5.11830","0.89942"
"77.00000","5.13220","0.90008"
"77.20000","5.14520","0.89997"
"77.40000","5.15889","0.90050"
"77.60000","5.17173","0.90074"
"77.80000","5.18519","0.90195"
"78.00000","5.19881","0.90247"
"78.20000","5.21197","0.90253"
"78.40000","5.22512","0.90286"
"78.60000","5.23878","0.90349"
"78.80000","5.25179","0.90348"
"79.00000","5.26574","0.90412"
"79.20000","5.27808","0.90427"
"79.40000","5.29209","0.90545"
"79.60000","5.30526","0.90524"
"79.80000","5.31854","0.90594"
"80.00000","5.33175","0.90633"
"80.20000","5.34508","0.90775"
"80.40000","5.35853","0.90753"
"80.60000","5.37220","0.90806"
"80.80000","5.38488","0.90815"
"81.00000","5.39897","0.90856"
"81.20000","5.41177","0.90816"
"81.40000","5.42561","0.90895"
"81.60000","5.43851","0.90873"
"81.80000","5.45175","0.90980"
"82.00000","5.46544","0.90995"
"82.20000","5.47857","0.90995"
"82.40000","5.49188","0.91021"
"82.60000","5.50546","0.91072"
"82.80000","5.51841","0.91022"
"83.00000","5.53235","0.91068"
"83.20000","5.54501","0.91096"
"83.40000","5.55878","0.91191"
"83.60000","5.57207","0.91160"
"83.80000","5.58526","0.91205"
"84.00000","5.59874","0.91209"
"84.20000","5.61158","0.91178"
"84.40000","5.62527","0.91205"
"84.60000","5.63887","0.91244"
"84.80000","5.65177","0.91310"
"85.00000","5.66534","0.91442"
"85.20000","5.67839","0.91506"
"85.40000","5.69227","0.91549"
"85.60000","5.70550","0.91494"
"85.80000","5.71817","0.91597"
"86.00000","5.73224","0.91590"
"86.20000","5.74516","0.91580"
"86.40000","5.75886","0.91535"
"86.60000","5.77178","0.91486"
"86.80000","5.78520","0.91482"
"87.00000","5.79882","0.91594"
"87.20000","5.81194","0.91564"
"87.40000","5.82516","0.91576"
"87.60000","5.83874","0.91552"
"87.80000","5.85171","0.91580"
"88.00000","5.86584","0.91566"
"88.20000","5.87808","0.91577"
"88.40000","5.89215","0.91658"
"88.60000","5.90526","0.91607"
"88.80000","5.91852","0.91580"
"89.00000","5.93186","0.91624"
"89.20000","5.94512","0.91686"
"89.40000","5.95856","0.91768"
"89.60000","5.97228","0.91836"
"89.80000","5.98486","0.91832"
"90.00000","5.99896","0.91884"
"90.20000","6.01179","0.91824"
"90.40000","6.02566","0.91902"
"90.60000","6.03858","0.91922"
"90.80000","6.05174","0.91993"
"91.00000","6.06541","0.91977"
"91.20000","6.07863","0.91985"
"91.40000","6.09196","0.91954"
"91.60000","6.10536","0.91959"
"91.80000","6.11851","0.92018"
"92.00000","6.13236","0.92058"
"92.20000","6.14497","0.92022"
"92.40000","6.15886","0.92045"
"92.60000","6.17214","0.91952"
"92.80000","6.18530","0.91992"
"93.00000","6.19866","0.91976"
"93.20000","6.21166","0.92007"
"93.40000","6.22527","0.92035"
"93.60000","6.23899","0.92064"
"93.80000","6.25181","0.92056"
"94.00000","6.26532","0.92076"
"94.20000","6.27839","0.92045"
"94.40000","6.29227","0.92099"
"94.60000","6.30547","0.92100"
"94.80000","6.31819","0.92124"
"95.00000","6.33222","0.92090"
"95.20000","6.34532","0.92047"
"95.40000","6.35891","0.92080"
"95.60000","6.37172","0.91986"
"95.80000","6.38521","0.91930"
"96.00000","6.39884","0.91967"
"96.20000","6.41195","0.91885"
"96.40000","6.42503","0.91948"
"96.60000","6.43870","0.91951"
"96.80000","6.45183","0.91932"
"97.00000","6.46575","0.91855"
"97.20000","6.47822","0.91844"
"97.40000","6.49211","0.91869"
"97.60000","6.50530","0.91890"
"97.80000","6.51859","0.91849"
"98.00000","6.53172","0.91820"
"98.20000","6.54511","0.91812"
"98.40000","6.55860","0.91815"
"98.60000","6.57224","0.91778"
"98.80000","6.58483","0.91731"
"99.00000","6.59889","0.91744"
"99.20000","6.61179","0.91673"
"99.40000","6.62557","0.91644"
"99.60000","6.63859","0.91600"
"99.80000","6.65190","0.91716"
"100.00000","6.66538","0.91699"
"100.20000","6.67858","0.91646"
"100.40000","6.69195","0.91675"
"100.60000","6.70545","0.91680"
"100.80000","6.71850","0.91647"
"101.00000","6.73243","0.91649"
"101.20000","6.74501","0.91628"
"101.40000","6.75869","0.91645"
"101.60000","6.77207","0.91579"
"101.80000","6.78540","0.91557"
"102.00000","6.79865","0.91482"
"102.20000","6.81163","0.91433"
"102.40000","6.82531","0.91466"
"102.60000","6.83890","0.91527"
"102.80000","6.85177","0.91588"
"103.00000","6.86537","0.91643"
"103.20000","6.87847","0.91571"
"103.40000","6.89224","0.91663"
"103.60000","6.90547","0.91633"
"103.80000","6.91825","0.91620"
"104.00000","6.93221","0.91640"
"104.20000","6.94514","0.91598"
"104.40000","6.95888","0.91589"
"104.60000","6.97184","0.91560"
"104.80000","6.98521","0.91458"
"105.00000","6.99883","0.91382"
"105.20000","7.01195","0.91355"
"105.40000","7.02507","0.91380"
"105.60000","7.03890","0.91395"
"105.80000","7.05174","0.91377"
"106.00000","7.06578","0.91319"
"106.20000","7.07806","0.91197"
"106.40000","7.09219","0.91257"
"106.60000","7.10529","0.91161"
"106.80000","7.11864","0.91199"
"107.00000","7.13175","0.91111"
"107.20000","7.14507","0.91119"
"107.40000","7.15856","0.91084"
"107.60000","7.17233","0.91124"
"107.80000","7.18487","0.91123"
"108.00000","7.19895","0.91138"
"108.20000","7.21173","0.91076"
"108.40000","7.22563","0.91115"
"108.60000","7.23853","0.91051"
"108.80000","7.25184","0.91157"
"109.00000","7.26537","0.91173"
"109.20000","7.27864","0.91172"
"109.40000","7.29194","0.91136"
"109.60000","7.30545","0.91116"
"109.80000","7.31846","0.91099"
"110.00000","7.33243","0.91085"
"110.20000","7.34509","0.90934"
"110.40000","7.35864","0.90986"
"110.60000","7.37210","0.90882"
"110.80000","7.38527","0.90957"
"111.00000","7.39869","0.90879"
"111.20000","7.41165","0.90817"
"111.40000","7.42525","0.90760"
"111.60000","7.43898","0.90763"
"111.80000","7.45177","0.90777"
"112.00000","7.46533","0.90700"
"112.20000","7.47854","0.90672"
"112.40000","7.49221","0.90677"
"112.60000","7.50543","0.90560"
"112.80000","7.51836","0.90616"
"113.00000","7.53219","0.90577"
"113.20000","7.54521","0.90544"
"113.40000","7.55895","0.90473"
"113.60000","7.57169","0.90462"
"113.80000","7.58523","0.90471"
"114.00000","7.59871","0.90431"
"114.20000","7.61203","0.90422"
"114.40000","7.62510","0.90456"
"114.60000","7.63877","0.90324"
"114.80000","7.65185","0.90316"
"115.00000","7.66570","0.90303"
"115.20000","7.67811","0.90211"
"115.40000","7.69204","0.90258"
"115.60000","7.70544","0.90233"
"115.80000","7.71849","0.90150"
"116.00000","7.73177","0.90010"
"116.20000","7.74512","0.89956"
"116.40000","7.75855","0.89935"
"116.60000","7.77228","0.89846"
"116.80000","7.78493","0.89833"
"117.00000","7.79883","0.89837"
"117.20000","7.81179","0.89714"
"117.40000","7.82562","0.89722"
"117.60000","7.83856","0.89624"
"117.80000","7.85183","0.89692"
"118.00000","7.86537","0.89711"
"118.20000","7.87866","0.89633"
"118.40000","7.89195","0.89673"
"118.60000","7.90529","0.89586"
"118.80000","7.91845","0.89572"
"119.00000","7.93237","0.89473"
"119.20000","7.94503","0.89382"
"119.40000","7.95866","0.89282"
"119.60000","7.97207","0.89175"
"119.80000","7.98529","0.89151"
"120.00000","7.99871","0.89004"
"120.20000","8.01162","0.88964"
"120.40000","8.02537","0.88815"
"120.60000","8.03896","0.88749"
"120.80000","8.05173","0.88587"
"121.00000","8.06532","0.88516"
"121.20000","8.07837","0.88368"
"121.40000","8.09222","0.88344"
"121.60000","8.10544","0.88213"
"121.80000","8.11821","0.88238"
"122.00000","8.13222","0.88153"
"122.20000","8.14513","0.88070"
"122.40000","8.15892","0.87954"
"122.60000","8.17183","0.87794"
"122.80000","8.18511","0.87724"
"123.00000","8.19885","0.87711"
"123.20000","8.21192","0.87602"
"123.40000","8.22507","0.87627"
"123.60000","8.23879","0.87579"
"123.80000","8.25182","0.87626"
"124.00000","8.26579","0.87516"
"124.20000","8.27809","0.87418"
"124.40000","8.29208","0.87456"
"124.60000","8.30529","0.87354"
"124.80000","8.31858","0.87286"
"125.00000","8.33177","0.87189"
"125.20000","8.34513","0.87080"
"125.40000","8.35855","0.86928"
"125.60000","8.37229","0.86829"
"125.80000","8.38483","0.86726"
"126.00000","8.39892","0.86735"
"126.20000","8.41171","0.86595"
"126.40000","8.42573","0.86659"
"126.60000","8.43854","0.86431"
"126.80000","8.45177","0.86330"
"127.00000","8.46545","0.86214"
"127.20000","8.47854","0.86090"
"127.40000","8.49198","0.86025"
"127.60000","8.50548","0.85943"
"127.80000","8.51835","0.85878"
"128.00000","8.53248","0.85824"
"128.20000","8.54491","0.85652"
"128.40000","8.55874","0.85501"
"128.60000","8.57206","0.85315"
"128.80000","8.58526","0.85268"
"129.00000","8.59875","0.85124"
"129.20000","8.61156","0.85029"
"129.40000","8.62532","0.84930"
"129.60000","8.63911","0.84830"
"129.80000","8.65170","0.84707"
"130.00000","8.66536","0.84673"
"130.20000","8.67844","0.84486"
"130.40000","8.69228","0.84346"
"130.60000","8.70545","0.84120"
"130.80000","8.71820","0.84042"
"131.00000","8.73236","0.83845"
"131.20000","8.74508","0.83702"
"131.40000","8.75894","0.83548"
"131.60000","8.77175","0.83288"
"131.80000","8.78518","0.83109"
"132.00000","8.79893","0.82832"
"132.20000","8.81193","0.82535"
"132.40000","8.82508","0.82325"
"132.60000","8.83881","0.82073"
"132.80000","8.85172","0.81759"
"133.00000","8.86581","0.81437"
"133.20000","8.87813","0.81055"
"133.40000","8.89206","0.80773"
"133.60000","8.90521","0.80472"
"133.80000","8.91861","0.80114"
"134.00000","8.93185","0.79724"
"134.20000","8.94513","0.79362"
"134.40000","8.95864","0.79080"
"134.60000","8.97227","0.78790"
"134.80000","8.98486","0.78468"
"135.00000","8.99893","0.78308"
"135.20000","9.01173","0.78051"
"135.40000","9.02567","0.78002"
"135.60000","9.03844","0.77696"
"135.80000","9.05185","0.77558"
"136.00000","9.06534","0.77341"
"136.20000","9.07873","0.77117"
"136.40000","9.09196","0.76840"
"136.60000","9.10529","0.76580"
"136.80000","9.11853","0.76355"
"137.00000","9.13233","0.75987"
"137.20000","9.14505","0.75678"
"137.40000","9.15876","0.75528"
"137.60000","9.17203","0.75275"
"137.80000","9.18530","0.75187"
"138.00000","9.19869","0.74881"
"138.20000","9.21177","0.74639"
"138.40000","9.22527","0.74397"
"138.60000","9.23871","0.74071"
"138.80000","9.25186","0.73784"
"139.00000","9.26532","0.73595"
"139.20000","9.27851","0.73215"
"139.40000","9.29219","0.73053"
"139.60000","9.30535","0.72748"
"139.80000","9.31836","0.72489"
"140.00000","9.33215","0.72177"
"140.20000","9.34530","0.71834"
"140.40000","9.35886","0.71567"
"140.60000","9.37167","0.71228"
"140.80000","9.38534","0.70944"
"141.00000","9.39869","0.70632"
"141.20000","9.41216","0.70303"
"141.40000","9.42504","0.70044"
"141.60000","9.43870","0.69709"
"141.80000","9.45180","0.69411"
"142.00000","9.46566","0.69076"
"142.20000","9.47826","0.68618"
"142.40000","9.49203","0.68328"
"142.60000","9.50518","0.67917"
"142.80000","9.51869","0.67342"
"143.00000","9.53168","0.66847"
"143.20000","9.54519","0.66378"
"143.40000","9.55854","0.65838"
"143.60000","9.57208","0.65310"
"143.80000","9.58499","0.64741"
"144.00000","9.59877","0.64194"
"144.20000","9.61187","0.63441"
"144.40000","9.62568","0.62547"
"144.60000","9.63845","0.61299"
"144.80000","9.65194","0.60046"
"145.00000","9.66536","0.58299"
"145.20000","9.67872","0.56472"
"145.40000","9.69196","0.54969"
"145.60000","9.70527","0.53564"
"145.80000","9.71857","0.52383"
"146.00000","9.73228","0.51546"
"146.20000","9.74519","0.50857"
"146.40000","9.75879","0.50283"
"146.60000","9.77195","0.49711"
"146.80000","9.78545","0.49139"
"147.00000","9.79865","0.48497"
"147.20000","9.81181","0.47936"
"147.40000","9.82525","0.47330"
"147.60000","9.83884","0.46804"
"147.80000","9.85194","0.46196"
"148.00000","9.86516","0.45702"
"148.20000","9.87864","0.45222"
"148.40000","9.89220","0.44836"
"148.60000","9.90542","0.44409"
"148.80000","9.91833","0.44175"
"149.00000","9.93220","0.43772"
"149.20000","9.94528","0.43427"
"149.40000","9.95884","0.42997"
"149.60000","9.97157","0.42704"
"149.80000","9.98534","0.42280"
"150.00000","9.99874","0.41889"
"150.20000","10.01202","0.41526"
"150.40000","10.02505","0.41221"
"150.60000","10.03877","0.40860"
"150.80000","10.05187","0.40582"
"151.00000","10.06567","0.40276"
"151.20000","10.07819","0.40115"
"151.40000","10.09211","0.39917"
"151.60000","10.10520","0.39706"
"151.80000","10.11861","0.39568"
"152.00000","10.13175","0.39350"
"152.20000","10.14516","0.39156"
"152.40000","10.15854","0.39031"
"152.60000","10.17217","0.38856"
"152.80000","10.18493","0.38652"
"153.00000","10.19892","0.38504"
"153.20000","10.21176","0.38335"
"153.40000","10.22564","0.38225"
"153.60000","10.23850","0.38056"
"153.80000","10.25185","0.37965"
"154.00000","10.26536","0.37754"
"154.20000","10.27864","0.37610"
"154.40000","10.29194","0.37401"
"154.60000","10.30541","0.37297"
"154.80000","10.31848","0.37106"
"155.00000","10.33247","0.36995"
"155.20000","10.34494","0.36824"
"155.40000","10.35884","0.36786"
"155.51400","10.36654","0.36688"