File: 20.12.09/1Layer_7.is_flex_RawData/Specimen_RawData_1.csv
Specimen properties : Thickness,"4.30000",mm
Specimen properties : Width,"13.20000",mm
Specimen properties : Support span,"68.80000",mm

Time,Extension,Load
(s),(mm),(kgf)
"0.00000","0.00000","-0.00394"
"0.10000","0.00079","-0.00382"
"0.20000","0.00554","-0.00188"
"0.30000","0.01649","0.00317"
"0.40000","0.02495","0.00604"
"0.50000","0.03179","0.00865"
"0.60000","0.03814","0.01080"
"0.70000","0.04536","0.01361"
"0.80000","0.05238","0.01657"
"0.90000","0.05881","0.01846"
"1.00000","0.06503","0.02089"
"1.10000","0.07151","0.02289"
"1.20000","0.07856","0.02541"
"1.30000","0.08552","0.02778"
"1.40000","0.09208","0.03006"
"1.50000","0.09884","0.03245"
"1.60000","0.10529","0.03526"
"1.70000","0.11195","0.03713"
"1.80000","0.11852","0.03920"
"1.90000","0.12525","0.04122"
"2.00000","0.13210","0.04359"
"2.10000","0.13845","0.04553"
"2.20000","0.14511","0.04829"
"2.30000","0.15228","0.05031"
"2.40000","0.15914","0.05243"
"2.50000","0.16545","0.05429"
"2.60000","0.17156","0.05678"
"2.70000","0.17822","0.05860"
"2.80000","0.18553","0.06107"
"2.90000","0.19224","0.06265"
"3.00000","0.19858","0.06476"
"3.10000","0.20505","0.06651"
"3.20000","0.21208","0.06914"
"3.30000","0.21895","0.07096"
"3.40000","0.22529","0.07308"
"3.50000","0.23162","0.07475"
"3.60000","0.23846","0.07736"
"3.70000","0.24526","0.07911"
"3.80000","0.25191","0.08121"
"3.90000","0.25875","0.08266"
"4.00000","0.26549","0.08512"
"4.10000","0.27193","0.08672"
"4.20000","0.27844","0.08868"
"4.30000","0.28505","0.09040"
"4.40000","0.29217","0.09229"
"4.50000","0.29874","0.09377"
"4.60000","0.30505","0.09574"
"4.70000","0.31169","0.09781"
"4.80000","0.31910","0.09972"
"4.90000","0.32575","0.10186"
"5.00000","0.33195","0.10287"
"5.10000","0.33806","0.10466"
"5.20000","0.34513","0.10662"
"5.30000","0.35222","0.10830"
"5.40000","0.35875","0.11014"
"5.50000","0.36516","0.11166"
"5.60000","0.37188","0.11285"
"5.70000","0.37881","0.11499"
"5.80000","0.38546","0.11657"
"5.90000","0.39188","0.11786"
"6.00000","0.39848","0.12007"
"6.10000","0.40502","0.12134"
"6.20000","0.41202","0.12342"
"6.30000","0.41873","0.12487"
"6.40000","0.42563","0.12645"
"6.50000","0.43222","0.12814"
"6.60000","0.43853","0.12921"
"6.70000","0.44503","0.13055"
"6.80000","0.45181","0.13263"
"6.90000","0.45895","0.13427"
"7.00000","0.46546","0.13569"
"7.10000","0.47174","0.13683"
"7.20000","0.47859","0.13836"
"7.30000","0.48568","0.13990"
"7.40000","0.49234","0.14154"
"7.50000","0.49854","0.14274"
"7.60000","0.50472","0.14404"
"7.70000","0.51186","0.14581"
"7.80000","0.51887","0.14713"
"7.90000","0.52539","0.14853"
"8.00000","0.53193","0.15028"
"8.10000","0.53858","0.15127"
"8.20000","0.54541","0.15277"
"8.30000","0.55198","0.15417"
"8.40000","0.55847","0.15523"
"8.50000","0.56518","0.15664"
"8.60000","0.57167","0.15806"
"8.70000","0.57858","0.15930"
"8.80000","0.58543","0.16109"
"8.90000","0.59237","0.16187"
"9.00000","0.59886","0.16318"
"9.10000","0.60492","0.16420"
"9.20000","0.61147","0.16598"
"9.30000","0.61870","0.16746"
"9.40000","0.62557","0.16873"
"9.50000","0.63204","0.16980"
"9.60000","0.63827","0.17106"
"9.70000","0.64559","0.17216"
"9.80000","0.65245","0.17406"
"9.90000","0.65874","0.17513"
"10.00000","0.66499","0.17608"
"10.10000","0.67156","0.17746"
"10.20000","0.67863","0.17865"
"10.30000","0.68551","0.18002"
"10.40000","0.69201","0.18134"
"10.50000","0.69879","0.18245"
"10.60000","0.70527","0.18314"
"10.70000","0.71202","0.18499"
"10.80000","0.71854","0.18609"
"10.90000","0.72525","0.18731"
"11.00000","0.73203","0.18846"
"11.10000","0.73849","0.18952"
"11.20000","0.74508","0.19051"
"11.30000","0.75227","0.19210"
"11.40000","0.75913","0.19288"
"11.50000","0.76541","0.19405"
"11.60000","0.77158","0.19516"
"11.70000","0.77827","0.19677"
"11.80000","0.78562","0.19789"
"11.90000","0.79229","0.19897"
"12.00000","0.79859","0.19978"
"12.10000","0.80504","0.20089"
"12.20000","0.81207","0.20235"
"12.30000","0.81898","0.20392"
"12.40000","0.82530","0.20467"
"12.50000","0.83168","0.20550"
"12.60000","0.83830","0.20651"
"12.70000","0.84517","0.20792"
"12.80000","0.85209","0.20871"
"12.90000","0.85873","0.20998"
"13.00000","0.86539","0.21117"
"13.10000","0.87186","0.21277"
"13.20000","0.87840","0.21332"
"13.30000","0.88511","0.21461"
"13.40000","0.89224","0.21600"
"13.50000","0.89862","0.21639"
"13.60000","0.90498","0.21759"
"13.70000","0.91174","0.21893"
"13.80000","0.91920","0.21999"
"13.90000","0.92586","0.22150"
"14.00000","0.93190","0.22210"
"14.10000","0.93810","0.22311"
"14.20000","0.94512","0.22426"
"14.30000","0.95225","0.22517"
"14.40000","0.95883","0.22631"
"14.50000","0.96516","0.22714"
"14.60000","0.97184","0.22832"
"14.70000","0.97876","0.22948"
"14.80000","0.98556","0.23050"
"14.90000","0.99198","0.23134"
"15.00000","0.99847","0.23243"
"15.10000","1.00513","0.23319"
"15.20000","1.01191","0.23392"
"15.30000","1.01873","0.23565"
"15.40000","1.02567","0.23722"
"15.50000","1.03212","0.23743"
"15.60000","1.03848","0.23832"
"15.70000","1.04497","0.23941"
"15.80000","1.05190","0.24046"
"15.90000","1.05891","0.24139"
"16.00000","1.06535","0.24224"
"16.10000","1.07177","0.24371"
"16.20000","1.07861","0.24479"
"16.30000","1.08578","0.24573"
"16.40000","1.09232","0.24667"
"16.50000","1.09848","0.24717"
"16.60000","1.10475","0.24831"
"16.70000","1.11185","0.24900"
"16.80000","1.11885","0.25037"
"16.90000","1.12541","0.25142"
"17.00000","1.13187","0.25197"
"17.10000","1.13853","0.25291"
"17.20000","1.14533","0.25414"
"17.30000","1.15201","0.25551"
"17.40000","1.15855","0.25586"
"17.50000","1.16530","0.25672"
"17.60000","1.17172","0.25789"
"17.70000","1.17846","0.25896"
"17.80000","1.18524","0.25959"
"17.90000","1.19241","0.26078"
"18.00000","1.19886","0.26191"
"18.10000","1.20502","0.26253"
"18.20000","1.21146","0.26360"
"18.30000","1.21876","0.26420"
"18.40000","1.22556","0.26561"
"18.50000","1.23209","0.26618"
"18.60000","1.23837","0.26715"
"18.70000","1.24532","0.26851"
"18.80000","1.25240","0.26931"
"18.90000","1.25881","0.26991"
"19.00000","1.26514","0.27080"
"19.10000","1.27157","0.27192"
"19.20000","1.27852","0.27262"
"19.30000","1.28545","0.27361"
"19.40000","1.29206","0.27470"
"19.50000","1.29883","0.27575"
"19.60000","1.30524","0.27644"
"19.70000","1.31186","0.27733"
"19.80000","1.31855","0.27812"
"19.90000","1.32524","0.27910"
"20.00000","1.33206","0.28004"
"20.10000","1.33852","0.28082"
"20.20000","1.34510","0.28148"
"20.30000","1.35223","0.28268"
"20.40000","1.35908","0.28356"
"20.50000","1.36547","0.28452"
"20.60000","1.37167","0.28552"
"20.70000","1.37817","0.28597"
"20.80000","1.38547","0.28747"
"20.90000","1.39233","0.28845"
"21.00000","1.39870","0.28863"
"21.10000","1.40498","0.28937"
"21.20000","1.41202","0.29029"
"21.30000","1.41901","0.29133"
"21.40000","1.42530","0.29224"
"21.50000","1.43158","0.29290"
"21.60000","1.43838","0.29374"
"21.70000","1.44533","0.29502"
"21.80000","1.45201","0.29566"
"21.90000","1.45869","0.29664"
"22.00000","1.46551","0.29713"
"22.10000","1.47190","0.29795"
"22.20000","1.47844","0.29875"
"22.30000","1.48503","0.29955"
"22.40000","1.49215","0.30070"
"22.50000","1.49876","0.30141"
"22.60000","1.50507","0.30193"
"22.70000","1.51166","0.30307"
"22.80000","1.51908","0.30397"
"22.90000","1.52578","0.30485"
"23.00000","1.53192","0.30537"
"23.10000","1.53803","0.30558"
"23.20000","1.54517","0.30706"
"23.30000","1.55225","0.30821"
"23.40000","1.55880","0.30875"
"23.50000","1.56520","0.30949"
"23.60000","1.57181","0.31034"
"23.70000","1.57877","0.31120"
"23.80000","1.58545","0.31212"
"23.90000","1.59188","0.31278"
"24.00000","1.59854","0.31327"
"24.10000","1.60518","0.31427"
"24.20000","1.61196","0.31505"
"24.30000","1.61868","0.31565"
"24.40000","1.62570","0.31667"
"24.50000","1.63221","0.31703"
"24.60000","1.63844","0.31813"
"24.70000","1.64499","0.31875"
"24.80000","1.65196","0.31954"
"24.90000","1.65896","0.32081"
"25.00000","1.66539","0.32089"
"25.10000","1.67173","0.32117"
"25.20000","1.67864","0.32244"
"25.30000","1.68577","0.32319"
"25.40000","1.69236","0.32406"
"25.50000","1.69847","0.32482"
"25.60000","1.70473","0.32529"
"25.70000","1.71185","0.32617"
"25.80000","1.71889","0.32699"
"25.90000","1.72542","0.32746"
"26.00000","1.73196","0.32836"
"26.10000","1.73856","0.32882"
"26.20000","1.74538","0.32980"
"26.30000","1.75189","0.33064"
"26.40000","1.75846","0.33110"
"26.50000","1.76530","0.33193"
"26.60000","1.77173","0.33216"
"26.70000","1.77849","0.33316"
"26.80000","1.78531","0.33345"
"26.90000","1.79242","0.33482"
"27.00000","1.79885","0.33529"
"27.10000","1.80507","0.33594"
"27.20000","1.81152","0.33661"
"27.30000","1.81871","0.33754"
"27.40000","1.82559","0.33822"
"27.50000","1.83202","0.33857"
"27.60000","1.83826","0.33899"
"27.70000","1.84537","0.33977"
"27.80000","1.85243","0.34111"
"27.90000","1.85876","0.34133"
"28.00000","1.86497","0.34199"
"28.10000","1.87156","0.34248"
"28.20000","1.87857","0.34337"
"28.30000","1.88549","0.34419"
"28.40000","1.89204","0.34489"
"28.50000","1.89880","0.34533"
"28.60000","1.90527","0.34596"
"28.70000","1.91194","0.34649"
"28.80000","1.91854","0.34742"
"28.90000","1.92525","0.34812"
"29.00000","1.93209","0.34860"
"29.10000","1.93849","0.34937"
"29.20000","1.94514","0.34948"
"29.30000","1.95229","0.35047"
"29.40000","1.95903","0.35148"
"29.50000","1.96530","0.35184"
"29.60000","1.97156","0.35238"
"29.70000","1.97837","0.35289"
"29.80000","1.98562","0.35386"
"29.90000","1.99229","0.35419"
"30.00000","1.99854","0.35489"
"30.10000","2.00504","0.35520"
"30.20000","2.01201","0.35617"
"30.30000","2.01898","0.35680"
"30.40000","2.02527","0.35711"
"30.50000","2.03162","0.35748"
"30.60000","2.03838","0.35872"
"30.70000","2.04523","0.35910"
"30.80000","2.05194","0.36015"
"30.90000","2.05885","0.36055"
"31.00000","2.06552","0.36129"
"31.10000","2.07186","0.36186"
"31.20000","2.07839","0.36214"
"31.30000","2.08507","0.36305"
"31.40000","2.09219","0.36334"
"31.50000","2.09867","0.36396"
"31.60000","2.10499","0.36444"
"31.70000","2.11173","0.36510"
"31.80000","2.11915","0.36610"
"31.90000","2.12581","0.36661"
"32.00000","2.13196","0.36699"
"32.10000","2.13812","0.36731"
"32.20000","2.14525","0.36823"
"32.30000","2.15219","0.36906"
"32.40000","2.15883","0.36915"
"32.50000","2.16521","0.36999"
"32.60000","2.17185","0.37063"
"32.70000","2.17863","0.37093"
"32.80000","2.18548","0.37164"
"32.90000","2.19198","0.37234"
"33.00000","2.19854","0.37270"
"33.10000","2.20514","0.37332"
"33.20000","2.21190","0.37369"
"33.30000","2.21872","0.37482"
"33.40000","2.22568","0.37521"
"33.50000","2.23222","0.37647"
"33.60000","2.23851","0.37620"
"33.70000","2.24496","0.37655"
"33.80000","2.25195","0.37762"
"33.90000","2.25896","0.37805"
"34.00000","2.26538","0.37874"
"34.10000","2.27164","0.37883"
"34.20000","2.27859","0.37969"
"34.30000","2.28577","0.38010"
"34.40000","2.29240","0.38099"
"34.50000","2.29842","0.38144"
"34.60000","2.30474","0.38149"
"34.70000","2.31185","0.38237"
"34.80000","2.31890","0.38312"
"34.90000","2.32547","0.38403"
"35.00000","2.33193","0.38381"
"35.10000","2.33856","0.38441"
"35.20000","2.34534","0.38539"
"35.30000","2.35200","0.38574"
"35.40000","2.35848","0.38626"
"35.50000","2.36516","0.38676"
"35.60000","2.37172","0.38696"
"35.70000","2.37851","0.38785"
"35.80000","2.38537","0.38834"
"35.90000","2.39247","0.38902"
"36.00000","2.39878","0.38947"
"36.10000","2.40496","0.39002"
"36.20000","2.41153","0.39060"
"36.30000","2.41878","0.39091"
"36.40000","2.42555","0.39161"
"36.50000","2.43211","0.39244"
"36.60000","2.43829","0.39248"
"36.70000","2.44539","0.39328"
"36.80000","2.45252","0.39370"
"36.90000","2.45876","0.39413"
"37.00000","2.46500","0.39423"
"37.10000","2.47154","0.39512"
"37.20000","2.47860","0.39578"
"37.30000","2.48551","0.39636"
"37.40000","2.49213","0.39683"
"37.50000","2.49877","0.39720"
"37.60000","2.50514","0.39798"
"37.70000","2.51188","0.39796"
"37.80000","2.51859","0.39857"
"37.90000","2.52531","0.39918"
"38.00000","2.53210","0.39931"
"38.10000","2.53843","0.39989"
"38.20000","2.54504","0.40049"
"38.30000","2.55223","0.40166"
"38.40000","2.55912","0.40161"
"38.50000","2.56538","0.40252"
"38.60000","2.57161","0.40268"
"38.70000","2.57833","0.40365"
"38.80000","2.58559","0.40373"
"38.90000","2.59228","0.40463"
"39.00000","2.59859","0.40446"
"39.10000","2.60501","0.40525"
"39.20000","2.61207","0.40570"
"39.30000","2.61896","0.40623"
"39.40000","2.62531","0.40688"
"39.50000","2.63169","0.40699"
"39.60000","2.63830","0.40778"
"39.70000","2.64523","0.40830"
"39.80000","2.65206","0.40872"
"39.90000","2.65869","0.40938"
"40.00000","2.66543","0.40982"
"40.10000","2.67189","0.41008"
"40.20000","2.67837","0.41063"
"40.30000","2.68511","0.41106"
"40.40000","2.69211","0.41157"
"40.50000","2.69869","0.41216"
"40.60000","2.70504","0.41255"
"40.70000","2.71171","0.41296"
"40.80000","2.71903","0.41393"
"40.90000","2.72575","0.41427"
"41.00000","2.73195","0.41428"
"41.10000","2.73808","0.41469"
"41.20000","2.74516","0.41560"
"41.30000","2.75224","0.41638"
"41.40000","2.75885","0.41649"
"41.50000","2.76525","0.41729"
"41.60000","2.77186","0.41731"
"41.70000","2.77873","0.41852"
"41.80000","2.78552","0.41881"
"41.90000","2.79189","0.41887"
"42.00000","2.79845","0.41916"
"42.10000","2.80514","0.41994"
"42.20000","2.81192","0.42059"
"42.30000","2.81870","0.42109"
"42.40000","2.82565","0.42175"
"42.50000","2.83225","0.42200"
"42.60000","2.83855","0.42202"
"42.70000","2.84499","0.42250"
"42.80000","2.85188","0.42317"
"42.90000","2.85894","0.42361"
"43.00000","2.86543","0.42411"
"43.10000","2.87180","0.42464"
"43.20000","2.87854","0.42514"
"43.30000","2.88564","0.42551"
"43.40000","2.89233","0.42617"
"43.50000","2.89853","0.42610"
"43.60000","2.90481","0.42659"
"43.70000","2.91190","0.42711"
"43.80000","2.91886","0.42770"
"43.90000","2.92533","0.42823"
"44.00000","2.93190","0.42812"
"44.10000","2.93863","0.42912"
"44.20000","2.94532","0.42932"
"44.30000","2.95193","0.42956"
"44.40000","2.95830","0.43028"
"44.50000","2.96522","0.43088"
"44.60000","2.97185","0.43121"
"44.70000","2.97856","0.43150"
"44.80000","2.98526","0.43200"
"44.90000","2.99229","0.43225"
"45.00000","2.99884","0.43299"
"45.10000","3.00507","0.43308"
"45.20000","3.01158","0.43393"
"45.30000","3.01867","0.43415"
"45.40000","3.02546","0.43450"
"45.50000","3.03204","0.43521"
"45.60000","3.03843","0.43511"
"45.70000","3.04548","0.43619"
"45.80000","3.05241","0.43649"
"45.90000","3.05869","0.43687"
"46.00000","3.06496","0.43710"
"46.10000","3.07169","0.43751"
"46.20000","3.07866","0.43762"
"46.30000","3.08542","0.43817"
"46.40000","3.09199","0.43858"
"46.50000","3.09875","0.43926"
"46.60000","3.10537","0.43931"
"46.70000","3.11203","0.44011"
"46.80000","3.11847","0.43978"
"46.90000","3.12519","0.44060"
"47.00000","3.13201","0.44105"
"47.10000","3.13866","0.44114"
"47.20000","3.14515","0.44156"
"47.30000","3.15214","0.44232"
"47.40000","3.15905","0.44264"
"47.50000","3.16538","0.44239"
"47.60000","3.17173","0.44363"
"47.70000","3.17833","0.44380"
"47.80000","3.18551","0.44412"
"47.90000","3.19212","0.44467"
"48.00000","3.19857","0.44483"
"48.10000","3.20512","0.44544"
"48.20000","3.21211","0.44580"
"48.30000","3.21885","0.44612"
"48.40000","3.22518","0.44636"
"48.50000","3.23158","0.44671"
"48.60000","3.23852","0.44733"
"48.70000","3.24524","0.44754"
"48.80000","3.25191","0.44783"
"48.90000","3.25859","0.44830"
"49.00000","3.26542","0.44897"
"49.10000","3.27212","0.44934"
"49.20000","3.27846","0.44945"
"49.30000","3.28502","0.44987"
"49.40000","3.29202","0.45088"
"49.50000","3.29870","0.45101"
"49.60000","3.30526","0.45100"
"49.70000","3.31181","0.45200"
"49.80000","3.31893","0.45189"
"49.90000","3.32566","0.45248"
"50.00000","3.33194","0.45262"
"50.10000","3.33815","0.45256"
"50.20000","3.34521","0.45342"
"50.30000","3.35213","0.45354"
"50.40000","3.35869","0.45431"
"50.50000","3.36519","0.45460"
"50.60000","3.37205","0.45474"
"50.70000","3.37883","0.45541"
"50.80000","3.38539","0.45559"
"50.90000","3.39176","0.45546"
"51.00000","3.39847","0.45665"
"51.10000","3.40536","0.45668"
"51.20000","3.41204","0.45722"
"51.30000","3.41858","0.45720"
"51.40000","3.42538","0.45791"
"51.50000","3.43224","0.45843"
"51.60000","3.43872","0.45851"
"51.70000","3.44521","0.45907"
"51.80000","3.45174","0.45930"
"51.90000","3.45868","0.45974"
"52.00000","3.46530","0.45993"
"52.10000","3.47193","0.46081"
"52.20000","3.47872","0.46109"
"52.30000","3.48560","0.46144"
"52.40000","3.49222","0.46174"
"52.50000","3.49858","0.46171"
"52.60000","3.50492","0.46241"
"52.70000","3.51192","0.46297"
"52.80000","3.51883","0.46336"
"52.90000","3.52532","0.46355"
"53.00000","3.53187","0.46407"
"53.10000","3.53877","0.46438"
"53.20000","3.54541","0.46458"
"53.30000","3.55186","0.46456"
"53.40000","3.55823","0.46553"
"53.50000","3.56518","0.46574"
"53.60000","3.57187","0.46583"
"53.70000","3.57858","0.46647"
"53.80000","3.58526","0.46698"
"53.90000","3.59224","0.46725"
"54.00000","3.59885","0.46748"
"54.10000","3.60521","0.46763"
"54.20000","3.61157","0.46842"
"54.30000","3.61866","0.46894"
"54.40000","3.62540","0.46896"
"54.50000","3.63203","0.46915"
"54.60000","3.63852","0.46918"
"54.70000","3.64554","0.46934"
"54.80000","3.65236","0.46994"
"54.90000","3.65863","0.47044"
"55.00000","3.66495","0.47023"
"55.10000","3.67169","0.47072"
"55.20000","3.67866","0.47090"
"55.30000","3.68541","0.47132"
"55.40000","3.69200","0.47165"
"55.50000","3.69884","0.47263"
"55.60000","3.70539","0.47233"
"55.70000","3.71199","0.47270"
"55.80000","3.71847","0.47307"
"55.90000","3.72521","0.47372"
"56.00000","3.73200","0.47359"
"56.10000","3.73866","0.47417"
"56.20000","3.74513","0.47397"
"56.30000","3.75214","0.47437"
"56.40000","3.75904","0.47513"
"56.50000","3.76537","0.47517"
"56.60000","3.77175","0.47549"
"56.70000","3.77835","0.47579"
"56.80000","3.78547","0.47639"
"56.90000","3.79219","0.47663"
"57.00000","3.79857","0.47665"
"57.10000","3.80509","0.47736"
"57.20000","3.81213","0.47761"
"57.30000","3.81893","0.47793"
"57.40000","3.82521","0.47786"
"57.50000","3.83159","0.47815"
"57.60000","3.83845","0.47881"
"57.70000","3.84529","0.47893"
"57.80000","3.85190","0.47937"
"57.90000","3.85856","0.47957"
"58.00000","3.86550","0.48032"
"58.10000","3.87206","0.47996"
"58.20000","3.87845","0.48065"
"58.30000","3.88494","0.48070"
"58.40000","3.89195","0.48105"
"58.50000","3.89874","0.48151"
"58.60000","3.90510","0.48187"
"58.70000","3.91180","0.48223"
"58.80000","3.91902","0.48231"
"58.90000","3.92572","0.48266"
"59.00000","3.93198","0.48308"
"59.10000","3.93813","0.48299"
"59.20000","3.94521","0.48340"
"59.30000","3.95216","0.48422"
"59.40000","3.95871","0.48383"
"59.50000","3.96520","0.48389"
"59.60000","3.97199","0.48473"
"59.70000","3.97885","0.48518"
"59.80000","3.98546","0.48509"
"59.90000","3.99181","0.48511"
"60.00000","3.99845","0.48587"
"60.10000","4.00517","0.48590"
"60.20000","4.01195","0.48633"
"60.30000","4.01871","0.48671"
"60.40000","4.02552","0.48680"
"60.50000","4.03225","0.48752"
"60.60000","4.03862","0.48734"
"60.70000","4.04507","0.48777"
"60.80000","4.05182","0.48804"
"60.90000","4.05880","0.48853"
"61.00000","4.06538","0.48890"
"61.10000","4.07180","0.48893"
"61.20000","4.07877","0.48910"
"61.30000","4.08564","0.48918"
"61.40000","4.09219","0.48952"
"61.50000","4.09847","0.48970"
"61.60000","4.10481","0.48966"
"61.70000","4.11196","0.49012"
"61.80000","4.11877","0.49044"
"61.90000","4.12536","0.49063"
"62.00000","4.13190","0.49090"
"62.10000","4.13858","0.49070"
"62.20000","4.14544","0.49163"
"62.30000","4.15190","0.49158"
"62.40000","4.15837","0.49218"
"62.50000","4.16520","0.49229"
"62.60000","4.17177","0.49256"
"62.70000","4.17856","0.49302"
"62.80000","4.18521","0.49272"
"62.90000","4.19237","0.49348"
"63.00000","4.19884","0.49361"
"63.10000","4.20504","0.49366"
"63.20000","4.21157","0.49403"
"63.30000","4.21872","0.49441"
"63.40000","4.22549","0.49430"
"63.50000","4.23194","0.49471"
"63.60000","4.23826","0.49520"
"63.70000","4.24559","0.49472"
"63.80000","4.25246","0.49545"
"63.90000","4.25881","0.49536"
"64.00000","4.26502","0.49576"
"64.10000","4.27154","0.49581"
"64.20000","4.27865","0.49631"
"64.30000","4.28553","0.49680"
"64.40000","4.29204","0.49667"
"64.50000","4.29876","0.49712"
"64.60000","4.30525","0.49716"
"64.70000","4.31195","0.49733"
"64.80000","4.31863","0.49791"
"64.90000","4.32530","0.49815"
"65.00000","4.33192","0.49784"
"65.10000","4.33834","0.49874"
"65.20000","4.34517","0.49864"
"65.30000","4.35231","0.49898"
"65.40000","4.35901","0.49923"
"65.50000","4.36537","0.49938"
"65.60000","4.37156","0.49928"
"65.70000","4.37822","0.50030"
"65.80000","4.38562","0.50071"
"65.90000","4.39229","0.50053"
"66.00000","4.39862","0.50064"
"66.10000","4.40505","0.50103"
"66.20000","4.41197","0.50139"
"66.30000","4.41907","0.50179"
"66.40000","4.42533","0.50131"
"66.50000","4.43158","0.50188"
"66.60000","4.43833","0.50230"
"66.70000","4.44530","0.50289"
"66.80000","4.45208","0.50297"
"66.90000","4.45878","0.50299"
"67.00000","4.46535","0.50323"
"67.10000","4.47192","0.50362"
"67.20000","4.47847","0.50315"
"67.30000","4.48512","0.50399"
"67.40000","4.49216","0.50464"
"67.50000","4.49866","0.50458"
"67.60000","4.50498","0.50471"
"67.70000","4.51173","0.50476"
"67.80000","4.51915","0.50504"
"67.90000","4.52572","0.50551"
"68.00000","4.53194","0.50539"
"68.10000","4.53806","0.50513"
"68.20000","4.54514","0.50617"
"68.30000","4.55232","0.50618"
"68.40000","4.55882","0.50634"
"68.50000","4.56514","0.50646"
"68.60000","4.57185","0.50690"
"68.70000","4.57879","0.50750"
"68.80000","4.58547","0.50767"
"68.90000","4.59194","0.50759"
"69.00000","4.59858","0.50782"
"69.10000","4.60511","0.50796"
"69.20000","4.61188","0.50821"
"69.30000","4.61863","0.50848"
"69.40000","4.62563","0.50903"
"69.50000","4.63225","0.50915"
"69.60000","4.63853","0.50889"
"69.70000","4.64504","0.50916"
"69.80000","4.65187","0.50995"
"69.90000","4.65883","0.50994"
"70.00000","4.66544","0.51040"
"70.10000","4.67181","0.51044"
"70.20000","4.67862","0.51103"
"70.30000","4.68575","0.51084"
"70.40000","4.69234","0.51110"
"70.50000","4.69862","0.51081"
"70.60000","4.70485","0.51106"
"70.70000","4.71185","0.51101"
"70.80000","4.71882","0.51155"
"70.90000","4.72538","0.51120"
"71.00000","4.73185","0.51152"
"71.10000","4.73858","0.51134"
"71.20000","4.74538","0.51189"
"71.30000","4.75199","0.51152"
"71.40000","4.75841","0.51160"
"71.50000","4.76522","0.51175"
"71.60000","4.77174","0.51245"
"71.70000","4.77856","0.51214"
"71.80000","4.78529","0.51296"
"71.90000","4.79234","0.51329"
"72.00000","4.79889","0.51337"
"72.10000","4.80505","0.51381"
"72.20000","4.81153","0.51317"
"72.30000","4.81864","0.51413"
"72.40000","4.82550","0.51412"
"72.50000","4.83202","0.51414"
"72.60000","4.83830","0.51416"
"72.70000","4.84561","0.51469"
"72.80000","4.85247","0.51506"
"72.90000","4.85864","0.51482"
"73.00000","4.86502","0.51471"
"73.10000","4.87168","0.51532"
"73.20000","4.87869","0.51545"
"73.30000","4.88547","0.51553"
"73.40000","4.89197","0.51561"
"73.50000","4.89879","0.51593"
"73.60000","4.90527","0.51584"
"73.70000","4.91198","0.51608"
"73.80000","4.91857","0.51600"
"73.90000","4.92518","0.51600"
"74.00000","4.93208","0.51616"
"74.10000","4.93858","0.51642"
"74.20000","4.94513","0.51629"
"74.30000","4.95218","0.51714"
"74.40000","4.95901","0.51713"
"74.50000","4.96544","0.51718"
"74.60000","4.97173","0.51767"
"74.70000","4.97836","0.51775"
"74.80000","4.98551","0.51816"
"74.90000","4.99219","0.51824"
"75.00000","4.99865","0.51828"
"75.10000","5.00504","0.51849"
"75.20000","5.01200","0.51894"
"75.30000","5.01893","0.51918"
"75.40000","5.02524","0.51862"
"75.50000","5.03161","0.51876"
"75.60000","5.03843","0.51913"
"75.70000","5.04532","0.51921"
"75.80000","5.05205","0.51950"
"75.90000","5.05867","0.51971"
"76.00000","5.06545","0.51978"
"76.10000","5.07187","0.51966"
"76.20000","5.07846","0.51992"
"76.30000","5.08507","0.52015"
"76.40000","5.09206","0.52023"
"76.50000","5.09867","0.52037"
"76.60000","5.10506","0.52019"
"76.70000","5.11174","0.52088"
"76.80000","5.11910","0.52088"
"76.90000","5.12569","0.52078"
"77.00000","5.13192","0.52036"
"77.10000","5.13810","0.52045"
"77.20000","5.14523","0.52110"
"77.30000","5.15228","0.52126"
"77.40000","5.15873","0.52155"
"77.50000","5.16518","0.52162"
"77.60000","5.17188","0.52162"
"77.70000","5.17877","0.52224"
"77.80000","5.18547","0.52221"
"77.90000","5.19192","0.52249"
"78.00000","5.19844","0.52275"
"78.10000","5.20513","0.52260"
"78.20000","5.21198","0.52294"
"78.30000","5.21871","0.52285"
"78.40000","5.22555","0.52320"
"78.50000","5.23228","0.52292"
"78.60000","5.23849","0.52327"
"78.70000","5.24501","0.52348"
"78.80000","5.25186","0.52286"
"78.90000","5.25880","0.52332"
"79.00000","5.26543","0.52323"
"79.10000","5.27179","0.52346"
"79.20000","5.27868","0.52334"
"79.30000","5.28573","0.52353"
"79.40000","5.29228","0.52370"
"79.50000","5.29857","0.52385"
"79.60000","5.30479","0.52367"
"79.70000","5.31192","0.52418"
"79.80000","5.31887","0.52414"
"79.90000","5.32549","0.52409"
"80.00000","5.33191","0.52412"
"80.10000","5.33851","0.52439"
"80.20000","5.34538","0.52464"
"80.30000","5.35193","0.52434"
"80.40000","5.35840","0.52439"
"80.50000","5.36523","0.52426"
"80.60000","5.37176","0.52473"
"80.70000","5.37853","0.52461"
"80.80000","5.38530","0.52496"
"80.90000","5.39236","0.52513"
"81.00000","5.39881","0.52492"
"81.10000","5.40502","0.52492"
"81.20000","5.41158","0.52439"
"81.30000","5.41869","0.52527"
"81.40000","5.42550","0.52503"
"81.50000","5.43204","0.52506"
"81.60000","5.43831","0.52462"
"81.70000","5.44552","0.52534"
"81.80000","5.45239","0.52505"
"81.90000","5.45878","0.52494"
"82.00000","5.46503","0.52449"
"82.10000","5.47148","0.52490"
"82.20000","5.47861","0.52518"
"82.30000","5.48552","0.52537"
"82.40000","5.49204","0.52495"
"82.50000","5.49888","0.52531"
"82.60000","5.50526","0.52525"
"82.70000","5.51198","0.52505"
"82.80000","5.51856","0.52474"
"82.90000","5.52524","0.52518"
"83.00000","5.53207","0.52464"
"83.10000","5.53847","0.52450"
"83.20000","5.54509","0.52517"
"83.30000","5.55232","0.52467"
"83.40000","5.55912","0.52489"
"83.50000","5.56544","0.52435"
"83.60000","5.57159","0.52417"
"83.70000","5.57831","0.52437"
"83.80000","5.58547","0.52451"
"83.90000","5.59226","0.52444"
"84.00000","5.59863","0.52442"
"84.10000","5.60500","0.52391"
"84.20000","5.61198","0.52403"
"84.30000","5.61903","0.52440"
"84.40000","5.62531","0.52407"
"84.50000","5.63161","0.52421"
"84.60000","5.63836","0.52409"
"84.70000","5.64532","0.52444"
"84.80000","5.65201","0.52332"
"84.90000","5.65869","0.52413"
"85.00000","5.66552","0.52442"
"85.10000","5.67201","0.52378"
"85.20000","5.67848","0.52396"
"85.30000","5.68504","0.52366"
"85.40000","5.69206","0.52381"
"85.50000","5.69877","0.52381"
"85.60000","5.70502","0.52310"
"85.70000","5.71165","0.52349"
"85.80000","5.71907","0.52371"
"85.90000","5.72573","0.52353"
"86.00000","5.73196","0.52339"
"86.10000","5.73812","0.52295"
"86.20000","5.74514","0.52272"
"86.30000","5.75224","0.52318"
"86.40000","5.75882","0.52233"
"86.50000","5.76526","0.52245"
"86.60000","5.77190","0.52180"
"86.70000","5.77875","0.52248"
"86.80000","5.78546","0.52171"
"86.90000","5.79191","0.52126"
"87.00000","5.79851","0.52126"
"87.10000","5.80508","0.52128"
"87.20000","5.81188","0.52092"
"87.30000","5.81875","0.52099"
"87.40000","5.82563","0.52068"
"87.50000","5.83222","0.52061"
"87.60000","5.83847","0.52003"
"87.70000","5.84501","0.52001"
"87.80000","5.85194","0.52052"
"87.90000","5.85893","0.51977"
"88.00000","5.86541","0.51939"
"88.10000","5.87183","0.51952"
"88.20000","5.87867","0.51926"
"88.30000","5.88563","0.51908"
"88.40000","5.89230","0.51898"
"88.50000","5.89853","0.51832"
"88.60000","5.90473","0.51772"
"88.70000","5.91184","0.51795"
"88.80000","5.91878","0.51767"
"88.90000","5.92545","0.51756"
"89.00000","5.93186","0.51671"
"89.10000","5.93853","0.51656"
"89.20000","5.94534","0.51613"
"89.30000","5.95189","0.51587"
"89.40000","5.95845","0.51567"
"89.50000","5.96521","0.51537"
"89.60000","5.97166","0.51493"
"89.70000","5.97861","0.51493"
"89.80000","5.98546","0.51438"
"89.90000","5.99236","0.51419"
"90.00000","5.99877","0.51391"
"90.10000","6.00502","0.51283"
"90.20000","6.01145","0.51282"
"90.30000","6.01862","0.51318"
"90.40000","6.02559","0.51247"
"90.50000","6.03217","0.51207"
"90.60000","6.03832","0.51151"
"90.70000","6.04541","0.51133"
"90.80000","6.05244","0.51098"
"90.90000","6.05881","0.51013"
"91.00000","6.06504","0.50971"
"91.10000","6.07161","0.50937"
"91.20000","6.07858","0.50904"
"91.30000","6.08544","0.50837"
"91.40000","6.09209","0.50760"
"91.50000","6.09881","0.50781"
"91.60000","6.10520","0.50677"
"91.70000","6.11191","0.50667"
"91.80000","6.11855","0.50587"
"91.90000","6.12536","0.50528"
"92.00000","6.13210","0.50449"
"92.10000","6.13846","0.50395"
"92.20000","6.14509","0.50315"
"92.30000","6.15229","0.50237"
"92.40000","6.15917","0.50143"
"92.50000","6.16536","0.50008"
"92.60000","6.17153","0.49961"
"92.70000","6.17829","0.49893"
"92.80000","6.18553","0.49842"
"92.90000","6.19228","0.49724"
"93.00000","6.19857","0.49688"
"93.10000","6.20506","0.49633"
"93.20000","6.21211","0.49530"
"93.30000","6.21901","0.49457"
"93.40000","6.22528","0.49358"
"93.50000","6.23151","0.49303"
"93.60000","6.23827","0.49201"
"93.70000","6.24521","0.49151"
"93.80000","6.25207","0.49100"
"93.90000","6.25873","0.49018"
"94.00000","6.26548","0.48903"
"94.10000","6.27194","0.48796"
"94.20000","6.27839","0.48765"
"94.30000","6.28509","0.48644"
"94.40000","6.29222","0.48587"
"94.50000","6.29872","0.48464"
"94.60000","6.30493","0.48380"
"94.70000","6.31172","0.48305"
"94.80000","6.31910","0.48251"
"94.90000","6.32587","0.48173"
"95.00000","6.33186","0.47973"
"95.10000","6.33799","0.47919"
"95.20000","6.34520","0.47917"
"95.30000","6.35237","0.47803"
"95.40000","6.35876","0.47763"
"95.50000","6.36520","0.47608"
"95.60000","6.37188","0.47593"
"95.70000","6.37869","0.47505"
"95.80000","6.38547","0.47431"
"95.90000","6.39195","0.47336"
"96.00000","6.39854","0.47270"
"96.10000","6.40510","0.47212"
"96.20000","6.41190","0.47182"
"96.30000","6.41863","0.47103"
"96.40000","6.42574","0.47067"
"96.50000","6.43228","0.47014"
"96.60000","6.43845","0.46911"
"96.70000","6.44499","0.46861"
"96.80000","6.45193","0.46802"
"96.90000","6.45899","0.46710"
"97.00000","6.46535","0.46609"
"97.10000","6.47176","0.46553"
"97.20000","6.47858","0.46508"
"97.30000","6.48571","0.46429"
"97.40000","6.49233","0.46332"
"97.50000","6.49853","0.46253"
"97.60000","6.50477","0.46158"
"97.70000","6.51190","0.46123"
"97.80000","6.51885","0.46026"
"97.90000","6.52547","0.45941"
"98.00000","6.53195","0.45858"
"98.10000","6.53865","0.45785"
"98.20000","6.54531","0.45723"
"98.30000","6.55196","0.45609"
"98.40000","6.55846","0.45555"
"98.50000","6.56522","0.45479"
"98.60000","6.57175","0.45444"
"98.70000","6.57854","0.45384"
"98.80000","6.58535","0.45360"
"98.90000","6.59241","0.45277"
"99.00000","6.59882","0.45186"
"99.10000","6.60498","0.45107"
"99.20000","6.61143","0.45116"
"99.30000","6.61871","0.45024"
"99.40000","6.62554","0.44961"
"99.50000","6.63207","0.44897"
"99.60000","6.63840","0.44817"
"99.70000","6.64543","0.44760"
"99.80000","6.65244","0.44691"
"99.90000","6.65876","0.44612"
"100.00000","6.66505","0.44536"
"100.10000","6.67153","0.44487"
"100.20000","6.67856","0.44434"
"100.30000","6.68550","0.44372"
"100.40000","6.69203","0.44276"
"100.50000","6.69874","0.44251"
"100.60000","6.70524","0.44164"
"100.70000","6.71197","0.44067"
"100.80000","6.71854","0.43975"
"100.90000","6.72523","0.43934"
"101.00000","6.73201","0.43849"
"101.10000","6.73852","0.43793"
"101.20000","6.74511","0.43723"
"101.30000","6.75230","0.43647"
"101.40000","6.75908","0.43545"
"101.50000","6.76541","0.43406"
"101.60000","6.77154","0.43325"
"101.70000","6.77823","0.43268"
"101.80000","6.78559","0.43199"
"101.90000","6.79232","0.43096"
"102.00000","6.79868","0.42973"
"102.10000","6.80503","0.42951"
"102.20000","6.81205","0.42894"
"102.30000","6.81896","0.42814"
"102.40000","6.82529","0.42734"
"102.50000","6.83170","0.42660"
"102.60000","6.83844","0.42584"
"102.70000","6.84521","0.42492"
"102.80000","6.85189","0.42418"
"102.90000","6.85864","0.42392"
"103.00000","6.86550","0.42262"
"103.10000","6.87190","0.42162"
"103.20000","6.87841","0.42096"
"103.30000","6.88501","0.42022"
"103.40000","6.89221","0.41941"
"103.50000","6.89872","0.41889"
"103.60000","6.90505","0.41783"
"103.70000","6.91176","0.41741"
"103.80000","6.91908","0.41664"
"103.90000","6.92577","0.41537"
"104.00000","6.93199","0.41513"
"104.10000","6.93808","0.41379"
"104.20000","6.94512","0.41366"
"104.30000","6.95228","0.41314"
"104.40000","6.95882","0.41173"
"104.50000","6.96525","0.41075"
"104.60000","6.97190","0.40994"
"104.70000","6.97869","0.40979"
"104.80000","6.98548","0.40846"
"104.90000","6.99186","0.40773"
"105.00000","6.99849","0.40697"
"105.10000","7.00515","0.40625"
"105.20000","7.01194","0.40567"
"105.30000","7.01871","0.40452"
"105.40000","7.02566","0.40450"
"105.50000","7.03228","0.40369"
"105.60000","7.03852","0.40261"
"105.70000","7.04495","0.40166"
"105.80000","7.05182","0.40127"
"105.90000","7.05891","0.40078"
"106.00000","7.06541","0.39968"
"106.10000","7.07173","0.39901"
"106.20000","7.07860","0.39829"
"106.30000","7.08573","0.39778"
"106.40000","7.09233","0.39652"
"106.50000","7.09851","0.39589"
"106.60000","7.10478","0.39484"
"106.70000","7.11194","0.39426"
"106.80000","7.11886","0.39377"
"106.90000","7.12538","0.39307"
"107.00000","7.13192","0.39180"
"107.10000","7.13854","0.39137"
"107.20000","7.14543","0.39048"
"107.30000","7.15189","0.38934"
"107.40000","7.15836","0.38897"
"107.50000","7.16521","0.38840"
"107.60000","7.17173","0.38739"
"107.70000","7.17859","0.38682"
"107.80000","7.18531","0.38673"
"107.90000","7.19231","0.38550"
"108.00000","7.19891","0.38485"
"108.10000","7.20497","0.38429"
"108.20000","7.21152","0.38343"
"108.30000","7.21868","0.38313"
"108.40000","7.22553","0.38200"
"108.50000","7.23209","0.38140"
"108.60000","7.23831","0.38062"
"108.70000","7.24549","0.38068"
"108.80000","7.25244","0.37947"
"108.90000","7.25872","0.37888"
"109.00000","7.26501","0.37765"
"109.10000","7.27160","0.37742"
"109.20000","7.27870","0.37652"
"109.30000","7.28544","0.37575"
"109.40000","7.29201","0.37492"
"109.50000","7.29888","0.37437"
"109.60000","7.30528","0.37289"
"109.70000","7.31197","0.37254"
"109.80000","7.31855","0.37170"
"109.90000","7.32526","0.37098"
"110.00000","7.33206","0.36960"
"110.10000","7.33849","0.36905"
"110.20000","7.34518","0.36838"
"110.30000","7.35216","0.36756"
"110.40000","7.35907","0.36681"
"110.50000","7.36539","0.36541"
"110.60000","7.37162","0.36480"
"110.70000","7.37832","0.36442"
"110.80000","7.38549","0.36355"
"110.90000","7.39222","0.36310"
"111.00000","7.39862","0.36225"
"111.10000","7.40502","0.36158"
"111.20000","7.41215","0.36092"
"111.30000","7.41896","0.36052"
"111.40000","7.42528","0.35937"
"111.50000","7.43173","0.35887"
"111.60000","7.43829","0.35810"
"111.70000","7.44528","0.35775"
"111.80000","7.45202","0.35668"
"111.90000","7.45871","0.35644"
"112.00000","7.46547","0.35546"
"112.10000","7.47186","0.35441"
"112.20000","7.47846","0.35344"
"112.30000","7.48508","0.35298"
"112.40000","7.49212","0.35175"
"112.50000","7.49872","0.35113"
"112.60000","7.50502","0.35034"
"112.70000","7.51168","0.34996"
"112.80000","7.51904","0.34876"
"112.90000","7.52580","0.34813"
"113.00000","7.53195","0.34658"
"113.10000","7.53805","0.34561"
"113.20000","7.54519","0.34448"
"113.30000","7.55223","0.34372"
"113.40000","7.55877","0.34263"
"113.50000","7.56525","0.34150"
"113.60000","7.57187","0.34111"
"113.70000","7.57873","0.33975"
"113.80000","7.58543","0.33894"
"113.90000","7.59196","0.33756"
"114.00000","7.59849","0.33696"
"114.10000","7.60507","0.33565"
"114.20000","7.61194","0.33487"
"114.30000","7.61866","0.33405"
"114.40000","7.62572","0.33290"
"114.50000","7.63224","0.33213"
"114.60000","7.63852","0.33059"
"114.70000","7.64497","0.32944"
"114.80000","7.65186","0.32861"
"114.90000","7.65901","0.32754"
"115.00000","7.66542","0.32588"
"115.10000","7.67176","0.32533"
"115.20000","7.67857","0.32437"
"115.30000","7.68571","0.32305"
"115.40000","7.69231","0.32188"
"115.50000","7.69852","0.32041"
"115.60000","7.70472","0.31898"
"115.70000","7.71189","0.31895"
"115.80000","7.71887","0.31782"
"115.90000","7.72551","0.31594"
"116.00000","7.73202","0.31570"
"116.10000","7.73861","0.31409"
"116.20000","7.74540","0.31330"
"116.30000","7.75200","0.31177"
"116.40000","7.75841","0.31023"
"116.50000","7.76516","0.30925"
"116.60000","7.77175","0.30859"
"116.70000","7.77855","0.30740"
"116.80000","7.78530","0.30703"
"116.90000","7.79240","0.30553"
"117.00000","7.79883","0.30482"
"117.10000","7.80500","0.30351"
"117.20000","7.81144","0.30259"
"117.30000","7.81863","0.30200"
"117.40000","7.82557","0.30123"
"117.50000","7.83206","0.30003"
"117.60000","7.83836","0.29970"
"117.70000","7.84536","0.29893"
"117.80000","7.85240","0.29827"
"117.90000","7.85882","0.29767"
"118.00000","7.86502","0.29619"
"118.10000","7.87153","0.29567"
"118.20000","7.87865","0.29522"
"118.30000","7.88547","0.29435"
"118.40000","7.89204","0.29381"
"118.50000","7.89882","0.29298"
"118.60000","7.90525","0.29237"
"118.70000","7.91195","0.29146"
"118.80000","7.91850","0.29066"
"118.90000","7.92530","0.28964"
"119.00000","7.93205","0.28835"
"119.10000","7.93853","0.28785"
"119.20000","7.94513","0.28644"
"119.30000","7.95230","0.28617"
"119.40000","7.95908","0.28467"
"119.50000","7.96541","0.28383"
"119.60000","7.97164","0.28302"
"119.70000","7.97825","0.28277"
"119.80000","7.98550","0.28188"
"119.90000","7.99227","0.28053"
"120.00000","7.99865","0.27965"
"120.10000","8.00503","0.27875"
"120.20000","8.01203","0.27791"
"120.30000","8.01894","0.27701"
"120.40000","8.02531","0.27624"
"120.50000","8.03173","0.27499"
"120.60000","8.03836","0.27430"
"120.70000","8.04518","0.27386"
"120.80000","8.05193","0.27304"
"120.90000","8.05867","0.27218"
"121.00000","8.06556","0.27145"
"121.10000","8.07190","0.27096"
"121.20000","8.07845","0.27029"
"121.30000","8.08504","0.27011"
"121.40000","8.09213","0.26904"
"121.50000","8.09873","0.26819"
"121.60000","8.10504","0.26749"
"121.70000","8.11164","0.26649"
"121.80000","8.11905","0.26580"
"121.90000","8.12574","0.26515"
"122.00000","8.13199","0.26376"
"122.10000","8.13814","0.26289"
"122.20000","8.14522","0.26247"
"122.30000","8.15220","0.26140"
"122.40000","8.15878","0.26059"
"122.50000","8.16522","0.25956"
"122.60000","8.17190","0.25891"
"122.70000","8.17879","0.25786"
"122.80000","8.18542","0.25696"
"122.90000","8.19191","0.25584"
"123.00000","8.19849","0.25522"
"123.10000","8.20506","0.25443"
"123.20000","8.21197","0.25384"
"123.30000","8.21869","0.25214"
"123.40000","8.22557","0.25186"
"123.50000","8.23234","0.25006"
"123.60000","8.23857","0.24928"
"123.70000","8.24500","0.24801"
"123.80000","8.25183","0.24649"
"123.90000","8.25886","0.24532"
"124.00000","8.26541","0.24380"
"124.10000","8.27169","0.24280"
"124.20000","8.27863","0.24185"
"124.30000","8.28576","0.24041"
"124.40000","8.29234","0.23967"
"124.50000","8.29851","0.23861"
"124.60000","8.30474","0.23766"
"124.70000","8.31183","0.23672"
"124.80000","8.31874","0.23614"
"124.90000","8.32548","0.23483"
"125.00000","8.33210","0.23378"
"125.10000","8.33859","0.23296"
"125.20000","8.34530","0.23210"
"125.30000","8.35186","0.23129"
"125.40000","8.35845","0.23083"
"125.50000","8.36528","0.22949"
"125.60000","8.37174","0.22856"
"125.70000","8.37863","0.22766"
"125.80000","8.38537","0.22643"
"125.90000","8.39228","0.22531"
"126.00000","8.39890","0.22437"
"126.10000","8.40506","0.22287"
"126.20000","8.41152","0.22216"
"126.30000","8.41868","0.22104"
"126.40000","8.42551","0.22003"
"126.50000","8.43212","0.21831"
"126.60000","8.43837","0.21763"
"126.70000","8.44549","0.21686"
"126.80000","8.45241","0.21566"
"126.90000","8.45878","0.21453"
"127.00000","8.46505","0.21370"
"127.10000","8.47154","0.21291"
"127.20000","8.47865","0.21198"
"127.30000","8.48546","0.21061"
"127.40000","8.49201","0.20994"
"127.50000","8.49886","0.20923"
"127.60000","8.50522","0.20868"
"127.70000","8.51193","0.20749"
"127.80000","8.51865","0.20606"
"127.90000","8.52523","0.20503"
"128.00000","8.53193","0.20514"
"128.10000","8.53847","0.20405"
"128.20000","8.54520","0.20318"
"128.30000","8.55220","0.20230"
"128.40000","8.55905","0.20138"
"128.50000","8.56542","0.19968"
"128.60000","8.57162","0.19900"
"128.70000","8.57825","0.19799"
"128.80000","8.58555","0.19672"
"128.90000","8.59230","0.19537"
"129.00000","8.59863","0.19447"
"129.10000","8.60495","0.19379"
"129.20000","8.61202","0.19238"
"129.30000","8.61903","0.19182"
"129.40000","8.62532","0.19039"
"129.50000","8.63165","0.18947"
"129.60000","8.63832","0.18855"
"129.70000","8.64530","0.18743"
"129.80000","8.65202","0.18670"
"129.90000","8.65872","0.18563"
"130.00000","8.66555","0.18438"
"130.10000","8.67194","0.18357"
"130.20000","8.67846","0.18270"
"130.30000","8.68511","0.18228"
"130.40000","8.69204","0.18125"
"130.50000","8.69862","0.18013"
"130.60000","8.70500","0.17964"
"130.70000","8.71170","0.17882"
"130.80000","8.71907","0.17805"
"130.90000","8.72581","0.17690"
"131.00000","8.73194","0.17589"
"131.10000","8.73806","0.17487"
"131.20000","8.74506","0.17442"
"131.30000","8.75229","0.17392"
"131.40000","8.75882","0.17264"
"131.50000","8.76525","0.17228"
"131.60000","8.77187","0.17110"
"131.70000","8.77873","0.17057"
"131.80000","8.78551","0.16884"
"131.90000","8.79200","0.16812"
"132.00000","8.79845","0.16772"
"132.10000","8.80505","0.16685"
"132.20000","8.81192","0.16588"
"132.30000","8.81872","0.16559"
"132.40000","8.82561","0.16450"
"132.50000","8.83211","0.16365"
"132.60000","8.83846","0.16323"
"132.70000","8.84502","0.16210"
"132.80000","8.85190","0.16214"
"132.90000","8.85898","0.16116"
"133.00000","8.86547","0.16045"
"133.10000","8.87173","0.15880"
"133.20000","8.87859","0.15889"
"133.30000","8.88577","0.15764"
"133.40000","8.89236","0.15651"
"133.50000","8.89848","0.15607"
"133.60000","8.90471","0.15581"
"133.70000","8.91189","0.15529"
"133.70600","8.91232","0.15516"